Config '../configs/rf_kmeans_ft_mobi_cv8.yaml' has no VERSION. Assuming it to be compatible with latest v1.
Config '../configs/rf_kmeans_ft_mobi_cv8.yaml' has no VERSION. Assuming it to be compatible with latest v1.
  0%|          | 0/5 [00:00<?, ?it/s]  0%|          | 0/5 [00:00<?, ?it/s]Config '../configs/rf_kmeans_ft_mobi_cv8.yaml' has no VERSION. Assuming it to be compatible with latest v1.
  0%|          | 0/5 [00:00<?, ?it/s]Config '../configs/rf_kmeans_ft_mobi_cv8.yaml' has no VERSION. Assuming it to be compatible with latest v1.
Config '../configs/rf_kmeans_ft_mobi_cv8.yaml' has no VERSION. Assuming it to be compatible with latest v1.
  0%|          | 0/5 [00:00<?, ?it/s]  0%|          | 0/5 [00:00<?, ?it/s]Config '../configs/rf_kmeans_ft_mobi_cv8.yaml' has no VERSION. Assuming it to be compatible with latest v1.
Config '../configs/rf_kmeans_ft_mobi_cv8.yaml' has no VERSION. Assuming it to be compatible with latest v1.
  0%|          | 0/5 [00:00<?, ?it/s]Config '../configs/rf_kmeans_ft_mobi_cv8.yaml' has no VERSION. Assuming it to be compatible with latest v1.
Config '../configs/rf_kmeans_ft_mobi_cv8.yaml' has no VERSION. Assuming it to be compatible with latest v1.
  0%|          | 0/5 [00:00<?, ?it/s]  0%|          | 0/5 [00:00<?, ?it/s]Config '../configs/rf_kmeans_ft_mobi_cv8.yaml' has no VERSION. Assuming it to be compatible with latest v1.
  0%|          | 0/5 [00:00<?, ?it/s]  0%|          | 0/5 [00:00<?, ?it/s]Config '../configs/rf_kmeans_ft_mobi_cv8.yaml' has no VERSION. Assuming it to be compatible with latest v1.
  0%|          | 0/5 [00:00<?, ?it/s]Config '../configs/rf_kmeans_ft_mobi_cv8.yaml' has no VERSION. Assuming it to be compatible with latest v1.
Config '../configs/rf_kmeans_ft_mobi_cv8.yaml' has no VERSION. Assuming it to be compatible with latest v1.
  0%|          | 0/5 [00:00<?, ?it/s]  0%|          | 0/5 [00:00<?, ?it/s]Config '../configs/rf_kmeans_ft_mobi_cv8.yaml' has no VERSION. Assuming it to be compatible with latest v1.
  0%|          | 0/5 [00:00<?, ?it/s]Config '../configs/rf_kmeans_ft_mobi_cv8.yaml' has no VERSION. Assuming it to be compatible with latest v1.
Config '../configs/rf_kmeans_ft_mobi_cv8.yaml' has no VERSION. Assuming it to be compatible with latest v1.
  0%|          | 0/5 [00:00<?, ?it/s]Config '../configs/rf_kmeans_ft_mobi_cv8.yaml' has no VERSION. Assuming it to be compatible with latest v1.
  0%|          | 0/5 [00:00<?, ?it/s]Config '../configs/rf_kmeans_ft_mobi_cv8.yaml' has no VERSION. Assuming it to be compatible with latest v1.
Config '../configs/rf_kmeans_ft_mobi_cv8.yaml' has no VERSION. Assuming it to be compatible with latest v1.
Config '../configs/rf_kmeans_ft_mobi_cv8.yaml' has no VERSION. Assuming it to be compatible with latest v1.
Config '../configs/rf_kmeans_ft_mobi_cv8.yaml' has no VERSION. Assuming it to be compatible with latest v1.
Config '../configs/rf_kmeans_ft_mobi_cv8.yaml' has no VERSION. Assuming it to be compatible with latest v1.
Config '../configs/rf_kmeans_ft_mobi_cv8.yaml' has no VERSION. Assuming it to be compatible with latest v1.
  0%|          | 0/5 [00:00<?, ?it/s]  0%|          | 0/5 [00:00<?, ?it/s]Config '../configs/rf_kmeans_ft_mobi_cv8.yaml' has no VERSION. Assuming it to be compatible with latest v1.
  0%|          | 0/5 [00:00<?, ?it/s]  0%|          | 0/5 [00:00<?, ?it/s]  0%|          | 0/5 [00:00<?, ?it/s]Config '../configs/rf_kmeans_ft_mobi_cv8.yaml' has no VERSION. Assuming it to be compatible with latest v1.
Config '../configs/rf_kmeans_ft_mobi_cv8.yaml' has no VERSION. Assuming it to be compatible with latest v1.
  0%|          | 0/5 [00:00<?, ?it/s]  0%|          | 0/5 [00:00<?, ?it/s]  0%|          | 0/5 [00:00<?, ?it/s]  0%|          | 0/5 [00:00<?, ?it/s]  0%|          | 0/5 [00:00<?, ?it/s]Config '../configs/rf_kmeans_ft_mobi_cv8.yaml' has no VERSION. Assuming it to be compatible with latest v1.
Config '../configs/rf_kmeans_ft_mobi_cv8.yaml' has no VERSION. Assuming it to be compatible with latest v1.
Config '../configs/rf_kmeans_ft_mobi_cv8.yaml' has no VERSION. Assuming it to be compatible with latest v1.
  0%|          | 0/5 [00:00<?, ?it/s]Config '../configs/rf_kmeans_ft_mobi_cv8.yaml' has no VERSION. Assuming it to be compatible with latest v1.
  0%|          | 0/5 [00:00<?, ?it/s]  0%|          | 0/5 [00:00<?, ?it/s]  0%|          | 0/5 [00:00<?, ?it/s]Config '../configs/rf_kmeans_ft_mobi_cv8.yaml' has no VERSION. Assuming it to be compatible with latest v1.
  0%|          | 0/5 [00:00<?, ?it/s]Config '../configs/rf_kmeans_ft_mobi_cv8.yaml' has no VERSION. Assuming it to be compatible with latest v1.
Config '../configs/rf_kmeans_ft_mobi_cv8.yaml' has no VERSION. Assuming it to be compatible with latest v1.
  0%|          | 0/5 [00:00<?, ?it/s]  0%|          | 0/5 [00:00<?, ?it/s]Config '../configs/rf_kmeans_ft_mobi_cv8.yaml' has no VERSION. Assuming it to be compatible with latest v1.
Config '../configs/rf_kmeans_ft_mobi_cv8.yaml' has no VERSION. Assuming it to be compatible with latest v1.
  0%|          | 0/5 [00:00<?, ?it/s]  0%|          | 0/5 [00:00<?, ?it/s]Config '../configs/rf_kmeans_ft_mobi_cv8.yaml' has no VERSION. Assuming it to be compatible with latest v1.
  0%|          | 0/5 [00:00<?, ?it/s]Config '../configs/rf_kmeans_ft_mobi_cv8.yaml' has no VERSION. Assuming it to be compatible with latest v1.
  0%|          | 0/5 [00:00<?, ?it/s]Config '../configs/rf_kmeans_ft_mobi_cv8.yaml' has no VERSION. Assuming it to be compatible with latest v1.
  0%|          | 0/5 [00:00<?, ?it/s]Config '../configs/rf_kmeans_ft_mobi_cv8.yaml' has no VERSION. Assuming it to be compatible with latest v1.
  0%|          | 0/5 [00:00<?, ?it/s]Config '../configs/rf_kmeans_ft_mobi_cv8.yaml' has no VERSION. Assuming it to be compatible with latest v1.
  0%|          | 0/5 [00:00<?, ?it/s]5 / 22191
3 / 17784
5 / 22191
3 / 17784
5 / 22191
3 / 17784
5 / 22191
3 / 17784
5 / 22191
3 / 17784
5 / 22191
3 / 17784
5 / 22191
3 / 17784
5 / 22191
3 / 17784
5 / 22191
3 / 17784
5 / 22191
3 / 17784
5 / 22191
3 / 17784
5 / 22191
3 / 17784
5 / 22191
3 / 17784
5 / 22191
3 / 17784
5 / 22191
3 / 17784
5 / 22191
3 / 17784
5 / 22191
3 / 17784
5 / 22191
3 / 17784
5 / 22191
3 / 17784
5 / 22191
3 / 17784
5 / 22191
3 / 17784
exception calling callback for <Future at 0x2b497037f190 state=finished raised TerminatedWorkerError>
Traceback (most recent call last):
  File "/home/users/apopescu/anaconda3/envs/detectron2/lib/python3.8/site-packages/joblib/externals/loky/_base.py", line 625, in _invoke_callbacks
    callback(self)
  File "/home/users/apopescu/anaconda3/envs/detectron2/lib/python3.8/site-packages/joblib/parallel.py", line 347, in __call__
    self.parallel.dispatch_next()
  File "/home/users/apopescu/anaconda3/envs/detectron2/lib/python3.8/site-packages/joblib/parallel.py", line 780, in dispatch_next
    if not self.dispatch_one_batch(self._original_iterator):
  File "/home/users/apopescu/anaconda3/envs/detectron2/lib/python3.8/site-packages/joblib/parallel.py", line 847, in dispatch_one_batch
    self._dispatch(tasks)
  File "/home/users/apopescu/anaconda3/envs/detectron2/lib/python3.8/site-packages/joblib/parallel.py", line 765, in _dispatch
    job = self._backend.apply_async(batch, callback=cb)
  File "/home/users/apopescu/anaconda3/envs/detectron2/lib/python3.8/site-packages/joblib/_parallel_backends.py", line 531, in apply_async
    future = self._workers.submit(SafeFunction(func))
  File "/home/users/apopescu/anaconda3/envs/detectron2/lib/python3.8/site-packages/joblib/externals/loky/reusable_executor.py", line 177, in submit
    return super(_ReusablePoolExecutor, self).submit(
  File "/home/users/apopescu/anaconda3/envs/detectron2/lib/python3.8/site-packages/joblib/externals/loky/process_executor.py", line 1102, in submit
    raise self._flags.broken
joblib.externals.loky.process_executor.TerminatedWorkerError: A worker process managed by the executor was unexpectedly terminated. This could be caused by a segmentation fault while calling the function or by an excessive memory usage causing the Operating System to kill the worker.

The exit codes of the workers are {SIGBUS(-7)}
exception calling callback for <Future at 0x2b4970361910 state=finished raised TerminatedWorkerError>
Traceback (most recent call last):
  File "/home/users/apopescu/anaconda3/envs/detectron2/lib/python3.8/site-packages/joblib/externals/loky/_base.py", line 625, in _invoke_callbacks
    callback(self)
  File "/home/users/apopescu/anaconda3/envs/detectron2/lib/python3.8/site-packages/joblib/parallel.py", line 347, in __call__
    self.parallel.dispatch_next()
  File "/home/users/apopescu/anaconda3/envs/detectron2/lib/python3.8/site-packages/joblib/parallel.py", line 780, in dispatch_next
    if not self.dispatch_one_batch(self._original_iterator):
  File "/home/users/apopescu/anaconda3/envs/detectron2/lib/python3.8/site-packages/joblib/parallel.py", line 847, in dispatch_one_batch
    self._dispatch(tasks)
  File "/home/users/apopescu/anaconda3/envs/detectron2/lib/python3.8/site-packages/joblib/parallel.py", line 765, in _dispatch
    job = self._backend.apply_async(batch, callback=cb)
  File "/home/users/apopescu/anaconda3/envs/detectron2/lib/python3.8/site-packages/joblib/_parallel_backends.py", line 531, in apply_async
    future = self._workers.submit(SafeFunction(func))
  File "/home/users/apopescu/anaconda3/envs/detectron2/lib/python3.8/site-packages/joblib/externals/loky/reusable_executor.py", line 177, in submit
    return super(_ReusablePoolExecutor, self).submit(
  File "/home/users/apopescu/anaconda3/envs/detectron2/lib/python3.8/site-packages/joblib/externals/loky/process_executor.py", line 1102, in submit
    raise self._flags.broken
  File "/home/users/apopescu/anaconda3/envs/detectron2/lib/python3.8/site-packages/joblib/externals/loky/_base.py", line 625, in _invoke_callbacks
    callback(self)
  File "/home/users/apopescu/anaconda3/envs/detectron2/lib/python3.8/site-packages/joblib/parallel.py", line 347, in __call__
    self.parallel.dispatch_next()
  File "/home/users/apopescu/anaconda3/envs/detectron2/lib/python3.8/site-packages/joblib/parallel.py", line 780, in dispatch_next
    if not self.dispatch_one_batch(self._original_iterator):
  File "/home/users/apopescu/anaconda3/envs/detectron2/lib/python3.8/site-packages/joblib/parallel.py", line 847, in dispatch_one_batch
    self._dispatch(tasks)
  File "/home/users/apopescu/anaconda3/envs/detectron2/lib/python3.8/site-packages/joblib/parallel.py", line 765, in _dispatch
    job = self._backend.apply_async(batch, callback=cb)
  File "/home/users/apopescu/anaconda3/envs/detectron2/lib/python3.8/site-packages/joblib/_parallel_backends.py", line 531, in apply_async
    future = self._workers.submit(SafeFunction(func))
  File "/home/users/apopescu/anaconda3/envs/detectron2/lib/python3.8/site-packages/joblib/externals/loky/reusable_executor.py", line 177, in submit
    return super(_ReusablePoolExecutor, self).submit(
  File "/home/users/apopescu/anaconda3/envs/detectron2/lib/python3.8/site-packages/joblib/externals/loky/process_executor.py", line 1102, in submit
    raise self._flags.broken
joblib.externals.loky.process_executor.TerminatedWorkerError: A worker process managed by the executor was unexpectedly terminated. This could be caused by a segmentation fault while calling the function or by an excessive memory usage causing the Operating System to kill the worker.

The exit codes of the workers are {SIGBUS(-7)}
exception calling callback for <Future at 0x2b4970361d60 state=finished raised TerminatedWorkerError>
Traceback (most recent call last):
  File "/home/users/apopescu/anaconda3/envs/detectron2/lib/python3.8/site-packages/joblib/externals/loky/_base.py", line 625, in _invoke_callbacks
    callback(self)
  File "/home/users/apopescu/anaconda3/envs/detectron2/lib/python3.8/site-packages/joblib/parallel.py", line 347, in __call__
    self.parallel.dispatch_next()
  File "/home/users/apopescu/anaconda3/envs/detectron2/lib/python3.8/site-packages/joblib/parallel.py", line 780, in dispatch_next
    if not self.dispatch_one_batch(self._original_iterator):
  File "/home/users/apopescu/anaconda3/envs/detectron2/lib/python3.8/site-packages/joblib/parallel.py", line 847, in dispatch_one_batch
    self._dispatch(tasks)
  File "/home/users/apopescu/anaconda3/envs/detectron2/lib/python3.8/site-packages/joblib/parallel.py", line 765, in _dispatch
    job = self._backend.apply_async(batch, callback=cb)
  File "/home/users/apopescu/anaconda3/envs/detectron2/lib/python3.8/site-packages/joblib/_parallel_backends.py", line 531, in apply_async
    future = self._workers.submit(SafeFunction(func))
  File "/home/users/apopescu/anaconda3/envs/detectron2/lib/python3.8/site-packages/joblib/externals/loky/reusable_executor.py", line 177, in submit
    return super(_ReusablePoolExecutor, self).submit(
  File "/home/users/apopescu/anaconda3/envs/detectron2/lib/python3.8/site-packages/joblib/externals/loky/process_executor.py", line 1102, in submit
    raise self._flags.broken
  File "/home/users/apopescu/anaconda3/envs/detectron2/lib/python3.8/site-packages/joblib/externals/loky/_base.py", line 625, in _invoke_callbacks
    callback(self)
  File "/home/users/apopescu/anaconda3/envs/detectron2/lib/python3.8/site-packages/joblib/parallel.py", line 347, in __call__
    self.parallel.dispatch_next()
  File "/home/users/apopescu/anaconda3/envs/detectron2/lib/python3.8/site-packages/joblib/parallel.py", line 780, in dispatch_next
    if not self.dispatch_one_batch(self._original_iterator):
  File "/home/users/apopescu/anaconda3/envs/detectron2/lib/python3.8/site-packages/joblib/parallel.py", line 847, in dispatch_one_batch
    self._dispatch(tasks)
  File "/home/users/apopescu/anaconda3/envs/detectron2/lib/python3.8/site-packages/joblib/parallel.py", line 765, in _dispatch
    job = self._backend.apply_async(batch, callback=cb)
  File "/home/users/apopescu/anaconda3/envs/detectron2/lib/python3.8/site-packages/joblib/_parallel_backends.py", line 531, in apply_async
    future = self._workers.submit(SafeFunction(func))
  File "/home/users/apopescu/anaconda3/envs/detectron2/lib/python3.8/site-packages/joblib/externals/loky/reusable_executor.py", line 177, in submit
    return super(_ReusablePoolExecutor, self).submit(
  File "/home/users/apopescu/anaconda3/envs/detectron2/lib/python3.8/site-packages/joblib/externals/loky/process_executor.py", line 1102, in submit
    raise self._flags.broken
  File "/home/users/apopescu/anaconda3/envs/detectron2/lib/python3.8/site-packages/joblib/externals/loky/_base.py", line 625, in _invoke_callbacks
    callback(self)
  File "/home/users/apopescu/anaconda3/envs/detectron2/lib/python3.8/site-packages/joblib/parallel.py", line 347, in __call__
    self.parallel.dispatch_next()
  File "/home/users/apopescu/anaconda3/envs/detectron2/lib/python3.8/site-packages/joblib/parallel.py", line 780, in dispatch_next
    if not self.dispatch_one_batch(self._original_iterator):
  File "/home/users/apopescu/anaconda3/envs/detectron2/lib/python3.8/site-packages/joblib/parallel.py", line 847, in dispatch_one_batch
    self._dispatch(tasks)
  File "/home/users/apopescu/anaconda3/envs/detectron2/lib/python3.8/site-packages/joblib/parallel.py", line 765, in _dispatch
    job = self._backend.apply_async(batch, callback=cb)
  File "/home/users/apopescu/anaconda3/envs/detectron2/lib/python3.8/site-packages/joblib/_parallel_backends.py", line 531, in apply_async
    future = self._workers.submit(SafeFunction(func))
  File "/home/users/apopescu/anaconda3/envs/detectron2/lib/python3.8/site-packages/joblib/externals/loky/reusable_executor.py", line 177, in submit
    return super(_ReusablePoolExecutor, self).submit(
  File "/home/users/apopescu/anaconda3/envs/detectron2/lib/python3.8/site-packages/joblib/externals/loky/process_executor.py", line 1102, in submit
    raise self._flags.broken
joblib.externals.loky.process_executor.TerminatedWorkerError: A worker process managed by the executor was unexpectedly terminated. This could be caused by a segmentation fault while calling the function or by an excessive memory usage causing the Operating System to kill the worker.

The exit codes of the workers are {SIGBUS(-7)}
exception calling callback for <Future at 0x2b4970361e80 state=finished raised TerminatedWorkerError>
Traceback (most recent call last):
  File "/home/users/apopescu/anaconda3/envs/detectron2/lib/python3.8/site-packages/joblib/externals/loky/_base.py", line 625, in _invoke_callbacks
    callback(self)
  File "/home/users/apopescu/anaconda3/envs/detectron2/lib/python3.8/site-packages/joblib/parallel.py", line 347, in __call__
    self.parallel.dispatch_next()
  File "/home/users/apopescu/anaconda3/envs/detectron2/lib/python3.8/site-packages/joblib/parallel.py", line 780, in dispatch_next
    if not self.dispatch_one_batch(self._original_iterator):
  File "/home/users/apopescu/anaconda3/envs/detectron2/lib/python3.8/site-packages/joblib/parallel.py", line 847, in dispatch_one_batch
    self._dispatch(tasks)
  File "/home/users/apopescu/anaconda3/envs/detectron2/lib/python3.8/site-packages/joblib/parallel.py", line 765, in _dispatch
    job = self._backend.apply_async(batch, callback=cb)
  File "/home/users/apopescu/anaconda3/envs/detectron2/lib/python3.8/site-packages/joblib/_parallel_backends.py", line 531, in apply_async
    future = self._workers.submit(SafeFunction(func))
  File "/home/users/apopescu/anaconda3/envs/detectron2/lib/python3.8/site-packages/joblib/externals/loky/reusable_executor.py", line 177, in submit
    return super(_ReusablePoolExecutor, self).submit(
  File "/home/users/apopescu/anaconda3/envs/detectron2/lib/python3.8/site-packages/joblib/externals/loky/process_executor.py", line 1102, in submit
    raise self._flags.broken
  File "/home/users/apopescu/anaconda3/envs/detectron2/lib/python3.8/site-packages/joblib/externals/loky/_base.py", line 625, in _invoke_callbacks
    callback(self)
  File "/home/users/apopescu/anaconda3/envs/detectron2/lib/python3.8/site-packages/joblib/parallel.py", line 347, in __call__
    self.parallel.dispatch_next()
  File "/home/users/apopescu/anaconda3/envs/detectron2/lib/python3.8/site-packages/joblib/parallel.py", line 780, in dispatch_next
    if not self.dispatch_one_batch(self._original_iterator):
  File "/home/users/apopescu/anaconda3/envs/detectron2/lib/python3.8/site-packages/joblib/parallel.py", line 847, in dispatch_one_batch
    self._dispatch(tasks)
  File "/home/users/apopescu/anaconda3/envs/detectron2/lib/python3.8/site-packages/joblib/parallel.py", line 765, in _dispatch
    job = self._backend.apply_async(batch, callback=cb)
  File "/home/users/apopescu/anaconda3/envs/detectron2/lib/python3.8/site-packages/joblib/_parallel_backends.py", line 531, in apply_async
    future = self._workers.submit(SafeFunction(func))
  File "/home/users/apopescu/anaconda3/envs/detectron2/lib/python3.8/site-packages/joblib/externals/loky/reusable_executor.py", line 177, in submit
    return super(_ReusablePoolExecutor, self).submit(
  File "/home/users/apopescu/anaconda3/envs/detectron2/lib/python3.8/site-packages/joblib/externals/loky/process_executor.py", line 1102, in submit
    raise self._flags.broken
  File "/home/users/apopescu/anaconda3/envs/detectron2/lib/python3.8/site-packages/joblib/externals/loky/_base.py", line 625, in _invoke_callbacks
    callback(self)
  File "/home/users/apopescu/anaconda3/envs/detectron2/lib/python3.8/site-packages/joblib/parallel.py", line 347, in __call__
    self.parallel.dispatch_next()
  File "/home/users/apopescu/anaconda3/envs/detectron2/lib/python3.8/site-packages/joblib/parallel.py", line 780, in dispatch_next
    if not self.dispatch_one_batch(self._original_iterator):
  File "/home/users/apopescu/anaconda3/envs/detectron2/lib/python3.8/site-packages/joblib/parallel.py", line 847, in dispatch_one_batch
    self._dispatch(tasks)
  File "/home/users/apopescu/anaconda3/envs/detectron2/lib/python3.8/site-packages/joblib/parallel.py", line 765, in _dispatch
    job = self._backend.apply_async(batch, callback=cb)
  File "/home/users/apopescu/anaconda3/envs/detectron2/lib/python3.8/site-packages/joblib/_parallel_backends.py", line 531, in apply_async
    future = self._workers.submit(SafeFunction(func))
  File "/home/users/apopescu/anaconda3/envs/detectron2/lib/python3.8/site-packages/joblib/externals/loky/reusable_executor.py", line 177, in submit
    return super(_ReusablePoolExecutor, self).submit(
  File "/home/users/apopescu/anaconda3/envs/detectron2/lib/python3.8/site-packages/joblib/externals/loky/process_executor.py", line 1102, in submit
    raise self._flags.broken
  File "/home/users/apopescu/anaconda3/envs/detectron2/lib/python3.8/site-packages/joblib/externals/loky/_base.py", line 625, in _invoke_callbacks
    callback(self)
  File "/home/users/apopescu/anaconda3/envs/detectron2/lib/python3.8/site-packages/joblib/parallel.py", line 347, in __call__
    self.parallel.dispatch_next()
  File "/home/users/apopescu/anaconda3/envs/detectron2/lib/python3.8/site-packages/joblib/parallel.py", line 780, in dispatch_next
    if not self.dispatch_one_batch(self._original_iterator):
  File "/home/users/apopescu/anaconda3/envs/detectron2/lib/python3.8/site-packages/joblib/parallel.py", line 847, in dispatch_one_batch
    self._dispatch(tasks)
  File "/home/users/apopescu/anaconda3/envs/detectron2/lib/python3.8/site-packages/joblib/parallel.py", line 765, in _dispatch
    job = self._backend.apply_async(batch, callback=cb)
  File "/home/users/apopescu/anaconda3/envs/detectron2/lib/python3.8/site-packages/joblib/_parallel_backends.py", line 531, in apply_async
    future = self._workers.submit(SafeFunction(func))
  File "/home/users/apopescu/anaconda3/envs/detectron2/lib/python3.8/site-packages/joblib/externals/loky/reusable_executor.py", line 177, in submit
    return super(_ReusablePoolExecutor, self).submit(
  File "/home/users/apopescu/anaconda3/envs/detectron2/lib/python3.8/site-packages/joblib/externals/loky/process_executor.py", line 1102, in submit
    raise self._flags.broken
joblib.externals.loky.process_executor.TerminatedWorkerError: A worker process managed by the executor was unexpectedly terminated. This could be caused by a segmentation fault while calling the function or by an excessive memory usage causing the Operating System to kill the worker.

The exit codes of the workers are {SIGBUS(-7)}
5 / 22191
3 / 17784
5 / 22191
3 / 17784
5 / 22191
3 / 17784
5 / 22191
3 / 17784
5 / 22191
3 / 17784
5 / 22191
3 / 17784
exception calling callback for <Future at 0x2b3353a35190 state=finished raised TerminatedWorkerError>
Traceback (most recent call last):
  File "/home/users/apopescu/anaconda3/envs/detectron2/lib/python3.8/site-packages/joblib/externals/loky/_base.py", line 625, in _invoke_callbacks
    callback(self)
  File "/home/users/apopescu/anaconda3/envs/detectron2/lib/python3.8/site-packages/joblib/parallel.py", line 347, in __call__
    self.parallel.dispatch_next()
  File "/home/users/apopescu/anaconda3/envs/detectron2/lib/python3.8/site-packages/joblib/parallel.py", line 780, in dispatch_next
    if not self.dispatch_one_batch(self._original_iterator):
  File "/home/users/apopescu/anaconda3/envs/detectron2/lib/python3.8/site-packages/joblib/parallel.py", line 847, in dispatch_one_batch
    self._dispatch(tasks)
  File "/home/users/apopescu/anaconda3/envs/detectron2/lib/python3.8/site-packages/joblib/parallel.py", line 765, in _dispatch
    job = self._backend.apply_async(batch, callback=cb)
  File "/home/users/apopescu/anaconda3/envs/detectron2/lib/python3.8/site-packages/joblib/_parallel_backends.py", line 531, in apply_async
    future = self._workers.submit(SafeFunction(func))
  File "/home/users/apopescu/anaconda3/envs/detectron2/lib/python3.8/site-packages/joblib/externals/loky/reusable_executor.py", line 177, in submit
    return super(_ReusablePoolExecutor, self).submit(
  File "/home/users/apopescu/anaconda3/envs/detectron2/lib/python3.8/site-packages/joblib/externals/loky/process_executor.py", line 1102, in submit
    raise self._flags.broken
joblib.externals.loky.process_executor.TerminatedWorkerError: A worker process managed by the executor was unexpectedly terminated. This could be caused by a segmentation fault while calling the function or by an excessive memory usage causing the Operating System to kill the worker.

The exit codes of the workers are {SIGBUS(-7)}
5 / 22191
3 / 17784
  0%|          | 0/5 [00:56<?, ?it/s]
5 / 22191
3 / 17784
5 / 22191
3 / 17784
5 / 22191
3 / 17784
5 / 22191
3 / 17784
5 / 22191
3 / 17784
5 / 22191
3 / 17784
5 / 22191
3 / 17784
5 / 22191
3 / 17784
5 / 22191
3 / 17784
5 / 22191
3 / 17784
5 / 22191
3 / 17784
exception calling callback for <Future at 0x2ad2c9568190 state=finished raised TerminatedWorkerError>
Traceback (most recent call last):
  File "/home/users/apopescu/anaconda3/envs/detectron2/lib/python3.8/site-packages/joblib/externals/loky/_base.py", line 625, in _invoke_callbacks
    callback(self)
  File "/home/users/apopescu/anaconda3/envs/detectron2/lib/python3.8/site-packages/joblib/parallel.py", line 347, in __call__
    self.parallel.dispatch_next()
  File "/home/users/apopescu/anaconda3/envs/detectron2/lib/python3.8/site-packages/joblib/parallel.py", line 780, in dispatch_next
    if not self.dispatch_one_batch(self._original_iterator):
  File "/home/users/apopescu/anaconda3/envs/detectron2/lib/python3.8/site-packages/joblib/parallel.py", line 847, in dispatch_one_batch
    self._dispatch(tasks)
  File "/home/users/apopescu/anaconda3/envs/detectron2/lib/python3.8/site-packages/joblib/parallel.py", line 765, in _dispatch
    job = self._backend.apply_async(batch, callback=cb)
  File "/home/users/apopescu/anaconda3/envs/detectron2/lib/python3.8/site-packages/joblib/_parallel_backends.py", line 531, in apply_async
    future = self._workers.submit(SafeFunction(func))
  File "/home/users/apopescu/anaconda3/envs/detectron2/lib/python3.8/site-packages/joblib/externals/loky/reusable_executor.py", line 177, in submit
    return super(_ReusablePoolExecutor, self).submit(
  File "/home/users/apopescu/anaconda3/envs/detectron2/lib/python3.8/site-packages/joblib/externals/loky/process_executor.py", line 1102, in submit
    raise self._flags.broken
joblib.externals.loky.process_executor.TerminatedWorkerError: A worker process managed by the executor was unexpectedly terminated. This could be caused by a segmentation fault while calling the function or by an excessive memory usage causing the Operating System to kill the worker.

The exit codes of the workers are {SIGBUS(-7)}
exception calling callback for <Future at 0x2ad5f29f3190 state=finished raised TerminatedWorkerError>
Traceback (most recent call last):
  File "/home/users/apopescu/anaconda3/envs/detectron2/lib/python3.8/site-packages/joblib/externals/loky/_base.py", line 625, in _invoke_callbacks
    callback(self)
  File "/home/users/apopescu/anaconda3/envs/detectron2/lib/python3.8/site-packages/joblib/parallel.py", line 347, in __call__
    self.parallel.dispatch_next()
  File "/home/users/apopescu/anaconda3/envs/detectron2/lib/python3.8/site-packages/joblib/parallel.py", line 780, in dispatch_next
    if not self.dispatch_one_batch(self._original_iterator):
  File "/home/users/apopescu/anaconda3/envs/detectron2/lib/python3.8/site-packages/joblib/parallel.py", line 847, in dispatch_one_batch
    self._dispatch(tasks)
  File "/home/users/apopescu/anaconda3/envs/detectron2/lib/python3.8/site-packages/joblib/parallel.py", line 765, in _dispatch
    job = self._backend.apply_async(batch, callback=cb)
  File "/home/users/apopescu/anaconda3/envs/detectron2/lib/python3.8/site-packages/joblib/_parallel_backends.py", line 531, in apply_async
    future = self._workers.submit(SafeFunction(func))
  File "/home/users/apopescu/anaconda3/envs/detectron2/lib/python3.8/site-packages/joblib/externals/loky/reusable_executor.py", line 177, in submit
    return super(_ReusablePoolExecutor, self).submit(
  File "/home/users/apopescu/anaconda3/envs/detectron2/lib/python3.8/site-packages/joblib/externals/loky/process_executor.py", line 1102, in submit
    raise self._flags.broken
joblib.externals.loky.process_executor.TerminatedWorkerError: A worker process managed by the executor was unexpectedly terminated. This could be caused by a segmentation fault while calling the function or by an excessive memory usage causing the Operating System to kill the worker.

The exit codes of the workers are {SIGBUS(-7)}
exception calling callback for <Future at 0x2af9f82ff190 state=finished raised TerminatedWorkerError>
Traceback (most recent call last):
  File "/home/users/apopescu/anaconda3/envs/detectron2/lib/python3.8/site-packages/joblib/externals/loky/_base.py", line 625, in _invoke_callbacks
    callback(self)
  File "/home/users/apopescu/anaconda3/envs/detectron2/lib/python3.8/site-packages/joblib/parallel.py", line 347, in __call__
    self.parallel.dispatch_next()
  File "/home/users/apopescu/anaconda3/envs/detectron2/lib/python3.8/site-packages/joblib/parallel.py", line 780, in dispatch_next
    if not self.dispatch_one_batch(self._original_iterator):
  File "/home/users/apopescu/anaconda3/envs/detectron2/lib/python3.8/site-packages/joblib/parallel.py", line 847, in dispatch_one_batch
    self._dispatch(tasks)
  File "/home/users/apopescu/anaconda3/envs/detectron2/lib/python3.8/site-packages/joblib/parallel.py", line 765, in _dispatch
    job = self._backend.apply_async(batch, callback=cb)
  File "/home/users/apopescu/anaconda3/envs/detectron2/lib/python3.8/site-packages/joblib/_parallel_backends.py", line 531, in apply_async
    future = self._workers.submit(SafeFunction(func))
  File "/home/users/apopescu/anaconda3/envs/detectron2/lib/python3.8/site-packages/joblib/externals/loky/reusable_executor.py", line 177, in submit
    return super(_ReusablePoolExecutor, self).submit(
  File "/home/users/apopescu/anaconda3/envs/detectron2/lib/python3.8/site-packages/joblib/externals/loky/process_executor.py", line 1102, in submit
    raise self._flags.broken
joblib.externals.loky.process_executor.TerminatedWorkerError: A worker process managed by the executor was unexpectedly terminated. This could be caused by a segmentation fault while calling the function or by an excessive memory usage causing the Operating System to kill the worker.

The exit codes of the workers are {SIGBUS(-7)}
  0%|          | 0/5 [01:06<?, ?it/s]
Traceback (most recent call last):
  File "ft_official.py", line 118, in <module>
    main()
  File "ft_official.py", line 100, in main
    model.train_vispel()
  File "/home/users/apopescu/van-khoa/Vis-Priva-Expos/privacy/vispel/vispel/vispel.py", line 54, in train_vispel
    trained_clusteror, trained_regressor, feature_selector = trainer(self.situation, self.X_train, self.X_community,\
  File "/home/users/apopescu/van-khoa/Vis-Priva-Expos/privacy/vispel/vispel/trainer.py", line 64, in trainer
    trained_regressor = train_regressor(regressor, X_train_rd, gt_train_expos, cfg)
  File "/home/users/apopescu/van-khoa/Vis-Priva-Expos/privacy/lib/regressor/regression.py", line 22, in train_regressor
    model.fit(x_train, y_train)
  File "/home/users/apopescu/anaconda3/envs/detectron2/lib/python3.8/site-packages/sklearn/utils/validation.py", line 73, in inner_f
    return f(**kwargs)
  File "/home/users/apopescu/anaconda3/envs/detectron2/lib/python3.8/site-packages/sklearn/model_selection/_search.py", line 736, in fit
    self._run_search(evaluate_candidates)
  File "/home/users/apopescu/anaconda3/envs/detectron2/lib/python3.8/site-packages/sklearn/model_selection/_search.py", line 1188, in _run_search
    evaluate_candidates(ParameterGrid(self.param_grid))
  File "/home/users/apopescu/anaconda3/envs/detectron2/lib/python3.8/site-packages/sklearn/model_selection/_search.py", line 708, in evaluate_candidates
    out = parallel(delayed(_fit_and_score)(clone(base_estimator),
  File "/home/users/apopescu/anaconda3/envs/detectron2/lib/python3.8/site-packages/joblib/parallel.py", line 1042, in __call__
    self.retrieve()
  File "/home/users/apopescu/anaconda3/envs/detectron2/lib/python3.8/site-packages/joblib/parallel.py", line 921, in retrieve
    self._output.extend(job.get(timeout=self.timeout))
  File "/home/users/apopescu/anaconda3/envs/detectron2/lib/python3.8/site-packages/joblib/_parallel_backends.py", line 542, in wrap_future_result
    return future.result(timeout=timeout)
  File "/home/users/apopescu/anaconda3/envs/detectron2/lib/python3.8/concurrent/futures/_base.py", line 439, in result
    return self.__get_result()
  File "/home/users/apopescu/anaconda3/envs/detectron2/lib/python3.8/concurrent/futures/_base.py", line 388, in __get_result
    raise self._exception
  File "/home/users/apopescu/anaconda3/envs/detectron2/lib/python3.8/site-packages/joblib/externals/loky/_base.py", line 625, in _invoke_callbacks
    callback(self)
  File "/home/users/apopescu/anaconda3/envs/detectron2/lib/python3.8/site-packages/joblib/parallel.py", line 347, in __call__
    self.parallel.dispatch_next()
  File "/home/users/apopescu/anaconda3/envs/detectron2/lib/python3.8/site-packages/joblib/parallel.py", line 780, in dispatch_next
    if not self.dispatch_one_batch(self._original_iterator):
  File "/home/users/apopescu/anaconda3/envs/detectron2/lib/python3.8/site-packages/joblib/parallel.py", line 847, in dispatch_one_batch
    self._dispatch(tasks)
  File "/home/users/apopescu/anaconda3/envs/detectron2/lib/python3.8/site-packages/joblib/parallel.py", line 765, in _dispatch
    job = self._backend.apply_async(batch, callback=cb)
  File "/home/users/apopescu/anaconda3/envs/detectron2/lib/python3.8/site-packages/joblib/_parallel_backends.py", line 531, in apply_async
    future = self._workers.submit(SafeFunction(func))
  File "/home/users/apopescu/anaconda3/envs/detectron2/lib/python3.8/site-packages/joblib/externals/loky/reusable_executor.py", line 177, in submit
    return super(_ReusablePoolExecutor, self).submit(
  File "/home/users/apopescu/anaconda3/envs/detectron2/lib/python3.8/site-packages/joblib/externals/loky/process_executor.py", line 1102, in submit
    raise self._flags.broken
  File "/home/users/apopescu/anaconda3/envs/detectron2/lib/python3.8/site-packages/joblib/externals/loky/_base.py", line 625, in _invoke_callbacks
    callback(self)
  File "/home/users/apopescu/anaconda3/envs/detectron2/lib/python3.8/site-packages/joblib/parallel.py", line 347, in __call__
    self.parallel.dispatch_next()
  File "/home/users/apopescu/anaconda3/envs/detectron2/lib/python3.8/site-packages/joblib/parallel.py", line 780, in dispatch_next
    if not self.dispatch_one_batch(self._original_iterator):
  File "/home/users/apopescu/anaconda3/envs/detectron2/lib/python3.8/site-packages/joblib/parallel.py", line 847, in dispatch_one_batch
    self._dispatch(tasks)
  File "/home/users/apopescu/anaconda3/envs/detectron2/lib/python3.8/site-packages/joblib/parallel.py", line 765, in _dispatch
    job = self._backend.apply_async(batch, callback=cb)
  File "/home/users/apopescu/anaconda3/envs/detectron2/lib/python3.8/site-packages/joblib/_parallel_backends.py", line 531, in apply_async
    future = self._workers.submit(SafeFunction(func))
  File "/home/users/apopescu/anaconda3/envs/detectron2/lib/python3.8/site-packages/joblib/externals/loky/reusable_executor.py", line 177, in submit
    return super(_ReusablePoolExecutor, self).submit(
  File "/home/users/apopescu/anaconda3/envs/detectron2/lib/python3.8/site-packages/joblib/externals/loky/process_executor.py", line 1102, in submit
    raise self._flags.broken
  File "/home/users/apopescu/anaconda3/envs/detectron2/lib/python3.8/site-packages/joblib/externals/loky/_base.py", line 625, in _invoke_callbacks
    callback(self)
  File "/home/users/apopescu/anaconda3/envs/detectron2/lib/python3.8/site-packages/joblib/parallel.py", line 347, in __call__
    self.parallel.dispatch_next()
  File "/home/users/apopescu/anaconda3/envs/detectron2/lib/python3.8/site-packages/joblib/parallel.py", line 780, in dispatch_next
    if not self.dispatch_one_batch(self._original_iterator):
  File "/home/users/apopescu/anaconda3/envs/detectron2/lib/python3.8/site-packages/joblib/parallel.py", line 847, in dispatch_one_batch
    self._dispatch(tasks)
  File "/home/users/apopescu/anaconda3/envs/detectron2/lib/python3.8/site-packages/joblib/parallel.py", line 765, in _dispatch
    job = self._backend.apply_async(batch, callback=cb)
  File "/home/users/apopescu/anaconda3/envs/detectron2/lib/python3.8/site-packages/joblib/_parallel_backends.py", line 531, in apply_async
    future = self._workers.submit(SafeFunction(func))
  File "/home/users/apopescu/anaconda3/envs/detectron2/lib/python3.8/site-packages/joblib/externals/loky/reusable_executor.py", line 177, in submit
    return super(_ReusablePoolExecutor, self).submit(
  File "/home/users/apopescu/anaconda3/envs/detectron2/lib/python3.8/site-packages/joblib/externals/loky/process_executor.py", line 1102, in submit
    raise self._flags.broken
  File "/home/users/apopescu/anaconda3/envs/detectron2/lib/python3.8/site-packages/joblib/externals/loky/_base.py", line 625, in _invoke_callbacks
    callback(self)
  File "/home/users/apopescu/anaconda3/envs/detectron2/lib/python3.8/site-packages/joblib/parallel.py", line 347, in __call__
    self.parallel.dispatch_next()
  File "/home/users/apopescu/anaconda3/envs/detectron2/lib/python3.8/site-packages/joblib/parallel.py", line 780, in dispatch_next
    if not self.dispatch_one_batch(self._original_iterator):
  File "/home/users/apopescu/anaconda3/envs/detectron2/lib/python3.8/site-packages/joblib/parallel.py", line 847, in dispatch_one_batch
    self._dispatch(tasks)
  File "/home/users/apopescu/anaconda3/envs/detectron2/lib/python3.8/site-packages/joblib/parallel.py", line 765, in _dispatch
    job = self._backend.apply_async(batch, callback=cb)
  File "/home/users/apopescu/anaconda3/envs/detectron2/lib/python3.8/site-packages/joblib/_parallel_backends.py", line 531, in apply_async
    future = self._workers.submit(SafeFunction(func))
  File "/home/users/apopescu/anaconda3/envs/detectron2/lib/python3.8/site-packages/joblib/externals/loky/reusable_executor.py", line 177, in submit
    return super(_ReusablePoolExecutor, self).submit(
  File "/home/users/apopescu/anaconda3/envs/detectron2/lib/python3.8/site-packages/joblib/externals/loky/process_executor.py", line 1102, in submit
    raise self._flags.broken
joblib.externals.loky.process_executor.TerminatedWorkerError: A worker process managed by the executor was unexpectedly terminated. This could be caused by a segmentation fault while calling the function or by an excessive memory usage causing the Operating System to kill the worker.

The exit codes of the workers are {SIGBUS(-7)}
Traceback (most recent call last):
  File "ft_official.py", line 118, in <module>
    main()
  File "ft_official.py", line 100, in main
    model.train_vispel()
  File "/home/users/apopescu/van-khoa/Vis-Priva-Expos/privacy/vispel/vispel/vispel.py", line 54, in train_vispel
    trained_clusteror, trained_regressor, feature_selector = trainer(self.situation, self.X_train, self.X_community,\
  File "/home/users/apopescu/van-khoa/Vis-Priva-Expos/privacy/vispel/vispel/trainer.py", line 64, in trainer
    trained_regressor = train_regressor(regressor, X_train_rd, gt_train_expos, cfg)
  File "/home/users/apopescu/van-khoa/Vis-Priva-Expos/privacy/lib/regressor/regression.py", line 22, in train_regressor
    model.fit(x_train, y_train)
  File "/home/users/apopescu/anaconda3/envs/detectron2/lib/python3.8/site-packages/sklearn/utils/validation.py", line 73, in inner_f
    return f(**kwargs)
  File "/home/users/apopescu/anaconda3/envs/detectron2/lib/python3.8/site-packages/sklearn/model_selection/_search.py", line 736, in fit
    self._run_search(evaluate_candidates)
  File "/home/users/apopescu/anaconda3/envs/detectron2/lib/python3.8/site-packages/sklearn/model_selection/_search.py", line 1188, in _run_search
    evaluate_candidates(ParameterGrid(self.param_grid))
  File "/home/users/apopescu/anaconda3/envs/detectron2/lib/python3.8/site-packages/sklearn/model_selection/_search.py", line 708, in evaluate_candidates
    out = parallel(delayed(_fit_and_score)(clone(base_estimator),
  File "/home/users/apopescu/anaconda3/envs/detectron2/lib/python3.8/site-packages/joblib/parallel.py", line 1042, in __call__
    self.retrieve()
  File "/home/users/apopescu/anaconda3/envs/detectron2/lib/python3.8/site-packages/joblib/parallel.py", line 921, in retrieve
    self._output.extend(job.get(timeout=self.timeout))
  File "/home/users/apopescu/anaconda3/envs/detectron2/lib/python3.8/site-packages/joblib/_parallel_backends.py", line 542, in wrap_future_result
    return future.result(timeout=timeout)
  File "/home/users/apopescu/anaconda3/envs/detectron2/lib/python3.8/concurrent/futures/_base.py", line 439, in result
    return self.__get_result()
  File "/home/users/apopescu/anaconda3/envs/detectron2/lib/python3.8/concurrent/futures/_base.py", line 388, in __get_result
    raise self._exception
  File "/home/users/apopescu/anaconda3/envs/detectron2/lib/python3.8/site-packages/joblib/externals/loky/_base.py", line 625, in _invoke_callbacks
    callback(self)
  File "/home/users/apopescu/anaconda3/envs/detectron2/lib/python3.8/site-packages/joblib/parallel.py", line 347, in __call__
    self.parallel.dispatch_next()
  File "/home/users/apopescu/anaconda3/envs/detectron2/lib/python3.8/site-packages/joblib/parallel.py", line 780, in dispatch_next
    if not self.dispatch_one_batch(self._original_iterator):
  File "/home/users/apopescu/anaconda3/envs/detectron2/lib/python3.8/site-packages/joblib/parallel.py", line 847, in dispatch_one_batch
    self._dispatch(tasks)
  File "/home/users/apopescu/anaconda3/envs/detectron2/lib/python3.8/site-packages/joblib/parallel.py", line 765, in _dispatch
    job = self._backend.apply_async(batch, callback=cb)
  File "/home/users/apopescu/anaconda3/envs/detectron2/lib/python3.8/site-packages/joblib/_parallel_backends.py", line 531, in apply_async
    future = self._workers.submit(SafeFunction(func))
  File "/home/users/apopescu/anaconda3/envs/detectron2/lib/python3.8/site-packages/joblib/externals/loky/reusable_executor.py", line 177, in submit
    return super(_ReusablePoolExecutor, self).submit(
  File "/home/users/apopescu/anaconda3/envs/detectron2/lib/python3.8/site-packages/joblib/externals/loky/process_executor.py", line 1102, in submit
    raise self._flags.broken
joblib.externals.loky.process_executor.TerminatedWorkerError: A worker process managed by the executor was unexpectedly terminated. This could be caused by a segmentation fault while calling the function or by an excessive memory usage causing the Operating System to kill the worker.

The exit codes of the workers are {SIGBUS(-7)}
  0%|          | 0/5 [01:19<?, ?it/s]
  0%|          | 0/5 [01:15<?, ?it/s]
  0%|          | 0/5 [01:19<?, ?it/s]
/home/users/apopescu/anaconda3/envs/detectron2/lib/python3.8/site-packages/joblib/externals/loky/backend/resource_tracker.py:120: UserWarning: resource_tracker: process died unexpectedly, relaunching.  Some folders/sempahores might leak.
  warnings.warn('resource_tracker: process died unexpectedly, '
  0%|          | 0/5 [01:17<?, ?it/s]
Traceback (most recent call last):
  File "ft_official.py", line 118, in <module>
    main()
  File "ft_official.py", line 100, in main
    model.train_vispel()
  File "/home/users/apopescu/van-khoa/Vis-Priva-Expos/privacy/vispel/vispel/vispel.py", line 54, in train_vispel
    trained_clusteror, trained_regressor, feature_selector = trainer(self.situation, self.X_train, self.X_community,\
  File "/home/users/apopescu/van-khoa/Vis-Priva-Expos/privacy/vispel/vispel/trainer.py", line 64, in trainer
    trained_regressor = train_regressor(regressor, X_train_rd, gt_train_expos, cfg)
  File "/home/users/apopescu/van-khoa/Vis-Priva-Expos/privacy/lib/regressor/regression.py", line 22, in train_regressor
    model.fit(x_train, y_train)
  File "/home/users/apopescu/anaconda3/envs/detectron2/lib/python3.8/site-packages/sklearn/utils/validation.py", line 73, in inner_f
    return f(**kwargs)
  File "/home/users/apopescu/anaconda3/envs/detectron2/lib/python3.8/site-packages/sklearn/model_selection/_search.py", line 736, in fit
    self._run_search(evaluate_candidates)
  File "/home/users/apopescu/anaconda3/envs/detectron2/lib/python3.8/site-packages/sklearn/model_selection/_search.py", line 1188, in _run_search
    evaluate_candidates(ParameterGrid(self.param_grid))
  File "/home/users/apopescu/anaconda3/envs/detectron2/lib/python3.8/site-packages/sklearn/model_selection/_search.py", line 708, in evaluate_candidates
    out = parallel(delayed(_fit_and_score)(clone(base_estimator),
  File "/home/users/apopescu/anaconda3/envs/detectron2/lib/python3.8/site-packages/joblib/parallel.py", line 1042, in __call__
    self.retrieve()
  File "/home/users/apopescu/anaconda3/envs/detectron2/lib/python3.8/site-packages/joblib/parallel.py", line 921, in retrieve
    self._output.extend(job.get(timeout=self.timeout))
  File "/home/users/apopescu/anaconda3/envs/detectron2/lib/python3.8/site-packages/joblib/_parallel_backends.py", line 542, in wrap_future_result
    return future.result(timeout=timeout)
  File "/home/users/apopescu/anaconda3/envs/detectron2/lib/python3.8/concurrent/futures/_base.py", line 439, in result
    return self.__get_result()
  File "/home/users/apopescu/anaconda3/envs/detectron2/lib/python3.8/concurrent/futures/_base.py", line 388, in __get_result
    raise self._exception
  File "/home/users/apopescu/anaconda3/envs/detectron2/lib/python3.8/site-packages/joblib/externals/loky/_base.py", line 625, in _invoke_callbacks
    callback(self)
  File "/home/users/apopescu/anaconda3/envs/detectron2/lib/python3.8/site-packages/joblib/parallel.py", line 347, in __call__
    self.parallel.dispatch_next()
  File "/home/users/apopescu/anaconda3/envs/detectron2/lib/python3.8/site-packages/joblib/parallel.py", line 780, in dispatch_next
    if not self.dispatch_one_batch(self._original_iterator):
  File "/home/users/apopescu/anaconda3/envs/detectron2/lib/python3.8/site-packages/joblib/parallel.py", line 847, in dispatch_one_batch
    self._dispatch(tasks)
  File "/home/users/apopescu/anaconda3/envs/detectron2/lib/python3.8/site-packages/joblib/parallel.py", line 765, in _dispatch
    job = self._backend.apply_async(batch, callback=cb)
  File "/home/users/apopescu/anaconda3/envs/detectron2/lib/python3.8/site-packages/joblib/_parallel_backends.py", line 531, in apply_async
    future = self._workers.submit(SafeFunction(func))
  File "/home/users/apopescu/anaconda3/envs/detectron2/lib/python3.8/site-packages/joblib/externals/loky/reusable_executor.py", line 177, in submit
    return super(_ReusablePoolExecutor, self).submit(
  File "/home/users/apopescu/anaconda3/envs/detectron2/lib/python3.8/site-packages/joblib/externals/loky/process_executor.py", line 1102, in submit
    raise self._flags.broken
joblib.externals.loky.process_executor.TerminatedWorkerError: A worker process managed by the executor was unexpectedly terminated. This could be caused by a segmentation fault while calling the function or by an excessive memory usage causing the Operating System to kill the worker.

The exit codes of the workers are {SIGBUS(-7)}
Traceback (most recent call last):
  File "ft_official.py", line 118, in <module>
    main()
  File "ft_official.py", line 100, in main
    model.train_vispel()
  File "/home/users/apopescu/van-khoa/Vis-Priva-Expos/privacy/vispel/vispel/vispel.py", line 54, in train_vispel
    trained_clusteror, trained_regressor, feature_selector = trainer(self.situation, self.X_train, self.X_community,\
  File "/home/users/apopescu/van-khoa/Vis-Priva-Expos/privacy/vispel/vispel/trainer.py", line 64, in trainer
    trained_regressor = train_regressor(regressor, X_train_rd, gt_train_expos, cfg)
  File "/home/users/apopescu/van-khoa/Vis-Priva-Expos/privacy/lib/regressor/regression.py", line 22, in train_regressor
    model.fit(x_train, y_train)
  File "/home/users/apopescu/anaconda3/envs/detectron2/lib/python3.8/site-packages/sklearn/utils/validation.py", line 73, in inner_f
    return f(**kwargs)
  File "/home/users/apopescu/anaconda3/envs/detectron2/lib/python3.8/site-packages/sklearn/model_selection/_search.py", line 736, in fit
    self._run_search(evaluate_candidates)
  File "/home/users/apopescu/anaconda3/envs/detectron2/lib/python3.8/site-packages/sklearn/model_selection/_search.py", line 1188, in _run_search
    evaluate_candidates(ParameterGrid(self.param_grid))
  File "/home/users/apopescu/anaconda3/envs/detectron2/lib/python3.8/site-packages/sklearn/model_selection/_search.py", line 708, in evaluate_candidates
    out = parallel(delayed(_fit_and_score)(clone(base_estimator),
  File "/home/users/apopescu/anaconda3/envs/detectron2/lib/python3.8/site-packages/joblib/parallel.py", line 1042, in __call__
    self.retrieve()
  File "/home/users/apopescu/anaconda3/envs/detectron2/lib/python3.8/site-packages/joblib/parallel.py", line 921, in retrieve
    self._output.extend(job.get(timeout=self.timeout))
  File "/home/users/apopescu/anaconda3/envs/detectron2/lib/python3.8/site-packages/joblib/_parallel_backends.py", line 542, in wrap_future_result
    return future.result(timeout=timeout)
  File "/home/users/apopescu/anaconda3/envs/detectron2/lib/python3.8/concurrent/futures/_base.py", line 439, in result
    return self.__get_result()
  File "/home/users/apopescu/anaconda3/envs/detectron2/lib/python3.8/concurrent/futures/_base.py", line 388, in __get_result
    raise self._exception
  File "/home/users/apopescu/anaconda3/envs/detectron2/lib/python3.8/site-packages/joblib/externals/loky/_base.py", line 625, in _invoke_callbacks
    callback(self)
  File "/home/users/apopescu/anaconda3/envs/detectron2/lib/python3.8/site-packages/joblib/parallel.py", line 347, in __call__
    self.parallel.dispatch_next()
  File "/home/users/apopescu/anaconda3/envs/detectron2/lib/python3.8/site-packages/joblib/parallel.py", line 780, in dispatch_next
    if not self.dispatch_one_batch(self._original_iterator):
  File "/home/users/apopescu/anaconda3/envs/detectron2/lib/python3.8/site-packages/joblib/parallel.py", line 847, in dispatch_one_batch
    self._dispatch(tasks)
  File "/home/users/apopescu/anaconda3/envs/detectron2/lib/python3.8/site-packages/joblib/parallel.py", line 765, in _dispatch
    job = self._backend.apply_async(batch, callback=cb)
  File "/home/users/apopescu/anaconda3/envs/detectron2/lib/python3.8/site-packages/joblib/_parallel_backends.py", line 531, in apply_async
    future = self._workers.submit(SafeFunction(func))
  File "/home/users/apopescu/anaconda3/envs/detectron2/lib/python3.8/site-packages/joblib/externals/loky/reusable_executor.py", line 177, in submit
    return super(_ReusablePoolExecutor, self).submit(
  File "/home/users/apopescu/anaconda3/envs/detectron2/lib/python3.8/site-packages/joblib/externals/loky/process_executor.py", line 1102, in submit
    raise self._flags.broken
joblib.externals.loky.process_executor.TerminatedWorkerError: A worker process managed by the executor was unexpectedly terminated. This could be caused by a segmentation fault while calling the function or by an excessive memory usage causing the Operating System to kill the worker.

The exit codes of the workers are {SIGBUS(-7)}
Traceback (most recent call last):
  File "ft_official.py", line 118, in <module>
    main()
  File "ft_official.py", line 100, in main
    model.train_vispel()
  File "/home/users/apopescu/van-khoa/Vis-Priva-Expos/privacy/vispel/vispel/vispel.py", line 54, in train_vispel
    trained_clusteror, trained_regressor, feature_selector = trainer(self.situation, self.X_train, self.X_community,\
  File "/home/users/apopescu/van-khoa/Vis-Priva-Expos/privacy/vispel/vispel/trainer.py", line 64, in trainer
    trained_regressor = train_regressor(regressor, X_train_rd, gt_train_expos, cfg)
  File "/home/users/apopescu/van-khoa/Vis-Priva-Expos/privacy/lib/regressor/regression.py", line 22, in train_regressor
    model.fit(x_train, y_train)
  File "/home/users/apopescu/anaconda3/envs/detectron2/lib/python3.8/site-packages/sklearn/utils/validation.py", line 73, in inner_f
    return f(**kwargs)
  File "/home/users/apopescu/anaconda3/envs/detectron2/lib/python3.8/site-packages/sklearn/model_selection/_search.py", line 736, in fit
    self._run_search(evaluate_candidates)
  File "/home/users/apopescu/anaconda3/envs/detectron2/lib/python3.8/site-packages/sklearn/model_selection/_search.py", line 1188, in _run_search
    evaluate_candidates(ParameterGrid(self.param_grid))
  File "/home/users/apopescu/anaconda3/envs/detectron2/lib/python3.8/site-packages/sklearn/model_selection/_search.py", line 708, in evaluate_candidates
    out = parallel(delayed(_fit_and_score)(clone(base_estimator),
  File "/home/users/apopescu/anaconda3/envs/detectron2/lib/python3.8/site-packages/joblib/parallel.py", line 1042, in __call__
    self.retrieve()
  File "/home/users/apopescu/anaconda3/envs/detectron2/lib/python3.8/site-packages/joblib/parallel.py", line 921, in retrieve
    self._output.extend(job.get(timeout=self.timeout))
  File "/home/users/apopescu/anaconda3/envs/detectron2/lib/python3.8/site-packages/joblib/_parallel_backends.py", line 542, in wrap_future_result
    return future.result(timeout=timeout)
  File "/home/users/apopescu/anaconda3/envs/detectron2/lib/python3.8/concurrent/futures/_base.py", line 439, in result
    return self.__get_result()
  File "/home/users/apopescu/anaconda3/envs/detectron2/lib/python3.8/concurrent/futures/_base.py", line 388, in __get_result
    raise self._exception
  File "/home/users/apopescu/anaconda3/envs/detectron2/lib/python3.8/site-packages/joblib/externals/loky/_base.py", line 625, in _invoke_callbacks
    callback(self)
  File "/home/users/apopescu/anaconda3/envs/detectron2/lib/python3.8/site-packages/joblib/parallel.py", line 347, in __call__
    self.parallel.dispatch_next()
  File "/home/users/apopescu/anaconda3/envs/detectron2/lib/python3.8/site-packages/joblib/parallel.py", line 780, in dispatch_next
    if not self.dispatch_one_batch(self._original_iterator):
  File "/home/users/apopescu/anaconda3/envs/detectron2/lib/python3.8/site-packages/joblib/parallel.py", line 847, in dispatch_one_batch
    self._dispatch(tasks)
  File "/home/users/apopescu/anaconda3/envs/detectron2/lib/python3.8/site-packages/joblib/parallel.py", line 765, in _dispatch
    job = self._backend.apply_async(batch, callback=cb)
  File "/home/users/apopescu/anaconda3/envs/detectron2/lib/python3.8/site-packages/joblib/_parallel_backends.py", line 531, in apply_async
    future = self._workers.submit(SafeFunction(func))
  File "/home/users/apopescu/anaconda3/envs/detectron2/lib/python3.8/site-packages/joblib/externals/loky/reusable_executor.py", line 177, in submit
    return super(_ReusablePoolExecutor, self).submit(
  File "/home/users/apopescu/anaconda3/envs/detectron2/lib/python3.8/site-packages/joblib/externals/loky/process_executor.py", line 1102, in submit
    raise self._flags.broken
joblib.externals.loky.process_executor.TerminatedWorkerError: A worker process managed by the executor was unexpectedly terminated. This could be caused by a segmentation fault while calling the function or by an excessive memory usage causing the Operating System to kill the worker.

The exit codes of the workers are {SIGBUS(-7)}
Traceback (most recent call last):
  File "ft_official.py", line 118, in <module>
    main()
  File "ft_official.py", line 100, in main
    model.train_vispel()
  File "/home/users/apopescu/van-khoa/Vis-Priva-Expos/privacy/vispel/vispel/vispel.py", line 54, in train_vispel
    trained_clusteror, trained_regressor, feature_selector = trainer(self.situation, self.X_train, self.X_community,\
  File "/home/users/apopescu/van-khoa/Vis-Priva-Expos/privacy/vispel/vispel/trainer.py", line 64, in trainer
    trained_regressor = train_regressor(regressor, X_train_rd, gt_train_expos, cfg)
  File "/home/users/apopescu/van-khoa/Vis-Priva-Expos/privacy/lib/regressor/regression.py", line 22, in train_regressor
    model.fit(x_train, y_train)
  File "/home/users/apopescu/anaconda3/envs/detectron2/lib/python3.8/site-packages/sklearn/utils/validation.py", line 73, in inner_f
    return f(**kwargs)
  File "/home/users/apopescu/anaconda3/envs/detectron2/lib/python3.8/site-packages/sklearn/model_selection/_search.py", line 736, in fit
    self._run_search(evaluate_candidates)
  File "/home/users/apopescu/anaconda3/envs/detectron2/lib/python3.8/site-packages/sklearn/model_selection/_search.py", line 1188, in _run_search
    evaluate_candidates(ParameterGrid(self.param_grid))
  File "/home/users/apopescu/anaconda3/envs/detectron2/lib/python3.8/site-packages/sklearn/model_selection/_search.py", line 708, in evaluate_candidates
    out = parallel(delayed(_fit_and_score)(clone(base_estimator),
  File "/home/users/apopescu/anaconda3/envs/detectron2/lib/python3.8/site-packages/joblib/parallel.py", line 1042, in __call__
    self.retrieve()
  File "/home/users/apopescu/anaconda3/envs/detectron2/lib/python3.8/site-packages/joblib/parallel.py", line 921, in retrieve
    self._output.extend(job.get(timeout=self.timeout))
  File "/home/users/apopescu/anaconda3/envs/detectron2/lib/python3.8/site-packages/joblib/_parallel_backends.py", line 542, in wrap_future_result
    return future.result(timeout=timeout)
  File "/home/users/apopescu/anaconda3/envs/detectron2/lib/python3.8/concurrent/futures/_base.py", line 439, in result
    return self.__get_result()
  File "/home/users/apopescu/anaconda3/envs/detectron2/lib/python3.8/concurrent/futures/_base.py", line 388, in __get_result
    raise self._exception
joblib.externals.loky.process_executor.TerminatedWorkerError: A worker process managed by the executor was unexpectedly terminated. This could be caused by a segmentation fault while calling the function or by an excessive memory usage causing the Operating System to kill the worker.

The exit codes of the workers are {SIGKILL(-9)}
exception calling callback for <Future at 0x2b0e2abd7190 state=finished raised TerminatedWorkerError>
Traceback (most recent call last):
  File "/home/users/apopescu/anaconda3/envs/detectron2/lib/python3.8/site-packages/joblib/externals/loky/_base.py", line 625, in _invoke_callbacks
    callback(self)
  File "/home/users/apopescu/anaconda3/envs/detectron2/lib/python3.8/site-packages/joblib/parallel.py", line 347, in __call__
    self.parallel.dispatch_next()
  File "/home/users/apopescu/anaconda3/envs/detectron2/lib/python3.8/site-packages/joblib/parallel.py", line 780, in dispatch_next
    if not self.dispatch_one_batch(self._original_iterator):
  File "/home/users/apopescu/anaconda3/envs/detectron2/lib/python3.8/site-packages/joblib/parallel.py", line 847, in dispatch_one_batch
    self._dispatch(tasks)
  File "/home/users/apopescu/anaconda3/envs/detectron2/lib/python3.8/site-packages/joblib/parallel.py", line 765, in _dispatch
    job = self._backend.apply_async(batch, callback=cb)
  File "/home/users/apopescu/anaconda3/envs/detectron2/lib/python3.8/site-packages/joblib/_parallel_backends.py", line 531, in apply_async
    future = self._workers.submit(SafeFunction(func))
  File "/home/users/apopescu/anaconda3/envs/detectron2/lib/python3.8/site-packages/joblib/externals/loky/reusable_executor.py", line 177, in submit
    return super(_ReusablePoolExecutor, self).submit(
  File "/home/users/apopescu/anaconda3/envs/detectron2/lib/python3.8/site-packages/joblib/externals/loky/process_executor.py", line 1102, in submit
    raise self._flags.broken
joblib.externals.loky.process_executor.TerminatedWorkerError: A worker process managed by the executor was unexpectedly terminated. This could be caused by a segmentation fault while calling the function or by an excessive memory usage causing the Operating System to kill the worker.

The exit codes of the workers are {SIGBUS(-7)}
exception calling callback for <Future at 0x2ad379c23190 state=finished raised TerminatedWorkerError>
Traceback (most recent call last):
  File "/home/users/apopescu/anaconda3/envs/detectron2/lib/python3.8/site-packages/joblib/externals/loky/_base.py", line 625, in _invoke_callbacks
    callback(self)
  File "/home/users/apopescu/anaconda3/envs/detectron2/lib/python3.8/site-packages/joblib/parallel.py", line 347, in __call__
    self.parallel.dispatch_next()
  File "/home/users/apopescu/anaconda3/envs/detectron2/lib/python3.8/site-packages/joblib/parallel.py", line 780, in dispatch_next
    if not self.dispatch_one_batch(self._original_iterator):
  File "/home/users/apopescu/anaconda3/envs/detectron2/lib/python3.8/site-packages/joblib/parallel.py", line 847, in dispatch_one_batch
    self._dispatch(tasks)
  File "/home/users/apopescu/anaconda3/envs/detectron2/lib/python3.8/site-packages/joblib/parallel.py", line 765, in _dispatch
    job = self._backend.apply_async(batch, callback=cb)
  File "/home/users/apopescu/anaconda3/envs/detectron2/lib/python3.8/site-packages/joblib/_parallel_backends.py", line 531, in apply_async
    future = self._workers.submit(SafeFunction(func))
  File "/home/users/apopescu/anaconda3/envs/detectron2/lib/python3.8/site-packages/joblib/externals/loky/reusable_executor.py", line 177, in submit
    return super(_ReusablePoolExecutor, self).submit(
  File "/home/users/apopescu/anaconda3/envs/detectron2/lib/python3.8/site-packages/joblib/externals/loky/process_executor.py", line 1102, in submit
    raise self._flags.broken
joblib.externals.loky.process_executor.TerminatedWorkerError: A worker process managed by the executor was unexpectedly terminated. This could be caused by a segmentation fault while calling the function or by an excessive memory usage causing the Operating System to kill the worker.

The exit codes of the workers are {SIGKILL(-9)}
exception calling callback for <Future at 0x2ad379bc8910 state=finished raised TerminatedWorkerError>
Traceback (most recent call last):
  File "/home/users/apopescu/anaconda3/envs/detectron2/lib/python3.8/site-packages/joblib/externals/loky/_base.py", line 625, in _invoke_callbacks
    callback(self)
  File "/home/users/apopescu/anaconda3/envs/detectron2/lib/python3.8/site-packages/joblib/parallel.py", line 347, in __call__
    self.parallel.dispatch_next()
  File "/home/users/apopescu/anaconda3/envs/detectron2/lib/python3.8/site-packages/joblib/parallel.py", line 780, in dispatch_next
    if not self.dispatch_one_batch(self._original_iterator):
  File "/home/users/apopescu/anaconda3/envs/detectron2/lib/python3.8/site-packages/joblib/parallel.py", line 847, in dispatch_one_batch
    self._dispatch(tasks)
  File "/home/users/apopescu/anaconda3/envs/detectron2/lib/python3.8/site-packages/joblib/parallel.py", line 765, in _dispatch
    job = self._backend.apply_async(batch, callback=cb)
  File "/home/users/apopescu/anaconda3/envs/detectron2/lib/python3.8/site-packages/joblib/_parallel_backends.py", line 531, in apply_async
    future = self._workers.submit(SafeFunction(func))
  File "/home/users/apopescu/anaconda3/envs/detectron2/lib/python3.8/site-packages/joblib/externals/loky/reusable_executor.py", line 177, in submit
    return super(_ReusablePoolExecutor, self).submit(
  File "/home/users/apopescu/anaconda3/envs/detectron2/lib/python3.8/site-packages/joblib/externals/loky/process_executor.py", line 1102, in submit
    raise self._flags.broken
  File "/home/users/apopescu/anaconda3/envs/detectron2/lib/python3.8/site-packages/joblib/externals/loky/_base.py", line 625, in _invoke_callbacks
    callback(self)
  File "/home/users/apopescu/anaconda3/envs/detectron2/lib/python3.8/site-packages/joblib/parallel.py", line 347, in __call__
    self.parallel.dispatch_next()
  File "/home/users/apopescu/anaconda3/envs/detectron2/lib/python3.8/site-packages/joblib/parallel.py", line 780, in dispatch_next
    if not self.dispatch_one_batch(self._original_iterator):
  File "/home/users/apopescu/anaconda3/envs/detectron2/lib/python3.8/site-packages/joblib/parallel.py", line 847, in dispatch_one_batch
    self._dispatch(tasks)
  File "/home/users/apopescu/anaconda3/envs/detectron2/lib/python3.8/site-packages/joblib/parallel.py", line 765, in _dispatch
    job = self._backend.apply_async(batch, callback=cb)
  File "/home/users/apopescu/anaconda3/envs/detectron2/lib/python3.8/site-packages/joblib/_parallel_backends.py", line 531, in apply_async
    future = self._workers.submit(SafeFunction(func))
  File "/home/users/apopescu/anaconda3/envs/detectron2/lib/python3.8/site-packages/joblib/externals/loky/reusable_executor.py", line 177, in submit
    return super(_ReusablePoolExecutor, self).submit(
  File "/home/users/apopescu/anaconda3/envs/detectron2/lib/python3.8/site-packages/joblib/externals/loky/process_executor.py", line 1102, in submit
    raise self._flags.broken
joblib.externals.loky.process_executor.TerminatedWorkerError: A worker process managed by the executor was unexpectedly terminated. This could be caused by a segmentation fault while calling the function or by an excessive memory usage causing the Operating System to kill the worker.

The exit codes of the workers are {SIGKILL(-9)}
exception calling callback for <Future at 0x2ad379bc8d60 state=finished raised TerminatedWorkerError>
Traceback (most recent call last):
  File "/home/users/apopescu/anaconda3/envs/detectron2/lib/python3.8/site-packages/joblib/externals/loky/_base.py", line 625, in _invoke_callbacks
    callback(self)
  File "/home/users/apopescu/anaconda3/envs/detectron2/lib/python3.8/site-packages/joblib/parallel.py", line 347, in __call__
    self.parallel.dispatch_next()
  File "/home/users/apopescu/anaconda3/envs/detectron2/lib/python3.8/site-packages/joblib/parallel.py", line 780, in dispatch_next
    if not self.dispatch_one_batch(self._original_iterator):
  File "/home/users/apopescu/anaconda3/envs/detectron2/lib/python3.8/site-packages/joblib/parallel.py", line 847, in dispatch_one_batch
    self._dispatch(tasks)
  File "/home/users/apopescu/anaconda3/envs/detectron2/lib/python3.8/site-packages/joblib/parallel.py", line 765, in _dispatch
    job = self._backend.apply_async(batch, callback=cb)
  File "/home/users/apopescu/anaconda3/envs/detectron2/lib/python3.8/site-packages/joblib/_parallel_backends.py", line 531, in apply_async
    future = self._workers.submit(SafeFunction(func))
  File "/home/users/apopescu/anaconda3/envs/detectron2/lib/python3.8/site-packages/joblib/externals/loky/reusable_executor.py", line 177, in submit
    return super(_ReusablePoolExecutor, self).submit(
  File "/home/users/apopescu/anaconda3/envs/detectron2/lib/python3.8/site-packages/joblib/externals/loky/process_executor.py", line 1102, in submit
    raise self._flags.broken
  File "/home/users/apopescu/anaconda3/envs/detectron2/lib/python3.8/site-packages/joblib/externals/loky/_base.py", line 625, in _invoke_callbacks
    callback(self)
  File "/home/users/apopescu/anaconda3/envs/detectron2/lib/python3.8/site-packages/joblib/parallel.py", line 347, in __call__
    self.parallel.dispatch_next()
  File "/home/users/apopescu/anaconda3/envs/detectron2/lib/python3.8/site-packages/joblib/parallel.py", line 780, in dispatch_next
    if not self.dispatch_one_batch(self._original_iterator):
  File "/home/users/apopescu/anaconda3/envs/detectron2/lib/python3.8/site-packages/joblib/parallel.py", line 847, in dispatch_one_batch
    self._dispatch(tasks)
  File "/home/users/apopescu/anaconda3/envs/detectron2/lib/python3.8/site-packages/joblib/parallel.py", line 765, in _dispatch
    job = self._backend.apply_async(batch, callback=cb)
  File "/home/users/apopescu/anaconda3/envs/detectron2/lib/python3.8/site-packages/joblib/_parallel_backends.py", line 531, in apply_async
    future = self._workers.submit(SafeFunction(func))
  File "/home/users/apopescu/anaconda3/envs/detectron2/lib/python3.8/site-packages/joblib/externals/loky/reusable_executor.py", line 177, in submit
    return super(_ReusablePoolExecutor, self).submit(
  File "/home/users/apopescu/anaconda3/envs/detectron2/lib/python3.8/site-packages/joblib/externals/loky/process_executor.py", line 1102, in submit
    raise self._flags.broken
  File "/home/users/apopescu/anaconda3/envs/detectron2/lib/python3.8/site-packages/joblib/externals/loky/_base.py", line 625, in _invoke_callbacks
    callback(self)
  File "/home/users/apopescu/anaconda3/envs/detectron2/lib/python3.8/site-packages/joblib/parallel.py", line 347, in __call__
    self.parallel.dispatch_next()
  File "/home/users/apopescu/anaconda3/envs/detectron2/lib/python3.8/site-packages/joblib/parallel.py", line 780, in dispatch_next
    if not self.dispatch_one_batch(self._original_iterator):
  File "/home/users/apopescu/anaconda3/envs/detectron2/lib/python3.8/site-packages/joblib/parallel.py", line 847, in dispatch_one_batch
    self._dispatch(tasks)
  File "/home/users/apopescu/anaconda3/envs/detectron2/lib/python3.8/site-packages/joblib/parallel.py", line 765, in _dispatch
    job = self._backend.apply_async(batch, callback=cb)
  File "/home/users/apopescu/anaconda3/envs/detectron2/lib/python3.8/site-packages/joblib/_parallel_backends.py", line 531, in apply_async
    future = self._workers.submit(SafeFunction(func))
  File "/home/users/apopescu/anaconda3/envs/detectron2/lib/python3.8/site-packages/joblib/externals/loky/reusable_executor.py", line 177, in submit
    return super(_ReusablePoolExecutor, self).submit(
  File "/home/users/apopescu/anaconda3/envs/detectron2/lib/python3.8/site-packages/joblib/externals/loky/process_executor.py", line 1102, in submit
    raise self._flags.broken
joblib.externals.loky.process_executor.TerminatedWorkerError: A worker process managed by the executor was unexpectedly terminated. This could be caused by a segmentation fault while calling the function or by an excessive memory usage causing the Operating System to kill the worker.

The exit codes of the workers are {SIGKILL(-9)}
exception calling callback for <Future at 0x2ad379bc8e80 state=finished raised TerminatedWorkerError>
Traceback (most recent call last):
  File "/home/users/apopescu/anaconda3/envs/detectron2/lib/python3.8/site-packages/joblib/externals/loky/_base.py", line 625, in _invoke_callbacks
    callback(self)
  File "/home/users/apopescu/anaconda3/envs/detectron2/lib/python3.8/site-packages/joblib/parallel.py", line 347, in __call__
    self.parallel.dispatch_next()
  File "/home/users/apopescu/anaconda3/envs/detectron2/lib/python3.8/site-packages/joblib/parallel.py", line 780, in dispatch_next
    if not self.dispatch_one_batch(self._original_iterator):
  File "/home/users/apopescu/anaconda3/envs/detectron2/lib/python3.8/site-packages/joblib/parallel.py", line 847, in dispatch_one_batch
    self._dispatch(tasks)
  File "/home/users/apopescu/anaconda3/envs/detectron2/lib/python3.8/site-packages/joblib/parallel.py", line 765, in _dispatch
    job = self._backend.apply_async(batch, callback=cb)
  File "/home/users/apopescu/anaconda3/envs/detectron2/lib/python3.8/site-packages/joblib/_parallel_backends.py", line 531, in apply_async
    future = self._workers.submit(SafeFunction(func))
  File "/home/users/apopescu/anaconda3/envs/detectron2/lib/python3.8/site-packages/joblib/externals/loky/reusable_executor.py", line 177, in submit
    return super(_ReusablePoolExecutor, self).submit(
  File "/home/users/apopescu/anaconda3/envs/detectron2/lib/python3.8/site-packages/joblib/externals/loky/process_executor.py", line 1102, in submit
    raise self._flags.broken
  File "/home/users/apopescu/anaconda3/envs/detectron2/lib/python3.8/site-packages/joblib/externals/loky/_base.py", line 625, in _invoke_callbacks
    callback(self)
  File "/home/users/apopescu/anaconda3/envs/detectron2/lib/python3.8/site-packages/joblib/parallel.py", line 347, in __call__
    self.parallel.dispatch_next()
  File "/home/users/apopescu/anaconda3/envs/detectron2/lib/python3.8/site-packages/joblib/parallel.py", line 780, in dispatch_next
    if not self.dispatch_one_batch(self._original_iterator):
  File "/home/users/apopescu/anaconda3/envs/detectron2/lib/python3.8/site-packages/joblib/parallel.py", line 847, in dispatch_one_batch
    self._dispatch(tasks)
  File "/home/users/apopescu/anaconda3/envs/detectron2/lib/python3.8/site-packages/joblib/parallel.py", line 765, in _dispatch
    job = self._backend.apply_async(batch, callback=cb)
  File "/home/users/apopescu/anaconda3/envs/detectron2/lib/python3.8/site-packages/joblib/_parallel_backends.py", line 531, in apply_async
    future = self._workers.submit(SafeFunction(func))
  File "/home/users/apopescu/anaconda3/envs/detectron2/lib/python3.8/site-packages/joblib/externals/loky/reusable_executor.py", line 177, in submit
    return super(_ReusablePoolExecutor, self).submit(
  File "/home/users/apopescu/anaconda3/envs/detectron2/lib/python3.8/site-packages/joblib/externals/loky/process_executor.py", line 1102, in submit
    raise self._flags.broken
  File "/home/users/apopescu/anaconda3/envs/detectron2/lib/python3.8/site-packages/joblib/externals/loky/_base.py", line 625, in _invoke_callbacks
    callback(self)
  File "/home/users/apopescu/anaconda3/envs/detectron2/lib/python3.8/site-packages/joblib/parallel.py", line 347, in __call__
    self.parallel.dispatch_next()
  File "/home/users/apopescu/anaconda3/envs/detectron2/lib/python3.8/site-packages/joblib/parallel.py", line 780, in dispatch_next
    if not self.dispatch_one_batch(self._original_iterator):
  File "/home/users/apopescu/anaconda3/envs/detectron2/lib/python3.8/site-packages/joblib/parallel.py", line 847, in dispatch_one_batch
    self._dispatch(tasks)
  File "/home/users/apopescu/anaconda3/envs/detectron2/lib/python3.8/site-packages/joblib/parallel.py", line 765, in _dispatch
    job = self._backend.apply_async(batch, callback=cb)
  File "/home/users/apopescu/anaconda3/envs/detectron2/lib/python3.8/site-packages/joblib/_parallel_backends.py", line 531, in apply_async
    future = self._workers.submit(SafeFunction(func))
  File "/home/users/apopescu/anaconda3/envs/detectron2/lib/python3.8/site-packages/joblib/externals/loky/reusable_executor.py", line 177, in submit
    return super(_ReusablePoolExecutor, self).submit(
  File "/home/users/apopescu/anaconda3/envs/detectron2/lib/python3.8/site-packages/joblib/externals/loky/process_executor.py", line 1102, in submit
    raise self._flags.broken
  File "/home/users/apopescu/anaconda3/envs/detectron2/lib/python3.8/site-packages/joblib/externals/loky/_base.py", line 625, in _invoke_callbacks
    callback(self)
  File "/home/users/apopescu/anaconda3/envs/detectron2/lib/python3.8/site-packages/joblib/parallel.py", line 347, in __call__
    self.parallel.dispatch_next()
  File "/home/users/apopescu/anaconda3/envs/detectron2/lib/python3.8/site-packages/joblib/parallel.py", line 780, in dispatch_next
    if not self.dispatch_one_batch(self._original_iterator):
  File "/home/users/apopescu/anaconda3/envs/detectron2/lib/python3.8/site-packages/joblib/parallel.py", line 847, in dispatch_one_batch
    self._dispatch(tasks)
  File "/home/users/apopescu/anaconda3/envs/detectron2/lib/python3.8/site-packages/joblib/parallel.py", line 765, in _dispatch
    job = self._backend.apply_async(batch, callback=cb)
  File "/home/users/apopescu/anaconda3/envs/detectron2/lib/python3.8/site-packages/joblib/_parallel_backends.py", line 531, in apply_async
    future = self._workers.submit(SafeFunction(func))
  File "/home/users/apopescu/anaconda3/envs/detectron2/lib/python3.8/site-packages/joblib/externals/loky/reusable_executor.py", line 177, in submit
    return super(_ReusablePoolExecutor, self).submit(
  File "/home/users/apopescu/anaconda3/envs/detectron2/lib/python3.8/site-packages/joblib/externals/loky/process_executor.py", line 1102, in submit
    raise self._flags.broken
joblib.externals.loky.process_executor.TerminatedWorkerError: A worker process managed by the executor was unexpectedly terminated. This could be caused by a segmentation fault while calling the function or by an excessive memory usage causing the Operating System to kill the worker.

The exit codes of the workers are {SIGKILL(-9)}
exception calling callback for <Future at 0x2aecc0136190 state=finished raised TerminatedWorkerError>
Traceback (most recent call last):
  File "/home/users/apopescu/anaconda3/envs/detectron2/lib/python3.8/site-packages/joblib/externals/loky/_base.py", line 625, in _invoke_callbacks
    callback(self)
  File "/home/users/apopescu/anaconda3/envs/detectron2/lib/python3.8/site-packages/joblib/parallel.py", line 347, in __call__
    self.parallel.dispatch_next()
  File "/home/users/apopescu/anaconda3/envs/detectron2/lib/python3.8/site-packages/joblib/parallel.py", line 780, in dispatch_next
    if not self.dispatch_one_batch(self._original_iterator):
  File "/home/users/apopescu/anaconda3/envs/detectron2/lib/python3.8/site-packages/joblib/parallel.py", line 847, in dispatch_one_batch
    self._dispatch(tasks)
  File "/home/users/apopescu/anaconda3/envs/detectron2/lib/python3.8/site-packages/joblib/parallel.py", line 765, in _dispatch
    job = self._backend.apply_async(batch, callback=cb)
  File "/home/users/apopescu/anaconda3/envs/detectron2/lib/python3.8/site-packages/joblib/_parallel_backends.py", line 531, in apply_async
    future = self._workers.submit(SafeFunction(func))
  File "/home/users/apopescu/anaconda3/envs/detectron2/lib/python3.8/site-packages/joblib/externals/loky/reusable_executor.py", line 177, in submit
    return super(_ReusablePoolExecutor, self).submit(
  File "/home/users/apopescu/anaconda3/envs/detectron2/lib/python3.8/site-packages/joblib/externals/loky/process_executor.py", line 1102, in submit
    raise self._flags.broken
joblib.externals.loky.process_executor.TerminatedWorkerError: A worker process managed by the executor was unexpectedly terminated. This could be caused by a segmentation fault while calling the function or by an excessive memory usage causing the Operating System to kill the worker.

The exit codes of the workers are {SIGBUS(-7)}
exception calling callback for <Future at 0x2ae0159c7190 state=finished raised TerminatedWorkerError>
Traceback (most recent call last):
  File "/home/users/apopescu/anaconda3/envs/detectron2/lib/python3.8/site-packages/joblib/externals/loky/_base.py", line 625, in _invoke_callbacks
    callback(self)
  File "/home/users/apopescu/anaconda3/envs/detectron2/lib/python3.8/site-packages/joblib/parallel.py", line 347, in __call__
    self.parallel.dispatch_next()
  File "/home/users/apopescu/anaconda3/envs/detectron2/lib/python3.8/site-packages/joblib/parallel.py", line 780, in dispatch_next
    if not self.dispatch_one_batch(self._original_iterator):
  File "/home/users/apopescu/anaconda3/envs/detectron2/lib/python3.8/site-packages/joblib/parallel.py", line 847, in dispatch_one_batch
    self._dispatch(tasks)
  File "/home/users/apopescu/anaconda3/envs/detectron2/lib/python3.8/site-packages/joblib/parallel.py", line 765, in _dispatch
    job = self._backend.apply_async(batch, callback=cb)
  File "/home/users/apopescu/anaconda3/envs/detectron2/lib/python3.8/site-packages/joblib/_parallel_backends.py", line 531, in apply_async
    future = self._workers.submit(SafeFunction(func))
  File "/home/users/apopescu/anaconda3/envs/detectron2/lib/python3.8/site-packages/joblib/externals/loky/reusable_executor.py", line 177, in submit
    return super(_ReusablePoolExecutor, self).submit(
  File "/home/users/apopescu/anaconda3/envs/detectron2/lib/python3.8/site-packages/joblib/externals/loky/process_executor.py", line 1102, in submit
    raise self._flags.broken
joblib.externals.loky.process_executor.TerminatedWorkerError: A worker process managed by the executor was unexpectedly terminated. This could be caused by a segmentation fault while calling the function or by an excessive memory usage causing the Operating System to kill the worker.

The exit codes of the workers are {SIGBUS(-7)}
exception calling callback for <Future at 0x2ac797dcb190 state=finished raised TerminatedWorkerError>
Traceback (most recent call last):
  File "/home/users/apopescu/anaconda3/envs/detectron2/lib/python3.8/site-packages/joblib/externals/loky/_base.py", line 625, in _invoke_callbacks
    callback(self)
  File "/home/users/apopescu/anaconda3/envs/detectron2/lib/python3.8/site-packages/joblib/parallel.py", line 347, in __call__
    self.parallel.dispatch_next()
  File "/home/users/apopescu/anaconda3/envs/detectron2/lib/python3.8/site-packages/joblib/parallel.py", line 780, in dispatch_next
    if not self.dispatch_one_batch(self._original_iterator):
  File "/home/users/apopescu/anaconda3/envs/detectron2/lib/python3.8/site-packages/joblib/parallel.py", line 847, in dispatch_one_batch
    self._dispatch(tasks)
  File "/home/users/apopescu/anaconda3/envs/detectron2/lib/python3.8/site-packages/joblib/parallel.py", line 765, in _dispatch
    job = self._backend.apply_async(batch, callback=cb)
  File "/home/users/apopescu/anaconda3/envs/detectron2/lib/python3.8/site-packages/joblib/_parallel_backends.py", line 531, in apply_async
    future = self._workers.submit(SafeFunction(func))
  File "/home/users/apopescu/anaconda3/envs/detectron2/lib/python3.8/site-packages/joblib/externals/loky/reusable_executor.py", line 177, in submit
    return super(_ReusablePoolExecutor, self).submit(
  File "/home/users/apopescu/anaconda3/envs/detectron2/lib/python3.8/site-packages/joblib/externals/loky/process_executor.py", line 1102, in submit
    raise self._flags.broken
joblib.externals.loky.process_executor.TerminatedWorkerError: A worker process managed by the executor was unexpectedly terminated. This could be caused by a segmentation fault while calling the function or by an excessive memory usage causing the Operating System to kill the worker.

The exit codes of the workers are {SIGBUS(-7)}
exception calling callback for <Future at 0x2b837e203190 state=finished raised TerminatedWorkerError>
Traceback (most recent call last):
  File "/home/users/apopescu/anaconda3/envs/detectron2/lib/python3.8/site-packages/joblib/externals/loky/_base.py", line 625, in _invoke_callbacks
    callback(self)
  File "/home/users/apopescu/anaconda3/envs/detectron2/lib/python3.8/site-packages/joblib/parallel.py", line 347, in __call__
    self.parallel.dispatch_next()
  File "/home/users/apopescu/anaconda3/envs/detectron2/lib/python3.8/site-packages/joblib/parallel.py", line 780, in dispatch_next
    if not self.dispatch_one_batch(self._original_iterator):
  File "/home/users/apopescu/anaconda3/envs/detectron2/lib/python3.8/site-packages/joblib/parallel.py", line 847, in dispatch_one_batch
    self._dispatch(tasks)
  File "/home/users/apopescu/anaconda3/envs/detectron2/lib/python3.8/site-packages/joblib/parallel.py", line 765, in _dispatch
    job = self._backend.apply_async(batch, callback=cb)
  File "/home/users/apopescu/anaconda3/envs/detectron2/lib/python3.8/site-packages/joblib/_parallel_backends.py", line 531, in apply_async
    future = self._workers.submit(SafeFunction(func))
  File "/home/users/apopescu/anaconda3/envs/detectron2/lib/python3.8/site-packages/joblib/externals/loky/reusable_executor.py", line 177, in submit
    return super(_ReusablePoolExecutor, self).submit(
  File "/home/users/apopescu/anaconda3/envs/detectron2/lib/python3.8/site-packages/joblib/externals/loky/process_executor.py", line 1102, in submit
    raise self._flags.broken
joblib.externals.loky.process_executor.TerminatedWorkerError: A worker process managed by the executor was unexpectedly terminated. This could be caused by a segmentation fault while calling the function or by an excessive memory usage causing the Operating System to kill the worker.

The exit codes of the workers are {SIGBUS(-7)}
  0%|          | 0/5 [01:41<?, ?it/s]
  0%|          | 0/5 [01:49<?, ?it/s]
  0%|          | 0/5 [01:31<?, ?it/s]
Traceback (most recent call last):
  File "ft_official.py", line 118, in <module>
    main()
  File "ft_official.py", line 100, in main
    model.train_vispel()
  File "/home/users/apopescu/van-khoa/Vis-Priva-Expos/privacy/vispel/vispel/vispel.py", line 54, in train_vispel
    trained_clusteror, trained_regressor, feature_selector = trainer(self.situation, self.X_train, self.X_community,\
  File "/home/users/apopescu/van-khoa/Vis-Priva-Expos/privacy/vispel/vispel/trainer.py", line 64, in trainer
    trained_regressor = train_regressor(regressor, X_train_rd, gt_train_expos, cfg)
  File "/home/users/apopescu/van-khoa/Vis-Priva-Expos/privacy/lib/regressor/regression.py", line 22, in train_regressor
    model.fit(x_train, y_train)
  File "/home/users/apopescu/anaconda3/envs/detectron2/lib/python3.8/site-packages/sklearn/utils/validation.py", line 73, in inner_f
    return f(**kwargs)
  File "/home/users/apopescu/anaconda3/envs/detectron2/lib/python3.8/site-packages/sklearn/model_selection/_search.py", line 736, in fit
    self._run_search(evaluate_candidates)
  File "/home/users/apopescu/anaconda3/envs/detectron2/lib/python3.8/site-packages/sklearn/model_selection/_search.py", line 1188, in _run_search
    evaluate_candidates(ParameterGrid(self.param_grid))
  File "/home/users/apopescu/anaconda3/envs/detectron2/lib/python3.8/site-packages/sklearn/model_selection/_search.py", line 708, in evaluate_candidates
    out = parallel(delayed(_fit_and_score)(clone(base_estimator),
  File "/home/users/apopescu/anaconda3/envs/detectron2/lib/python3.8/site-packages/joblib/parallel.py", line 1042, in __call__
    self.retrieve()
  File "/home/users/apopescu/anaconda3/envs/detectron2/lib/python3.8/site-packages/joblib/parallel.py", line 921, in retrieve
    self._output.extend(job.get(timeout=self.timeout))
  File "/home/users/apopescu/anaconda3/envs/detectron2/lib/python3.8/site-packages/joblib/_parallel_backends.py", line 542, in wrap_future_result
    return future.result(timeout=timeout)
  File "/home/users/apopescu/anaconda3/envs/detectron2/lib/python3.8/concurrent/futures/_base.py", line 439, in result
    return self.__get_result()
  File "/home/users/apopescu/anaconda3/envs/detectron2/lib/python3.8/concurrent/futures/_base.py", line 388, in __get_result
    raise self._exception
  File "/home/users/apopescu/anaconda3/envs/detectron2/lib/python3.8/site-packages/joblib/externals/loky/_base.py", line 625, in _invoke_callbacks
    callback(self)
  File "/home/users/apopescu/anaconda3/envs/detectron2/lib/python3.8/site-packages/joblib/parallel.py", line 347, in __call__
    self.parallel.dispatch_next()
  File "/home/users/apopescu/anaconda3/envs/detectron2/lib/python3.8/site-packages/joblib/parallel.py", line 780, in dispatch_next
    if not self.dispatch_one_batch(self._original_iterator):
  File "/home/users/apopescu/anaconda3/envs/detectron2/lib/python3.8/site-packages/joblib/parallel.py", line 847, in dispatch_one_batch
    self._dispatch(tasks)
  File "/home/users/apopescu/anaconda3/envs/detectron2/lib/python3.8/site-packages/joblib/parallel.py", line 765, in _dispatch
    job = self._backend.apply_async(batch, callback=cb)
  File "/home/users/apopescu/anaconda3/envs/detectron2/lib/python3.8/site-packages/joblib/_parallel_backends.py", line 531, in apply_async
    future = self._workers.submit(SafeFunction(func))
  File "/home/users/apopescu/anaconda3/envs/detectron2/lib/python3.8/site-packages/joblib/externals/loky/reusable_executor.py", line 177, in submit
    return super(_ReusablePoolExecutor, self).submit(
  File "/home/users/apopescu/anaconda3/envs/detectron2/lib/python3.8/site-packages/joblib/externals/loky/process_executor.py", line 1102, in submit
    raise self._flags.broken
joblib.externals.loky.process_executor.TerminatedWorkerError: A worker process managed by the executor was unexpectedly terminated. This could be caused by a segmentation fault while calling the function or by an excessive memory usage causing the Operating System to kill the worker.

The exit codes of the workers are {SIGBUS(-7)}
  0%|          | 0/5 [01:49<?, ?it/s]
  0%|          | 0/5 [01:32<?, ?it/s]
  0%|          | 0/5 [01:52<?, ?it/s]
Traceback (most recent call last):
  File "ft_official.py", line 118, in <module>
    main()
  File "ft_official.py", line 100, in main
    model.train_vispel()
  File "/home/users/apopescu/van-khoa/Vis-Priva-Expos/privacy/vispel/vispel/vispel.py", line 54, in train_vispel
    trained_clusteror, trained_regressor, feature_selector = trainer(self.situation, self.X_train, self.X_community,\
  File "/home/users/apopescu/van-khoa/Vis-Priva-Expos/privacy/vispel/vispel/trainer.py", line 64, in trainer
    trained_regressor = train_regressor(regressor, X_train_rd, gt_train_expos, cfg)
  File "/home/users/apopescu/van-khoa/Vis-Priva-Expos/privacy/lib/regressor/regression.py", line 22, in train_regressor
    model.fit(x_train, y_train)
  File "/home/users/apopescu/anaconda3/envs/detectron2/lib/python3.8/site-packages/sklearn/utils/validation.py", line 73, in inner_f
    return f(**kwargs)
  File "/home/users/apopescu/anaconda3/envs/detectron2/lib/python3.8/site-packages/sklearn/model_selection/_search.py", line 736, in fit
    self._run_search(evaluate_candidates)
  File "/home/users/apopescu/anaconda3/envs/detectron2/lib/python3.8/site-packages/sklearn/model_selection/_search.py", line 1188, in _run_search
    evaluate_candidates(ParameterGrid(self.param_grid))
  File "/home/users/apopescu/anaconda3/envs/detectron2/lib/python3.8/site-packages/sklearn/model_selection/_search.py", line 708, in evaluate_candidates
    out = parallel(delayed(_fit_and_score)(clone(base_estimator),
  File "/home/users/apopescu/anaconda3/envs/detectron2/lib/python3.8/site-packages/joblib/parallel.py", line 1042, in __call__
    self.retrieve()
  File "/home/users/apopescu/anaconda3/envs/detectron2/lib/python3.8/site-packages/joblib/parallel.py", line 921, in retrieve
    self._output.extend(job.get(timeout=self.timeout))
  File "/home/users/apopescu/anaconda3/envs/detectron2/lib/python3.8/site-packages/joblib/_parallel_backends.py", line 542, in wrap_future_result
    return future.result(timeout=timeout)
  File "/home/users/apopescu/anaconda3/envs/detectron2/lib/python3.8/concurrent/futures/_base.py", line 439, in result
    return self.__get_result()
  File "/home/users/apopescu/anaconda3/envs/detectron2/lib/python3.8/concurrent/futures/_base.py", line 388, in __get_result
    raise self._exception
  File "/home/users/apopescu/anaconda3/envs/detectron2/lib/python3.8/site-packages/joblib/externals/loky/_base.py", line 625, in _invoke_callbacks
    callback(self)
  File "/home/users/apopescu/anaconda3/envs/detectron2/lib/python3.8/site-packages/joblib/parallel.py", line 347, in __call__
    self.parallel.dispatch_next()
  File "/home/users/apopescu/anaconda3/envs/detectron2/lib/python3.8/site-packages/joblib/parallel.py", line 780, in dispatch_next
    if not self.dispatch_one_batch(self._original_iterator):
  File "/home/users/apopescu/anaconda3/envs/detectron2/lib/python3.8/site-packages/joblib/parallel.py", line 847, in dispatch_one_batch
    self._dispatch(tasks)
  File "/home/users/apopescu/anaconda3/envs/detectron2/lib/python3.8/site-packages/joblib/parallel.py", line 765, in _dispatch
    job = self._backend.apply_async(batch, callback=cb)
  File "/home/users/apopescu/anaconda3/envs/detectron2/lib/python3.8/site-packages/joblib/_parallel_backends.py", line 531, in apply_async
    future = self._workers.submit(SafeFunction(func))
  File "/home/users/apopescu/anaconda3/envs/detectron2/lib/python3.8/site-packages/joblib/externals/loky/reusable_executor.py", line 177, in submit
    return super(_ReusablePoolExecutor, self).submit(
  File "/home/users/apopescu/anaconda3/envs/detectron2/lib/python3.8/site-packages/joblib/externals/loky/process_executor.py", line 1102, in submit
    raise self._flags.broken
joblib.externals.loky.process_executor.TerminatedWorkerError: A worker process managed by the executor was unexpectedly terminated. This could be caused by a segmentation fault while calling the function or by an excessive memory usage causing the Operating System to kill the worker.

The exit codes of the workers are {SIGBUS(-7)}
Traceback (most recent call last):
  File "ft_official.py", line 118, in <module>
    main()
  File "ft_official.py", line 100, in main
    model.train_vispel()
  File "/home/users/apopescu/van-khoa/Vis-Priva-Expos/privacy/vispel/vispel/vispel.py", line 54, in train_vispel
    trained_clusteror, trained_regressor, feature_selector = trainer(self.situation, self.X_train, self.X_community,\
  File "/home/users/apopescu/van-khoa/Vis-Priva-Expos/privacy/vispel/vispel/trainer.py", line 64, in trainer
    trained_regressor = train_regressor(regressor, X_train_rd, gt_train_expos, cfg)
  File "/home/users/apopescu/van-khoa/Vis-Priva-Expos/privacy/lib/regressor/regression.py", line 22, in train_regressor
    model.fit(x_train, y_train)
  File "/home/users/apopescu/anaconda3/envs/detectron2/lib/python3.8/site-packages/sklearn/utils/validation.py", line 73, in inner_f
    return f(**kwargs)
  File "/home/users/apopescu/anaconda3/envs/detectron2/lib/python3.8/site-packages/sklearn/model_selection/_search.py", line 736, in fit
    self._run_search(evaluate_candidates)
  File "/home/users/apopescu/anaconda3/envs/detectron2/lib/python3.8/site-packages/sklearn/model_selection/_search.py", line 1188, in _run_search
    evaluate_candidates(ParameterGrid(self.param_grid))
  File "/home/users/apopescu/anaconda3/envs/detectron2/lib/python3.8/site-packages/sklearn/model_selection/_search.py", line 708, in evaluate_candidates
    out = parallel(delayed(_fit_and_score)(clone(base_estimator),
  File "/home/users/apopescu/anaconda3/envs/detectron2/lib/python3.8/site-packages/joblib/parallel.py", line 1042, in __call__
    self.retrieve()
  File "/home/users/apopescu/anaconda3/envs/detectron2/lib/python3.8/site-packages/joblib/parallel.py", line 921, in retrieve
    self._output.extend(job.get(timeout=self.timeout))
  File "/home/users/apopescu/anaconda3/envs/detectron2/lib/python3.8/site-packages/joblib/_parallel_backends.py", line 542, in wrap_future_result
    return future.result(timeout=timeout)
  File "/home/users/apopescu/anaconda3/envs/detectron2/lib/python3.8/concurrent/futures/_base.py", line 439, in result
    return self.__get_result()
  File "/home/users/apopescu/anaconda3/envs/detectron2/lib/python3.8/concurrent/futures/_base.py", line 388, in __get_result
    raise self._exception
  File "/home/users/apopescu/anaconda3/envs/detectron2/lib/python3.8/site-packages/joblib/externals/loky/_base.py", line 625, in _invoke_callbacks
    callback(self)
  File "/home/users/apopescu/anaconda3/envs/detectron2/lib/python3.8/site-packages/joblib/parallel.py", line 347, in __call__
    self.parallel.dispatch_next()
  File "/home/users/apopescu/anaconda3/envs/detectron2/lib/python3.8/site-packages/joblib/parallel.py", line 780, in dispatch_next
    if not self.dispatch_one_batch(self._original_iterator):
  File "/home/users/apopescu/anaconda3/envs/detectron2/lib/python3.8/site-packages/joblib/parallel.py", line 847, in dispatch_one_batch
    self._dispatch(tasks)
  File "/home/users/apopescu/anaconda3/envs/detectron2/lib/python3.8/site-packages/joblib/parallel.py", line 765, in _dispatch
    job = self._backend.apply_async(batch, callback=cb)
  File "/home/users/apopescu/anaconda3/envs/detectron2/lib/python3.8/site-packages/joblib/_parallel_backends.py", line 531, in apply_async
    future = self._workers.submit(SafeFunction(func))
  File "/home/users/apopescu/anaconda3/envs/detectron2/lib/python3.8/site-packages/joblib/externals/loky/reusable_executor.py", line 177, in submit
    return super(_ReusablePoolExecutor, self).submit(
  File "/home/users/apopescu/anaconda3/envs/detectron2/lib/python3.8/site-packages/joblib/externals/loky/process_executor.py", line 1102, in submit
    raise self._flags.broken
joblib.externals.loky.process_executor.TerminatedWorkerError: A worker process managed by the executor was unexpectedly terminated. This could be caused by a segmentation fault while calling the function or by an excessive memory usage causing the Operating System to kill the worker.

The exit codes of the workers are {SIGBUS(-7)}
Traceback (most recent call last):
  File "ft_official.py", line 118, in <module>
    main()
  File "ft_official.py", line 100, in main
    model.train_vispel()
  File "/home/users/apopescu/van-khoa/Vis-Priva-Expos/privacy/vispel/vispel/vispel.py", line 54, in train_vispel
    trained_clusteror, trained_regressor, feature_selector = trainer(self.situation, self.X_train, self.X_community,\
  File "/home/users/apopescu/van-khoa/Vis-Priva-Expos/privacy/vispel/vispel/trainer.py", line 64, in trainer
    trained_regressor = train_regressor(regressor, X_train_rd, gt_train_expos, cfg)
  File "/home/users/apopescu/van-khoa/Vis-Priva-Expos/privacy/lib/regressor/regression.py", line 22, in train_regressor
    model.fit(x_train, y_train)
  File "/home/users/apopescu/anaconda3/envs/detectron2/lib/python3.8/site-packages/sklearn/utils/validation.py", line 73, in inner_f
    return f(**kwargs)
  File "/home/users/apopescu/anaconda3/envs/detectron2/lib/python3.8/site-packages/sklearn/model_selection/_search.py", line 736, in fit
    self._run_search(evaluate_candidates)
  File "/home/users/apopescu/anaconda3/envs/detectron2/lib/python3.8/site-packages/sklearn/model_selection/_search.py", line 1188, in _run_search
    evaluate_candidates(ParameterGrid(self.param_grid))
  File "/home/users/apopescu/anaconda3/envs/detectron2/lib/python3.8/site-packages/sklearn/model_selection/_search.py", line 708, in evaluate_candidates
    out = parallel(delayed(_fit_and_score)(clone(base_estimator),
  File "/home/users/apopescu/anaconda3/envs/detectron2/lib/python3.8/site-packages/joblib/parallel.py", line 1042, in __call__
    self.retrieve()
  File "/home/users/apopescu/anaconda3/envs/detectron2/lib/python3.8/site-packages/joblib/parallel.py", line 921, in retrieve
    self._output.extend(job.get(timeout=self.timeout))
  File "/home/users/apopescu/anaconda3/envs/detectron2/lib/python3.8/site-packages/joblib/_parallel_backends.py", line 542, in wrap_future_result
    return future.result(timeout=timeout)
  File "/home/users/apopescu/anaconda3/envs/detectron2/lib/python3.8/concurrent/futures/_base.py", line 439, in result
    return self.__get_result()
  File "/home/users/apopescu/anaconda3/envs/detectron2/lib/python3.8/concurrent/futures/_base.py", line 388, in __get_result
    raise self._exception
  File "/home/users/apopescu/anaconda3/envs/detectron2/lib/python3.8/site-packages/joblib/externals/loky/_base.py", line 625, in _invoke_callbacks
    callback(self)
  File "/home/users/apopescu/anaconda3/envs/detectron2/lib/python3.8/site-packages/joblib/parallel.py", line 347, in __call__
    self.parallel.dispatch_next()
  File "/home/users/apopescu/anaconda3/envs/detectron2/lib/python3.8/site-packages/joblib/parallel.py", line 780, in dispatch_next
    if not self.dispatch_one_batch(self._original_iterator):
  File "/home/users/apopescu/anaconda3/envs/detectron2/lib/python3.8/site-packages/joblib/parallel.py", line 847, in dispatch_one_batch
    self._dispatch(tasks)
  File "/home/users/apopescu/anaconda3/envs/detectron2/lib/python3.8/site-packages/joblib/parallel.py", line 765, in _dispatch
    job = self._backend.apply_async(batch, callback=cb)
  File "/home/users/apopescu/anaconda3/envs/detectron2/lib/python3.8/site-packages/joblib/_parallel_backends.py", line 531, in apply_async
    future = self._workers.submit(SafeFunction(func))
  File "/home/users/apopescu/anaconda3/envs/detectron2/lib/python3.8/site-packages/joblib/externals/loky/reusable_executor.py", line 177, in submit
    return super(_ReusablePoolExecutor, self).submit(
  File "/home/users/apopescu/anaconda3/envs/detectron2/lib/python3.8/site-packages/joblib/externals/loky/process_executor.py", line 1102, in submit
    raise self._flags.broken
joblib.externals.loky.process_executor.TerminatedWorkerError: A worker process managed by the executor was unexpectedly terminated. This could be caused by a segmentation fault while calling the function or by an excessive memory usage causing the Operating System to kill the worker.

The exit codes of the workers are {SIGBUS(-7)}
Traceback (most recent call last):
  File "ft_official.py", line 118, in <module>
    main()
  File "ft_official.py", line 100, in main
    model.train_vispel()
  File "/home/users/apopescu/van-khoa/Vis-Priva-Expos/privacy/vispel/vispel/vispel.py", line 54, in train_vispel
    trained_clusteror, trained_regressor, feature_selector = trainer(self.situation, self.X_train, self.X_community,\
  File "/home/users/apopescu/van-khoa/Vis-Priva-Expos/privacy/vispel/vispel/trainer.py", line 64, in trainer
    trained_regressor = train_regressor(regressor, X_train_rd, gt_train_expos, cfg)
  File "/home/users/apopescu/van-khoa/Vis-Priva-Expos/privacy/lib/regressor/regression.py", line 22, in train_regressor
    model.fit(x_train, y_train)
  File "/home/users/apopescu/anaconda3/envs/detectron2/lib/python3.8/site-packages/sklearn/utils/validation.py", line 73, in inner_f
    return f(**kwargs)
  File "/home/users/apopescu/anaconda3/envs/detectron2/lib/python3.8/site-packages/sklearn/model_selection/_search.py", line 736, in fit
    self._run_search(evaluate_candidates)
  File "/home/users/apopescu/anaconda3/envs/detectron2/lib/python3.8/site-packages/sklearn/model_selection/_search.py", line 1188, in _run_search
    evaluate_candidates(ParameterGrid(self.param_grid))
  File "/home/users/apopescu/anaconda3/envs/detectron2/lib/python3.8/site-packages/sklearn/model_selection/_search.py", line 708, in evaluate_candidates
    out = parallel(delayed(_fit_and_score)(clone(base_estimator),
  File "/home/users/apopescu/anaconda3/envs/detectron2/lib/python3.8/site-packages/joblib/parallel.py", line 1042, in __call__
    self.retrieve()
  File "/home/users/apopescu/anaconda3/envs/detectron2/lib/python3.8/site-packages/joblib/parallel.py", line 921, in retrieve
    self._output.extend(job.get(timeout=self.timeout))
  File "/home/users/apopescu/anaconda3/envs/detectron2/lib/python3.8/site-packages/joblib/_parallel_backends.py", line 542, in wrap_future_result
    return future.result(timeout=timeout)
  File "/home/users/apopescu/anaconda3/envs/detectron2/lib/python3.8/concurrent/futures/_base.py", line 439, in result
    return self.__get_result()
  File "/home/users/apopescu/anaconda3/envs/detectron2/lib/python3.8/concurrent/futures/_base.py", line 388, in __get_result
    raise self._exception
  File "/home/users/apopescu/anaconda3/envs/detectron2/lib/python3.8/site-packages/joblib/externals/loky/_base.py", line 625, in _invoke_callbacks
    callback(self)
  File "/home/users/apopescu/anaconda3/envs/detectron2/lib/python3.8/site-packages/joblib/parallel.py", line 347, in __call__
    self.parallel.dispatch_next()
  File "/home/users/apopescu/anaconda3/envs/detectron2/lib/python3.8/site-packages/joblib/parallel.py", line 780, in dispatch_next
    if not self.dispatch_one_batch(self._original_iterator):
  File "/home/users/apopescu/anaconda3/envs/detectron2/lib/python3.8/site-packages/joblib/parallel.py", line 847, in dispatch_one_batch
    self._dispatch(tasks)
  File "/home/users/apopescu/anaconda3/envs/detectron2/lib/python3.8/site-packages/joblib/parallel.py", line 765, in _dispatch
    job = self._backend.apply_async(batch, callback=cb)
  File "/home/users/apopescu/anaconda3/envs/detectron2/lib/python3.8/site-packages/joblib/_parallel_backends.py", line 531, in apply_async
    future = self._workers.submit(SafeFunction(func))
  File "/home/users/apopescu/anaconda3/envs/detectron2/lib/python3.8/site-packages/joblib/externals/loky/reusable_executor.py", line 177, in submit
    return super(_ReusablePoolExecutor, self).submit(
  File "/home/users/apopescu/anaconda3/envs/detectron2/lib/python3.8/site-packages/joblib/externals/loky/process_executor.py", line 1102, in submit
    raise self._flags.broken
  File "/home/users/apopescu/anaconda3/envs/detectron2/lib/python3.8/site-packages/joblib/externals/loky/_base.py", line 625, in _invoke_callbacks
    callback(self)
  File "/home/users/apopescu/anaconda3/envs/detectron2/lib/python3.8/site-packages/joblib/parallel.py", line 347, in __call__
    self.parallel.dispatch_next()
  File "/home/users/apopescu/anaconda3/envs/detectron2/lib/python3.8/site-packages/joblib/parallel.py", line 780, in dispatch_next
    if not self.dispatch_one_batch(self._original_iterator):
  File "/home/users/apopescu/anaconda3/envs/detectron2/lib/python3.8/site-packages/joblib/parallel.py", line 847, in dispatch_one_batch
    self._dispatch(tasks)
  File "/home/users/apopescu/anaconda3/envs/detectron2/lib/python3.8/site-packages/joblib/parallel.py", line 765, in _dispatch
    job = self._backend.apply_async(batch, callback=cb)
  File "/home/users/apopescu/anaconda3/envs/detectron2/lib/python3.8/site-packages/joblib/_parallel_backends.py", line 531, in apply_async
    future = self._workers.submit(SafeFunction(func))
  File "/home/users/apopescu/anaconda3/envs/detectron2/lib/python3.8/site-packages/joblib/externals/loky/reusable_executor.py", line 177, in submit
    return super(_ReusablePoolExecutor, self).submit(
  File "/home/users/apopescu/anaconda3/envs/detectron2/lib/python3.8/site-packages/joblib/externals/loky/process_executor.py", line 1102, in submit
    raise self._flags.broken
  File "/home/users/apopescu/anaconda3/envs/detectron2/lib/python3.8/site-packages/joblib/externals/loky/_base.py", line 625, in _invoke_callbacks
    callback(self)
  File "/home/users/apopescu/anaconda3/envs/detectron2/lib/python3.8/site-packages/joblib/parallel.py", line 347, in __call__
    self.parallel.dispatch_next()
  File "/home/users/apopescu/anaconda3/envs/detectron2/lib/python3.8/site-packages/joblib/parallel.py", line 780, in dispatch_next
    if not self.dispatch_one_batch(self._original_iterator):
  File "/home/users/apopescu/anaconda3/envs/detectron2/lib/python3.8/site-packages/joblib/parallel.py", line 847, in dispatch_one_batch
    self._dispatch(tasks)
  File "/home/users/apopescu/anaconda3/envs/detectron2/lib/python3.8/site-packages/joblib/parallel.py", line 765, in _dispatch
    job = self._backend.apply_async(batch, callback=cb)
  File "/home/users/apopescu/anaconda3/envs/detectron2/lib/python3.8/site-packages/joblib/_parallel_backends.py", line 531, in apply_async
    future = self._workers.submit(SafeFunction(func))
  File "/home/users/apopescu/anaconda3/envs/detectron2/lib/python3.8/site-packages/joblib/externals/loky/reusable_executor.py", line 177, in submit
    return super(_ReusablePoolExecutor, self).submit(
  File "/home/users/apopescu/anaconda3/envs/detectron2/lib/python3.8/site-packages/joblib/externals/loky/process_executor.py", line 1102, in submit
    raise self._flags.broken
  File "/home/users/apopescu/anaconda3/envs/detectron2/lib/python3.8/site-packages/joblib/externals/loky/_base.py", line 625, in _invoke_callbacks
    callback(self)
  File "/home/users/apopescu/anaconda3/envs/detectron2/lib/python3.8/site-packages/joblib/parallel.py", line 347, in __call__
    self.parallel.dispatch_next()
  File "/home/users/apopescu/anaconda3/envs/detectron2/lib/python3.8/site-packages/joblib/parallel.py", line 780, in dispatch_next
    if not self.dispatch_one_batch(self._original_iterator):
  File "/home/users/apopescu/anaconda3/envs/detectron2/lib/python3.8/site-packages/joblib/parallel.py", line 847, in dispatch_one_batch
    self._dispatch(tasks)
  File "/home/users/apopescu/anaconda3/envs/detectron2/lib/python3.8/site-packages/joblib/parallel.py", line 765, in _dispatch
    job = self._backend.apply_async(batch, callback=cb)
  File "/home/users/apopescu/anaconda3/envs/detectron2/lib/python3.8/site-packages/joblib/_parallel_backends.py", line 531, in apply_async
    future = self._workers.submit(SafeFunction(func))
  File "/home/users/apopescu/anaconda3/envs/detectron2/lib/python3.8/site-packages/joblib/externals/loky/reusable_executor.py", line 177, in submit
    return super(_ReusablePoolExecutor, self).submit(
  File "/home/users/apopescu/anaconda3/envs/detectron2/lib/python3.8/site-packages/joblib/externals/loky/process_executor.py", line 1102, in submit
    raise self._flags.broken
joblib.externals.loky.process_executor.TerminatedWorkerError: A worker process managed by the executor was unexpectedly terminated. This could be caused by a segmentation fault while calling the function or by an excessive memory usage causing the Operating System to kill the worker.

The exit codes of the workers are {SIGKILL(-9)}
/home/users/apopescu/anaconda3/envs/detectron2/lib/python3.8/site-packages/joblib/externals/loky/backend/resource_tracker.py:120: UserWarning: resource_tracker: process died unexpectedly, relaunching.  Some folders/sempahores might leak.
  warnings.warn('resource_tracker: process died unexpectedly, '
Traceback (most recent call last):
  File "ft_official.py", line 118, in <module>
    main()
  File "ft_official.py", line 100, in main
    model.train_vispel()
  File "/home/users/apopescu/van-khoa/Vis-Priva-Expos/privacy/vispel/vispel/vispel.py", line 54, in train_vispel
    trained_clusteror, trained_regressor, feature_selector = trainer(self.situation, self.X_train, self.X_community,\
  File "/home/users/apopescu/van-khoa/Vis-Priva-Expos/privacy/vispel/vispel/trainer.py", line 64, in trainer
    trained_regressor = train_regressor(regressor, X_train_rd, gt_train_expos, cfg)
  File "/home/users/apopescu/van-khoa/Vis-Priva-Expos/privacy/lib/regressor/regression.py", line 22, in train_regressor
    model.fit(x_train, y_train)
  File "/home/users/apopescu/anaconda3/envs/detectron2/lib/python3.8/site-packages/sklearn/utils/validation.py", line 73, in inner_f
    return f(**kwargs)
  File "/home/users/apopescu/anaconda3/envs/detectron2/lib/python3.8/site-packages/sklearn/model_selection/_search.py", line 736, in fit
    self._run_search(evaluate_candidates)
  File "/home/users/apopescu/anaconda3/envs/detectron2/lib/python3.8/site-packages/sklearn/model_selection/_search.py", line 1188, in _run_search
    evaluate_candidates(ParameterGrid(self.param_grid))
  File "/home/users/apopescu/anaconda3/envs/detectron2/lib/python3.8/site-packages/sklearn/model_selection/_search.py", line 708, in evaluate_candidates
    out = parallel(delayed(_fit_and_score)(clone(base_estimator),
  File "/home/users/apopescu/anaconda3/envs/detectron2/lib/python3.8/site-packages/joblib/parallel.py", line 1042, in __call__
    self.retrieve()
  File "/home/users/apopescu/anaconda3/envs/detectron2/lib/python3.8/site-packages/joblib/parallel.py", line 921, in retrieve
    self._output.extend(job.get(timeout=self.timeout))
  File "/home/users/apopescu/anaconda3/envs/detectron2/lib/python3.8/site-packages/joblib/_parallel_backends.py", line 542, in wrap_future_result
    return future.result(timeout=timeout)
  File "/home/users/apopescu/anaconda3/envs/detectron2/lib/python3.8/concurrent/futures/_base.py", line 439, in result
    return self.__get_result()
  File "/home/users/apopescu/anaconda3/envs/detectron2/lib/python3.8/concurrent/futures/_base.py", line 388, in __get_result
    raise self._exception
  File "/home/users/apopescu/anaconda3/envs/detectron2/lib/python3.8/site-packages/joblib/externals/loky/_base.py", line 625, in _invoke_callbacks
    callback(self)
  File "/home/users/apopescu/anaconda3/envs/detectron2/lib/python3.8/site-packages/joblib/parallel.py", line 347, in __call__
    self.parallel.dispatch_next()
  File "/home/users/apopescu/anaconda3/envs/detectron2/lib/python3.8/site-packages/joblib/parallel.py", line 780, in dispatch_next
    if not self.dispatch_one_batch(self._original_iterator):
  File "/home/users/apopescu/anaconda3/envs/detectron2/lib/python3.8/site-packages/joblib/parallel.py", line 847, in dispatch_one_batch
    self._dispatch(tasks)
  File "/home/users/apopescu/anaconda3/envs/detectron2/lib/python3.8/site-packages/joblib/parallel.py", line 765, in _dispatch
    job = self._backend.apply_async(batch, callback=cb)
  File "/home/users/apopescu/anaconda3/envs/detectron2/lib/python3.8/site-packages/joblib/_parallel_backends.py", line 531, in apply_async
    future = self._workers.submit(SafeFunction(func))
  File "/home/users/apopescu/anaconda3/envs/detectron2/lib/python3.8/site-packages/joblib/externals/loky/reusable_executor.py", line 177, in submit
    return super(_ReusablePoolExecutor, self).submit(
  File "/home/users/apopescu/anaconda3/envs/detectron2/lib/python3.8/site-packages/joblib/externals/loky/process_executor.py", line 1102, in submit
    raise self._flags.broken
joblib.externals.loky.process_executor.TerminatedWorkerError: A worker process managed by the executor was unexpectedly terminated. This could be caused by a segmentation fault while calling the function or by an excessive memory usage causing the Operating System to kill the worker.

The exit codes of the workers are {SIGBUS(-7)}
exception calling callback for <Future at 0x2b7a411be190 state=finished raised TerminatedWorkerError>
Traceback (most recent call last):
  File "/home/users/apopescu/anaconda3/envs/detectron2/lib/python3.8/site-packages/joblib/externals/loky/_base.py", line 625, in _invoke_callbacks
    callback(self)
  File "/home/users/apopescu/anaconda3/envs/detectron2/lib/python3.8/site-packages/joblib/parallel.py", line 347, in __call__
    self.parallel.dispatch_next()
  File "/home/users/apopescu/anaconda3/envs/detectron2/lib/python3.8/site-packages/joblib/parallel.py", line 780, in dispatch_next
    if not self.dispatch_one_batch(self._original_iterator):
  File "/home/users/apopescu/anaconda3/envs/detectron2/lib/python3.8/site-packages/joblib/parallel.py", line 847, in dispatch_one_batch
    self._dispatch(tasks)
  File "/home/users/apopescu/anaconda3/envs/detectron2/lib/python3.8/site-packages/joblib/parallel.py", line 765, in _dispatch
    job = self._backend.apply_async(batch, callback=cb)
  File "/home/users/apopescu/anaconda3/envs/detectron2/lib/python3.8/site-packages/joblib/_parallel_backends.py", line 531, in apply_async
    future = self._workers.submit(SafeFunction(func))
  File "/home/users/apopescu/anaconda3/envs/detectron2/lib/python3.8/site-packages/joblib/externals/loky/reusable_executor.py", line 177, in submit
    return super(_ReusablePoolExecutor, self).submit(
  File "/home/users/apopescu/anaconda3/envs/detectron2/lib/python3.8/site-packages/joblib/externals/loky/process_executor.py", line 1102, in submit
    raise self._flags.broken
joblib.externals.loky.process_executor.TerminatedWorkerError: A worker process managed by the executor was unexpectedly terminated. This could be caused by a segmentation fault while calling the function or by an excessive memory usage causing the Operating System to kill the worker.

The exit codes of the workers are {SIGBUS(-7)}
  0%|          | 0/5 [01:57<?, ?it/s]
Traceback (most recent call last):
  File "ft_official.py", line 118, in <module>
    main()
  File "ft_official.py", line 100, in main
    model.train_vispel()
  File "/home/users/apopescu/van-khoa/Vis-Priva-Expos/privacy/vispel/vispel/vispel.py", line 54, in train_vispel
    trained_clusteror, trained_regressor, feature_selector = trainer(self.situation, self.X_train, self.X_community,\
  File "/home/users/apopescu/van-khoa/Vis-Priva-Expos/privacy/vispel/vispel/trainer.py", line 64, in trainer
    trained_regressor = train_regressor(regressor, X_train_rd, gt_train_expos, cfg)
  File "/home/users/apopescu/van-khoa/Vis-Priva-Expos/privacy/lib/regressor/regression.py", line 22, in train_regressor
    model.fit(x_train, y_train)
  File "/home/users/apopescu/anaconda3/envs/detectron2/lib/python3.8/site-packages/sklearn/utils/validation.py", line 73, in inner_f
    return f(**kwargs)
  File "/home/users/apopescu/anaconda3/envs/detectron2/lib/python3.8/site-packages/sklearn/model_selection/_search.py", line 736, in fit
    self._run_search(evaluate_candidates)
  File "/home/users/apopescu/anaconda3/envs/detectron2/lib/python3.8/site-packages/sklearn/model_selection/_search.py", line 1188, in _run_search
    evaluate_candidates(ParameterGrid(self.param_grid))
  File "/home/users/apopescu/anaconda3/envs/detectron2/lib/python3.8/site-packages/sklearn/model_selection/_search.py", line 708, in evaluate_candidates
    out = parallel(delayed(_fit_and_score)(clone(base_estimator),
  File "/home/users/apopescu/anaconda3/envs/detectron2/lib/python3.8/site-packages/joblib/parallel.py", line 1042, in __call__
    self.retrieve()
  File "/home/users/apopescu/anaconda3/envs/detectron2/lib/python3.8/site-packages/joblib/parallel.py", line 921, in retrieve
    self._output.extend(job.get(timeout=self.timeout))
  File "/home/users/apopescu/anaconda3/envs/detectron2/lib/python3.8/site-packages/joblib/_parallel_backends.py", line 542, in wrap_future_result
    return future.result(timeout=timeout)
  File "/home/users/apopescu/anaconda3/envs/detectron2/lib/python3.8/concurrent/futures/_base.py", line 439, in result
    return self.__get_result()
  File "/home/users/apopescu/anaconda3/envs/detectron2/lib/python3.8/concurrent/futures/_base.py", line 388, in __get_result
    raise self._exception
  File "/home/users/apopescu/anaconda3/envs/detectron2/lib/python3.8/site-packages/joblib/externals/loky/_base.py", line 625, in _invoke_callbacks
    callback(self)
  File "/home/users/apopescu/anaconda3/envs/detectron2/lib/python3.8/site-packages/joblib/parallel.py", line 347, in __call__
    self.parallel.dispatch_next()
  File "/home/users/apopescu/anaconda3/envs/detectron2/lib/python3.8/site-packages/joblib/parallel.py", line 780, in dispatch_next
    if not self.dispatch_one_batch(self._original_iterator):
  File "/home/users/apopescu/anaconda3/envs/detectron2/lib/python3.8/site-packages/joblib/parallel.py", line 847, in dispatch_one_batch
    self._dispatch(tasks)
  File "/home/users/apopescu/anaconda3/envs/detectron2/lib/python3.8/site-packages/joblib/parallel.py", line 765, in _dispatch
    job = self._backend.apply_async(batch, callback=cb)
  File "/home/users/apopescu/anaconda3/envs/detectron2/lib/python3.8/site-packages/joblib/_parallel_backends.py", line 531, in apply_async
    future = self._workers.submit(SafeFunction(func))
  File "/home/users/apopescu/anaconda3/envs/detectron2/lib/python3.8/site-packages/joblib/externals/loky/reusable_executor.py", line 177, in submit
    return super(_ReusablePoolExecutor, self).submit(
  File "/home/users/apopescu/anaconda3/envs/detectron2/lib/python3.8/site-packages/joblib/externals/loky/process_executor.py", line 1102, in submit
    raise self._flags.broken
joblib.externals.loky.process_executor.TerminatedWorkerError: A worker process managed by the executor was unexpectedly terminated. This could be caused by a segmentation fault while calling the function or by an excessive memory usage causing the Operating System to kill the worker.

The exit codes of the workers are {SIGBUS(-7)}
/home/users/apopescu/anaconda3/envs/detectron2/lib/python3.8/site-packages/joblib/externals/loky/backend/resource_tracker.py:318: UserWarning: resource_tracker: There appear to be 7 leaked semlock objects to clean up at shutdown
  warnings.warn('resource_tracker: There appear to be %d '
/home/users/apopescu/anaconda3/envs/detectron2/lib/python3.8/site-packages/joblib/externals/loky/backend/resource_tracker.py:318: UserWarning: resource_tracker: There appear to be 2 leaked folder objects to clean up at shutdown
  warnings.warn('resource_tracker: There appear to be %d '
Traceback (most recent call last):
  File "/home/users/apopescu/anaconda3/envs/detectron2/lib/python3.8/site-packages/joblib/externals/loky/backend/resource_tracker.py", line 281, in main
    del registry[rtype][name]
KeyError: '/loky-173584-wem5ft4y'
Traceback (most recent call last):
  File "/home/users/apopescu/anaconda3/envs/detectron2/lib/python3.8/site-packages/joblib/externals/loky/backend/resource_tracker.py", line 281, in main
    del registry[rtype][name]
KeyError: '/loky-173584-z3jvwhvr'
Traceback (most recent call last):
  File "/home/users/apopescu/anaconda3/envs/detectron2/lib/python3.8/site-packages/joblib/externals/loky/backend/resource_tracker.py", line 281, in main
    del registry[rtype][name]
KeyError: '/loky-173584-uemmtl2v'
Traceback (most recent call last):
  File "/home/users/apopescu/anaconda3/envs/detectron2/lib/python3.8/site-packages/joblib/externals/loky/backend/resource_tracker.py", line 281, in main
    del registry[rtype][name]
KeyError: '/loky-173584-7vj1zcem'
Traceback (most recent call last):
  File "/home/users/apopescu/anaconda3/envs/detectron2/lib/python3.8/site-packages/joblib/externals/loky/backend/resource_tracker.py", line 281, in main
    del registry[rtype][name]
KeyError: '/loky-173584-72odb6rr'
Traceback (most recent call last):
  File "/home/users/apopescu/anaconda3/envs/detectron2/lib/python3.8/site-packages/joblib/externals/loky/backend/resource_tracker.py", line 281, in main
    del registry[rtype][name]
KeyError: '/loky-173584-caa9fthn'
Traceback (most recent call last):
  File "/home/users/apopescu/anaconda3/envs/detectron2/lib/python3.8/site-packages/joblib/externals/loky/backend/resource_tracker.py", line 281, in main
    del registry[rtype][name]
KeyError: '/loky-173584-vhzzqmj5'
Traceback (most recent call last):
  File "/home/users/apopescu/anaconda3/envs/detectron2/lib/python3.8/site-packages/joblib/externals/loky/backend/resource_tracker.py", line 281, in main
    del registry[rtype][name]
KeyError: '/loky-173584-p4zewwp0'
Traceback (most recent call last):
  File "/home/users/apopescu/anaconda3/envs/detectron2/lib/python3.8/site-packages/joblib/externals/loky/backend/resource_tracker.py", line 281, in main
    del registry[rtype][name]
KeyError: '/dev/shm/joblib_memmapping_folder_173584_d22b8e7e57f1400f9971f56cf3242259_62ad8da4e35445948602b11fe64442f9'
Traceback (most recent call last):
  File "/home/users/apopescu/anaconda3/envs/detectron2/lib/python3.8/site-packages/joblib/externals/loky/backend/resource_tracker.py", line 281, in main
    del registry[rtype][name]
KeyError: '/dev/shm/joblib_memmapping_folder_173584_d22b8e7e57f1400f9971f56cf3242259_c2105b4bb09e417685023ef8eb878abf'
Traceback (most recent call last):
  File "/home/users/apopescu/anaconda3/envs/detectron2/lib/python3.8/site-packages/joblib/externals/loky/backend/resource_tracker.py", line 281, in main
    del registry[rtype][name]
KeyError: '/dev/shm/joblib_memmapping_folder_173536_50582ec4e63b4621aaf9004da974adaa_153a48f5a60e45679795bb0bd5d4d10c'
Traceback (most recent call last):
  File "/home/users/apopescu/anaconda3/envs/detectron2/lib/python3.8/site-packages/joblib/externals/loky/backend/resource_tracker.py", line 281, in main
    del registry[rtype][name]
KeyError: '/loky-173536-_is90f52'
Traceback (most recent call last):
  File "/home/users/apopescu/anaconda3/envs/detectron2/lib/python3.8/site-packages/joblib/externals/loky/backend/resource_tracker.py", line 281, in main
    del registry[rtype][name]
KeyError: '/loky-173536-e6spu66y'
Traceback (most recent call last):
  File "/home/users/apopescu/anaconda3/envs/detectron2/lib/python3.8/site-packages/joblib/externals/loky/backend/resource_tracker.py", line 281, in main
    del registry[rtype][name]
KeyError: '/loky-173536-0vrx6a0q'
Traceback (most recent call last):
  File "/home/users/apopescu/anaconda3/envs/detectron2/lib/python3.8/site-packages/joblib/externals/loky/backend/resource_tracker.py", line 281, in main
    del registry[rtype][name]
KeyError: '/loky-173536-ouo4a2fq'
Traceback (most recent call last):
  File "/home/users/apopescu/anaconda3/envs/detectron2/lib/python3.8/site-packages/joblib/externals/loky/backend/resource_tracker.py", line 281, in main
    del registry[rtype][name]
KeyError: '/loky-173536-aa2qd6sw'
Traceback (most recent call last):
  File "/home/users/apopescu/anaconda3/envs/detectron2/lib/python3.8/site-packages/joblib/externals/loky/backend/resource_tracker.py", line 281, in main
    del registry[rtype][name]
KeyError: '/loky-173536-ytf3dwx0'
Traceback (most recent call last):
  File "/home/users/apopescu/anaconda3/envs/detectron2/lib/python3.8/site-packages/joblib/externals/loky/backend/resource_tracker.py", line 281, in main
    del registry[rtype][name]
KeyError: '/loky-173536-t3yoek9d'
Traceback (most recent call last):
  File "/home/users/apopescu/anaconda3/envs/detectron2/lib/python3.8/site-packages/joblib/externals/loky/backend/resource_tracker.py", line 281, in main
    del registry[rtype][name]
KeyError: '/loky-173536-0vmigbt0'
Traceback (most recent call last):
  File "/home/users/apopescu/anaconda3/envs/detectron2/lib/python3.8/site-packages/joblib/externals/loky/backend/resource_tracker.py", line 281, in main
    del registry[rtype][name]
KeyError: '/loky-173536-n3wipz2z'
Traceback (most recent call last):
  File "/home/users/apopescu/anaconda3/envs/detectron2/lib/python3.8/site-packages/joblib/externals/loky/backend/resource_tracker.py", line 281, in main
    del registry[rtype][name]
KeyError: '/loky-173536-7s9698j2'
Traceback (most recent call last):
  File "/home/users/apopescu/anaconda3/envs/detectron2/lib/python3.8/site-packages/joblib/externals/loky/backend/resource_tracker.py", line 281, in main
    del registry[rtype][name]
KeyError: '/loky-173536-6915nq57'
Traceback (most recent call last):
  File "/home/users/apopescu/anaconda3/envs/detectron2/lib/python3.8/site-packages/joblib/externals/loky/backend/resource_tracker.py", line 281, in main
    del registry[rtype][name]
KeyError: '/loky-173536-vqvuzcjb'
exception calling callback for <Future at 0x2b96400d5190 state=finished raised TerminatedWorkerError>
Traceback (most recent call last):
  File "/home/users/apopescu/anaconda3/envs/detectron2/lib/python3.8/site-packages/joblib/externals/loky/_base.py", line 625, in _invoke_callbacks
    callback(self)
  File "/home/users/apopescu/anaconda3/envs/detectron2/lib/python3.8/site-packages/joblib/parallel.py", line 347, in __call__
    self.parallel.dispatch_next()
  File "/home/users/apopescu/anaconda3/envs/detectron2/lib/python3.8/site-packages/joblib/parallel.py", line 780, in dispatch_next
    if not self.dispatch_one_batch(self._original_iterator):
  File "/home/users/apopescu/anaconda3/envs/detectron2/lib/python3.8/site-packages/joblib/parallel.py", line 847, in dispatch_one_batch
    self._dispatch(tasks)
  File "/home/users/apopescu/anaconda3/envs/detectron2/lib/python3.8/site-packages/joblib/parallel.py", line 765, in _dispatch
    job = self._backend.apply_async(batch, callback=cb)
  File "/home/users/apopescu/anaconda3/envs/detectron2/lib/python3.8/site-packages/joblib/_parallel_backends.py", line 531, in apply_async
    future = self._workers.submit(SafeFunction(func))
  File "/home/users/apopescu/anaconda3/envs/detectron2/lib/python3.8/site-packages/joblib/externals/loky/reusable_executor.py", line 177, in submit
    return super(_ReusablePoolExecutor, self).submit(
  File "/home/users/apopescu/anaconda3/envs/detectron2/lib/python3.8/site-packages/joblib/externals/loky/process_executor.py", line 1102, in submit
    raise self._flags.broken
joblib.externals.loky.process_executor.TerminatedWorkerError: A worker process managed by the executor was unexpectedly terminated. This could be caused by a segmentation fault while calling the function or by an excessive memory usage causing the Operating System to kill the worker.

The exit codes of the workers are {SIGKILL(-9)}
exception calling callback for <Future at 0x2b964007e910 state=finished raised TerminatedWorkerError>
Traceback (most recent call last):
  File "/home/users/apopescu/anaconda3/envs/detectron2/lib/python3.8/site-packages/joblib/externals/loky/_base.py", line 625, in _invoke_callbacks
    callback(self)
  File "/home/users/apopescu/anaconda3/envs/detectron2/lib/python3.8/site-packages/joblib/parallel.py", line 347, in __call__
    self.parallel.dispatch_next()
  File "/home/users/apopescu/anaconda3/envs/detectron2/lib/python3.8/site-packages/joblib/parallel.py", line 780, in dispatch_next
    if not self.dispatch_one_batch(self._original_iterator):
  File "/home/users/apopescu/anaconda3/envs/detectron2/lib/python3.8/site-packages/joblib/parallel.py", line 847, in dispatch_one_batch
    self._dispatch(tasks)
  File "/home/users/apopescu/anaconda3/envs/detectron2/lib/python3.8/site-packages/joblib/parallel.py", line 765, in _dispatch
    job = self._backend.apply_async(batch, callback=cb)
  File "/home/users/apopescu/anaconda3/envs/detectron2/lib/python3.8/site-packages/joblib/_parallel_backends.py", line 531, in apply_async
    future = self._workers.submit(SafeFunction(func))
  File "/home/users/apopescu/anaconda3/envs/detectron2/lib/python3.8/site-packages/joblib/externals/loky/reusable_executor.py", line 177, in submit
    return super(_ReusablePoolExecutor, self).submit(
  File "/home/users/apopescu/anaconda3/envs/detectron2/lib/python3.8/site-packages/joblib/externals/loky/process_executor.py", line 1102, in submit
    raise self._flags.broken
  File "/home/users/apopescu/anaconda3/envs/detectron2/lib/python3.8/site-packages/joblib/externals/loky/_base.py", line 625, in _invoke_callbacks
    callback(self)
  File "/home/users/apopescu/anaconda3/envs/detectron2/lib/python3.8/site-packages/joblib/parallel.py", line 347, in __call__
    self.parallel.dispatch_next()
  File "/home/users/apopescu/anaconda3/envs/detectron2/lib/python3.8/site-packages/joblib/parallel.py", line 780, in dispatch_next
    if not self.dispatch_one_batch(self._original_iterator):
  File "/home/users/apopescu/anaconda3/envs/detectron2/lib/python3.8/site-packages/joblib/parallel.py", line 847, in dispatch_one_batch
    self._dispatch(tasks)
  File "/home/users/apopescu/anaconda3/envs/detectron2/lib/python3.8/site-packages/joblib/parallel.py", line 765, in _dispatch
    job = self._backend.apply_async(batch, callback=cb)
  File "/home/users/apopescu/anaconda3/envs/detectron2/lib/python3.8/site-packages/joblib/_parallel_backends.py", line 531, in apply_async
    future = self._workers.submit(SafeFunction(func))
  File "/home/users/apopescu/anaconda3/envs/detectron2/lib/python3.8/site-packages/joblib/externals/loky/reusable_executor.py", line 177, in submit
    return super(_ReusablePoolExecutor, self).submit(
  File "/home/users/apopescu/anaconda3/envs/detectron2/lib/python3.8/site-packages/joblib/externals/loky/process_executor.py", line 1102, in submit
    raise self._flags.broken
joblib.externals.loky.process_executor.TerminatedWorkerError: A worker process managed by the executor was unexpectedly terminated. This could be caused by a segmentation fault while calling the function or by an excessive memory usage causing the Operating System to kill the worker.

The exit codes of the workers are {SIGKILL(-9)}
exception calling callback for <Future at 0x2b964007ed60 state=finished raised TerminatedWorkerError>
Traceback (most recent call last):
  File "/home/users/apopescu/anaconda3/envs/detectron2/lib/python3.8/site-packages/joblib/externals/loky/_base.py", line 625, in _invoke_callbacks
    callback(self)
  File "/home/users/apopescu/anaconda3/envs/detectron2/lib/python3.8/site-packages/joblib/parallel.py", line 347, in __call__
    self.parallel.dispatch_next()
  File "/home/users/apopescu/anaconda3/envs/detectron2/lib/python3.8/site-packages/joblib/parallel.py", line 780, in dispatch_next
    if not self.dispatch_one_batch(self._original_iterator):
  File "/home/users/apopescu/anaconda3/envs/detectron2/lib/python3.8/site-packages/joblib/parallel.py", line 847, in dispatch_one_batch
    self._dispatch(tasks)
  File "/home/users/apopescu/anaconda3/envs/detectron2/lib/python3.8/site-packages/joblib/parallel.py", line 765, in _dispatch
    job = self._backend.apply_async(batch, callback=cb)
  File "/home/users/apopescu/anaconda3/envs/detectron2/lib/python3.8/site-packages/joblib/_parallel_backends.py", line 531, in apply_async
    future = self._workers.submit(SafeFunction(func))
  File "/home/users/apopescu/anaconda3/envs/detectron2/lib/python3.8/site-packages/joblib/externals/loky/reusable_executor.py", line 177, in submit
    return super(_ReusablePoolExecutor, self).submit(
  File "/home/users/apopescu/anaconda3/envs/detectron2/lib/python3.8/site-packages/joblib/externals/loky/process_executor.py", line 1102, in submit
    raise self._flags.broken
  File "/home/users/apopescu/anaconda3/envs/detectron2/lib/python3.8/site-packages/joblib/externals/loky/_base.py", line 625, in _invoke_callbacks
    callback(self)
  File "/home/users/apopescu/anaconda3/envs/detectron2/lib/python3.8/site-packages/joblib/parallel.py", line 347, in __call__
    self.parallel.dispatch_next()
  File "/home/users/apopescu/anaconda3/envs/detectron2/lib/python3.8/site-packages/joblib/parallel.py", line 780, in dispatch_next
    if not self.dispatch_one_batch(self._original_iterator):
  File "/home/users/apopescu/anaconda3/envs/detectron2/lib/python3.8/site-packages/joblib/parallel.py", line 847, in dispatch_one_batch
    self._dispatch(tasks)
  File "/home/users/apopescu/anaconda3/envs/detectron2/lib/python3.8/site-packages/joblib/parallel.py", line 765, in _dispatch
    job = self._backend.apply_async(batch, callback=cb)
  File "/home/users/apopescu/anaconda3/envs/detectron2/lib/python3.8/site-packages/joblib/_parallel_backends.py", line 531, in apply_async
    future = self._workers.submit(SafeFunction(func))
  File "/home/users/apopescu/anaconda3/envs/detectron2/lib/python3.8/site-packages/joblib/externals/loky/reusable_executor.py", line 177, in submit
    return super(_ReusablePoolExecutor, self).submit(
  File "/home/users/apopescu/anaconda3/envs/detectron2/lib/python3.8/site-packages/joblib/externals/loky/process_executor.py", line 1102, in submit
    raise self._flags.broken
  File "/home/users/apopescu/anaconda3/envs/detectron2/lib/python3.8/site-packages/joblib/externals/loky/_base.py", line 625, in _invoke_callbacks
    callback(self)
  File "/home/users/apopescu/anaconda3/envs/detectron2/lib/python3.8/site-packages/joblib/parallel.py", line 347, in __call__
    self.parallel.dispatch_next()
  File "/home/users/apopescu/anaconda3/envs/detectron2/lib/python3.8/site-packages/joblib/parallel.py", line 780, in dispatch_next
    if not self.dispatch_one_batch(self._original_iterator):
  File "/home/users/apopescu/anaconda3/envs/detectron2/lib/python3.8/site-packages/joblib/parallel.py", line 847, in dispatch_one_batch
    self._dispatch(tasks)
  File "/home/users/apopescu/anaconda3/envs/detectron2/lib/python3.8/site-packages/joblib/parallel.py", line 765, in _dispatch
    job = self._backend.apply_async(batch, callback=cb)
  File "/home/users/apopescu/anaconda3/envs/detectron2/lib/python3.8/site-packages/joblib/_parallel_backends.py", line 531, in apply_async
    future = self._workers.submit(SafeFunction(func))
  File "/home/users/apopescu/anaconda3/envs/detectron2/lib/python3.8/site-packages/joblib/externals/loky/reusable_executor.py", line 177, in submit
    return super(_ReusablePoolExecutor, self).submit(
  File "/home/users/apopescu/anaconda3/envs/detectron2/lib/python3.8/site-packages/joblib/externals/loky/process_executor.py", line 1102, in submit
    raise self._flags.broken
joblib.externals.loky.process_executor.TerminatedWorkerError: A worker process managed by the executor was unexpectedly terminated. This could be caused by a segmentation fault while calling the function or by an excessive memory usage causing the Operating System to kill the worker.

The exit codes of the workers are {SIGKILL(-9)}
exception calling callback for <Future at 0x2acbbf87f190 state=finished raised TerminatedWorkerError>
Traceback (most recent call last):
  File "/home/users/apopescu/anaconda3/envs/detectron2/lib/python3.8/site-packages/joblib/externals/loky/_base.py", line 625, in _invoke_callbacks
    callback(self)
  File "/home/users/apopescu/anaconda3/envs/detectron2/lib/python3.8/site-packages/joblib/parallel.py", line 347, in __call__
    self.parallel.dispatch_next()
  File "/home/users/apopescu/anaconda3/envs/detectron2/lib/python3.8/site-packages/joblib/parallel.py", line 780, in dispatch_next
    if not self.dispatch_one_batch(self._original_iterator):
  File "/home/users/apopescu/anaconda3/envs/detectron2/lib/python3.8/site-packages/joblib/parallel.py", line 847, in dispatch_one_batch
    self._dispatch(tasks)
  File "/home/users/apopescu/anaconda3/envs/detectron2/lib/python3.8/site-packages/joblib/parallel.py", line 765, in _dispatch
    job = self._backend.apply_async(batch, callback=cb)
  File "/home/users/apopescu/anaconda3/envs/detectron2/lib/python3.8/site-packages/joblib/_parallel_backends.py", line 531, in apply_async
    future = self._workers.submit(SafeFunction(func))
  File "/home/users/apopescu/anaconda3/envs/detectron2/lib/python3.8/site-packages/joblib/externals/loky/reusable_executor.py", line 177, in submit
    return super(_ReusablePoolExecutor, self).submit(
  File "/home/users/apopescu/anaconda3/envs/detectron2/lib/python3.8/site-packages/joblib/externals/loky/process_executor.py", line 1102, in submit
    raise self._flags.broken
joblib.externals.loky.process_executor.TerminatedWorkerError: A worker process managed by the executor was unexpectedly terminated. This could be caused by a segmentation fault while calling the function or by an excessive memory usage causing the Operating System to kill the worker.

The exit codes of the workers are {SIGBUS(-7)}
exception calling callback for <Future at 0x2acbbf862910 state=finished raised TerminatedWorkerError>
Traceback (most recent call last):
  File "/home/users/apopescu/anaconda3/envs/detectron2/lib/python3.8/site-packages/joblib/externals/loky/_base.py", line 625, in _invoke_callbacks
    callback(self)
  File "/home/users/apopescu/anaconda3/envs/detectron2/lib/python3.8/site-packages/joblib/parallel.py", line 347, in __call__
    self.parallel.dispatch_next()
  File "/home/users/apopescu/anaconda3/envs/detectron2/lib/python3.8/site-packages/joblib/parallel.py", line 780, in dispatch_next
    if not self.dispatch_one_batch(self._original_iterator):
  File "/home/users/apopescu/anaconda3/envs/detectron2/lib/python3.8/site-packages/joblib/parallel.py", line 847, in dispatch_one_batch
    self._dispatch(tasks)
  File "/home/users/apopescu/anaconda3/envs/detectron2/lib/python3.8/site-packages/joblib/parallel.py", line 765, in _dispatch
    job = self._backend.apply_async(batch, callback=cb)
  File "/home/users/apopescu/anaconda3/envs/detectron2/lib/python3.8/site-packages/joblib/_parallel_backends.py", line 531, in apply_async
    future = self._workers.submit(SafeFunction(func))
  File "/home/users/apopescu/anaconda3/envs/detectron2/lib/python3.8/site-packages/joblib/externals/loky/reusable_executor.py", line 177, in submit
    return super(_ReusablePoolExecutor, self).submit(
  File "/home/users/apopescu/anaconda3/envs/detectron2/lib/python3.8/site-packages/joblib/externals/loky/process_executor.py", line 1102, in submit
    raise self._flags.broken
  File "/home/users/apopescu/anaconda3/envs/detectron2/lib/python3.8/site-packages/joblib/externals/loky/_base.py", line 625, in _invoke_callbacks
    callback(self)
  File "/home/users/apopescu/anaconda3/envs/detectron2/lib/python3.8/site-packages/joblib/parallel.py", line 347, in __call__
    self.parallel.dispatch_next()
  File "/home/users/apopescu/anaconda3/envs/detectron2/lib/python3.8/site-packages/joblib/parallel.py", line 780, in dispatch_next
    if not self.dispatch_one_batch(self._original_iterator):
  File "/home/users/apopescu/anaconda3/envs/detectron2/lib/python3.8/site-packages/joblib/parallel.py", line 847, in dispatch_one_batch
    self._dispatch(tasks)
  File "/home/users/apopescu/anaconda3/envs/detectron2/lib/python3.8/site-packages/joblib/parallel.py", line 765, in _dispatch
    job = self._backend.apply_async(batch, callback=cb)
  File "/home/users/apopescu/anaconda3/envs/detectron2/lib/python3.8/site-packages/joblib/_parallel_backends.py", line 531, in apply_async
    future = self._workers.submit(SafeFunction(func))
  File "/home/users/apopescu/anaconda3/envs/detectron2/lib/python3.8/site-packages/joblib/externals/loky/reusable_executor.py", line 177, in submit
    return super(_ReusablePoolExecutor, self).submit(
  File "/home/users/apopescu/anaconda3/envs/detectron2/lib/python3.8/site-packages/joblib/externals/loky/process_executor.py", line 1102, in submit
    raise self._flags.broken
joblib.externals.loky.process_executor.TerminatedWorkerError: A worker process managed by the executor was unexpectedly terminated. This could be caused by a segmentation fault while calling the function or by an excessive memory usage causing the Operating System to kill the worker.

The exit codes of the workers are {SIGBUS(-7)}
exception calling callback for <Future at 0x2acbbf862d60 state=finished raised TerminatedWorkerError>
Traceback (most recent call last):
  File "/home/users/apopescu/anaconda3/envs/detectron2/lib/python3.8/site-packages/joblib/externals/loky/_base.py", line 625, in _invoke_callbacks
    callback(self)
  File "/home/users/apopescu/anaconda3/envs/detectron2/lib/python3.8/site-packages/joblib/parallel.py", line 347, in __call__
    self.parallel.dispatch_next()
  File "/home/users/apopescu/anaconda3/envs/detectron2/lib/python3.8/site-packages/joblib/parallel.py", line 780, in dispatch_next
    if not self.dispatch_one_batch(self._original_iterator):
  File "/home/users/apopescu/anaconda3/envs/detectron2/lib/python3.8/site-packages/joblib/parallel.py", line 847, in dispatch_one_batch
    self._dispatch(tasks)
  File "/home/users/apopescu/anaconda3/envs/detectron2/lib/python3.8/site-packages/joblib/parallel.py", line 765, in _dispatch
    job = self._backend.apply_async(batch, callback=cb)
  File "/home/users/apopescu/anaconda3/envs/detectron2/lib/python3.8/site-packages/joblib/_parallel_backends.py", line 531, in apply_async
    future = self._workers.submit(SafeFunction(func))
  File "/home/users/apopescu/anaconda3/envs/detectron2/lib/python3.8/site-packages/joblib/externals/loky/reusable_executor.py", line 177, in submit
    return super(_ReusablePoolExecutor, self).submit(
  File "/home/users/apopescu/anaconda3/envs/detectron2/lib/python3.8/site-packages/joblib/externals/loky/process_executor.py", line 1102, in submit
    raise self._flags.broken
  File "/home/users/apopescu/anaconda3/envs/detectron2/lib/python3.8/site-packages/joblib/externals/loky/_base.py", line 625, in _invoke_callbacks
    callback(self)
  File "/home/users/apopescu/anaconda3/envs/detectron2/lib/python3.8/site-packages/joblib/parallel.py", line 347, in __call__
    self.parallel.dispatch_next()
  File "/home/users/apopescu/anaconda3/envs/detectron2/lib/python3.8/site-packages/joblib/parallel.py", line 780, in dispatch_next
    if not self.dispatch_one_batch(self._original_iterator):
  File "/home/users/apopescu/anaconda3/envs/detectron2/lib/python3.8/site-packages/joblib/parallel.py", line 847, in dispatch_one_batch
    self._dispatch(tasks)
  File "/home/users/apopescu/anaconda3/envs/detectron2/lib/python3.8/site-packages/joblib/parallel.py", line 765, in _dispatch
    job = self._backend.apply_async(batch, callback=cb)
  File "/home/users/apopescu/anaconda3/envs/detectron2/lib/python3.8/site-packages/joblib/_parallel_backends.py", line 531, in apply_async
    future = self._workers.submit(SafeFunction(func))
  File "/home/users/apopescu/anaconda3/envs/detectron2/lib/python3.8/site-packages/joblib/externals/loky/reusable_executor.py", line 177, in submit
    return super(_ReusablePoolExecutor, self).submit(
  File "/home/users/apopescu/anaconda3/envs/detectron2/lib/python3.8/site-packages/joblib/externals/loky/process_executor.py", line 1102, in submit
    raise self._flags.broken
  File "/home/users/apopescu/anaconda3/envs/detectron2/lib/python3.8/site-packages/joblib/externals/loky/_base.py", line 625, in _invoke_callbacks
    callback(self)
  File "/home/users/apopescu/anaconda3/envs/detectron2/lib/python3.8/site-packages/joblib/parallel.py", line 347, in __call__
    self.parallel.dispatch_next()
  File "/home/users/apopescu/anaconda3/envs/detectron2/lib/python3.8/site-packages/joblib/parallel.py", line 780, in dispatch_next
    if not self.dispatch_one_batch(self._original_iterator):
  File "/home/users/apopescu/anaconda3/envs/detectron2/lib/python3.8/site-packages/joblib/parallel.py", line 847, in dispatch_one_batch
    self._dispatch(tasks)
  File "/home/users/apopescu/anaconda3/envs/detectron2/lib/python3.8/site-packages/joblib/parallel.py", line 765, in _dispatch
    job = self._backend.apply_async(batch, callback=cb)
  File "/home/users/apopescu/anaconda3/envs/detectron2/lib/python3.8/site-packages/joblib/_parallel_backends.py", line 531, in apply_async
    future = self._workers.submit(SafeFunction(func))
  File "/home/users/apopescu/anaconda3/envs/detectron2/lib/python3.8/site-packages/joblib/externals/loky/reusable_executor.py", line 177, in submit
    return super(_ReusablePoolExecutor, self).submit(
  File "/home/users/apopescu/anaconda3/envs/detectron2/lib/python3.8/site-packages/joblib/externals/loky/process_executor.py", line 1102, in submit
    raise self._flags.broken
joblib.externals.loky.process_executor.TerminatedWorkerError: A worker process managed by the executor was unexpectedly terminated. This could be caused by a segmentation fault while calling the function or by an excessive memory usage causing the Operating System to kill the worker.

The exit codes of the workers are {SIGBUS(-7)}
exception calling callback for <Future at 0x2acbbf862e80 state=finished raised TerminatedWorkerError>
Traceback (most recent call last):
  File "/home/users/apopescu/anaconda3/envs/detectron2/lib/python3.8/site-packages/joblib/externals/loky/_base.py", line 625, in _invoke_callbacks
    callback(self)
  File "/home/users/apopescu/anaconda3/envs/detectron2/lib/python3.8/site-packages/joblib/parallel.py", line 347, in __call__
    self.parallel.dispatch_next()
  File "/home/users/apopescu/anaconda3/envs/detectron2/lib/python3.8/site-packages/joblib/parallel.py", line 780, in dispatch_next
    if not self.dispatch_one_batch(self._original_iterator):
  File "/home/users/apopescu/anaconda3/envs/detectron2/lib/python3.8/site-packages/joblib/parallel.py", line 847, in dispatch_one_batch
    self._dispatch(tasks)
  File "/home/users/apopescu/anaconda3/envs/detectron2/lib/python3.8/site-packages/joblib/parallel.py", line 765, in _dispatch
    job = self._backend.apply_async(batch, callback=cb)
  File "/home/users/apopescu/anaconda3/envs/detectron2/lib/python3.8/site-packages/joblib/_parallel_backends.py", line 531, in apply_async
    future = self._workers.submit(SafeFunction(func))
  File "/home/users/apopescu/anaconda3/envs/detectron2/lib/python3.8/site-packages/joblib/externals/loky/reusable_executor.py", line 177, in submit
    return super(_ReusablePoolExecutor, self).submit(
  File "/home/users/apopescu/anaconda3/envs/detectron2/lib/python3.8/site-packages/joblib/externals/loky/process_executor.py", line 1102, in submit
    raise self._flags.broken
  File "/home/users/apopescu/anaconda3/envs/detectron2/lib/python3.8/site-packages/joblib/externals/loky/_base.py", line 625, in _invoke_callbacks
    callback(self)
  File "/home/users/apopescu/anaconda3/envs/detectron2/lib/python3.8/site-packages/joblib/parallel.py", line 347, in __call__
    self.parallel.dispatch_next()
  File "/home/users/apopescu/anaconda3/envs/detectron2/lib/python3.8/site-packages/joblib/parallel.py", line 780, in dispatch_next
    if not self.dispatch_one_batch(self._original_iterator):
  File "/home/users/apopescu/anaconda3/envs/detectron2/lib/python3.8/site-packages/joblib/parallel.py", line 847, in dispatch_one_batch
    self._dispatch(tasks)
  File "/home/users/apopescu/anaconda3/envs/detectron2/lib/python3.8/site-packages/joblib/parallel.py", line 765, in _dispatch
    job = self._backend.apply_async(batch, callback=cb)
  File "/home/users/apopescu/anaconda3/envs/detectron2/lib/python3.8/site-packages/joblib/_parallel_backends.py", line 531, in apply_async
    future = self._workers.submit(SafeFunction(func))
  File "/home/users/apopescu/anaconda3/envs/detectron2/lib/python3.8/site-packages/joblib/externals/loky/reusable_executor.py", line 177, in submit
    return super(_ReusablePoolExecutor, self).submit(
  File "/home/users/apopescu/anaconda3/envs/detectron2/lib/python3.8/site-packages/joblib/externals/loky/process_executor.py", line 1102, in submit
    raise self._flags.broken
  File "/home/users/apopescu/anaconda3/envs/detectron2/lib/python3.8/site-packages/joblib/externals/loky/_base.py", line 625, in _invoke_callbacks
    callback(self)
  File "/home/users/apopescu/anaconda3/envs/detectron2/lib/python3.8/site-packages/joblib/parallel.py", line 347, in __call__
    self.parallel.dispatch_next()
  File "/home/users/apopescu/anaconda3/envs/detectron2/lib/python3.8/site-packages/joblib/parallel.py", line 780, in dispatch_next
    if not self.dispatch_one_batch(self._original_iterator):
  File "/home/users/apopescu/anaconda3/envs/detectron2/lib/python3.8/site-packages/joblib/parallel.py", line 847, in dispatch_one_batch
    self._dispatch(tasks)
  File "/home/users/apopescu/anaconda3/envs/detectron2/lib/python3.8/site-packages/joblib/parallel.py", line 765, in _dispatch
    job = self._backend.apply_async(batch, callback=cb)
  File "/home/users/apopescu/anaconda3/envs/detectron2/lib/python3.8/site-packages/joblib/_parallel_backends.py", line 531, in apply_async
    future = self._workers.submit(SafeFunction(func))
  File "/home/users/apopescu/anaconda3/envs/detectron2/lib/python3.8/site-packages/joblib/externals/loky/reusable_executor.py", line 177, in submit
    return super(_ReusablePoolExecutor, self).submit(
  File "/home/users/apopescu/anaconda3/envs/detectron2/lib/python3.8/site-packages/joblib/externals/loky/process_executor.py", line 1102, in submit
    raise self._flags.broken
  File "/home/users/apopescu/anaconda3/envs/detectron2/lib/python3.8/site-packages/joblib/externals/loky/_base.py", line 625, in _invoke_callbacks
    callback(self)
  File "/home/users/apopescu/anaconda3/envs/detectron2/lib/python3.8/site-packages/joblib/parallel.py", line 347, in __call__
    self.parallel.dispatch_next()
  File "/home/users/apopescu/anaconda3/envs/detectron2/lib/python3.8/site-packages/joblib/parallel.py", line 780, in dispatch_next
    if not self.dispatch_one_batch(self._original_iterator):
  File "/home/users/apopescu/anaconda3/envs/detectron2/lib/python3.8/site-packages/joblib/parallel.py", line 847, in dispatch_one_batch
    self._dispatch(tasks)
  File "/home/users/apopescu/anaconda3/envs/detectron2/lib/python3.8/site-packages/joblib/parallel.py", line 765, in _dispatch
    job = self._backend.apply_async(batch, callback=cb)
  File "/home/users/apopescu/anaconda3/envs/detectron2/lib/python3.8/site-packages/joblib/_parallel_backends.py", line 531, in apply_async
    future = self._workers.submit(SafeFunction(func))
  File "/home/users/apopescu/anaconda3/envs/detectron2/lib/python3.8/site-packages/joblib/externals/loky/reusable_executor.py", line 177, in submit
    return super(_ReusablePoolExecutor, self).submit(
  File "/home/users/apopescu/anaconda3/envs/detectron2/lib/python3.8/site-packages/joblib/externals/loky/process_executor.py", line 1102, in submit
    raise self._flags.broken
joblib.externals.loky.process_executor.TerminatedWorkerError: A worker process managed by the executor was unexpectedly terminated. This could be caused by a segmentation fault while calling the function or by an excessive memory usage causing the Operating System to kill the worker.

The exit codes of the workers are {SIGBUS(-7)}
  0%|          | 0/5 [02:13<?, ?it/s]
Traceback (most recent call last):
  File "ft_official.py", line 118, in <module>
    main()
  File "ft_official.py", line 100, in main
    model.train_vispel()
  File "/home/users/apopescu/van-khoa/Vis-Priva-Expos/privacy/vispel/vispel/vispel.py", line 54, in train_vispel
    trained_clusteror, trained_regressor, feature_selector = trainer(self.situation, self.X_train, self.X_community,\
  File "/home/users/apopescu/van-khoa/Vis-Priva-Expos/privacy/vispel/vispel/trainer.py", line 64, in trainer
    trained_regressor = train_regressor(regressor, X_train_rd, gt_train_expos, cfg)
  File "/home/users/apopescu/van-khoa/Vis-Priva-Expos/privacy/lib/regressor/regression.py", line 22, in train_regressor
    model.fit(x_train, y_train)
  File "/home/users/apopescu/anaconda3/envs/detectron2/lib/python3.8/site-packages/sklearn/utils/validation.py", line 73, in inner_f
    return f(**kwargs)
  File "/home/users/apopescu/anaconda3/envs/detectron2/lib/python3.8/site-packages/sklearn/model_selection/_search.py", line 736, in fit
    self._run_search(evaluate_candidates)
  File "/home/users/apopescu/anaconda3/envs/detectron2/lib/python3.8/site-packages/sklearn/model_selection/_search.py", line 1188, in _run_search
    evaluate_candidates(ParameterGrid(self.param_grid))
  File "/home/users/apopescu/anaconda3/envs/detectron2/lib/python3.8/site-packages/sklearn/model_selection/_search.py", line 708, in evaluate_candidates
    out = parallel(delayed(_fit_and_score)(clone(base_estimator),
  File "/home/users/apopescu/anaconda3/envs/detectron2/lib/python3.8/site-packages/joblib/parallel.py", line 1042, in __call__
    self.retrieve()
  File "/home/users/apopescu/anaconda3/envs/detectron2/lib/python3.8/site-packages/joblib/parallel.py", line 921, in retrieve
    self._output.extend(job.get(timeout=self.timeout))
  File "/home/users/apopescu/anaconda3/envs/detectron2/lib/python3.8/site-packages/joblib/_parallel_backends.py", line 542, in wrap_future_result
    return future.result(timeout=timeout)
  File "/home/users/apopescu/anaconda3/envs/detectron2/lib/python3.8/concurrent/futures/_base.py", line 439, in result
    return self.__get_result()
  File "/home/users/apopescu/anaconda3/envs/detectron2/lib/python3.8/concurrent/futures/_base.py", line 388, in __get_result
    raise self._exception
  File "/home/users/apopescu/anaconda3/envs/detectron2/lib/python3.8/site-packages/joblib/externals/loky/_base.py", line 625, in _invoke_callbacks
    callback(self)
  File "/home/users/apopescu/anaconda3/envs/detectron2/lib/python3.8/site-packages/joblib/parallel.py", line 347, in __call__
    self.parallel.dispatch_next()
  File "/home/users/apopescu/anaconda3/envs/detectron2/lib/python3.8/site-packages/joblib/parallel.py", line 780, in dispatch_next
    if not self.dispatch_one_batch(self._original_iterator):
  File "/home/users/apopescu/anaconda3/envs/detectron2/lib/python3.8/site-packages/joblib/parallel.py", line 847, in dispatch_one_batch
    self._dispatch(tasks)
  File "/home/users/apopescu/anaconda3/envs/detectron2/lib/python3.8/site-packages/joblib/parallel.py", line 765, in _dispatch
    job = self._backend.apply_async(batch, callback=cb)
  File "/home/users/apopescu/anaconda3/envs/detectron2/lib/python3.8/site-packages/joblib/_parallel_backends.py", line 531, in apply_async
    future = self._workers.submit(SafeFunction(func))
  File "/home/users/apopescu/anaconda3/envs/detectron2/lib/python3.8/site-packages/joblib/externals/loky/reusable_executor.py", line 177, in submit
    return super(_ReusablePoolExecutor, self).submit(
  File "/home/users/apopescu/anaconda3/envs/detectron2/lib/python3.8/site-packages/joblib/externals/loky/process_executor.py", line 1102, in submit
    raise self._flags.broken
  File "/home/users/apopescu/anaconda3/envs/detectron2/lib/python3.8/site-packages/joblib/externals/loky/_base.py", line 625, in _invoke_callbacks
    callback(self)
  File "/home/users/apopescu/anaconda3/envs/detectron2/lib/python3.8/site-packages/joblib/parallel.py", line 347, in __call__
    self.parallel.dispatch_next()
  File "/home/users/apopescu/anaconda3/envs/detectron2/lib/python3.8/site-packages/joblib/parallel.py", line 780, in dispatch_next
    if not self.dispatch_one_batch(self._original_iterator):
  File "/home/users/apopescu/anaconda3/envs/detectron2/lib/python3.8/site-packages/joblib/parallel.py", line 847, in dispatch_one_batch
    self._dispatch(tasks)
  File "/home/users/apopescu/anaconda3/envs/detectron2/lib/python3.8/site-packages/joblib/parallel.py", line 765, in _dispatch
    job = self._backend.apply_async(batch, callback=cb)
  File "/home/users/apopescu/anaconda3/envs/detectron2/lib/python3.8/site-packages/joblib/_parallel_backends.py", line 531, in apply_async
    future = self._workers.submit(SafeFunction(func))
  File "/home/users/apopescu/anaconda3/envs/detectron2/lib/python3.8/site-packages/joblib/externals/loky/reusable_executor.py", line 177, in submit
    return super(_ReusablePoolExecutor, self).submit(
  File "/home/users/apopescu/anaconda3/envs/detectron2/lib/python3.8/site-packages/joblib/externals/loky/process_executor.py", line 1102, in submit
    raise self._flags.broken
  File "/home/users/apopescu/anaconda3/envs/detectron2/lib/python3.8/site-packages/joblib/externals/loky/_base.py", line 625, in _invoke_callbacks
    callback(self)
  File "/home/users/apopescu/anaconda3/envs/detectron2/lib/python3.8/site-packages/joblib/parallel.py", line 347, in __call__
    self.parallel.dispatch_next()
  File "/home/users/apopescu/anaconda3/envs/detectron2/lib/python3.8/site-packages/joblib/parallel.py", line 780, in dispatch_next
    if not self.dispatch_one_batch(self._original_iterator):
  File "/home/users/apopescu/anaconda3/envs/detectron2/lib/python3.8/site-packages/joblib/parallel.py", line 847, in dispatch_one_batch
    self._dispatch(tasks)
  File "/home/users/apopescu/anaconda3/envs/detectron2/lib/python3.8/site-packages/joblib/parallel.py", line 765, in _dispatch
    job = self._backend.apply_async(batch, callback=cb)
  File "/home/users/apopescu/anaconda3/envs/detectron2/lib/python3.8/site-packages/joblib/_parallel_backends.py", line 531, in apply_async
    future = self._workers.submit(SafeFunction(func))
  File "/home/users/apopescu/anaconda3/envs/detectron2/lib/python3.8/site-packages/joblib/externals/loky/reusable_executor.py", line 177, in submit
    return super(_ReusablePoolExecutor, self).submit(
  File "/home/users/apopescu/anaconda3/envs/detectron2/lib/python3.8/site-packages/joblib/externals/loky/process_executor.py", line 1102, in submit
    raise self._flags.broken
joblib.externals.loky.process_executor.TerminatedWorkerError: A worker process managed by the executor was unexpectedly terminated. This could be caused by a segmentation fault while calling the function or by an excessive memory usage causing the Operating System to kill the worker.

The exit codes of the workers are {SIGKILL(-9)}
/home/users/apopescu/anaconda3/envs/detectron2/lib/python3.8/site-packages/joblib/externals/loky/backend/resource_tracker.py:120: UserWarning: resource_tracker: process died unexpectedly, relaunching.  Some folders/sempahores might leak.
  warnings.warn('resource_tracker: process died unexpectedly, '
  0%|          | 0/5 [02:08<?, ?it/s]
Traceback (most recent call last):
  File "ft_official.py", line 118, in <module>
    main()
  File "ft_official.py", line 100, in main
    model.train_vispel()
  File "/home/users/apopescu/van-khoa/Vis-Priva-Expos/privacy/vispel/vispel/vispel.py", line 54, in train_vispel
    trained_clusteror, trained_regressor, feature_selector = trainer(self.situation, self.X_train, self.X_community,\
  File "/home/users/apopescu/van-khoa/Vis-Priva-Expos/privacy/vispel/vispel/trainer.py", line 64, in trainer
    trained_regressor = train_regressor(regressor, X_train_rd, gt_train_expos, cfg)
  File "/home/users/apopescu/van-khoa/Vis-Priva-Expos/privacy/lib/regressor/regression.py", line 22, in train_regressor
    model.fit(x_train, y_train)
  File "/home/users/apopescu/anaconda3/envs/detectron2/lib/python3.8/site-packages/sklearn/utils/validation.py", line 73, in inner_f
    return f(**kwargs)
  File "/home/users/apopescu/anaconda3/envs/detectron2/lib/python3.8/site-packages/sklearn/model_selection/_search.py", line 736, in fit
    self._run_search(evaluate_candidates)
  File "/home/users/apopescu/anaconda3/envs/detectron2/lib/python3.8/site-packages/sklearn/model_selection/_search.py", line 1188, in _run_search
    evaluate_candidates(ParameterGrid(self.param_grid))
  File "/home/users/apopescu/anaconda3/envs/detectron2/lib/python3.8/site-packages/sklearn/model_selection/_search.py", line 708, in evaluate_candidates
    out = parallel(delayed(_fit_and_score)(clone(base_estimator),
  File "/home/users/apopescu/anaconda3/envs/detectron2/lib/python3.8/site-packages/joblib/parallel.py", line 1042, in __call__
    self.retrieve()
  File "/home/users/apopescu/anaconda3/envs/detectron2/lib/python3.8/site-packages/joblib/parallel.py", line 921, in retrieve
    self._output.extend(job.get(timeout=self.timeout))
  File "/home/users/apopescu/anaconda3/envs/detectron2/lib/python3.8/site-packages/joblib/_parallel_backends.py", line 542, in wrap_future_result
    return future.result(timeout=timeout)
  File "/home/users/apopescu/anaconda3/envs/detectron2/lib/python3.8/concurrent/futures/_base.py", line 439, in result
    return self.__get_result()
  File "/home/users/apopescu/anaconda3/envs/detectron2/lib/python3.8/concurrent/futures/_base.py", line 388, in __get_result
    raise self._exception
  File "/home/users/apopescu/anaconda3/envs/detectron2/lib/python3.8/site-packages/joblib/externals/loky/_base.py", line 625, in _invoke_callbacks
    callback(self)
  File "/home/users/apopescu/anaconda3/envs/detectron2/lib/python3.8/site-packages/joblib/parallel.py", line 347, in __call__
    self.parallel.dispatch_next()
  File "/home/users/apopescu/anaconda3/envs/detectron2/lib/python3.8/site-packages/joblib/parallel.py", line 780, in dispatch_next
    if not self.dispatch_one_batch(self._original_iterator):
  File "/home/users/apopescu/anaconda3/envs/detectron2/lib/python3.8/site-packages/joblib/parallel.py", line 847, in dispatch_one_batch
    self._dispatch(tasks)
  File "/home/users/apopescu/anaconda3/envs/detectron2/lib/python3.8/site-packages/joblib/parallel.py", line 765, in _dispatch
    job = self._backend.apply_async(batch, callback=cb)
  File "/home/users/apopescu/anaconda3/envs/detectron2/lib/python3.8/site-packages/joblib/_parallel_backends.py", line 531, in apply_async
    future = self._workers.submit(SafeFunction(func))
  File "/home/users/apopescu/anaconda3/envs/detectron2/lib/python3.8/site-packages/joblib/externals/loky/reusable_executor.py", line 177, in submit
    return super(_ReusablePoolExecutor, self).submit(
  File "/home/users/apopescu/anaconda3/envs/detectron2/lib/python3.8/site-packages/joblib/externals/loky/process_executor.py", line 1102, in submit
    raise self._flags.broken
  File "/home/users/apopescu/anaconda3/envs/detectron2/lib/python3.8/site-packages/joblib/externals/loky/_base.py", line 625, in _invoke_callbacks
    callback(self)
  File "/home/users/apopescu/anaconda3/envs/detectron2/lib/python3.8/site-packages/joblib/parallel.py", line 347, in __call__
    self.parallel.dispatch_next()
  File "/home/users/apopescu/anaconda3/envs/detectron2/lib/python3.8/site-packages/joblib/parallel.py", line 780, in dispatch_next
    if not self.dispatch_one_batch(self._original_iterator):
  File "/home/users/apopescu/anaconda3/envs/detectron2/lib/python3.8/site-packages/joblib/parallel.py", line 847, in dispatch_one_batch
    self._dispatch(tasks)
  File "/home/users/apopescu/anaconda3/envs/detectron2/lib/python3.8/site-packages/joblib/parallel.py", line 765, in _dispatch
    job = self._backend.apply_async(batch, callback=cb)
  File "/home/users/apopescu/anaconda3/envs/detectron2/lib/python3.8/site-packages/joblib/_parallel_backends.py", line 531, in apply_async
    future = self._workers.submit(SafeFunction(func))
  File "/home/users/apopescu/anaconda3/envs/detectron2/lib/python3.8/site-packages/joblib/externals/loky/reusable_executor.py", line 177, in submit
    return super(_ReusablePoolExecutor, self).submit(
  File "/home/users/apopescu/anaconda3/envs/detectron2/lib/python3.8/site-packages/joblib/externals/loky/process_executor.py", line 1102, in submit
    raise self._flags.broken
  File "/home/users/apopescu/anaconda3/envs/detectron2/lib/python3.8/site-packages/joblib/externals/loky/_base.py", line 625, in _invoke_callbacks
    callback(self)
  File "/home/users/apopescu/anaconda3/envs/detectron2/lib/python3.8/site-packages/joblib/parallel.py", line 347, in __call__
    self.parallel.dispatch_next()
  File "/home/users/apopescu/anaconda3/envs/detectron2/lib/python3.8/site-packages/joblib/parallel.py", line 780, in dispatch_next
    if not self.dispatch_one_batch(self._original_iterator):
  File "/home/users/apopescu/anaconda3/envs/detectron2/lib/python3.8/site-packages/joblib/parallel.py", line 847, in dispatch_one_batch
    self._dispatch(tasks)
  File "/home/users/apopescu/anaconda3/envs/detectron2/lib/python3.8/site-packages/joblib/parallel.py", line 765, in _dispatch
    job = self._backend.apply_async(batch, callback=cb)
  File "/home/users/apopescu/anaconda3/envs/detectron2/lib/python3.8/site-packages/joblib/_parallel_backends.py", line 531, in apply_async
    future = self._workers.submit(SafeFunction(func))
  File "/home/users/apopescu/anaconda3/envs/detectron2/lib/python3.8/site-packages/joblib/externals/loky/reusable_executor.py", line 177, in submit
    return super(_ReusablePoolExecutor, self).submit(
  File "/home/users/apopescu/anaconda3/envs/detectron2/lib/python3.8/site-packages/joblib/externals/loky/process_executor.py", line 1102, in submit
    raise self._flags.broken
  File "/home/users/apopescu/anaconda3/envs/detectron2/lib/python3.8/site-packages/joblib/externals/loky/_base.py", line 625, in _invoke_callbacks
    callback(self)
  File "/home/users/apopescu/anaconda3/envs/detectron2/lib/python3.8/site-packages/joblib/parallel.py", line 347, in __call__
    self.parallel.dispatch_next()
  File "/home/users/apopescu/anaconda3/envs/detectron2/lib/python3.8/site-packages/joblib/parallel.py", line 780, in dispatch_next
    if not self.dispatch_one_batch(self._original_iterator):
  File "/home/users/apopescu/anaconda3/envs/detectron2/lib/python3.8/site-packages/joblib/parallel.py", line 847, in dispatch_one_batch
    self._dispatch(tasks)
  File "/home/users/apopescu/anaconda3/envs/detectron2/lib/python3.8/site-packages/joblib/parallel.py", line 765, in _dispatch
    job = self._backend.apply_async(batch, callback=cb)
  File "/home/users/apopescu/anaconda3/envs/detectron2/lib/python3.8/site-packages/joblib/_parallel_backends.py", line 531, in apply_async
    future = self._workers.submit(SafeFunction(func))
  File "/home/users/apopescu/anaconda3/envs/detectron2/lib/python3.8/site-packages/joblib/externals/loky/reusable_executor.py", line 177, in submit
    return super(_ReusablePoolExecutor, self).submit(
  File "/home/users/apopescu/anaconda3/envs/detectron2/lib/python3.8/site-packages/joblib/externals/loky/process_executor.py", line 1102, in submit
    raise self._flags.broken
joblib.externals.loky.process_executor.TerminatedWorkerError: A worker process managed by the executor was unexpectedly terminated. This could be caused by a segmentation fault while calling the function or by an excessive memory usage causing the Operating System to kill the worker.

The exit codes of the workers are {SIGBUS(-7)}
exception calling callback for <Future at 0x2aed7a339190 state=finished raised TerminatedWorkerError>
Traceback (most recent call last):
  File "/home/users/apopescu/anaconda3/envs/detectron2/lib/python3.8/site-packages/joblib/externals/loky/_base.py", line 625, in _invoke_callbacks
    callback(self)
  File "/home/users/apopescu/anaconda3/envs/detectron2/lib/python3.8/site-packages/joblib/parallel.py", line 347, in __call__
    self.parallel.dispatch_next()
  File "/home/users/apopescu/anaconda3/envs/detectron2/lib/python3.8/site-packages/joblib/parallel.py", line 780, in dispatch_next
    if not self.dispatch_one_batch(self._original_iterator):
  File "/home/users/apopescu/anaconda3/envs/detectron2/lib/python3.8/site-packages/joblib/parallel.py", line 847, in dispatch_one_batch
    self._dispatch(tasks)
  File "/home/users/apopescu/anaconda3/envs/detectron2/lib/python3.8/site-packages/joblib/parallel.py", line 765, in _dispatch
    job = self._backend.apply_async(batch, callback=cb)
  File "/home/users/apopescu/anaconda3/envs/detectron2/lib/python3.8/site-packages/joblib/_parallel_backends.py", line 531, in apply_async
    future = self._workers.submit(SafeFunction(func))
  File "/home/users/apopescu/anaconda3/envs/detectron2/lib/python3.8/site-packages/joblib/externals/loky/reusable_executor.py", line 177, in submit
    return super(_ReusablePoolExecutor, self).submit(
  File "/home/users/apopescu/anaconda3/envs/detectron2/lib/python3.8/site-packages/joblib/externals/loky/process_executor.py", line 1102, in submit
    raise self._flags.broken
joblib.externals.loky.process_executor.TerminatedWorkerError: A worker process managed by the executor was unexpectedly terminated. This could be caused by a segmentation fault while calling the function or by an excessive memory usage causing the Operating System to kill the worker.

The exit codes of the workers are {SIGBUS(-7)}
exception calling callback for <Future at 0x2aed7a318910 state=finished raised TerminatedWorkerError>
Traceback (most recent call last):
  File "/home/users/apopescu/anaconda3/envs/detectron2/lib/python3.8/site-packages/joblib/externals/loky/_base.py", line 625, in _invoke_callbacks
    callback(self)
  File "/home/users/apopescu/anaconda3/envs/detectron2/lib/python3.8/site-packages/joblib/parallel.py", line 347, in __call__
    self.parallel.dispatch_next()
  File "/home/users/apopescu/anaconda3/envs/detectron2/lib/python3.8/site-packages/joblib/parallel.py", line 780, in dispatch_next
    if not self.dispatch_one_batch(self._original_iterator):
  File "/home/users/apopescu/anaconda3/envs/detectron2/lib/python3.8/site-packages/joblib/parallel.py", line 847, in dispatch_one_batch
    self._dispatch(tasks)
  File "/home/users/apopescu/anaconda3/envs/detectron2/lib/python3.8/site-packages/joblib/parallel.py", line 765, in _dispatch
    job = self._backend.apply_async(batch, callback=cb)
  File "/home/users/apopescu/anaconda3/envs/detectron2/lib/python3.8/site-packages/joblib/_parallel_backends.py", line 531, in apply_async
    future = self._workers.submit(SafeFunction(func))
  File "/home/users/apopescu/anaconda3/envs/detectron2/lib/python3.8/site-packages/joblib/externals/loky/reusable_executor.py", line 177, in submit
    return super(_ReusablePoolExecutor, self).submit(
  File "/home/users/apopescu/anaconda3/envs/detectron2/lib/python3.8/site-packages/joblib/externals/loky/process_executor.py", line 1102, in submit
    raise self._flags.broken
  File "/home/users/apopescu/anaconda3/envs/detectron2/lib/python3.8/site-packages/joblib/externals/loky/_base.py", line 625, in _invoke_callbacks
    callback(self)
  File "/home/users/apopescu/anaconda3/envs/detectron2/lib/python3.8/site-packages/joblib/parallel.py", line 347, in __call__
    self.parallel.dispatch_next()
  File "/home/users/apopescu/anaconda3/envs/detectron2/lib/python3.8/site-packages/joblib/parallel.py", line 780, in dispatch_next
    if not self.dispatch_one_batch(self._original_iterator):
  File "/home/users/apopescu/anaconda3/envs/detectron2/lib/python3.8/site-packages/joblib/parallel.py", line 847, in dispatch_one_batch
    self._dispatch(tasks)
  File "/home/users/apopescu/anaconda3/envs/detectron2/lib/python3.8/site-packages/joblib/parallel.py", line 765, in _dispatch
    job = self._backend.apply_async(batch, callback=cb)
  File "/home/users/apopescu/anaconda3/envs/detectron2/lib/python3.8/site-packages/joblib/_parallel_backends.py", line 531, in apply_async
    future = self._workers.submit(SafeFunction(func))
  File "/home/users/apopescu/anaconda3/envs/detectron2/lib/python3.8/site-packages/joblib/externals/loky/reusable_executor.py", line 177, in submit
    return super(_ReusablePoolExecutor, self).submit(
  File "/home/users/apopescu/anaconda3/envs/detectron2/lib/python3.8/site-packages/joblib/externals/loky/process_executor.py", line 1102, in submit
    raise self._flags.broken
joblib.externals.loky.process_executor.TerminatedWorkerError: A worker process managed by the executor was unexpectedly terminated. This could be caused by a segmentation fault while calling the function or by an excessive memory usage causing the Operating System to kill the worker.

The exit codes of the workers are {SIGBUS(-7)}
exception calling callback for <Future at 0x2aed7a318d60 state=finished raised TerminatedWorkerError>
Traceback (most recent call last):
  File "/home/users/apopescu/anaconda3/envs/detectron2/lib/python3.8/site-packages/joblib/externals/loky/_base.py", line 625, in _invoke_callbacks
    callback(self)
  File "/home/users/apopescu/anaconda3/envs/detectron2/lib/python3.8/site-packages/joblib/parallel.py", line 347, in __call__
    self.parallel.dispatch_next()
  File "/home/users/apopescu/anaconda3/envs/detectron2/lib/python3.8/site-packages/joblib/parallel.py", line 780, in dispatch_next
    if not self.dispatch_one_batch(self._original_iterator):
  File "/home/users/apopescu/anaconda3/envs/detectron2/lib/python3.8/site-packages/joblib/parallel.py", line 847, in dispatch_one_batch
    self._dispatch(tasks)
  File "/home/users/apopescu/anaconda3/envs/detectron2/lib/python3.8/site-packages/joblib/parallel.py", line 765, in _dispatch
    job = self._backend.apply_async(batch, callback=cb)
  File "/home/users/apopescu/anaconda3/envs/detectron2/lib/python3.8/site-packages/joblib/_parallel_backends.py", line 531, in apply_async
    future = self._workers.submit(SafeFunction(func))
  File "/home/users/apopescu/anaconda3/envs/detectron2/lib/python3.8/site-packages/joblib/externals/loky/reusable_executor.py", line 177, in submit
    return super(_ReusablePoolExecutor, self).submit(
  File "/home/users/apopescu/anaconda3/envs/detectron2/lib/python3.8/site-packages/joblib/externals/loky/process_executor.py", line 1102, in submit
    raise self._flags.broken
  File "/home/users/apopescu/anaconda3/envs/detectron2/lib/python3.8/site-packages/joblib/externals/loky/_base.py", line 625, in _invoke_callbacks
    callback(self)
  File "/home/users/apopescu/anaconda3/envs/detectron2/lib/python3.8/site-packages/joblib/parallel.py", line 347, in __call__
    self.parallel.dispatch_next()
  File "/home/users/apopescu/anaconda3/envs/detectron2/lib/python3.8/site-packages/joblib/parallel.py", line 780, in dispatch_next
    if not self.dispatch_one_batch(self._original_iterator):
  File "/home/users/apopescu/anaconda3/envs/detectron2/lib/python3.8/site-packages/joblib/parallel.py", line 847, in dispatch_one_batch
    self._dispatch(tasks)
  File "/home/users/apopescu/anaconda3/envs/detectron2/lib/python3.8/site-packages/joblib/parallel.py", line 765, in _dispatch
    job = self._backend.apply_async(batch, callback=cb)
  File "/home/users/apopescu/anaconda3/envs/detectron2/lib/python3.8/site-packages/joblib/_parallel_backends.py", line 531, in apply_async
    future = self._workers.submit(SafeFunction(func))
  File "/home/users/apopescu/anaconda3/envs/detectron2/lib/python3.8/site-packages/joblib/externals/loky/reusable_executor.py", line 177, in submit
    return super(_ReusablePoolExecutor, self).submit(
  File "/home/users/apopescu/anaconda3/envs/detectron2/lib/python3.8/site-packages/joblib/externals/loky/process_executor.py", line 1102, in submit
    raise self._flags.broken
  File "/home/users/apopescu/anaconda3/envs/detectron2/lib/python3.8/site-packages/joblib/externals/loky/_base.py", line 625, in _invoke_callbacks
    callback(self)
  File "/home/users/apopescu/anaconda3/envs/detectron2/lib/python3.8/site-packages/joblib/parallel.py", line 347, in __call__
    self.parallel.dispatch_next()
  File "/home/users/apopescu/anaconda3/envs/detectron2/lib/python3.8/site-packages/joblib/parallel.py", line 780, in dispatch_next
    if not self.dispatch_one_batch(self._original_iterator):
  File "/home/users/apopescu/anaconda3/envs/detectron2/lib/python3.8/site-packages/joblib/parallel.py", line 847, in dispatch_one_batch
    self._dispatch(tasks)
  File "/home/users/apopescu/anaconda3/envs/detectron2/lib/python3.8/site-packages/joblib/parallel.py", line 765, in _dispatch
    job = self._backend.apply_async(batch, callback=cb)
  File "/home/users/apopescu/anaconda3/envs/detectron2/lib/python3.8/site-packages/joblib/_parallel_backends.py", line 531, in apply_async
    future = self._workers.submit(SafeFunction(func))
  File "/home/users/apopescu/anaconda3/envs/detectron2/lib/python3.8/site-packages/joblib/externals/loky/reusable_executor.py", line 177, in submit
    return super(_ReusablePoolExecutor, self).submit(
  File "/home/users/apopescu/anaconda3/envs/detectron2/lib/python3.8/site-packages/joblib/externals/loky/process_executor.py", line 1102, in submit
    raise self._flags.broken
joblib.externals.loky.process_executor.TerminatedWorkerError: A worker process managed by the executor was unexpectedly terminated. This could be caused by a segmentation fault while calling the function or by an excessive memory usage causing the Operating System to kill the worker.

The exit codes of the workers are {SIGBUS(-7)}
exception calling callback for <Future at 0x2aed7a318e80 state=finished raised TerminatedWorkerError>
Traceback (most recent call last):
  File "/home/users/apopescu/anaconda3/envs/detectron2/lib/python3.8/site-packages/joblib/externals/loky/_base.py", line 625, in _invoke_callbacks
    callback(self)
  File "/home/users/apopescu/anaconda3/envs/detectron2/lib/python3.8/site-packages/joblib/parallel.py", line 347, in __call__
    self.parallel.dispatch_next()
  File "/home/users/apopescu/anaconda3/envs/detectron2/lib/python3.8/site-packages/joblib/parallel.py", line 780, in dispatch_next
    if not self.dispatch_one_batch(self._original_iterator):
  File "/home/users/apopescu/anaconda3/envs/detectron2/lib/python3.8/site-packages/joblib/parallel.py", line 847, in dispatch_one_batch
    self._dispatch(tasks)
  File "/home/users/apopescu/anaconda3/envs/detectron2/lib/python3.8/site-packages/joblib/parallel.py", line 765, in _dispatch
    job = self._backend.apply_async(batch, callback=cb)
  File "/home/users/apopescu/anaconda3/envs/detectron2/lib/python3.8/site-packages/joblib/_parallel_backends.py", line 531, in apply_async
    future = self._workers.submit(SafeFunction(func))
  File "/home/users/apopescu/anaconda3/envs/detectron2/lib/python3.8/site-packages/joblib/externals/loky/reusable_executor.py", line 177, in submit
    return super(_ReusablePoolExecutor, self).submit(
  File "/home/users/apopescu/anaconda3/envs/detectron2/lib/python3.8/site-packages/joblib/externals/loky/process_executor.py", line 1102, in submit
    raise self._flags.broken
  File "/home/users/apopescu/anaconda3/envs/detectron2/lib/python3.8/site-packages/joblib/externals/loky/_base.py", line 625, in _invoke_callbacks
    callback(self)
  File "/home/users/apopescu/anaconda3/envs/detectron2/lib/python3.8/site-packages/joblib/parallel.py", line 347, in __call__
    self.parallel.dispatch_next()
  File "/home/users/apopescu/anaconda3/envs/detectron2/lib/python3.8/site-packages/joblib/parallel.py", line 780, in dispatch_next
    if not self.dispatch_one_batch(self._original_iterator):
  File "/home/users/apopescu/anaconda3/envs/detectron2/lib/python3.8/site-packages/joblib/parallel.py", line 847, in dispatch_one_batch
    self._dispatch(tasks)
  File "/home/users/apopescu/anaconda3/envs/detectron2/lib/python3.8/site-packages/joblib/parallel.py", line 765, in _dispatch
    job = self._backend.apply_async(batch, callback=cb)
  File "/home/users/apopescu/anaconda3/envs/detectron2/lib/python3.8/site-packages/joblib/_parallel_backends.py", line 531, in apply_async
    future = self._workers.submit(SafeFunction(func))
  File "/home/users/apopescu/anaconda3/envs/detectron2/lib/python3.8/site-packages/joblib/externals/loky/reusable_executor.py", line 177, in submit
    return super(_ReusablePoolExecutor, self).submit(
  File "/home/users/apopescu/anaconda3/envs/detectron2/lib/python3.8/site-packages/joblib/externals/loky/process_executor.py", line 1102, in submit
    raise self._flags.broken
  File "/home/users/apopescu/anaconda3/envs/detectron2/lib/python3.8/site-packages/joblib/externals/loky/_base.py", line 625, in _invoke_callbacks
    callback(self)
  File "/home/users/apopescu/anaconda3/envs/detectron2/lib/python3.8/site-packages/joblib/parallel.py", line 347, in __call__
    self.parallel.dispatch_next()
  File "/home/users/apopescu/anaconda3/envs/detectron2/lib/python3.8/site-packages/joblib/parallel.py", line 780, in dispatch_next
    if not self.dispatch_one_batch(self._original_iterator):
  File "/home/users/apopescu/anaconda3/envs/detectron2/lib/python3.8/site-packages/joblib/parallel.py", line 847, in dispatch_one_batch
    self._dispatch(tasks)
  File "/home/users/apopescu/anaconda3/envs/detectron2/lib/python3.8/site-packages/joblib/parallel.py", line 765, in _dispatch
    job = self._backend.apply_async(batch, callback=cb)
  File "/home/users/apopescu/anaconda3/envs/detectron2/lib/python3.8/site-packages/joblib/_parallel_backends.py", line 531, in apply_async
    future = self._workers.submit(SafeFunction(func))
  File "/home/users/apopescu/anaconda3/envs/detectron2/lib/python3.8/site-packages/joblib/externals/loky/reusable_executor.py", line 177, in submit
    return super(_ReusablePoolExecutor, self).submit(
  File "/home/users/apopescu/anaconda3/envs/detectron2/lib/python3.8/site-packages/joblib/externals/loky/process_executor.py", line 1102, in submit
    raise self._flags.broken
  File "/home/users/apopescu/anaconda3/envs/detectron2/lib/python3.8/site-packages/joblib/externals/loky/_base.py", line 625, in _invoke_callbacks
    callback(self)
  File "/home/users/apopescu/anaconda3/envs/detectron2/lib/python3.8/site-packages/joblib/parallel.py", line 347, in __call__
    self.parallel.dispatch_next()
  File "/home/users/apopescu/anaconda3/envs/detectron2/lib/python3.8/site-packages/joblib/parallel.py", line 780, in dispatch_next
    if not self.dispatch_one_batch(self._original_iterator):
  File "/home/users/apopescu/anaconda3/envs/detectron2/lib/python3.8/site-packages/joblib/parallel.py", line 847, in dispatch_one_batch
    self._dispatch(tasks)
  File "/home/users/apopescu/anaconda3/envs/detectron2/lib/python3.8/site-packages/joblib/parallel.py", line 765, in _dispatch
    job = self._backend.apply_async(batch, callback=cb)
  File "/home/users/apopescu/anaconda3/envs/detectron2/lib/python3.8/site-packages/joblib/_parallel_backends.py", line 531, in apply_async
    future = self._workers.submit(SafeFunction(func))
  File "/home/users/apopescu/anaconda3/envs/detectron2/lib/python3.8/site-packages/joblib/externals/loky/reusable_executor.py", line 177, in submit
    return super(_ReusablePoolExecutor, self).submit(
  File "/home/users/apopescu/anaconda3/envs/detectron2/lib/python3.8/site-packages/joblib/externals/loky/process_executor.py", line 1102, in submit
    raise self._flags.broken
joblib.externals.loky.process_executor.TerminatedWorkerError: A worker process managed by the executor was unexpectedly terminated. This could be caused by a segmentation fault while calling the function or by an excessive memory usage causing the Operating System to kill the worker.

The exit codes of the workers are {SIGBUS(-7)}
  0%|          | 0/5 [02:06<?, ?it/s]
Traceback (most recent call last):
  File "ft_official.py", line 118, in <module>
    main()
  File "ft_official.py", line 100, in main
    model.train_vispel()
  File "/home/users/apopescu/van-khoa/Vis-Priva-Expos/privacy/vispel/vispel/vispel.py", line 54, in train_vispel
    trained_clusteror, trained_regressor, feature_selector = trainer(self.situation, self.X_train, self.X_community,\
  File "/home/users/apopescu/van-khoa/Vis-Priva-Expos/privacy/vispel/vispel/trainer.py", line 64, in trainer
    trained_regressor = train_regressor(regressor, X_train_rd, gt_train_expos, cfg)
  File "/home/users/apopescu/van-khoa/Vis-Priva-Expos/privacy/lib/regressor/regression.py", line 22, in train_regressor
    model.fit(x_train, y_train)
  File "/home/users/apopescu/anaconda3/envs/detectron2/lib/python3.8/site-packages/sklearn/utils/validation.py", line 73, in inner_f
    return f(**kwargs)
  File "/home/users/apopescu/anaconda3/envs/detectron2/lib/python3.8/site-packages/sklearn/model_selection/_search.py", line 736, in fit
    self._run_search(evaluate_candidates)
  File "/home/users/apopescu/anaconda3/envs/detectron2/lib/python3.8/site-packages/sklearn/model_selection/_search.py", line 1188, in _run_search
    evaluate_candidates(ParameterGrid(self.param_grid))
  File "/home/users/apopescu/anaconda3/envs/detectron2/lib/python3.8/site-packages/sklearn/model_selection/_search.py", line 708, in evaluate_candidates
    out = parallel(delayed(_fit_and_score)(clone(base_estimator),
  File "/home/users/apopescu/anaconda3/envs/detectron2/lib/python3.8/site-packages/joblib/parallel.py", line 1042, in __call__
    self.retrieve()
  File "/home/users/apopescu/anaconda3/envs/detectron2/lib/python3.8/site-packages/joblib/parallel.py", line 921, in retrieve
    self._output.extend(job.get(timeout=self.timeout))
  File "/home/users/apopescu/anaconda3/envs/detectron2/lib/python3.8/site-packages/joblib/_parallel_backends.py", line 542, in wrap_future_result
    return future.result(timeout=timeout)
  File "/home/users/apopescu/anaconda3/envs/detectron2/lib/python3.8/concurrent/futures/_base.py", line 439, in result
    return self.__get_result()
  File "/home/users/apopescu/anaconda3/envs/detectron2/lib/python3.8/concurrent/futures/_base.py", line 388, in __get_result
    raise self._exception
  File "/home/users/apopescu/anaconda3/envs/detectron2/lib/python3.8/site-packages/joblib/externals/loky/_base.py", line 625, in _invoke_callbacks
    callback(self)
  File "/home/users/apopescu/anaconda3/envs/detectron2/lib/python3.8/site-packages/joblib/parallel.py", line 347, in __call__
    self.parallel.dispatch_next()
  File "/home/users/apopescu/anaconda3/envs/detectron2/lib/python3.8/site-packages/joblib/parallel.py", line 780, in dispatch_next
    if not self.dispatch_one_batch(self._original_iterator):
  File "/home/users/apopescu/anaconda3/envs/detectron2/lib/python3.8/site-packages/joblib/parallel.py", line 847, in dispatch_one_batch
    self._dispatch(tasks)
  File "/home/users/apopescu/anaconda3/envs/detectron2/lib/python3.8/site-packages/joblib/parallel.py", line 765, in _dispatch
    job = self._backend.apply_async(batch, callback=cb)
  File "/home/users/apopescu/anaconda3/envs/detectron2/lib/python3.8/site-packages/joblib/_parallel_backends.py", line 531, in apply_async
    future = self._workers.submit(SafeFunction(func))
  File "/home/users/apopescu/anaconda3/envs/detectron2/lib/python3.8/site-packages/joblib/externals/loky/reusable_executor.py", line 177, in submit
    return super(_ReusablePoolExecutor, self).submit(
  File "/home/users/apopescu/anaconda3/envs/detectron2/lib/python3.8/site-packages/joblib/externals/loky/process_executor.py", line 1102, in submit
    raise self._flags.broken
  File "/home/users/apopescu/anaconda3/envs/detectron2/lib/python3.8/site-packages/joblib/externals/loky/_base.py", line 625, in _invoke_callbacks
    callback(self)
  File "/home/users/apopescu/anaconda3/envs/detectron2/lib/python3.8/site-packages/joblib/parallel.py", line 347, in __call__
    self.parallel.dispatch_next()
  File "/home/users/apopescu/anaconda3/envs/detectron2/lib/python3.8/site-packages/joblib/parallel.py", line 780, in dispatch_next
    if not self.dispatch_one_batch(self._original_iterator):
  File "/home/users/apopescu/anaconda3/envs/detectron2/lib/python3.8/site-packages/joblib/parallel.py", line 847, in dispatch_one_batch
    self._dispatch(tasks)
  File "/home/users/apopescu/anaconda3/envs/detectron2/lib/python3.8/site-packages/joblib/parallel.py", line 765, in _dispatch
    job = self._backend.apply_async(batch, callback=cb)
  File "/home/users/apopescu/anaconda3/envs/detectron2/lib/python3.8/site-packages/joblib/_parallel_backends.py", line 531, in apply_async
    future = self._workers.submit(SafeFunction(func))
  File "/home/users/apopescu/anaconda3/envs/detectron2/lib/python3.8/site-packages/joblib/externals/loky/reusable_executor.py", line 177, in submit
    return super(_ReusablePoolExecutor, self).submit(
  File "/home/users/apopescu/anaconda3/envs/detectron2/lib/python3.8/site-packages/joblib/externals/loky/process_executor.py", line 1102, in submit
    raise self._flags.broken
  File "/home/users/apopescu/anaconda3/envs/detectron2/lib/python3.8/site-packages/joblib/externals/loky/_base.py", line 625, in _invoke_callbacks
    callback(self)
  File "/home/users/apopescu/anaconda3/envs/detectron2/lib/python3.8/site-packages/joblib/parallel.py", line 347, in __call__
    self.parallel.dispatch_next()
  File "/home/users/apopescu/anaconda3/envs/detectron2/lib/python3.8/site-packages/joblib/parallel.py", line 780, in dispatch_next
    if not self.dispatch_one_batch(self._original_iterator):
  File "/home/users/apopescu/anaconda3/envs/detectron2/lib/python3.8/site-packages/joblib/parallel.py", line 847, in dispatch_one_batch
    self._dispatch(tasks)
  File "/home/users/apopescu/anaconda3/envs/detectron2/lib/python3.8/site-packages/joblib/parallel.py", line 765, in _dispatch
    job = self._backend.apply_async(batch, callback=cb)
  File "/home/users/apopescu/anaconda3/envs/detectron2/lib/python3.8/site-packages/joblib/_parallel_backends.py", line 531, in apply_async
    future = self._workers.submit(SafeFunction(func))
  File "/home/users/apopescu/anaconda3/envs/detectron2/lib/python3.8/site-packages/joblib/externals/loky/reusable_executor.py", line 177, in submit
    return super(_ReusablePoolExecutor, self).submit(
  File "/home/users/apopescu/anaconda3/envs/detectron2/lib/python3.8/site-packages/joblib/externals/loky/process_executor.py", line 1102, in submit
    raise self._flags.broken
  File "/home/users/apopescu/anaconda3/envs/detectron2/lib/python3.8/site-packages/joblib/externals/loky/_base.py", line 625, in _invoke_callbacks
    callback(self)
  File "/home/users/apopescu/anaconda3/envs/detectron2/lib/python3.8/site-packages/joblib/parallel.py", line 347, in __call__
    self.parallel.dispatch_next()
  File "/home/users/apopescu/anaconda3/envs/detectron2/lib/python3.8/site-packages/joblib/parallel.py", line 780, in dispatch_next
    if not self.dispatch_one_batch(self._original_iterator):
  File "/home/users/apopescu/anaconda3/envs/detectron2/lib/python3.8/site-packages/joblib/parallel.py", line 847, in dispatch_one_batch
    self._dispatch(tasks)
  File "/home/users/apopescu/anaconda3/envs/detectron2/lib/python3.8/site-packages/joblib/parallel.py", line 765, in _dispatch
    job = self._backend.apply_async(batch, callback=cb)
  File "/home/users/apopescu/anaconda3/envs/detectron2/lib/python3.8/site-packages/joblib/_parallel_backends.py", line 531, in apply_async
    future = self._workers.submit(SafeFunction(func))
  File "/home/users/apopescu/anaconda3/envs/detectron2/lib/python3.8/site-packages/joblib/externals/loky/reusable_executor.py", line 177, in submit
    return super(_ReusablePoolExecutor, self).submit(
  File "/home/users/apopescu/anaconda3/envs/detectron2/lib/python3.8/site-packages/joblib/externals/loky/process_executor.py", line 1102, in submit
    raise self._flags.broken
joblib.externals.loky.process_executor.TerminatedWorkerError: A worker process managed by the executor was unexpectedly terminated. This could be caused by a segmentation fault while calling the function or by an excessive memory usage causing the Operating System to kill the worker.

The exit codes of the workers are {SIGBUS(-7)}
/var/spool/slurm//job66119/slurm_script: line 50: 173524 Bus error               python3 ft_official.py --config_file ../configs/rf_kmeans_ft_mobi_cv8.yaml --model_name wait_mobi_11.pkl --situation WAIT --opts USER_SELECTOR.EPS 0.1 USER_SELECTOR.KEEP 0.8 SOLVER.FEATURE_TYPE ORG OUTPUT.DIR /home/users/apopescu/van-khoa/saved_models/wait_mobi
/var/spool/slurm//job66119/slurm_script: line 50: 173579 Bus error               python3 ft_official.py --config_file ../configs/rf_kmeans_ft_mobi_cv8.yaml --model_name wait_mobi_34.pkl --situation WAIT --opts USER_SELECTOR.EPS 0.2 USER_SELECTOR.KEEP 0.9 SOLVER.FEATURE_TYPE VOTE OUTPUT.DIR /home/users/apopescu/van-khoa/saved_models/wait_mobi
