Config '../configs/rf_kmeans_ft_mobi_cv8.yaml' has no VERSION. Assuming it to be compatible with latest v1.
Config '../configs/rf_kmeans_ft_mobi_cv8.yaml' has no VERSION. Assuming it to be compatible with latest v1.
Config '../configs/rf_kmeans_ft_mobi_cv8.yaml' has no VERSION. Assuming it to be compatible with latest v1.
Config '../configs/rf_kmeans_ft_mobi_cv8.yaml' has no VERSION. Assuming it to be compatible with latest v1.
Config '../configs/rf_kmeans_ft_mobi_cv8.yaml' has no VERSION. Assuming it to be compatible with latest v1.
Config '../configs/rf_kmeans_ft_mobi_cv8.yaml' has no VERSION. Assuming it to be compatible with latest v1.
Config '../configs/rf_kmeans_ft_mobi_cv8.yaml' has no VERSION. Assuming it to be compatible with latest v1.
Config '../configs/rf_kmeans_ft_mobi_cv8.yaml' has no VERSION. Assuming it to be compatible with latest v1.
Config '../configs/rf_kmeans_ft_mobi_cv8.yaml' has no VERSION. Assuming it to be compatible with latest v1.
Config '../configs/rf_kmeans_ft_mobi_cv8.yaml' has no VERSION. Assuming it to be compatible with latest v1.
Config '../configs/rf_kmeans_ft_mobi_cv8.yaml' has no VERSION. Assuming it to be compatible with latest v1.
Config '../configs/rf_kmeans_ft_mobi_cv8.yaml' has no VERSION. Assuming it to be compatible with latest v1.
Config '../configs/rf_kmeans_ft_mobi_cv8.yaml' has no VERSION. Assuming it to be compatible with latest v1.
Config '../configs/rf_kmeans_ft_mobi_cv8.yaml' has no VERSION. Assuming it to be compatible with latest v1.
Config '../configs/rf_kmeans_ft_mobi_cv8.yaml' has no VERSION. Assuming it to be compatible with latest v1.
Config '../configs/rf_kmeans_ft_mobi_cv8.yaml' has no VERSION. Assuming it to be compatible with latest v1.
Config '../configs/rf_kmeans_ft_mobi_cv8.yaml' has no VERSION. Assuming it to be compatible with latest v1.
Config '../configs/rf_kmeans_ft_mobi_cv8.yaml' has no VERSION. Assuming it to be compatible with latest v1.
Config '../configs/rf_kmeans_ft_mobi_cv8.yaml' has no VERSION. Assuming it to be compatible with latest v1.
Config '../configs/rf_kmeans_ft_mobi_cv8.yaml' has no VERSION. Assuming it to be compatible with latest v1.
Config '../configs/rf_kmeans_ft_mobi_cv8.yaml' has no VERSION. Assuming it to be compatible with latest v1.
Config '../configs/rf_kmeans_ft_mobi_cv8.yaml' has no VERSION. Assuming it to be compatible with latest v1.
Config '../configs/rf_kmeans_ft_mobi_cv8.yaml' has no VERSION. Assuming it to be compatible with latest v1.
Config '../configs/rf_kmeans_ft_mobi_cv8.yaml' has no VERSION. Assuming it to be compatible with latest v1.
  0%|          | 0/5 [00:00<?, ?it/s]  0%|          | 0/5 [00:00<?, ?it/s]Config '../configs/rf_kmeans_ft_mobi_cv8.yaml' has no VERSION. Assuming it to be compatible with latest v1.
  0%|          | 0/5 [00:00<?, ?it/s]Config '../configs/rf_kmeans_ft_mobi_cv8.yaml' has no VERSION. Assuming it to be compatible with latest v1.
  0%|          | 0/5 [00:00<?, ?it/s]  0%|          | 0/5 [00:00<?, ?it/s]Config '../configs/rf_kmeans_ft_mobi_cv8.yaml' has no VERSION. Assuming it to be compatible with latest v1.
Config '../configs/rf_kmeans_ft_mobi_cv8.yaml' has no VERSION. Assuming it to be compatible with latest v1.
Config '../configs/rf_kmeans_ft_mobi_cv8.yaml' has no VERSION. Assuming it to be compatible with latest v1.
Config '../configs/rf_kmeans_ft_mobi_cv8.yaml' has no VERSION. Assuming it to be compatible with latest v1.
Config '../configs/rf_kmeans_ft_mobi_cv8.yaml' has no VERSION. Assuming it to be compatible with latest v1.
Config '../configs/rf_kmeans_ft_mobi_cv8.yaml' has no VERSION. Assuming it to be compatible with latest v1.
Config '../configs/rf_kmeans_ft_mobi_cv8.yaml' has no VERSION. Assuming it to be compatible with latest v1.
Config '../configs/rf_kmeans_ft_mobi_cv8.yaml' has no VERSION. Assuming it to be compatible with latest v1.
Config '../configs/rf_kmeans_ft_mobi_cv8.yaml' has no VERSION. Assuming it to be compatible with latest v1.
Config '../configs/rf_kmeans_ft_mobi_cv8.yaml' has no VERSION. Assuming it to be compatible with latest v1.
Config '../configs/rf_kmeans_ft_mobi_cv8.yaml' has no VERSION. Assuming it to be compatible with latest v1.
  0%|          | 0/5 [00:00<?, ?it/s]  0%|          | 0/5 [00:00<?, ?it/s]  0%|          | 0/5 [00:00<?, ?it/s]  0%|          | 0/5 [00:00<?, ?it/s]  0%|          | 0/5 [00:00<?, ?it/s]  0%|          | 0/5 [00:00<?, ?it/s]  0%|          | 0/5 [00:00<?, ?it/s]Config '../configs/rf_kmeans_ft_mobi_cv8.yaml' has no VERSION. Assuming it to be compatible with latest v1.
  0%|          | 0/5 [00:00<?, ?it/s]  0%|          | 0/5 [00:00<?, ?it/s]  0%|          | 0/5 [00:00<?, ?it/s]  0%|          | 0/5 [00:00<?, ?it/s]  0%|          | 0/5 [00:00<?, ?it/s]  0%|          | 0/5 [00:00<?, ?it/s]  0%|          | 0/5 [00:00<?, ?it/s]  0%|          | 0/5 [00:00<?, ?it/s]  0%|          | 0/5 [00:00<?, ?it/s]  0%|          | 0/5 [00:00<?, ?it/s]  0%|          | 0/5 [00:00<?, ?it/s]  0%|          | 0/5 [00:00<?, ?it/s]  0%|          | 0/5 [00:00<?, ?it/s]  0%|          | 0/5 [00:00<?, ?it/s]  0%|          | 0/5 [00:00<?, ?it/s]  0%|          | 0/5 [00:00<?, ?it/s]  0%|          | 0/5 [00:00<?, ?it/s]  0%|          | 0/5 [00:00<?, ?it/s]  0%|          | 0/5 [00:00<?, ?it/s]Config '../configs/rf_kmeans_ft_mobi_cv8.yaml' has no VERSION. Assuming it to be compatible with latest v1.
Config '../configs/rf_kmeans_ft_mobi_cv8.yaml' has no VERSION. Assuming it to be compatible with latest v1.
  0%|          | 0/5 [00:00<?, ?it/s]  0%|          | 0/5 [00:00<?, ?it/s]  0%|          | 0/5 [00:00<?, ?it/s]  0%|          | 0/5 [00:00<?, ?it/s]  0%|          | 0/5 [00:00<?, ?it/s]  0%|          | 0/5 [00:00<?, ?it/s]  0%|          | 0/5 [00:00<?, ?it/s]  0%|          | 0/5 [00:00<?, ?it/s]  0%|          | 0/5 [00:00<?, ?it/s]9 / 22191
7 / 17784
9 / 22191
7 / 17784
9 / 22191
7 / 17784
9 / 22191
7 / 17784
9 / 22191
7 / 17784
9 / 22191
7 / 17784
9 / 22191
7 / 17784
9 / 22191
7 / 17784
9 / 22191
7 / 17784
9 / 22191
7 / 17784
9 / 22191
7 / 17784
9 / 22191
7 / 17784
9 / 22191
7 / 17784
9 / 22191
7 / 17784
9 / 22191
7 / 17784
9 / 22191
7 / 17784
9 / 22191
7 / 17784
9 / 22191
7 / 17784
9 / 22191
7 / 17784
9 / 22191
7 / 17784
9 / 22191
7 / 17784
9 / 22191
7 / 17784
9 / 22191
7 / 17784
9 / 22191
7 / 17784
9 / 22191
7 / 17784
9 / 22191
7 / 17784
9 / 22191
7 / 17784
9 / 22191
7 / 17784
9 / 22191
7 / 17784
9 / 22191
7 / 17784
9 / 22191
7 / 17784
9 / 22191
7 / 17784
9 / 22191
7 / 17784
9 / 22191
7 / 17784
exception calling callback for <Future at 0x2b234a875190 state=finished raised TerminatedWorkerError>
Traceback (most recent call last):
  File "/home/users/apopescu/anaconda3/envs/detectron2/lib/python3.8/site-packages/joblib/externals/loky/_base.py", line 625, in _invoke_callbacks
    callback(self)
  File "/home/users/apopescu/anaconda3/envs/detectron2/lib/python3.8/site-packages/joblib/parallel.py", line 347, in __call__
    self.parallel.dispatch_next()
  File "/home/users/apopescu/anaconda3/envs/detectron2/lib/python3.8/site-packages/joblib/parallel.py", line 780, in dispatch_next
    if not self.dispatch_one_batch(self._original_iterator):
  File "/home/users/apopescu/anaconda3/envs/detectron2/lib/python3.8/site-packages/joblib/parallel.py", line 847, in dispatch_one_batch
    self._dispatch(tasks)
  File "/home/users/apopescu/anaconda3/envs/detectron2/lib/python3.8/site-packages/joblib/parallel.py", line 765, in _dispatch
    job = self._backend.apply_async(batch, callback=cb)
  File "/home/users/apopescu/anaconda3/envs/detectron2/lib/python3.8/site-packages/joblib/_parallel_backends.py", line 531, in apply_async
    future = self._workers.submit(SafeFunction(func))
  File "/home/users/apopescu/anaconda3/envs/detectron2/lib/python3.8/site-packages/joblib/externals/loky/reusable_executor.py", line 177, in submit
    return super(_ReusablePoolExecutor, self).submit(
  File "/home/users/apopescu/anaconda3/envs/detectron2/lib/python3.8/site-packages/joblib/externals/loky/process_executor.py", line 1102, in submit
    raise self._flags.broken
joblib.externals.loky.process_executor.TerminatedWorkerError: A worker process managed by the executor was unexpectedly terminated. This could be caused by a segmentation fault while calling the function or by an excessive memory usage causing the Operating System to kill the worker.

The exit codes of the workers are {SIGBUS(-7)}
9 / 22191
7 / 17784
9 / 22191
7 / 17784
9 / 22191
7 / 17784
exception calling callback for <Future at 0x2b6f12e2a190 state=finished raised TerminatedWorkerError>
Traceback (most recent call last):
  File "/home/users/apopescu/anaconda3/envs/detectron2/lib/python3.8/site-packages/joblib/externals/loky/_base.py", line 625, in _invoke_callbacks
    callback(self)
  File "/home/users/apopescu/anaconda3/envs/detectron2/lib/python3.8/site-packages/joblib/parallel.py", line 347, in __call__
    self.parallel.dispatch_next()
  File "/home/users/apopescu/anaconda3/envs/detectron2/lib/python3.8/site-packages/joblib/parallel.py", line 780, in dispatch_next
    if not self.dispatch_one_batch(self._original_iterator):
  File "/home/users/apopescu/anaconda3/envs/detectron2/lib/python3.8/site-packages/joblib/parallel.py", line 847, in dispatch_one_batch
    self._dispatch(tasks)
  File "/home/users/apopescu/anaconda3/envs/detectron2/lib/python3.8/site-packages/joblib/parallel.py", line 765, in _dispatch
    job = self._backend.apply_async(batch, callback=cb)
  File "/home/users/apopescu/anaconda3/envs/detectron2/lib/python3.8/site-packages/joblib/_parallel_backends.py", line 531, in apply_async
    future = self._workers.submit(SafeFunction(func))
  File "/home/users/apopescu/anaconda3/envs/detectron2/lib/python3.8/site-packages/joblib/externals/loky/reusable_executor.py", line 177, in submit
    return super(_ReusablePoolExecutor, self).submit(
  File "/home/users/apopescu/anaconda3/envs/detectron2/lib/python3.8/site-packages/joblib/externals/loky/process_executor.py", line 1102, in submit
    raise self._flags.broken
joblib.externals.loky.process_executor.TerminatedWorkerError: A worker process managed by the executor was unexpectedly terminated. This could be caused by a segmentation fault while calling the function or by an excessive memory usage causing the Operating System to kill the worker.

The exit codes of the workers are {SIGBUS(-7)}
exception calling callback for <Future at 0x2ab35147b190 state=finished raised TerminatedWorkerError>
Traceback (most recent call last):
  File "/home/users/apopescu/anaconda3/envs/detectron2/lib/python3.8/site-packages/joblib/externals/loky/_base.py", line 625, in _invoke_callbacks
    callback(self)
  File "/home/users/apopescu/anaconda3/envs/detectron2/lib/python3.8/site-packages/joblib/parallel.py", line 347, in __call__
    self.parallel.dispatch_next()
  File "/home/users/apopescu/anaconda3/envs/detectron2/lib/python3.8/site-packages/joblib/parallel.py", line 780, in dispatch_next
    if not self.dispatch_one_batch(self._original_iterator):
  File "/home/users/apopescu/anaconda3/envs/detectron2/lib/python3.8/site-packages/joblib/parallel.py", line 847, in dispatch_one_batch
    self._dispatch(tasks)
  File "/home/users/apopescu/anaconda3/envs/detectron2/lib/python3.8/site-packages/joblib/parallel.py", line 765, in _dispatch
    job = self._backend.apply_async(batch, callback=cb)
  File "/home/users/apopescu/anaconda3/envs/detectron2/lib/python3.8/site-packages/joblib/_parallel_backends.py", line 531, in apply_async
    future = self._workers.submit(SafeFunction(func))
  File "/home/users/apopescu/anaconda3/envs/detectron2/lib/python3.8/site-packages/joblib/externals/loky/reusable_executor.py", line 177, in submit
    return super(_ReusablePoolExecutor, self).submit(
  File "/home/users/apopescu/anaconda3/envs/detectron2/lib/python3.8/site-packages/joblib/externals/loky/process_executor.py", line 1102, in submit
    raise self._flags.broken
joblib.externals.loky.process_executor.TerminatedWorkerError: A worker process managed by the executor was unexpectedly terminated. This could be caused by a segmentation fault while calling the function or by an excessive memory usage causing the Operating System to kill the worker.

The exit codes of the workers are {SIGBUS(-7)}
9 / 22191
7 / 17784
9 / 22191
7 / 17784
exception calling callback for <Future at 0x2b881f303190 state=finished raised TerminatedWorkerError>
Traceback (most recent call last):
  File "/home/users/apopescu/anaconda3/envs/detectron2/lib/python3.8/site-packages/joblib/externals/loky/_base.py", line 625, in _invoke_callbacks
    callback(self)
  File "/home/users/apopescu/anaconda3/envs/detectron2/lib/python3.8/site-packages/joblib/parallel.py", line 347, in __call__
    self.parallel.dispatch_next()
  File "/home/users/apopescu/anaconda3/envs/detectron2/lib/python3.8/site-packages/joblib/parallel.py", line 780, in dispatch_next
    if not self.dispatch_one_batch(self._original_iterator):
  File "/home/users/apopescu/anaconda3/envs/detectron2/lib/python3.8/site-packages/joblib/parallel.py", line 847, in dispatch_one_batch
    self._dispatch(tasks)
  File "/home/users/apopescu/anaconda3/envs/detectron2/lib/python3.8/site-packages/joblib/parallel.py", line 765, in _dispatch
    job = self._backend.apply_async(batch, callback=cb)
  File "/home/users/apopescu/anaconda3/envs/detectron2/lib/python3.8/site-packages/joblib/_parallel_backends.py", line 531, in apply_async
    future = self._workers.submit(SafeFunction(func))
  File "/home/users/apopescu/anaconda3/envs/detectron2/lib/python3.8/site-packages/joblib/externals/loky/reusable_executor.py", line 177, in submit
    return super(_ReusablePoolExecutor, self).submit(
  File "/home/users/apopescu/anaconda3/envs/detectron2/lib/python3.8/site-packages/joblib/externals/loky/process_executor.py", line 1102, in submit
    raise self._flags.broken
joblib.externals.loky.process_executor.TerminatedWorkerError: A worker process managed by the executor was unexpectedly terminated. This could be caused by a segmentation fault while calling the function or by an excessive memory usage causing the Operating System to kill the worker.

The exit codes of the workers are {SIGBUS(-7)}
exception calling callback for <Future at 0x2b73c9581190 state=finished raised TerminatedWorkerError>
Traceback (most recent call last):
  File "/home/users/apopescu/anaconda3/envs/detectron2/lib/python3.8/site-packages/joblib/externals/loky/_base.py", line 625, in _invoke_callbacks
    callback(self)
  File "/home/users/apopescu/anaconda3/envs/detectron2/lib/python3.8/site-packages/joblib/parallel.py", line 347, in __call__
    self.parallel.dispatch_next()
  File "/home/users/apopescu/anaconda3/envs/detectron2/lib/python3.8/site-packages/joblib/parallel.py", line 780, in dispatch_next
    if not self.dispatch_one_batch(self._original_iterator):
  File "/home/users/apopescu/anaconda3/envs/detectron2/lib/python3.8/site-packages/joblib/parallel.py", line 847, in dispatch_one_batch
    self._dispatch(tasks)
  File "/home/users/apopescu/anaconda3/envs/detectron2/lib/python3.8/site-packages/joblib/parallel.py", line 765, in _dispatch
    job = self._backend.apply_async(batch, callback=cb)
  File "/home/users/apopescu/anaconda3/envs/detectron2/lib/python3.8/site-packages/joblib/_parallel_backends.py", line 531, in apply_async
    future = self._workers.submit(SafeFunction(func))
  File "/home/users/apopescu/anaconda3/envs/detectron2/lib/python3.8/site-packages/joblib/externals/loky/reusable_executor.py", line 177, in submit
    return super(_ReusablePoolExecutor, self).submit(
  File "/home/users/apopescu/anaconda3/envs/detectron2/lib/python3.8/site-packages/joblib/externals/loky/process_executor.py", line 1102, in submit
    raise self._flags.broken
joblib.externals.loky.process_executor.TerminatedWorkerError: A worker process managed by the executor was unexpectedly terminated. This could be caused by a segmentation fault while calling the function or by an excessive memory usage causing the Operating System to kill the worker.

The exit codes of the workers are {SIGBUS(-7)}
exception calling callback for <Future at 0x2b73c9569910 state=finished raised TerminatedWorkerError>
Traceback (most recent call last):
  File "/home/users/apopescu/anaconda3/envs/detectron2/lib/python3.8/site-packages/joblib/externals/loky/_base.py", line 625, in _invoke_callbacks
    callback(self)
  File "/home/users/apopescu/anaconda3/envs/detectron2/lib/python3.8/site-packages/joblib/parallel.py", line 347, in __call__
    self.parallel.dispatch_next()
  File "/home/users/apopescu/anaconda3/envs/detectron2/lib/python3.8/site-packages/joblib/parallel.py", line 780, in dispatch_next
    if not self.dispatch_one_batch(self._original_iterator):
  File "/home/users/apopescu/anaconda3/envs/detectron2/lib/python3.8/site-packages/joblib/parallel.py", line 847, in dispatch_one_batch
    self._dispatch(tasks)
  File "/home/users/apopescu/anaconda3/envs/detectron2/lib/python3.8/site-packages/joblib/parallel.py", line 765, in _dispatch
    job = self._backend.apply_async(batch, callback=cb)
  File "/home/users/apopescu/anaconda3/envs/detectron2/lib/python3.8/site-packages/joblib/_parallel_backends.py", line 531, in apply_async
    future = self._workers.submit(SafeFunction(func))
  File "/home/users/apopescu/anaconda3/envs/detectron2/lib/python3.8/site-packages/joblib/externals/loky/reusable_executor.py", line 177, in submit
    return super(_ReusablePoolExecutor, self).submit(
  File "/home/users/apopescu/anaconda3/envs/detectron2/lib/python3.8/site-packages/joblib/externals/loky/process_executor.py", line 1102, in submit
    raise self._flags.broken
  File "/home/users/apopescu/anaconda3/envs/detectron2/lib/python3.8/site-packages/joblib/externals/loky/_base.py", line 625, in _invoke_callbacks
    callback(self)
  File "/home/users/apopescu/anaconda3/envs/detectron2/lib/python3.8/site-packages/joblib/parallel.py", line 347, in __call__
    self.parallel.dispatch_next()
  File "/home/users/apopescu/anaconda3/envs/detectron2/lib/python3.8/site-packages/joblib/parallel.py", line 780, in dispatch_next
    if not self.dispatch_one_batch(self._original_iterator):
  File "/home/users/apopescu/anaconda3/envs/detectron2/lib/python3.8/site-packages/joblib/parallel.py", line 847, in dispatch_one_batch
    self._dispatch(tasks)
  File "/home/users/apopescu/anaconda3/envs/detectron2/lib/python3.8/site-packages/joblib/parallel.py", line 765, in _dispatch
    job = self._backend.apply_async(batch, callback=cb)
  File "/home/users/apopescu/anaconda3/envs/detectron2/lib/python3.8/site-packages/joblib/_parallel_backends.py", line 531, in apply_async
    future = self._workers.submit(SafeFunction(func))
  File "/home/users/apopescu/anaconda3/envs/detectron2/lib/python3.8/site-packages/joblib/externals/loky/reusable_executor.py", line 177, in submit
    return super(_ReusablePoolExecutor, self).submit(
  File "/home/users/apopescu/anaconda3/envs/detectron2/lib/python3.8/site-packages/joblib/externals/loky/process_executor.py", line 1102, in submit
    raise self._flags.broken
joblib.externals.loky.process_executor.TerminatedWorkerError: A worker process managed by the executor was unexpectedly terminated. This could be caused by a segmentation fault while calling the function or by an excessive memory usage causing the Operating System to kill the worker.

The exit codes of the workers are {SIGBUS(-7)}
exception calling callback for <Future at 0x2abf97a3f190 state=finished raised TerminatedWorkerError>
Traceback (most recent call last):
  File "/home/users/apopescu/anaconda3/envs/detectron2/lib/python3.8/site-packages/joblib/externals/loky/_base.py", line 625, in _invoke_callbacks
    callback(self)
  File "/home/users/apopescu/anaconda3/envs/detectron2/lib/python3.8/site-packages/joblib/parallel.py", line 347, in __call__
    self.parallel.dispatch_next()
  File "/home/users/apopescu/anaconda3/envs/detectron2/lib/python3.8/site-packages/joblib/parallel.py", line 780, in dispatch_next
    if not self.dispatch_one_batch(self._original_iterator):
  File "/home/users/apopescu/anaconda3/envs/detectron2/lib/python3.8/site-packages/joblib/parallel.py", line 847, in dispatch_one_batch
    self._dispatch(tasks)
  File "/home/users/apopescu/anaconda3/envs/detectron2/lib/python3.8/site-packages/joblib/parallel.py", line 765, in _dispatch
    job = self._backend.apply_async(batch, callback=cb)
  File "/home/users/apopescu/anaconda3/envs/detectron2/lib/python3.8/site-packages/joblib/_parallel_backends.py", line 531, in apply_async
    future = self._workers.submit(SafeFunction(func))
  File "/home/users/apopescu/anaconda3/envs/detectron2/lib/python3.8/site-packages/joblib/externals/loky/reusable_executor.py", line 177, in submit
    return super(_ReusablePoolExecutor, self).submit(
  File "/home/users/apopescu/anaconda3/envs/detectron2/lib/python3.8/site-packages/joblib/externals/loky/process_executor.py", line 1102, in submit
    raise self._flags.broken
joblib.externals.loky.process_executor.TerminatedWorkerError: A worker process managed by the executor was unexpectedly terminated. This could be caused by a segmentation fault while calling the function or by an excessive memory usage causing the Operating System to kill the worker.

The exit codes of the workers are {SIGBUS(-7)}
exception calling callback for <Future at 0x2abf97a30910 state=finished raised TerminatedWorkerError>
Traceback (most recent call last):
  File "/home/users/apopescu/anaconda3/envs/detectron2/lib/python3.8/site-packages/joblib/externals/loky/_base.py", line 625, in _invoke_callbacks
    callback(self)
  File "/home/users/apopescu/anaconda3/envs/detectron2/lib/python3.8/site-packages/joblib/parallel.py", line 347, in __call__
    self.parallel.dispatch_next()
  File "/home/users/apopescu/anaconda3/envs/detectron2/lib/python3.8/site-packages/joblib/parallel.py", line 780, in dispatch_next
    if not self.dispatch_one_batch(self._original_iterator):
  File "/home/users/apopescu/anaconda3/envs/detectron2/lib/python3.8/site-packages/joblib/parallel.py", line 847, in dispatch_one_batch
    self._dispatch(tasks)
  File "/home/users/apopescu/anaconda3/envs/detectron2/lib/python3.8/site-packages/joblib/parallel.py", line 765, in _dispatch
    job = self._backend.apply_async(batch, callback=cb)
  File "/home/users/apopescu/anaconda3/envs/detectron2/lib/python3.8/site-packages/joblib/_parallel_backends.py", line 531, in apply_async
    future = self._workers.submit(SafeFunction(func))
  File "/home/users/apopescu/anaconda3/envs/detectron2/lib/python3.8/site-packages/joblib/externals/loky/reusable_executor.py", line 177, in submit
    return super(_ReusablePoolExecutor, self).submit(
  File "/home/users/apopescu/anaconda3/envs/detectron2/lib/python3.8/site-packages/joblib/externals/loky/process_executor.py", line 1102, in submit
    raise self._flags.broken
  File "/home/users/apopescu/anaconda3/envs/detectron2/lib/python3.8/site-packages/joblib/externals/loky/_base.py", line 625, in _invoke_callbacks
    callback(self)
  File "/home/users/apopescu/anaconda3/envs/detectron2/lib/python3.8/site-packages/joblib/parallel.py", line 347, in __call__
    self.parallel.dispatch_next()
  File "/home/users/apopescu/anaconda3/envs/detectron2/lib/python3.8/site-packages/joblib/parallel.py", line 780, in dispatch_next
    if not self.dispatch_one_batch(self._original_iterator):
  File "/home/users/apopescu/anaconda3/envs/detectron2/lib/python3.8/site-packages/joblib/parallel.py", line 847, in dispatch_one_batch
    self._dispatch(tasks)
  File "/home/users/apopescu/anaconda3/envs/detectron2/lib/python3.8/site-packages/joblib/parallel.py", line 765, in _dispatch
    job = self._backend.apply_async(batch, callback=cb)
  File "/home/users/apopescu/anaconda3/envs/detectron2/lib/python3.8/site-packages/joblib/_parallel_backends.py", line 531, in apply_async
    future = self._workers.submit(SafeFunction(func))
  File "/home/users/apopescu/anaconda3/envs/detectron2/lib/python3.8/site-packages/joblib/externals/loky/reusable_executor.py", line 177, in submit
    return super(_ReusablePoolExecutor, self).submit(
  File "/home/users/apopescu/anaconda3/envs/detectron2/lib/python3.8/site-packages/joblib/externals/loky/process_executor.py", line 1102, in submit
    raise self._flags.broken
joblib.externals.loky.process_executor.TerminatedWorkerError: A worker process managed by the executor was unexpectedly terminated. This could be caused by a segmentation fault while calling the function or by an excessive memory usage causing the Operating System to kill the worker.

The exit codes of the workers are {SIGBUS(-7)}
exception calling callback for <Future at 0x2abf97a30d60 state=finished raised TerminatedWorkerError>
Traceback (most recent call last):
  File "/home/users/apopescu/anaconda3/envs/detectron2/lib/python3.8/site-packages/joblib/externals/loky/_base.py", line 625, in _invoke_callbacks
    callback(self)
  File "/home/users/apopescu/anaconda3/envs/detectron2/lib/python3.8/site-packages/joblib/parallel.py", line 347, in __call__
    self.parallel.dispatch_next()
  File "/home/users/apopescu/anaconda3/envs/detectron2/lib/python3.8/site-packages/joblib/parallel.py", line 780, in dispatch_next
    if not self.dispatch_one_batch(self._original_iterator):
  File "/home/users/apopescu/anaconda3/envs/detectron2/lib/python3.8/site-packages/joblib/parallel.py", line 847, in dispatch_one_batch
    self._dispatch(tasks)
  File "/home/users/apopescu/anaconda3/envs/detectron2/lib/python3.8/site-packages/joblib/parallel.py", line 765, in _dispatch
    job = self._backend.apply_async(batch, callback=cb)
  File "/home/users/apopescu/anaconda3/envs/detectron2/lib/python3.8/site-packages/joblib/_parallel_backends.py", line 531, in apply_async
    future = self._workers.submit(SafeFunction(func))
  File "/home/users/apopescu/anaconda3/envs/detectron2/lib/python3.8/site-packages/joblib/externals/loky/reusable_executor.py", line 177, in submit
    return super(_ReusablePoolExecutor, self).submit(
  File "/home/users/apopescu/anaconda3/envs/detectron2/lib/python3.8/site-packages/joblib/externals/loky/process_executor.py", line 1102, in submit
    raise self._flags.broken
  File "/home/users/apopescu/anaconda3/envs/detectron2/lib/python3.8/site-packages/joblib/externals/loky/_base.py", line 625, in _invoke_callbacks
    callback(self)
  File "/home/users/apopescu/anaconda3/envs/detectron2/lib/python3.8/site-packages/joblib/parallel.py", line 347, in __call__
    self.parallel.dispatch_next()
  File "/home/users/apopescu/anaconda3/envs/detectron2/lib/python3.8/site-packages/joblib/parallel.py", line 780, in dispatch_next
    if not self.dispatch_one_batch(self._original_iterator):
  File "/home/users/apopescu/anaconda3/envs/detectron2/lib/python3.8/site-packages/joblib/parallel.py", line 847, in dispatch_one_batch
    self._dispatch(tasks)
  File "/home/users/apopescu/anaconda3/envs/detectron2/lib/python3.8/site-packages/joblib/parallel.py", line 765, in _dispatch
    job = self._backend.apply_async(batch, callback=cb)
  File "/home/users/apopescu/anaconda3/envs/detectron2/lib/python3.8/site-packages/joblib/_parallel_backends.py", line 531, in apply_async
    future = self._workers.submit(SafeFunction(func))
  File "/home/users/apopescu/anaconda3/envs/detectron2/lib/python3.8/site-packages/joblib/externals/loky/reusable_executor.py", line 177, in submit
    return super(_ReusablePoolExecutor, self).submit(
  File "/home/users/apopescu/anaconda3/envs/detectron2/lib/python3.8/site-packages/joblib/externals/loky/process_executor.py", line 1102, in submit
    raise self._flags.broken
  File "/home/users/apopescu/anaconda3/envs/detectron2/lib/python3.8/site-packages/joblib/externals/loky/_base.py", line 625, in _invoke_callbacks
    callback(self)
  File "/home/users/apopescu/anaconda3/envs/detectron2/lib/python3.8/site-packages/joblib/parallel.py", line 347, in __call__
    self.parallel.dispatch_next()
  File "/home/users/apopescu/anaconda3/envs/detectron2/lib/python3.8/site-packages/joblib/parallel.py", line 780, in dispatch_next
    if not self.dispatch_one_batch(self._original_iterator):
  File "/home/users/apopescu/anaconda3/envs/detectron2/lib/python3.8/site-packages/joblib/parallel.py", line 847, in dispatch_one_batch
    self._dispatch(tasks)
  File "/home/users/apopescu/anaconda3/envs/detectron2/lib/python3.8/site-packages/joblib/parallel.py", line 765, in _dispatch
    job = self._backend.apply_async(batch, callback=cb)
  File "/home/users/apopescu/anaconda3/envs/detectron2/lib/python3.8/site-packages/joblib/_parallel_backends.py", line 531, in apply_async
    future = self._workers.submit(SafeFunction(func))
  File "/home/users/apopescu/anaconda3/envs/detectron2/lib/python3.8/site-packages/joblib/externals/loky/reusable_executor.py", line 177, in submit
    return super(_ReusablePoolExecutor, self).submit(
  File "/home/users/apopescu/anaconda3/envs/detectron2/lib/python3.8/site-packages/joblib/externals/loky/process_executor.py", line 1102, in submit
    raise self._flags.broken
joblib.externals.loky.process_executor.TerminatedWorkerError: A worker process managed by the executor was unexpectedly terminated. This could be caused by a segmentation fault while calling the function or by an excessive memory usage causing the Operating System to kill the worker.

The exit codes of the workers are {SIGBUS(-7)}
exception calling callback for <Future at 0x2b8364f40190 state=finished raised TerminatedWorkerError>
Traceback (most recent call last):
  File "/home/users/apopescu/anaconda3/envs/detectron2/lib/python3.8/site-packages/joblib/externals/loky/_base.py", line 625, in _invoke_callbacks
    callback(self)
  File "/home/users/apopescu/anaconda3/envs/detectron2/lib/python3.8/site-packages/joblib/parallel.py", line 347, in __call__
    self.parallel.dispatch_next()
  File "/home/users/apopescu/anaconda3/envs/detectron2/lib/python3.8/site-packages/joblib/parallel.py", line 780, in dispatch_next
    if not self.dispatch_one_batch(self._original_iterator):
  File "/home/users/apopescu/anaconda3/envs/detectron2/lib/python3.8/site-packages/joblib/parallel.py", line 847, in dispatch_one_batch
    self._dispatch(tasks)
  File "/home/users/apopescu/anaconda3/envs/detectron2/lib/python3.8/site-packages/joblib/parallel.py", line 765, in _dispatch
    job = self._backend.apply_async(batch, callback=cb)
  File "/home/users/apopescu/anaconda3/envs/detectron2/lib/python3.8/site-packages/joblib/_parallel_backends.py", line 531, in apply_async
    future = self._workers.submit(SafeFunction(func))
  File "/home/users/apopescu/anaconda3/envs/detectron2/lib/python3.8/site-packages/joblib/externals/loky/reusable_executor.py", line 177, in submit
    return super(_ReusablePoolExecutor, self).submit(
  File "/home/users/apopescu/anaconda3/envs/detectron2/lib/python3.8/site-packages/joblib/externals/loky/process_executor.py", line 1102, in submit
    raise self._flags.broken
joblib.externals.loky.process_executor.TerminatedWorkerError: A worker process managed by the executor was unexpectedly terminated. This could be caused by a segmentation fault while calling the function or by an excessive memory usage causing the Operating System to kill the worker.

The exit codes of the workers are {SIGBUS(-7)}
exception calling callback for <Future at 0x2b8364f30910 state=finished raised TerminatedWorkerError>
Traceback (most recent call last):
  File "/home/users/apopescu/anaconda3/envs/detectron2/lib/python3.8/site-packages/joblib/externals/loky/_base.py", line 625, in _invoke_callbacks
    callback(self)
  File "/home/users/apopescu/anaconda3/envs/detectron2/lib/python3.8/site-packages/joblib/parallel.py", line 347, in __call__
    self.parallel.dispatch_next()
  File "/home/users/apopescu/anaconda3/envs/detectron2/lib/python3.8/site-packages/joblib/parallel.py", line 780, in dispatch_next
    if not self.dispatch_one_batch(self._original_iterator):
  File "/home/users/apopescu/anaconda3/envs/detectron2/lib/python3.8/site-packages/joblib/parallel.py", line 847, in dispatch_one_batch
    self._dispatch(tasks)
  File "/home/users/apopescu/anaconda3/envs/detectron2/lib/python3.8/site-packages/joblib/parallel.py", line 765, in _dispatch
    job = self._backend.apply_async(batch, callback=cb)
  File "/home/users/apopescu/anaconda3/envs/detectron2/lib/python3.8/site-packages/joblib/_parallel_backends.py", line 531, in apply_async
    future = self._workers.submit(SafeFunction(func))
  File "/home/users/apopescu/anaconda3/envs/detectron2/lib/python3.8/site-packages/joblib/externals/loky/reusable_executor.py", line 177, in submit
    return super(_ReusablePoolExecutor, self).submit(
  File "/home/users/apopescu/anaconda3/envs/detectron2/lib/python3.8/site-packages/joblib/externals/loky/process_executor.py", line 1102, in submit
    raise self._flags.broken
  File "/home/users/apopescu/anaconda3/envs/detectron2/lib/python3.8/site-packages/joblib/externals/loky/_base.py", line 625, in _invoke_callbacks
    callback(self)
  File "/home/users/apopescu/anaconda3/envs/detectron2/lib/python3.8/site-packages/joblib/parallel.py", line 347, in __call__
    self.parallel.dispatch_next()
  File "/home/users/apopescu/anaconda3/envs/detectron2/lib/python3.8/site-packages/joblib/parallel.py", line 780, in dispatch_next
    if not self.dispatch_one_batch(self._original_iterator):
  File "/home/users/apopescu/anaconda3/envs/detectron2/lib/python3.8/site-packages/joblib/parallel.py", line 847, in dispatch_one_batch
    self._dispatch(tasks)
  File "/home/users/apopescu/anaconda3/envs/detectron2/lib/python3.8/site-packages/joblib/parallel.py", line 765, in _dispatch
    job = self._backend.apply_async(batch, callback=cb)
  File "/home/users/apopescu/anaconda3/envs/detectron2/lib/python3.8/site-packages/joblib/_parallel_backends.py", line 531, in apply_async
    future = self._workers.submit(SafeFunction(func))
  File "/home/users/apopescu/anaconda3/envs/detectron2/lib/python3.8/site-packages/joblib/externals/loky/reusable_executor.py", line 177, in submit
    return super(_ReusablePoolExecutor, self).submit(
  File "/home/users/apopescu/anaconda3/envs/detectron2/lib/python3.8/site-packages/joblib/externals/loky/process_executor.py", line 1102, in submit
    raise self._flags.broken
joblib.externals.loky.process_executor.TerminatedWorkerError: A worker process managed by the executor was unexpectedly terminated. This could be caused by a segmentation fault while calling the function or by an excessive memory usage causing the Operating System to kill the worker.

The exit codes of the workers are {SIGBUS(-7)}
exception calling callback for <Future at 0x2b8364f30d60 state=finished raised TerminatedWorkerError>
Traceback (most recent call last):
  File "/home/users/apopescu/anaconda3/envs/detectron2/lib/python3.8/site-packages/joblib/externals/loky/_base.py", line 625, in _invoke_callbacks
    callback(self)
  File "/home/users/apopescu/anaconda3/envs/detectron2/lib/python3.8/site-packages/joblib/parallel.py", line 347, in __call__
    self.parallel.dispatch_next()
  File "/home/users/apopescu/anaconda3/envs/detectron2/lib/python3.8/site-packages/joblib/parallel.py", line 780, in dispatch_next
    if not self.dispatch_one_batch(self._original_iterator):
  File "/home/users/apopescu/anaconda3/envs/detectron2/lib/python3.8/site-packages/joblib/parallel.py", line 847, in dispatch_one_batch
    self._dispatch(tasks)
  File "/home/users/apopescu/anaconda3/envs/detectron2/lib/python3.8/site-packages/joblib/parallel.py", line 765, in _dispatch
    job = self._backend.apply_async(batch, callback=cb)
  File "/home/users/apopescu/anaconda3/envs/detectron2/lib/python3.8/site-packages/joblib/_parallel_backends.py", line 531, in apply_async
    future = self._workers.submit(SafeFunction(func))
  File "/home/users/apopescu/anaconda3/envs/detectron2/lib/python3.8/site-packages/joblib/externals/loky/reusable_executor.py", line 177, in submit
    return super(_ReusablePoolExecutor, self).submit(
  File "/home/users/apopescu/anaconda3/envs/detectron2/lib/python3.8/site-packages/joblib/externals/loky/process_executor.py", line 1102, in submit
    raise self._flags.broken
  File "/home/users/apopescu/anaconda3/envs/detectron2/lib/python3.8/site-packages/joblib/externals/loky/_base.py", line 625, in _invoke_callbacks
    callback(self)
  File "/home/users/apopescu/anaconda3/envs/detectron2/lib/python3.8/site-packages/joblib/parallel.py", line 347, in __call__
    self.parallel.dispatch_next()
  File "/home/users/apopescu/anaconda3/envs/detectron2/lib/python3.8/site-packages/joblib/parallel.py", line 780, in dispatch_next
    if not self.dispatch_one_batch(self._original_iterator):
  File "/home/users/apopescu/anaconda3/envs/detectron2/lib/python3.8/site-packages/joblib/parallel.py", line 847, in dispatch_one_batch
    self._dispatch(tasks)
  File "/home/users/apopescu/anaconda3/envs/detectron2/lib/python3.8/site-packages/joblib/parallel.py", line 765, in _dispatch
    job = self._backend.apply_async(batch, callback=cb)
  File "/home/users/apopescu/anaconda3/envs/detectron2/lib/python3.8/site-packages/joblib/_parallel_backends.py", line 531, in apply_async
    future = self._workers.submit(SafeFunction(func))
  File "/home/users/apopescu/anaconda3/envs/detectron2/lib/python3.8/site-packages/joblib/externals/loky/reusable_executor.py", line 177, in submit
    return super(_ReusablePoolExecutor, self).submit(
  File "/home/users/apopescu/anaconda3/envs/detectron2/lib/python3.8/site-packages/joblib/externals/loky/process_executor.py", line 1102, in submit
    raise self._flags.broken
  File "/home/users/apopescu/anaconda3/envs/detectron2/lib/python3.8/site-packages/joblib/externals/loky/_base.py", line 625, in _invoke_callbacks
    callback(self)
  File "/home/users/apopescu/anaconda3/envs/detectron2/lib/python3.8/site-packages/joblib/parallel.py", line 347, in __call__
    self.parallel.dispatch_next()
  File "/home/users/apopescu/anaconda3/envs/detectron2/lib/python3.8/site-packages/joblib/parallel.py", line 780, in dispatch_next
    if not self.dispatch_one_batch(self._original_iterator):
  File "/home/users/apopescu/anaconda3/envs/detectron2/lib/python3.8/site-packages/joblib/parallel.py", line 847, in dispatch_one_batch
    self._dispatch(tasks)
  File "/home/users/apopescu/anaconda3/envs/detectron2/lib/python3.8/site-packages/joblib/parallel.py", line 765, in _dispatch
    job = self._backend.apply_async(batch, callback=cb)
  File "/home/users/apopescu/anaconda3/envs/detectron2/lib/python3.8/site-packages/joblib/_parallel_backends.py", line 531, in apply_async
    future = self._workers.submit(SafeFunction(func))
  File "/home/users/apopescu/anaconda3/envs/detectron2/lib/python3.8/site-packages/joblib/externals/loky/reusable_executor.py", line 177, in submit
    return super(_ReusablePoolExecutor, self).submit(
  File "/home/users/apopescu/anaconda3/envs/detectron2/lib/python3.8/site-packages/joblib/externals/loky/process_executor.py", line 1102, in submit
    raise self._flags.broken
joblib.externals.loky.process_executor.TerminatedWorkerError: A worker process managed by the executor was unexpectedly terminated. This could be caused by a segmentation fault while calling the function or by an excessive memory usage causing the Operating System to kill the worker.

The exit codes of the workers are {SIGBUS(-7)}
exception calling callback for <Future at 0x2b82d5c51190 state=finished raised TerminatedWorkerError>
Traceback (most recent call last):
  File "/home/users/apopescu/anaconda3/envs/detectron2/lib/python3.8/site-packages/joblib/externals/loky/_base.py", line 625, in _invoke_callbacks
    callback(self)
  File "/home/users/apopescu/anaconda3/envs/detectron2/lib/python3.8/site-packages/joblib/parallel.py", line 347, in __call__
    self.parallel.dispatch_next()
  File "/home/users/apopescu/anaconda3/envs/detectron2/lib/python3.8/site-packages/joblib/parallel.py", line 780, in dispatch_next
    if not self.dispatch_one_batch(self._original_iterator):
  File "/home/users/apopescu/anaconda3/envs/detectron2/lib/python3.8/site-packages/joblib/parallel.py", line 847, in dispatch_one_batch
    self._dispatch(tasks)
  File "/home/users/apopescu/anaconda3/envs/detectron2/lib/python3.8/site-packages/joblib/parallel.py", line 765, in _dispatch
    job = self._backend.apply_async(batch, callback=cb)
  File "/home/users/apopescu/anaconda3/envs/detectron2/lib/python3.8/site-packages/joblib/_parallel_backends.py", line 531, in apply_async
    future = self._workers.submit(SafeFunction(func))
  File "/home/users/apopescu/anaconda3/envs/detectron2/lib/python3.8/site-packages/joblib/externals/loky/reusable_executor.py", line 177, in submit
    return super(_ReusablePoolExecutor, self).submit(
  File "/home/users/apopescu/anaconda3/envs/detectron2/lib/python3.8/site-packages/joblib/externals/loky/process_executor.py", line 1102, in submit
    raise self._flags.broken
joblib.externals.loky.process_executor.TerminatedWorkerError: A worker process managed by the executor was unexpectedly terminated. This could be caused by a segmentation fault while calling the function or by an excessive memory usage causing the Operating System to kill the worker.

The exit codes of the workers are {SIGBUS(-7)}
exception calling callback for <Future at 0x2ba7b0267190 state=finished raised TerminatedWorkerError>
Traceback (most recent call last):
  File "/home/users/apopescu/anaconda3/envs/detectron2/lib/python3.8/site-packages/joblib/externals/loky/_base.py", line 625, in _invoke_callbacks
    callback(self)
  File "/home/users/apopescu/anaconda3/envs/detectron2/lib/python3.8/site-packages/joblib/parallel.py", line 347, in __call__
    self.parallel.dispatch_next()
  File "/home/users/apopescu/anaconda3/envs/detectron2/lib/python3.8/site-packages/joblib/parallel.py", line 780, in dispatch_next
    if not self.dispatch_one_batch(self._original_iterator):
  File "/home/users/apopescu/anaconda3/envs/detectron2/lib/python3.8/site-packages/joblib/parallel.py", line 847, in dispatch_one_batch
    self._dispatch(tasks)
  File "/home/users/apopescu/anaconda3/envs/detectron2/lib/python3.8/site-packages/joblib/parallel.py", line 765, in _dispatch
    job = self._backend.apply_async(batch, callback=cb)
  File "/home/users/apopescu/anaconda3/envs/detectron2/lib/python3.8/site-packages/joblib/_parallel_backends.py", line 531, in apply_async
    future = self._workers.submit(SafeFunction(func))
  File "/home/users/apopescu/anaconda3/envs/detectron2/lib/python3.8/site-packages/joblib/externals/loky/reusable_executor.py", line 177, in submit
    return super(_ReusablePoolExecutor, self).submit(
  File "/home/users/apopescu/anaconda3/envs/detectron2/lib/python3.8/site-packages/joblib/externals/loky/process_executor.py", line 1102, in submit
    raise self._flags.broken
joblib.externals.loky.process_executor.TerminatedWorkerError: A worker process managed by the executor was unexpectedly terminated. This could be caused by a segmentation fault while calling the function or by an excessive memory usage causing the Operating System to kill the worker.

The exit codes of the workers are {SIGKILL(-9)}
/home/users/apopescu/anaconda3/envs/detectron2/lib/python3.8/site-packages/joblib/externals/loky/backend/resource_tracker.py:120: UserWarning: resource_tracker: process died unexpectedly, relaunching.  Some folders/sempahores might leak.
  warnings.warn('resource_tracker: process died unexpectedly, '
  0%|          | 0/5 [01:14<?, ?it/s]
  0%|          | 0/5 [01:14<?, ?it/s]
  0%|          | 0/5 [01:15<?, ?it/s]
Traceback (most recent call last):
  File "ft_official.py", line 118, in <module>
    main()
  File "ft_official.py", line 100, in main
    model.train_vispel()
  File "/home/users/apopescu/van-khoa/Vis-Priva-Expos/privacy/vispel/vispel/vispel.py", line 54, in train_vispel
    trained_clusteror, trained_regressor, feature_selector = trainer(self.situation, self.X_train, self.X_community,\
  File "/home/users/apopescu/van-khoa/Vis-Priva-Expos/privacy/vispel/vispel/trainer.py", line 64, in trainer
    trained_regressor = train_regressor(regressor, X_train_rd, gt_train_expos, cfg)
  File "/home/users/apopescu/van-khoa/Vis-Priva-Expos/privacy/lib/regressor/regression.py", line 22, in train_regressor
    model.fit(x_train, y_train)
  File "/home/users/apopescu/anaconda3/envs/detectron2/lib/python3.8/site-packages/sklearn/utils/validation.py", line 73, in inner_f
    return f(**kwargs)
  File "/home/users/apopescu/anaconda3/envs/detectron2/lib/python3.8/site-packages/sklearn/model_selection/_search.py", line 736, in fit
    self._run_search(evaluate_candidates)
  File "/home/users/apopescu/anaconda3/envs/detectron2/lib/python3.8/site-packages/sklearn/model_selection/_search.py", line 1188, in _run_search
    evaluate_candidates(ParameterGrid(self.param_grid))
  File "/home/users/apopescu/anaconda3/envs/detectron2/lib/python3.8/site-packages/sklearn/model_selection/_search.py", line 708, in evaluate_candidates
    out = parallel(delayed(_fit_and_score)(clone(base_estimator),
  File "/home/users/apopescu/anaconda3/envs/detectron2/lib/python3.8/site-packages/joblib/parallel.py", line 1042, in __call__
    self.retrieve()
  File "/home/users/apopescu/anaconda3/envs/detectron2/lib/python3.8/site-packages/joblib/parallel.py", line 921, in retrieve
    self._output.extend(job.get(timeout=self.timeout))
  File "/home/users/apopescu/anaconda3/envs/detectron2/lib/python3.8/site-packages/joblib/_parallel_backends.py", line 542, in wrap_future_result
    return future.result(timeout=timeout)
  File "/home/users/apopescu/anaconda3/envs/detectron2/lib/python3.8/concurrent/futures/_base.py", line 439, in result
    return self.__get_result()
  File "/home/users/apopescu/anaconda3/envs/detectron2/lib/python3.8/concurrent/futures/_base.py", line 388, in __get_result
    raise self._exception
  File "/home/users/apopescu/anaconda3/envs/detectron2/lib/python3.8/site-packages/joblib/externals/loky/_base.py", line 625, in _invoke_callbacks
    callback(self)
  File "/home/users/apopescu/anaconda3/envs/detectron2/lib/python3.8/site-packages/joblib/parallel.py", line 347, in __call__
    self.parallel.dispatch_next()
  File "/home/users/apopescu/anaconda3/envs/detectron2/lib/python3.8/site-packages/joblib/parallel.py", line 780, in dispatch_next
    if not self.dispatch_one_batch(self._original_iterator):
  File "/home/users/apopescu/anaconda3/envs/detectron2/lib/python3.8/site-packages/joblib/parallel.py", line 847, in dispatch_one_batch
    self._dispatch(tasks)
  File "/home/users/apopescu/anaconda3/envs/detectron2/lib/python3.8/site-packages/joblib/parallel.py", line 765, in _dispatch
    job = self._backend.apply_async(batch, callback=cb)
  File "/home/users/apopescu/anaconda3/envs/detectron2/lib/python3.8/site-packages/joblib/_parallel_backends.py", line 531, in apply_async
    future = self._workers.submit(SafeFunction(func))
  File "/home/users/apopescu/anaconda3/envs/detectron2/lib/python3.8/site-packages/joblib/externals/loky/reusable_executor.py", line 177, in submit
    return super(_ReusablePoolExecutor, self).submit(
  File "/home/users/apopescu/anaconda3/envs/detectron2/lib/python3.8/site-packages/joblib/externals/loky/process_executor.py", line 1102, in submit
    raise self._flags.broken
joblib.externals.loky.process_executor.TerminatedWorkerError: A worker process managed by the executor was unexpectedly terminated. This could be caused by a segmentation fault while calling the function or by an excessive memory usage causing the Operating System to kill the worker.

The exit codes of the workers are {SIGBUS(-7)}
Traceback (most recent call last):
  File "ft_official.py", line 118, in <module>
    main()
  File "ft_official.py", line 100, in main
    model.train_vispel()
  File "/home/users/apopescu/van-khoa/Vis-Priva-Expos/privacy/vispel/vispel/vispel.py", line 54, in train_vispel
    trained_clusteror, trained_regressor, feature_selector = trainer(self.situation, self.X_train, self.X_community,\
  File "/home/users/apopescu/van-khoa/Vis-Priva-Expos/privacy/vispel/vispel/trainer.py", line 64, in trainer
    trained_regressor = train_regressor(regressor, X_train_rd, gt_train_expos, cfg)
  File "/home/users/apopescu/van-khoa/Vis-Priva-Expos/privacy/lib/regressor/regression.py", line 22, in train_regressor
    model.fit(x_train, y_train)
  File "/home/users/apopescu/anaconda3/envs/detectron2/lib/python3.8/site-packages/sklearn/utils/validation.py", line 73, in inner_f
    return f(**kwargs)
  File "/home/users/apopescu/anaconda3/envs/detectron2/lib/python3.8/site-packages/sklearn/model_selection/_search.py", line 736, in fit
    self._run_search(evaluate_candidates)
  File "/home/users/apopescu/anaconda3/envs/detectron2/lib/python3.8/site-packages/sklearn/model_selection/_search.py", line 1188, in _run_search
    evaluate_candidates(ParameterGrid(self.param_grid))
  File "/home/users/apopescu/anaconda3/envs/detectron2/lib/python3.8/site-packages/sklearn/model_selection/_search.py", line 708, in evaluate_candidates
    out = parallel(delayed(_fit_and_score)(clone(base_estimator),
  File "/home/users/apopescu/anaconda3/envs/detectron2/lib/python3.8/site-packages/joblib/parallel.py", line 1042, in __call__
    self.retrieve()
  File "/home/users/apopescu/anaconda3/envs/detectron2/lib/python3.8/site-packages/joblib/parallel.py", line 921, in retrieve
    self._output.extend(job.get(timeout=self.timeout))
  File "/home/users/apopescu/anaconda3/envs/detectron2/lib/python3.8/site-packages/joblib/_parallel_backends.py", line 542, in wrap_future_result
    return future.result(timeout=timeout)
  File "/home/users/apopescu/anaconda3/envs/detectron2/lib/python3.8/concurrent/futures/_base.py", line 439, in result
    return self.__get_result()
  File "/home/users/apopescu/anaconda3/envs/detectron2/lib/python3.8/concurrent/futures/_base.py", line 388, in __get_result
    raise self._exception
  File "/home/users/apopescu/anaconda3/envs/detectron2/lib/python3.8/site-packages/joblib/externals/loky/_base.py", line 625, in _invoke_callbacks
    callback(self)
  File "/home/users/apopescu/anaconda3/envs/detectron2/lib/python3.8/site-packages/joblib/parallel.py", line 347, in __call__
    self.parallel.dispatch_next()
  File "/home/users/apopescu/anaconda3/envs/detectron2/lib/python3.8/site-packages/joblib/parallel.py", line 780, in dispatch_next
    if not self.dispatch_one_batch(self._original_iterator):
  File "/home/users/apopescu/anaconda3/envs/detectron2/lib/python3.8/site-packages/joblib/parallel.py", line 847, in dispatch_one_batch
    self._dispatch(tasks)
  File "/home/users/apopescu/anaconda3/envs/detectron2/lib/python3.8/site-packages/joblib/parallel.py", line 765, in _dispatch
    job = self._backend.apply_async(batch, callback=cb)
  File "/home/users/apopescu/anaconda3/envs/detectron2/lib/python3.8/site-packages/joblib/_parallel_backends.py", line 531, in apply_async
    future = self._workers.submit(SafeFunction(func))
  File "/home/users/apopescu/anaconda3/envs/detectron2/lib/python3.8/site-packages/joblib/externals/loky/reusable_executor.py", line 177, in submit
    return super(_ReusablePoolExecutor, self).submit(
  File "/home/users/apopescu/anaconda3/envs/detectron2/lib/python3.8/site-packages/joblib/externals/loky/process_executor.py", line 1102, in submit
    raise self._flags.broken
joblib.externals.loky.process_executor.TerminatedWorkerError: A worker process managed by the executor was unexpectedly terminated. This could be caused by a segmentation fault while calling the function or by an excessive memory usage causing the Operating System to kill the worker.

The exit codes of the workers are {SIGBUS(-7)}
  0%|          | 0/5 [01:16<?, ?it/s]
  0%|          | 0/5 [01:16<?, ?it/s]
  0%|          | 0/5 [01:16<?, ?it/s]
  0%|          | 0/5 [01:16<?, ?it/s]
Traceback (most recent call last):
  File "ft_official.py", line 118, in <module>
    main()
  File "ft_official.py", line 100, in main
    model.train_vispel()
  File "/home/users/apopescu/van-khoa/Vis-Priva-Expos/privacy/vispel/vispel/vispel.py", line 54, in train_vispel
    trained_clusteror, trained_regressor, feature_selector = trainer(self.situation, self.X_train, self.X_community,\
  File "/home/users/apopescu/van-khoa/Vis-Priva-Expos/privacy/vispel/vispel/trainer.py", line 64, in trainer
    trained_regressor = train_regressor(regressor, X_train_rd, gt_train_expos, cfg)
  File "/home/users/apopescu/van-khoa/Vis-Priva-Expos/privacy/lib/regressor/regression.py", line 22, in train_regressor
    model.fit(x_train, y_train)
  File "/home/users/apopescu/anaconda3/envs/detectron2/lib/python3.8/site-packages/sklearn/utils/validation.py", line 73, in inner_f
    return f(**kwargs)
  File "/home/users/apopescu/anaconda3/envs/detectron2/lib/python3.8/site-packages/sklearn/model_selection/_search.py", line 736, in fit
    self._run_search(evaluate_candidates)
  File "/home/users/apopescu/anaconda3/envs/detectron2/lib/python3.8/site-packages/sklearn/model_selection/_search.py", line 1188, in _run_search
    evaluate_candidates(ParameterGrid(self.param_grid))
  File "/home/users/apopescu/anaconda3/envs/detectron2/lib/python3.8/site-packages/sklearn/model_selection/_search.py", line 708, in evaluate_candidates
    out = parallel(delayed(_fit_and_score)(clone(base_estimator),
  File "/home/users/apopescu/anaconda3/envs/detectron2/lib/python3.8/site-packages/joblib/parallel.py", line 1042, in __call__
    self.retrieve()
  File "/home/users/apopescu/anaconda3/envs/detectron2/lib/python3.8/site-packages/joblib/parallel.py", line 921, in retrieve
    self._output.extend(job.get(timeout=self.timeout))
  File "/home/users/apopescu/anaconda3/envs/detectron2/lib/python3.8/site-packages/joblib/_parallel_backends.py", line 542, in wrap_future_result
    return future.result(timeout=timeout)
  File "/home/users/apopescu/anaconda3/envs/detectron2/lib/python3.8/concurrent/futures/_base.py", line 439, in result
    return self.__get_result()
  File "/home/users/apopescu/anaconda3/envs/detectron2/lib/python3.8/concurrent/futures/_base.py", line 388, in __get_result
    raise self._exception
  File "/home/users/apopescu/anaconda3/envs/detectron2/lib/python3.8/site-packages/joblib/externals/loky/_base.py", line 625, in _invoke_callbacks
    callback(self)
  File "/home/users/apopescu/anaconda3/envs/detectron2/lib/python3.8/site-packages/joblib/parallel.py", line 347, in __call__
    self.parallel.dispatch_next()
  File "/home/users/apopescu/anaconda3/envs/detectron2/lib/python3.8/site-packages/joblib/parallel.py", line 780, in dispatch_next
    if not self.dispatch_one_batch(self._original_iterator):
  File "/home/users/apopescu/anaconda3/envs/detectron2/lib/python3.8/site-packages/joblib/parallel.py", line 847, in dispatch_one_batch
    self._dispatch(tasks)
  File "/home/users/apopescu/anaconda3/envs/detectron2/lib/python3.8/site-packages/joblib/parallel.py", line 765, in _dispatch
    job = self._backend.apply_async(batch, callback=cb)
  File "/home/users/apopescu/anaconda3/envs/detectron2/lib/python3.8/site-packages/joblib/_parallel_backends.py", line 531, in apply_async
    future = self._workers.submit(SafeFunction(func))
  File "/home/users/apopescu/anaconda3/envs/detectron2/lib/python3.8/site-packages/joblib/externals/loky/reusable_executor.py", line 177, in submit
    return super(_ReusablePoolExecutor, self).submit(
  File "/home/users/apopescu/anaconda3/envs/detectron2/lib/python3.8/site-packages/joblib/externals/loky/process_executor.py", line 1102, in submit
    raise self._flags.broken
joblib.externals.loky.process_executor.TerminatedWorkerError: A worker process managed by the executor was unexpectedly terminated. This could be caused by a segmentation fault while calling the function or by an excessive memory usage causing the Operating System to kill the worker.

The exit codes of the workers are {SIGBUS(-7)}
Traceback (most recent call last):
  File "ft_official.py", line 118, in <module>
    main()
  File "ft_official.py", line 100, in main
    model.train_vispel()
  File "/home/users/apopescu/van-khoa/Vis-Priva-Expos/privacy/vispel/vispel/vispel.py", line 54, in train_vispel
    trained_clusteror, trained_regressor, feature_selector = trainer(self.situation, self.X_train, self.X_community,\
  File "/home/users/apopescu/van-khoa/Vis-Priva-Expos/privacy/vispel/vispel/trainer.py", line 64, in trainer
    trained_regressor = train_regressor(regressor, X_train_rd, gt_train_expos, cfg)
  File "/home/users/apopescu/van-khoa/Vis-Priva-Expos/privacy/lib/regressor/regression.py", line 22, in train_regressor
    model.fit(x_train, y_train)
  File "/home/users/apopescu/anaconda3/envs/detectron2/lib/python3.8/site-packages/sklearn/utils/validation.py", line 73, in inner_f
    return f(**kwargs)
  File "/home/users/apopescu/anaconda3/envs/detectron2/lib/python3.8/site-packages/sklearn/model_selection/_search.py", line 736, in fit
    self._run_search(evaluate_candidates)
  File "/home/users/apopescu/anaconda3/envs/detectron2/lib/python3.8/site-packages/sklearn/model_selection/_search.py", line 1188, in _run_search
    evaluate_candidates(ParameterGrid(self.param_grid))
  File "/home/users/apopescu/anaconda3/envs/detectron2/lib/python3.8/site-packages/sklearn/model_selection/_search.py", line 708, in evaluate_candidates
    out = parallel(delayed(_fit_and_score)(clone(base_estimator),
  File "/home/users/apopescu/anaconda3/envs/detectron2/lib/python3.8/site-packages/joblib/parallel.py", line 1042, in __call__
    self.retrieve()
  File "/home/users/apopescu/anaconda3/envs/detectron2/lib/python3.8/site-packages/joblib/parallel.py", line 921, in retrieve
    self._output.extend(job.get(timeout=self.timeout))
  File "/home/users/apopescu/anaconda3/envs/detectron2/lib/python3.8/site-packages/joblib/_parallel_backends.py", line 542, in wrap_future_result
    return future.result(timeout=timeout)
  File "/home/users/apopescu/anaconda3/envs/detectron2/lib/python3.8/concurrent/futures/_base.py", line 439, in result
    return self.__get_result()
  File "/home/users/apopescu/anaconda3/envs/detectron2/lib/python3.8/concurrent/futures/_base.py", line 388, in __get_result
    raise self._exception
  File "/home/users/apopescu/anaconda3/envs/detectron2/lib/python3.8/site-packages/joblib/externals/loky/_base.py", line 625, in _invoke_callbacks
    callback(self)
  File "/home/users/apopescu/anaconda3/envs/detectron2/lib/python3.8/site-packages/joblib/parallel.py", line 347, in __call__
    self.parallel.dispatch_next()
  File "/home/users/apopescu/anaconda3/envs/detectron2/lib/python3.8/site-packages/joblib/parallel.py", line 780, in dispatch_next
    if not self.dispatch_one_batch(self._original_iterator):
  File "/home/users/apopescu/anaconda3/envs/detectron2/lib/python3.8/site-packages/joblib/parallel.py", line 847, in dispatch_one_batch
    self._dispatch(tasks)
  File "/home/users/apopescu/anaconda3/envs/detectron2/lib/python3.8/site-packages/joblib/parallel.py", line 765, in _dispatch
    job = self._backend.apply_async(batch, callback=cb)
  File "/home/users/apopescu/anaconda3/envs/detectron2/lib/python3.8/site-packages/joblib/_parallel_backends.py", line 531, in apply_async
    future = self._workers.submit(SafeFunction(func))
  File "/home/users/apopescu/anaconda3/envs/detectron2/lib/python3.8/site-packages/joblib/externals/loky/reusable_executor.py", line 177, in submit
    return super(_ReusablePoolExecutor, self).submit(
  File "/home/users/apopescu/anaconda3/envs/detectron2/lib/python3.8/site-packages/joblib/externals/loky/process_executor.py", line 1102, in submit
    raise self._flags.broken
joblib.externals.loky.process_executor.TerminatedWorkerError: A worker process managed by the executor was unexpectedly terminated. This could be caused by a segmentation fault while calling the function or by an excessive memory usage causing the Operating System to kill the worker.

The exit codes of the workers are {SIGBUS(-7)}
exception calling callback for <Future at 0x2b5ad7f50190 state=finished raised TerminatedWorkerError>
Traceback (most recent call last):
  File "/home/users/apopescu/anaconda3/envs/detectron2/lib/python3.8/site-packages/joblib/externals/loky/_base.py", line 625, in _invoke_callbacks
    callback(self)
  File "/home/users/apopescu/anaconda3/envs/detectron2/lib/python3.8/site-packages/joblib/parallel.py", line 347, in __call__
    self.parallel.dispatch_next()
  File "/home/users/apopescu/anaconda3/envs/detectron2/lib/python3.8/site-packages/joblib/parallel.py", line 780, in dispatch_next
    if not self.dispatch_one_batch(self._original_iterator):
  File "/home/users/apopescu/anaconda3/envs/detectron2/lib/python3.8/site-packages/joblib/parallel.py", line 847, in dispatch_one_batch
    self._dispatch(tasks)
  File "/home/users/apopescu/anaconda3/envs/detectron2/lib/python3.8/site-packages/joblib/parallel.py", line 765, in _dispatch
    job = self._backend.apply_async(batch, callback=cb)
  File "/home/users/apopescu/anaconda3/envs/detectron2/lib/python3.8/site-packages/joblib/_parallel_backends.py", line 531, in apply_async
    future = self._workers.submit(SafeFunction(func))
  File "/home/users/apopescu/anaconda3/envs/detectron2/lib/python3.8/site-packages/joblib/externals/loky/reusable_executor.py", line 177, in submit
    return super(_ReusablePoolExecutor, self).submit(
  File "/home/users/apopescu/anaconda3/envs/detectron2/lib/python3.8/site-packages/joblib/externals/loky/process_executor.py", line 1102, in submit
    raise self._flags.broken
joblib.externals.loky.process_executor.TerminatedWorkerError: A worker process managed by the executor was unexpectedly terminated. This could be caused by a segmentation fault while calling the function or by an excessive memory usage causing the Operating System to kill the worker.

The exit codes of the workers are {SIGBUS(-7)}
Traceback (most recent call last):
  File "ft_official.py", line 118, in <module>
    main()
  File "ft_official.py", line 100, in main
    model.train_vispel()
  File "/home/users/apopescu/van-khoa/Vis-Priva-Expos/privacy/vispel/vispel/vispel.py", line 54, in train_vispel
    trained_clusteror, trained_regressor, feature_selector = trainer(self.situation, self.X_train, self.X_community,\
  File "/home/users/apopescu/van-khoa/Vis-Priva-Expos/privacy/vispel/vispel/trainer.py", line 64, in trainer
    trained_regressor = train_regressor(regressor, X_train_rd, gt_train_expos, cfg)
  File "/home/users/apopescu/van-khoa/Vis-Priva-Expos/privacy/lib/regressor/regression.py", line 22, in train_regressor
    model.fit(x_train, y_train)
  File "/home/users/apopescu/anaconda3/envs/detectron2/lib/python3.8/site-packages/sklearn/utils/validation.py", line 73, in inner_f
    return f(**kwargs)
  File "/home/users/apopescu/anaconda3/envs/detectron2/lib/python3.8/site-packages/sklearn/model_selection/_search.py", line 736, in fit
    self._run_search(evaluate_candidates)
  File "/home/users/apopescu/anaconda3/envs/detectron2/lib/python3.8/site-packages/sklearn/model_selection/_search.py", line 1188, in _run_search
    evaluate_candidates(ParameterGrid(self.param_grid))
  File "/home/users/apopescu/anaconda3/envs/detectron2/lib/python3.8/site-packages/sklearn/model_selection/_search.py", line 708, in evaluate_candidates
    out = parallel(delayed(_fit_and_score)(clone(base_estimator),
  File "/home/users/apopescu/anaconda3/envs/detectron2/lib/python3.8/site-packages/joblib/parallel.py", line 1042, in __call__
    self.retrieve()
  File "/home/users/apopescu/anaconda3/envs/detectron2/lib/python3.8/site-packages/joblib/parallel.py", line 921, in retrieve
    self._output.extend(job.get(timeout=self.timeout))
  File "/home/users/apopescu/anaconda3/envs/detectron2/lib/python3.8/site-packages/joblib/_parallel_backends.py", line 542, in wrap_future_result
    return future.result(timeout=timeout)
  File "/home/users/apopescu/anaconda3/envs/detectron2/lib/python3.8/concurrent/futures/_base.py", line 439, in result
    return self.__get_result()
  File "/home/users/apopescu/anaconda3/envs/detectron2/lib/python3.8/concurrent/futures/_base.py", line 388, in __get_result
    raise self._exception
  File "/home/users/apopescu/anaconda3/envs/detectron2/lib/python3.8/site-packages/joblib/externals/loky/_base.py", line 625, in _invoke_callbacks
    callback(self)
  File "/home/users/apopescu/anaconda3/envs/detectron2/lib/python3.8/site-packages/joblib/parallel.py", line 347, in __call__
    self.parallel.dispatch_next()
  File "/home/users/apopescu/anaconda3/envs/detectron2/lib/python3.8/site-packages/joblib/parallel.py", line 780, in dispatch_next
    if not self.dispatch_one_batch(self._original_iterator):
  File "/home/users/apopescu/anaconda3/envs/detectron2/lib/python3.8/site-packages/joblib/parallel.py", line 847, in dispatch_one_batch
    self._dispatch(tasks)
  File "/home/users/apopescu/anaconda3/envs/detectron2/lib/python3.8/site-packages/joblib/parallel.py", line 765, in _dispatch
    job = self._backend.apply_async(batch, callback=cb)
  File "/home/users/apopescu/anaconda3/envs/detectron2/lib/python3.8/site-packages/joblib/_parallel_backends.py", line 531, in apply_async
    future = self._workers.submit(SafeFunction(func))
  File "/home/users/apopescu/anaconda3/envs/detectron2/lib/python3.8/site-packages/joblib/externals/loky/reusable_executor.py", line 177, in submit
    return super(_ReusablePoolExecutor, self).submit(
  File "/home/users/apopescu/anaconda3/envs/detectron2/lib/python3.8/site-packages/joblib/externals/loky/process_executor.py", line 1102, in submit
    raise self._flags.broken
  File "/home/users/apopescu/anaconda3/envs/detectron2/lib/python3.8/site-packages/joblib/externals/loky/_base.py", line 625, in _invoke_callbacks
    callback(self)
  File "/home/users/apopescu/anaconda3/envs/detectron2/lib/python3.8/site-packages/joblib/parallel.py", line 347, in __call__
    self.parallel.dispatch_next()
  File "/home/users/apopescu/anaconda3/envs/detectron2/lib/python3.8/site-packages/joblib/parallel.py", line 780, in dispatch_next
    if not self.dispatch_one_batch(self._original_iterator):
  File "/home/users/apopescu/anaconda3/envs/detectron2/lib/python3.8/site-packages/joblib/parallel.py", line 847, in dispatch_one_batch
    self._dispatch(tasks)
  File "/home/users/apopescu/anaconda3/envs/detectron2/lib/python3.8/site-packages/joblib/parallel.py", line 765, in _dispatch
    job = self._backend.apply_async(batch, callback=cb)
  File "/home/users/apopescu/anaconda3/envs/detectron2/lib/python3.8/site-packages/joblib/_parallel_backends.py", line 531, in apply_async
    future = self._workers.submit(SafeFunction(func))
  File "/home/users/apopescu/anaconda3/envs/detectron2/lib/python3.8/site-packages/joblib/externals/loky/reusable_executor.py", line 177, in submit
    return super(_ReusablePoolExecutor, self).submit(
  File "/home/users/apopescu/anaconda3/envs/detectron2/lib/python3.8/site-packages/joblib/externals/loky/process_executor.py", line 1102, in submit
    raise self._flags.broken
joblib.externals.loky.process_executor.TerminatedWorkerError: A worker process managed by the executor was unexpectedly terminated. This could be caused by a segmentation fault while calling the function or by an excessive memory usage causing the Operating System to kill the worker.

The exit codes of the workers are {SIGBUS(-7)}
Traceback (most recent call last):
  File "ft_official.py", line 118, in <module>
    main()
  File "ft_official.py", line 100, in main
    model.train_vispel()
  File "/home/users/apopescu/van-khoa/Vis-Priva-Expos/privacy/vispel/vispel/vispel.py", line 54, in train_vispel
    trained_clusteror, trained_regressor, feature_selector = trainer(self.situation, self.X_train, self.X_community,\
  File "/home/users/apopescu/van-khoa/Vis-Priva-Expos/privacy/vispel/vispel/trainer.py", line 64, in trainer
    trained_regressor = train_regressor(regressor, X_train_rd, gt_train_expos, cfg)
  File "/home/users/apopescu/van-khoa/Vis-Priva-Expos/privacy/lib/regressor/regression.py", line 22, in train_regressor
    model.fit(x_train, y_train)
  File "/home/users/apopescu/anaconda3/envs/detectron2/lib/python3.8/site-packages/sklearn/utils/validation.py", line 73, in inner_f
    return f(**kwargs)
  File "/home/users/apopescu/anaconda3/envs/detectron2/lib/python3.8/site-packages/sklearn/model_selection/_search.py", line 736, in fit
    self._run_search(evaluate_candidates)
  File "/home/users/apopescu/anaconda3/envs/detectron2/lib/python3.8/site-packages/sklearn/model_selection/_search.py", line 1188, in _run_search
    evaluate_candidates(ParameterGrid(self.param_grid))
  File "/home/users/apopescu/anaconda3/envs/detectron2/lib/python3.8/site-packages/sklearn/model_selection/_search.py", line 708, in evaluate_candidates
    out = parallel(delayed(_fit_and_score)(clone(base_estimator),
  File "/home/users/apopescu/anaconda3/envs/detectron2/lib/python3.8/site-packages/joblib/parallel.py", line 1042, in __call__
    self.retrieve()
  File "/home/users/apopescu/anaconda3/envs/detectron2/lib/python3.8/site-packages/joblib/parallel.py", line 921, in retrieve
    self._output.extend(job.get(timeout=self.timeout))
  File "/home/users/apopescu/anaconda3/envs/detectron2/lib/python3.8/site-packages/joblib/_parallel_backends.py", line 542, in wrap_future_result
    return future.result(timeout=timeout)
  File "/home/users/apopescu/anaconda3/envs/detectron2/lib/python3.8/concurrent/futures/_base.py", line 439, in result
    return self.__get_result()
  File "/home/users/apopescu/anaconda3/envs/detectron2/lib/python3.8/concurrent/futures/_base.py", line 388, in __get_result
    raise self._exception
  File "/home/users/apopescu/anaconda3/envs/detectron2/lib/python3.8/site-packages/joblib/externals/loky/_base.py", line 625, in _invoke_callbacks
    callback(self)
  File "/home/users/apopescu/anaconda3/envs/detectron2/lib/python3.8/site-packages/joblib/parallel.py", line 347, in __call__
    self.parallel.dispatch_next()
  File "/home/users/apopescu/anaconda3/envs/detectron2/lib/python3.8/site-packages/joblib/parallel.py", line 780, in dispatch_next
    if not self.dispatch_one_batch(self._original_iterator):
  File "/home/users/apopescu/anaconda3/envs/detectron2/lib/python3.8/site-packages/joblib/parallel.py", line 847, in dispatch_one_batch
    self._dispatch(tasks)
  File "/home/users/apopescu/anaconda3/envs/detectron2/lib/python3.8/site-packages/joblib/parallel.py", line 765, in _dispatch
    job = self._backend.apply_async(batch, callback=cb)
  File "/home/users/apopescu/anaconda3/envs/detectron2/lib/python3.8/site-packages/joblib/_parallel_backends.py", line 531, in apply_async
    future = self._workers.submit(SafeFunction(func))
  File "/home/users/apopescu/anaconda3/envs/detectron2/lib/python3.8/site-packages/joblib/externals/loky/reusable_executor.py", line 177, in submit
    return super(_ReusablePoolExecutor, self).submit(
  File "/home/users/apopescu/anaconda3/envs/detectron2/lib/python3.8/site-packages/joblib/externals/loky/process_executor.py", line 1102, in submit
    raise self._flags.broken
  File "/home/users/apopescu/anaconda3/envs/detectron2/lib/python3.8/site-packages/joblib/externals/loky/_base.py", line 625, in _invoke_callbacks
    callback(self)
  File "/home/users/apopescu/anaconda3/envs/detectron2/lib/python3.8/site-packages/joblib/parallel.py", line 347, in __call__
    self.parallel.dispatch_next()
  File "/home/users/apopescu/anaconda3/envs/detectron2/lib/python3.8/site-packages/joblib/parallel.py", line 780, in dispatch_next
    if not self.dispatch_one_batch(self._original_iterator):
  File "/home/users/apopescu/anaconda3/envs/detectron2/lib/python3.8/site-packages/joblib/parallel.py", line 847, in dispatch_one_batch
    self._dispatch(tasks)
  File "/home/users/apopescu/anaconda3/envs/detectron2/lib/python3.8/site-packages/joblib/parallel.py", line 765, in _dispatch
    job = self._backend.apply_async(batch, callback=cb)
  File "/home/users/apopescu/anaconda3/envs/detectron2/lib/python3.8/site-packages/joblib/_parallel_backends.py", line 531, in apply_async
    future = self._workers.submit(SafeFunction(func))
  File "/home/users/apopescu/anaconda3/envs/detectron2/lib/python3.8/site-packages/joblib/externals/loky/reusable_executor.py", line 177, in submit
    return super(_ReusablePoolExecutor, self).submit(
  File "/home/users/apopescu/anaconda3/envs/detectron2/lib/python3.8/site-packages/joblib/externals/loky/process_executor.py", line 1102, in submit
    raise self._flags.broken
  File "/home/users/apopescu/anaconda3/envs/detectron2/lib/python3.8/site-packages/joblib/externals/loky/_base.py", line 625, in _invoke_callbacks
    callback(self)
  File "/home/users/apopescu/anaconda3/envs/detectron2/lib/python3.8/site-packages/joblib/parallel.py", line 347, in __call__
    self.parallel.dispatch_next()
  File "/home/users/apopescu/anaconda3/envs/detectron2/lib/python3.8/site-packages/joblib/parallel.py", line 780, in dispatch_next
    if not self.dispatch_one_batch(self._original_iterator):
  File "/home/users/apopescu/anaconda3/envs/detectron2/lib/python3.8/site-packages/joblib/parallel.py", line 847, in dispatch_one_batch
    self._dispatch(tasks)
  File "/home/users/apopescu/anaconda3/envs/detectron2/lib/python3.8/site-packages/joblib/parallel.py", line 765, in _dispatch
    job = self._backend.apply_async(batch, callback=cb)
  File "/home/users/apopescu/anaconda3/envs/detectron2/lib/python3.8/site-packages/joblib/_parallel_backends.py", line 531, in apply_async
    future = self._workers.submit(SafeFunction(func))
  File "/home/users/apopescu/anaconda3/envs/detectron2/lib/python3.8/site-packages/joblib/externals/loky/reusable_executor.py", line 177, in submit
    return super(_ReusablePoolExecutor, self).submit(
  File "/home/users/apopescu/anaconda3/envs/detectron2/lib/python3.8/site-packages/joblib/externals/loky/process_executor.py", line 1102, in submit
    raise self._flags.broken
joblib.externals.loky.process_executor.TerminatedWorkerError: A worker process managed by the executor was unexpectedly terminated. This could be caused by a segmentation fault while calling the function or by an excessive memory usage causing the Operating System to kill the worker.

The exit codes of the workers are {SIGBUS(-7)}
Traceback (most recent call last):
  File "ft_official.py", line 118, in <module>
    main()
  File "ft_official.py", line 100, in main
    model.train_vispel()
  File "/home/users/apopescu/van-khoa/Vis-Priva-Expos/privacy/vispel/vispel/vispel.py", line 54, in train_vispel
    trained_clusteror, trained_regressor, feature_selector = trainer(self.situation, self.X_train, self.X_community,\
  File "/home/users/apopescu/van-khoa/Vis-Priva-Expos/privacy/vispel/vispel/trainer.py", line 64, in trainer
    trained_regressor = train_regressor(regressor, X_train_rd, gt_train_expos, cfg)
  File "/home/users/apopescu/van-khoa/Vis-Priva-Expos/privacy/lib/regressor/regression.py", line 22, in train_regressor
    model.fit(x_train, y_train)
  File "/home/users/apopescu/anaconda3/envs/detectron2/lib/python3.8/site-packages/sklearn/utils/validation.py", line 73, in inner_f
    return f(**kwargs)
  File "/home/users/apopescu/anaconda3/envs/detectron2/lib/python3.8/site-packages/sklearn/model_selection/_search.py", line 736, in fit
    self._run_search(evaluate_candidates)
  File "/home/users/apopescu/anaconda3/envs/detectron2/lib/python3.8/site-packages/sklearn/model_selection/_search.py", line 1188, in _run_search
    evaluate_candidates(ParameterGrid(self.param_grid))
  File "/home/users/apopescu/anaconda3/envs/detectron2/lib/python3.8/site-packages/sklearn/model_selection/_search.py", line 708, in evaluate_candidates
    out = parallel(delayed(_fit_and_score)(clone(base_estimator),
  File "/home/users/apopescu/anaconda3/envs/detectron2/lib/python3.8/site-packages/joblib/parallel.py", line 1042, in __call__
    self.retrieve()
  File "/home/users/apopescu/anaconda3/envs/detectron2/lib/python3.8/site-packages/joblib/parallel.py", line 921, in retrieve
    self._output.extend(job.get(timeout=self.timeout))
  File "/home/users/apopescu/anaconda3/envs/detectron2/lib/python3.8/site-packages/joblib/_parallel_backends.py", line 542, in wrap_future_result
    return future.result(timeout=timeout)
  File "/home/users/apopescu/anaconda3/envs/detectron2/lib/python3.8/concurrent/futures/_base.py", line 439, in result
    return self.__get_result()
  File "/home/users/apopescu/anaconda3/envs/detectron2/lib/python3.8/concurrent/futures/_base.py", line 388, in __get_result
    raise self._exception
  File "/home/users/apopescu/anaconda3/envs/detectron2/lib/python3.8/site-packages/joblib/externals/loky/_base.py", line 625, in _invoke_callbacks
    callback(self)
  File "/home/users/apopescu/anaconda3/envs/detectron2/lib/python3.8/site-packages/joblib/parallel.py", line 347, in __call__
    self.parallel.dispatch_next()
  File "/home/users/apopescu/anaconda3/envs/detectron2/lib/python3.8/site-packages/joblib/parallel.py", line 780, in dispatch_next
    if not self.dispatch_one_batch(self._original_iterator):
  File "/home/users/apopescu/anaconda3/envs/detectron2/lib/python3.8/site-packages/joblib/parallel.py", line 847, in dispatch_one_batch
    self._dispatch(tasks)
  File "/home/users/apopescu/anaconda3/envs/detectron2/lib/python3.8/site-packages/joblib/parallel.py", line 765, in _dispatch
    job = self._backend.apply_async(batch, callback=cb)
  File "/home/users/apopescu/anaconda3/envs/detectron2/lib/python3.8/site-packages/joblib/_parallel_backends.py", line 531, in apply_async
    future = self._workers.submit(SafeFunction(func))
  File "/home/users/apopescu/anaconda3/envs/detectron2/lib/python3.8/site-packages/joblib/externals/loky/reusable_executor.py", line 177, in submit
    return super(_ReusablePoolExecutor, self).submit(
  File "/home/users/apopescu/anaconda3/envs/detectron2/lib/python3.8/site-packages/joblib/externals/loky/process_executor.py", line 1102, in submit
    raise self._flags.broken
  File "/home/users/apopescu/anaconda3/envs/detectron2/lib/python3.8/site-packages/joblib/externals/loky/_base.py", line 625, in _invoke_callbacks
    callback(self)
  File "/home/users/apopescu/anaconda3/envs/detectron2/lib/python3.8/site-packages/joblib/parallel.py", line 347, in __call__
    self.parallel.dispatch_next()
  File "/home/users/apopescu/anaconda3/envs/detectron2/lib/python3.8/site-packages/joblib/parallel.py", line 780, in dispatch_next
    if not self.dispatch_one_batch(self._original_iterator):
  File "/home/users/apopescu/anaconda3/envs/detectron2/lib/python3.8/site-packages/joblib/parallel.py", line 847, in dispatch_one_batch
    self._dispatch(tasks)
  File "/home/users/apopescu/anaconda3/envs/detectron2/lib/python3.8/site-packages/joblib/parallel.py", line 765, in _dispatch
    job = self._backend.apply_async(batch, callback=cb)
  File "/home/users/apopescu/anaconda3/envs/detectron2/lib/python3.8/site-packages/joblib/_parallel_backends.py", line 531, in apply_async
    future = self._workers.submit(SafeFunction(func))
  File "/home/users/apopescu/anaconda3/envs/detectron2/lib/python3.8/site-packages/joblib/externals/loky/reusable_executor.py", line 177, in submit
    return super(_ReusablePoolExecutor, self).submit(
  File "/home/users/apopescu/anaconda3/envs/detectron2/lib/python3.8/site-packages/joblib/externals/loky/process_executor.py", line 1102, in submit
    raise self._flags.broken
  File "/home/users/apopescu/anaconda3/envs/detectron2/lib/python3.8/site-packages/joblib/externals/loky/_base.py", line 625, in _invoke_callbacks
    callback(self)
  File "/home/users/apopescu/anaconda3/envs/detectron2/lib/python3.8/site-packages/joblib/parallel.py", line 347, in __call__
    self.parallel.dispatch_next()
  File "/home/users/apopescu/anaconda3/envs/detectron2/lib/python3.8/site-packages/joblib/parallel.py", line 780, in dispatch_next
    if not self.dispatch_one_batch(self._original_iterator):
  File "/home/users/apopescu/anaconda3/envs/detectron2/lib/python3.8/site-packages/joblib/parallel.py", line 847, in dispatch_one_batch
    self._dispatch(tasks)
  File "/home/users/apopescu/anaconda3/envs/detectron2/lib/python3.8/site-packages/joblib/parallel.py", line 765, in _dispatch
    job = self._backend.apply_async(batch, callback=cb)
  File "/home/users/apopescu/anaconda3/envs/detectron2/lib/python3.8/site-packages/joblib/_parallel_backends.py", line 531, in apply_async
    future = self._workers.submit(SafeFunction(func))
  File "/home/users/apopescu/anaconda3/envs/detectron2/lib/python3.8/site-packages/joblib/externals/loky/reusable_executor.py", line 177, in submit
    return super(_ReusablePoolExecutor, self).submit(
  File "/home/users/apopescu/anaconda3/envs/detectron2/lib/python3.8/site-packages/joblib/externals/loky/process_executor.py", line 1102, in submit
    raise self._flags.broken
joblib.externals.loky.process_executor.TerminatedWorkerError: A worker process managed by the executor was unexpectedly terminated. This could be caused by a segmentation fault while calling the function or by an excessive memory usage causing the Operating System to kill the worker.

The exit codes of the workers are {SIGBUS(-7)}
exception calling callback for <Future at 0x2abba9042190 state=finished raised TerminatedWorkerError>
Traceback (most recent call last):
  File "/home/users/apopescu/anaconda3/envs/detectron2/lib/python3.8/site-packages/joblib/externals/loky/_base.py", line 625, in _invoke_callbacks
    callback(self)
  File "/home/users/apopescu/anaconda3/envs/detectron2/lib/python3.8/site-packages/joblib/parallel.py", line 347, in __call__
    self.parallel.dispatch_next()
  File "/home/users/apopescu/anaconda3/envs/detectron2/lib/python3.8/site-packages/joblib/parallel.py", line 780, in dispatch_next
    if not self.dispatch_one_batch(self._original_iterator):
  File "/home/users/apopescu/anaconda3/envs/detectron2/lib/python3.8/site-packages/joblib/parallel.py", line 847, in dispatch_one_batch
    self._dispatch(tasks)
  File "/home/users/apopescu/anaconda3/envs/detectron2/lib/python3.8/site-packages/joblib/parallel.py", line 765, in _dispatch
    job = self._backend.apply_async(batch, callback=cb)
  File "/home/users/apopescu/anaconda3/envs/detectron2/lib/python3.8/site-packages/joblib/_parallel_backends.py", line 531, in apply_async
    future = self._workers.submit(SafeFunction(func))
  File "/home/users/apopescu/anaconda3/envs/detectron2/lib/python3.8/site-packages/joblib/externals/loky/reusable_executor.py", line 177, in submit
    return super(_ReusablePoolExecutor, self).submit(
  File "/home/users/apopescu/anaconda3/envs/detectron2/lib/python3.8/site-packages/joblib/externals/loky/process_executor.py", line 1102, in submit
    raise self._flags.broken
joblib.externals.loky.process_executor.TerminatedWorkerError: A worker process managed by the executor was unexpectedly terminated. This could be caused by a segmentation fault while calling the function or by an excessive memory usage causing the Operating System to kill the worker.

The exit codes of the workers are {SIGBUS(-7)}
exception calling callback for <Future at 0x2abba902f910 state=finished raised TerminatedWorkerError>
Traceback (most recent call last):
  File "/home/users/apopescu/anaconda3/envs/detectron2/lib/python3.8/site-packages/joblib/externals/loky/_base.py", line 625, in _invoke_callbacks
    callback(self)
  File "/home/users/apopescu/anaconda3/envs/detectron2/lib/python3.8/site-packages/joblib/parallel.py", line 347, in __call__
    self.parallel.dispatch_next()
  File "/home/users/apopescu/anaconda3/envs/detectron2/lib/python3.8/site-packages/joblib/parallel.py", line 780, in dispatch_next
    if not self.dispatch_one_batch(self._original_iterator):
  File "/home/users/apopescu/anaconda3/envs/detectron2/lib/python3.8/site-packages/joblib/parallel.py", line 847, in dispatch_one_batch
    self._dispatch(tasks)
  File "/home/users/apopescu/anaconda3/envs/detectron2/lib/python3.8/site-packages/joblib/parallel.py", line 765, in _dispatch
    job = self._backend.apply_async(batch, callback=cb)
  File "/home/users/apopescu/anaconda3/envs/detectron2/lib/python3.8/site-packages/joblib/_parallel_backends.py", line 531, in apply_async
    future = self._workers.submit(SafeFunction(func))
  File "/home/users/apopescu/anaconda3/envs/detectron2/lib/python3.8/site-packages/joblib/externals/loky/reusable_executor.py", line 177, in submit
    return super(_ReusablePoolExecutor, self).submit(
  File "/home/users/apopescu/anaconda3/envs/detectron2/lib/python3.8/site-packages/joblib/externals/loky/process_executor.py", line 1102, in submit
    raise self._flags.broken
  File "/home/users/apopescu/anaconda3/envs/detectron2/lib/python3.8/site-packages/joblib/externals/loky/_base.py", line 625, in _invoke_callbacks
    callback(self)
  File "/home/users/apopescu/anaconda3/envs/detectron2/lib/python3.8/site-packages/joblib/parallel.py", line 347, in __call__
    self.parallel.dispatch_next()
  File "/home/users/apopescu/anaconda3/envs/detectron2/lib/python3.8/site-packages/joblib/parallel.py", line 780, in dispatch_next
    if not self.dispatch_one_batch(self._original_iterator):
  File "/home/users/apopescu/anaconda3/envs/detectron2/lib/python3.8/site-packages/joblib/parallel.py", line 847, in dispatch_one_batch
    self._dispatch(tasks)
  File "/home/users/apopescu/anaconda3/envs/detectron2/lib/python3.8/site-packages/joblib/parallel.py", line 765, in _dispatch
    job = self._backend.apply_async(batch, callback=cb)
  File "/home/users/apopescu/anaconda3/envs/detectron2/lib/python3.8/site-packages/joblib/_parallel_backends.py", line 531, in apply_async
    future = self._workers.submit(SafeFunction(func))
  File "/home/users/apopescu/anaconda3/envs/detectron2/lib/python3.8/site-packages/joblib/externals/loky/reusable_executor.py", line 177, in submit
    return super(_ReusablePoolExecutor, self).submit(
  File "/home/users/apopescu/anaconda3/envs/detectron2/lib/python3.8/site-packages/joblib/externals/loky/process_executor.py", line 1102, in submit
    raise self._flags.broken
joblib.externals.loky.process_executor.TerminatedWorkerError: A worker process managed by the executor was unexpectedly terminated. This could be caused by a segmentation fault while calling the function or by an excessive memory usage causing the Operating System to kill the worker.

The exit codes of the workers are {SIGBUS(-7)}
  0%|          | 0/5 [01:20<?, ?it/s]
Traceback (most recent call last):
  File "ft_official.py", line 118, in <module>
    main()
  File "ft_official.py", line 100, in main
    model.train_vispel()
  File "/home/users/apopescu/van-khoa/Vis-Priva-Expos/privacy/vispel/vispel/vispel.py", line 54, in train_vispel
    trained_clusteror, trained_regressor, feature_selector = trainer(self.situation, self.X_train, self.X_community,\
  File "/home/users/apopescu/van-khoa/Vis-Priva-Expos/privacy/vispel/vispel/trainer.py", line 64, in trainer
    trained_regressor = train_regressor(regressor, X_train_rd, gt_train_expos, cfg)
  File "/home/users/apopescu/van-khoa/Vis-Priva-Expos/privacy/lib/regressor/regression.py", line 22, in train_regressor
    model.fit(x_train, y_train)
  File "/home/users/apopescu/anaconda3/envs/detectron2/lib/python3.8/site-packages/sklearn/utils/validation.py", line 73, in inner_f
    return f(**kwargs)
  File "/home/users/apopescu/anaconda3/envs/detectron2/lib/python3.8/site-packages/sklearn/model_selection/_search.py", line 736, in fit
    self._run_search(evaluate_candidates)
  File "/home/users/apopescu/anaconda3/envs/detectron2/lib/python3.8/site-packages/sklearn/model_selection/_search.py", line 1188, in _run_search
    evaluate_candidates(ParameterGrid(self.param_grid))
  File "/home/users/apopescu/anaconda3/envs/detectron2/lib/python3.8/site-packages/sklearn/model_selection/_search.py", line 708, in evaluate_candidates
    out = parallel(delayed(_fit_and_score)(clone(base_estimator),
  File "/home/users/apopescu/anaconda3/envs/detectron2/lib/python3.8/site-packages/joblib/parallel.py", line 1042, in __call__
    self.retrieve()
  File "/home/users/apopescu/anaconda3/envs/detectron2/lib/python3.8/site-packages/joblib/parallel.py", line 921, in retrieve
    self._output.extend(job.get(timeout=self.timeout))
  File "/home/users/apopescu/anaconda3/envs/detectron2/lib/python3.8/site-packages/joblib/_parallel_backends.py", line 542, in wrap_future_result
    return future.result(timeout=timeout)
  File "/home/users/apopescu/anaconda3/envs/detectron2/lib/python3.8/concurrent/futures/_base.py", line 439, in result
    return self.__get_result()
  File "/home/users/apopescu/anaconda3/envs/detectron2/lib/python3.8/concurrent/futures/_base.py", line 388, in __get_result
    raise self._exception
  File "/home/users/apopescu/anaconda3/envs/detectron2/lib/python3.8/site-packages/joblib/externals/loky/_base.py", line 625, in _invoke_callbacks
    callback(self)
  File "/home/users/apopescu/anaconda3/envs/detectron2/lib/python3.8/site-packages/joblib/parallel.py", line 347, in __call__
    self.parallel.dispatch_next()
  File "/home/users/apopescu/anaconda3/envs/detectron2/lib/python3.8/site-packages/joblib/parallel.py", line 780, in dispatch_next
    if not self.dispatch_one_batch(self._original_iterator):
  File "/home/users/apopescu/anaconda3/envs/detectron2/lib/python3.8/site-packages/joblib/parallel.py", line 847, in dispatch_one_batch
    self._dispatch(tasks)
  File "/home/users/apopescu/anaconda3/envs/detectron2/lib/python3.8/site-packages/joblib/parallel.py", line 765, in _dispatch
    job = self._backend.apply_async(batch, callback=cb)
  File "/home/users/apopescu/anaconda3/envs/detectron2/lib/python3.8/site-packages/joblib/_parallel_backends.py", line 531, in apply_async
    future = self._workers.submit(SafeFunction(func))
  File "/home/users/apopescu/anaconda3/envs/detectron2/lib/python3.8/site-packages/joblib/externals/loky/reusable_executor.py", line 177, in submit
    return super(_ReusablePoolExecutor, self).submit(
  File "/home/users/apopescu/anaconda3/envs/detectron2/lib/python3.8/site-packages/joblib/externals/loky/process_executor.py", line 1102, in submit
    raise self._flags.broken
joblib.externals.loky.process_executor.TerminatedWorkerError: A worker process managed by the executor was unexpectedly terminated. This could be caused by a segmentation fault while calling the function or by an excessive memory usage causing the Operating System to kill the worker.

The exit codes of the workers are {SIGBUS(-7)}
/home/users/apopescu/anaconda3/envs/detectron2/lib/python3.8/site-packages/joblib/externals/loky/backend/resource_tracker.py:120: UserWarning: resource_tracker: process died unexpectedly, relaunching.  Some folders/sempahores might leak.
  warnings.warn('resource_tracker: process died unexpectedly, '
  0%|          | 0/5 [01:19<?, ?it/s]
Traceback (most recent call last):
  File "ft_official.py", line 118, in <module>
    main()
  File "ft_official.py", line 100, in main
    model.train_vispel()
  File "/home/users/apopescu/van-khoa/Vis-Priva-Expos/privacy/vispel/vispel/vispel.py", line 54, in train_vispel
    trained_clusteror, trained_regressor, feature_selector = trainer(self.situation, self.X_train, self.X_community,\
  File "/home/users/apopescu/van-khoa/Vis-Priva-Expos/privacy/vispel/vispel/trainer.py", line 64, in trainer
    trained_regressor = train_regressor(regressor, X_train_rd, gt_train_expos, cfg)
  File "/home/users/apopescu/van-khoa/Vis-Priva-Expos/privacy/lib/regressor/regression.py", line 22, in train_regressor
    model.fit(x_train, y_train)
  File "/home/users/apopescu/anaconda3/envs/detectron2/lib/python3.8/site-packages/sklearn/utils/validation.py", line 73, in inner_f
    return f(**kwargs)
  File "/home/users/apopescu/anaconda3/envs/detectron2/lib/python3.8/site-packages/sklearn/model_selection/_search.py", line 736, in fit
    self._run_search(evaluate_candidates)
  File "/home/users/apopescu/anaconda3/envs/detectron2/lib/python3.8/site-packages/sklearn/model_selection/_search.py", line 1188, in _run_search
    evaluate_candidates(ParameterGrid(self.param_grid))
  File "/home/users/apopescu/anaconda3/envs/detectron2/lib/python3.8/site-packages/sklearn/model_selection/_search.py", line 708, in evaluate_candidates
    out = parallel(delayed(_fit_and_score)(clone(base_estimator),
  File "/home/users/apopescu/anaconda3/envs/detectron2/lib/python3.8/site-packages/joblib/parallel.py", line 1042, in __call__
    self.retrieve()
  File "/home/users/apopescu/anaconda3/envs/detectron2/lib/python3.8/site-packages/joblib/parallel.py", line 921, in retrieve
    self._output.extend(job.get(timeout=self.timeout))
  File "/home/users/apopescu/anaconda3/envs/detectron2/lib/python3.8/site-packages/joblib/_parallel_backends.py", line 542, in wrap_future_result
    return future.result(timeout=timeout)
  File "/home/users/apopescu/anaconda3/envs/detectron2/lib/python3.8/concurrent/futures/_base.py", line 439, in result
    return self.__get_result()
  File "/home/users/apopescu/anaconda3/envs/detectron2/lib/python3.8/concurrent/futures/_base.py", line 388, in __get_result
    raise self._exception
  File "/home/users/apopescu/anaconda3/envs/detectron2/lib/python3.8/site-packages/joblib/externals/loky/_base.py", line 625, in _invoke_callbacks
    callback(self)
  File "/home/users/apopescu/anaconda3/envs/detectron2/lib/python3.8/site-packages/joblib/parallel.py", line 347, in __call__
    self.parallel.dispatch_next()
  File "/home/users/apopescu/anaconda3/envs/detectron2/lib/python3.8/site-packages/joblib/parallel.py", line 780, in dispatch_next
    if not self.dispatch_one_batch(self._original_iterator):
  File "/home/users/apopescu/anaconda3/envs/detectron2/lib/python3.8/site-packages/joblib/parallel.py", line 847, in dispatch_one_batch
    self._dispatch(tasks)
  File "/home/users/apopescu/anaconda3/envs/detectron2/lib/python3.8/site-packages/joblib/parallel.py", line 765, in _dispatch
    job = self._backend.apply_async(batch, callback=cb)
  File "/home/users/apopescu/anaconda3/envs/detectron2/lib/python3.8/site-packages/joblib/_parallel_backends.py", line 531, in apply_async
    future = self._workers.submit(SafeFunction(func))
  File "/home/users/apopescu/anaconda3/envs/detectron2/lib/python3.8/site-packages/joblib/externals/loky/reusable_executor.py", line 177, in submit
    return super(_ReusablePoolExecutor, self).submit(
  File "/home/users/apopescu/anaconda3/envs/detectron2/lib/python3.8/site-packages/joblib/externals/loky/process_executor.py", line 1102, in submit
    raise self._flags.broken
joblib.externals.loky.process_executor.TerminatedWorkerError: A worker process managed by the executor was unexpectedly terminated. This could be caused by a segmentation fault while calling the function or by an excessive memory usage causing the Operating System to kill the worker.

The exit codes of the workers are {SIGKILL(-9)}
/var/spool/slurm//job66118/slurm_script: line 50: 173216 Killed                  python3 ft_official.py --config_file ../configs/rf_kmeans_ft_mobi_cv8.yaml --model_name it_mobi_20.pkl --situation IT --opts USER_SELECTOR.EPS 0.15 USER_SELECTOR.KEEP 0.8 SOLVER.FEATURE_TYPE VOTE OUTPUT.DIR /home/users/apopescu/van-khoa/saved_models/it_mobi
/var/spool/slurm//job66118/slurm_script: line 50: 173229 Bus error               python3 ft_official.py --config_file ../configs/rf_kmeans_ft_mobi_cv8.yaml --model_name it_mobi_33.pkl --situation IT --opts USER_SELECTOR.EPS 0.2 USER_SELECTOR.KEEP 0.85 SOLVER.FEATURE_TYPE ORG OUTPUT.DIR /home/users/apopescu/van-khoa/saved_models/it_mobi
  0%|          | 0/5 [01:22<?, ?it/s]
Traceback (most recent call last):
  File "ft_official.py", line 118, in <module>
    main()
  File "ft_official.py", line 100, in main
    model.train_vispel()
  File "/home/users/apopescu/van-khoa/Vis-Priva-Expos/privacy/vispel/vispel/vispel.py", line 54, in train_vispel
    trained_clusteror, trained_regressor, feature_selector = trainer(self.situation, self.X_train, self.X_community,\
  File "/home/users/apopescu/van-khoa/Vis-Priva-Expos/privacy/vispel/vispel/trainer.py", line 64, in trainer
    trained_regressor = train_regressor(regressor, X_train_rd, gt_train_expos, cfg)
  File "/home/users/apopescu/van-khoa/Vis-Priva-Expos/privacy/lib/regressor/regression.py", line 22, in train_regressor
    model.fit(x_train, y_train)
  File "/home/users/apopescu/anaconda3/envs/detectron2/lib/python3.8/site-packages/sklearn/utils/validation.py", line 73, in inner_f
    return f(**kwargs)
  File "/home/users/apopescu/anaconda3/envs/detectron2/lib/python3.8/site-packages/sklearn/model_selection/_search.py", line 736, in fit
    self._run_search(evaluate_candidates)
  File "/home/users/apopescu/anaconda3/envs/detectron2/lib/python3.8/site-packages/sklearn/model_selection/_search.py", line 1188, in _run_search
    evaluate_candidates(ParameterGrid(self.param_grid))
  File "/home/users/apopescu/anaconda3/envs/detectron2/lib/python3.8/site-packages/sklearn/model_selection/_search.py", line 708, in evaluate_candidates
    out = parallel(delayed(_fit_and_score)(clone(base_estimator),
  File "/home/users/apopescu/anaconda3/envs/detectron2/lib/python3.8/site-packages/joblib/parallel.py", line 1042, in __call__
    self.retrieve()
  File "/home/users/apopescu/anaconda3/envs/detectron2/lib/python3.8/site-packages/joblib/parallel.py", line 921, in retrieve
    self._output.extend(job.get(timeout=self.timeout))
  File "/home/users/apopescu/anaconda3/envs/detectron2/lib/python3.8/site-packages/joblib/_parallel_backends.py", line 542, in wrap_future_result
    return future.result(timeout=timeout)
  File "/home/users/apopescu/anaconda3/envs/detectron2/lib/python3.8/concurrent/futures/_base.py", line 439, in result
    return self.__get_result()
  File "/home/users/apopescu/anaconda3/envs/detectron2/lib/python3.8/concurrent/futures/_base.py", line 388, in __get_result
    raise self._exception
joblib.externals.loky.process_executor.TerminatedWorkerError: A worker process managed by the executor was unexpectedly terminated. This could be caused by a segmentation fault while calling the function or by an excessive memory usage causing the Operating System to kill the worker.

The exit codes of the workers are {SIGBUS(-7)}
  0%|          | 0/5 [01:22<?, ?it/s]
Traceback (most recent call last):
  File "ft_official.py", line 118, in <module>
    main()
  File "ft_official.py", line 100, in main
    model.train_vispel()
  File "/home/users/apopescu/van-khoa/Vis-Priva-Expos/privacy/vispel/vispel/vispel.py", line 54, in train_vispel
    trained_clusteror, trained_regressor, feature_selector = trainer(self.situation, self.X_train, self.X_community,\
  File "/home/users/apopescu/van-khoa/Vis-Priva-Expos/privacy/vispel/vispel/trainer.py", line 64, in trainer
    trained_regressor = train_regressor(regressor, X_train_rd, gt_train_expos, cfg)
  File "/home/users/apopescu/van-khoa/Vis-Priva-Expos/privacy/lib/regressor/regression.py", line 22, in train_regressor
    model.fit(x_train, y_train)
  File "/home/users/apopescu/anaconda3/envs/detectron2/lib/python3.8/site-packages/sklearn/utils/validation.py", line 73, in inner_f
    return f(**kwargs)
  File "/home/users/apopescu/anaconda3/envs/detectron2/lib/python3.8/site-packages/sklearn/model_selection/_search.py", line 736, in fit
    self._run_search(evaluate_candidates)
  File "/home/users/apopescu/anaconda3/envs/detectron2/lib/python3.8/site-packages/sklearn/model_selection/_search.py", line 1188, in _run_search
    evaluate_candidates(ParameterGrid(self.param_grid))
  File "/home/users/apopescu/anaconda3/envs/detectron2/lib/python3.8/site-packages/sklearn/model_selection/_search.py", line 708, in evaluate_candidates
    out = parallel(delayed(_fit_and_score)(clone(base_estimator),
  File "/home/users/apopescu/anaconda3/envs/detectron2/lib/python3.8/site-packages/joblib/parallel.py", line 1042, in __call__
    self.retrieve()
  File "/home/users/apopescu/anaconda3/envs/detectron2/lib/python3.8/site-packages/joblib/parallel.py", line 921, in retrieve
    self._output.extend(job.get(timeout=self.timeout))
  File "/home/users/apopescu/anaconda3/envs/detectron2/lib/python3.8/site-packages/joblib/_parallel_backends.py", line 542, in wrap_future_result
    return future.result(timeout=timeout)
  File "/home/users/apopescu/anaconda3/envs/detectron2/lib/python3.8/concurrent/futures/_base.py", line 439, in result
    return self.__get_result()
  File "/home/users/apopescu/anaconda3/envs/detectron2/lib/python3.8/concurrent/futures/_base.py", line 388, in __get_result
    raise self._exception
  File "/home/users/apopescu/anaconda3/envs/detectron2/lib/python3.8/site-packages/joblib/externals/loky/_base.py", line 625, in _invoke_callbacks
    callback(self)
  File "/home/users/apopescu/anaconda3/envs/detectron2/lib/python3.8/site-packages/joblib/parallel.py", line 347, in __call__
    self.parallel.dispatch_next()
  File "/home/users/apopescu/anaconda3/envs/detectron2/lib/python3.8/site-packages/joblib/parallel.py", line 780, in dispatch_next
    if not self.dispatch_one_batch(self._original_iterator):
  File "/home/users/apopescu/anaconda3/envs/detectron2/lib/python3.8/site-packages/joblib/parallel.py", line 847, in dispatch_one_batch
    self._dispatch(tasks)
  File "/home/users/apopescu/anaconda3/envs/detectron2/lib/python3.8/site-packages/joblib/parallel.py", line 765, in _dispatch
    job = self._backend.apply_async(batch, callback=cb)
  File "/home/users/apopescu/anaconda3/envs/detectron2/lib/python3.8/site-packages/joblib/_parallel_backends.py", line 531, in apply_async
    future = self._workers.submit(SafeFunction(func))
  File "/home/users/apopescu/anaconda3/envs/detectron2/lib/python3.8/site-packages/joblib/externals/loky/reusable_executor.py", line 177, in submit
    return super(_ReusablePoolExecutor, self).submit(
  File "/home/users/apopescu/anaconda3/envs/detectron2/lib/python3.8/site-packages/joblib/externals/loky/process_executor.py", line 1102, in submit
    raise self._flags.broken
  File "/home/users/apopescu/anaconda3/envs/detectron2/lib/python3.8/site-packages/joblib/externals/loky/_base.py", line 625, in _invoke_callbacks
    callback(self)
  File "/home/users/apopescu/anaconda3/envs/detectron2/lib/python3.8/site-packages/joblib/parallel.py", line 347, in __call__
    self.parallel.dispatch_next()
  File "/home/users/apopescu/anaconda3/envs/detectron2/lib/python3.8/site-packages/joblib/parallel.py", line 780, in dispatch_next
    if not self.dispatch_one_batch(self._original_iterator):
  File "/home/users/apopescu/anaconda3/envs/detectron2/lib/python3.8/site-packages/joblib/parallel.py", line 847, in dispatch_one_batch
    self._dispatch(tasks)
  File "/home/users/apopescu/anaconda3/envs/detectron2/lib/python3.8/site-packages/joblib/parallel.py", line 765, in _dispatch
    job = self._backend.apply_async(batch, callback=cb)
  File "/home/users/apopescu/anaconda3/envs/detectron2/lib/python3.8/site-packages/joblib/_parallel_backends.py", line 531, in apply_async
    future = self._workers.submit(SafeFunction(func))
  File "/home/users/apopescu/anaconda3/envs/detectron2/lib/python3.8/site-packages/joblib/externals/loky/reusable_executor.py", line 177, in submit
    return super(_ReusablePoolExecutor, self).submit(
  File "/home/users/apopescu/anaconda3/envs/detectron2/lib/python3.8/site-packages/joblib/externals/loky/process_executor.py", line 1102, in submit
    raise self._flags.broken
joblib.externals.loky.process_executor.TerminatedWorkerError: A worker process managed by the executor was unexpectedly terminated. This could be caused by a segmentation fault while calling the function or by an excessive memory usage causing the Operating System to kill the worker.

The exit codes of the workers are {SIGBUS(-7)}
  0%|          | 0/5 [01:23<?, ?it/s]
Traceback (most recent call last):
  File "ft_official.py", line 118, in <module>
    main()
  File "ft_official.py", line 100, in main
    model.train_vispel()
  File "/home/users/apopescu/van-khoa/Vis-Priva-Expos/privacy/vispel/vispel/vispel.py", line 54, in train_vispel
    trained_clusteror, trained_regressor, feature_selector = trainer(self.situation, self.X_train, self.X_community,\
  File "/home/users/apopescu/van-khoa/Vis-Priva-Expos/privacy/vispel/vispel/trainer.py", line 64, in trainer
    trained_regressor = train_regressor(regressor, X_train_rd, gt_train_expos, cfg)
  File "/home/users/apopescu/van-khoa/Vis-Priva-Expos/privacy/lib/regressor/regression.py", line 22, in train_regressor
    model.fit(x_train, y_train)
  File "/home/users/apopescu/anaconda3/envs/detectron2/lib/python3.8/site-packages/sklearn/utils/validation.py", line 73, in inner_f
    return f(**kwargs)
  File "/home/users/apopescu/anaconda3/envs/detectron2/lib/python3.8/site-packages/sklearn/model_selection/_search.py", line 736, in fit
    self._run_search(evaluate_candidates)
  File "/home/users/apopescu/anaconda3/envs/detectron2/lib/python3.8/site-packages/sklearn/model_selection/_search.py", line 1188, in _run_search
    evaluate_candidates(ParameterGrid(self.param_grid))
  File "/home/users/apopescu/anaconda3/envs/detectron2/lib/python3.8/site-packages/sklearn/model_selection/_search.py", line 708, in evaluate_candidates
    out = parallel(delayed(_fit_and_score)(clone(base_estimator),
  File "/home/users/apopescu/anaconda3/envs/detectron2/lib/python3.8/site-packages/joblib/parallel.py", line 1042, in __call__
    self.retrieve()
  File "/home/users/apopescu/anaconda3/envs/detectron2/lib/python3.8/site-packages/joblib/parallel.py", line 921, in retrieve
    self._output.extend(job.get(timeout=self.timeout))
  File "/home/users/apopescu/anaconda3/envs/detectron2/lib/python3.8/site-packages/joblib/_parallel_backends.py", line 542, in wrap_future_result
    return future.result(timeout=timeout)
  File "/home/users/apopescu/anaconda3/envs/detectron2/lib/python3.8/concurrent/futures/_base.py", line 439, in result
    return self.__get_result()
  File "/home/users/apopescu/anaconda3/envs/detectron2/lib/python3.8/concurrent/futures/_base.py", line 388, in __get_result
    raise self._exception
joblib.externals.loky.process_executor.TerminatedWorkerError: A worker process managed by the executor was unexpectedly terminated. This could be caused by a segmentation fault while calling the function or by an excessive memory usage causing the Operating System to kill the worker.

The exit codes of the workers are {SIGBUS(-7)}
exception calling callback for <Future at 0x2b89af970190 state=finished raised TerminatedWorkerError>
Traceback (most recent call last):
  File "/home/users/apopescu/anaconda3/envs/detectron2/lib/python3.8/site-packages/joblib/externals/loky/_base.py", line 625, in _invoke_callbacks
    callback(self)
  File "/home/users/apopescu/anaconda3/envs/detectron2/lib/python3.8/site-packages/joblib/parallel.py", line 347, in __call__
    self.parallel.dispatch_next()
  File "/home/users/apopescu/anaconda3/envs/detectron2/lib/python3.8/site-packages/joblib/parallel.py", line 780, in dispatch_next
    if not self.dispatch_one_batch(self._original_iterator):
  File "/home/users/apopescu/anaconda3/envs/detectron2/lib/python3.8/site-packages/joblib/parallel.py", line 847, in dispatch_one_batch
    self._dispatch(tasks)
  File "/home/users/apopescu/anaconda3/envs/detectron2/lib/python3.8/site-packages/joblib/parallel.py", line 765, in _dispatch
    job = self._backend.apply_async(batch, callback=cb)
  File "/home/users/apopescu/anaconda3/envs/detectron2/lib/python3.8/site-packages/joblib/_parallel_backends.py", line 531, in apply_async
    future = self._workers.submit(SafeFunction(func))
  File "/home/users/apopescu/anaconda3/envs/detectron2/lib/python3.8/site-packages/joblib/externals/loky/reusable_executor.py", line 177, in submit
    return super(_ReusablePoolExecutor, self).submit(
  File "/home/users/apopescu/anaconda3/envs/detectron2/lib/python3.8/site-packages/joblib/externals/loky/process_executor.py", line 1102, in submit
    raise self._flags.broken
joblib.externals.loky.process_executor.TerminatedWorkerError: A worker process managed by the executor was unexpectedly terminated. This could be caused by a segmentation fault while calling the function or by an excessive memory usage causing the Operating System to kill the worker.

The exit codes of the workers are {SIGBUS(-7)}
  0%|          | 0/5 [01:27<?, ?it/s]
Traceback (most recent call last):
  File "ft_official.py", line 118, in <module>
    main()
  File "ft_official.py", line 100, in main
    model.train_vispel()
  File "/home/users/apopescu/van-khoa/Vis-Priva-Expos/privacy/vispel/vispel/vispel.py", line 54, in train_vispel
    trained_clusteror, trained_regressor, feature_selector = trainer(self.situation, self.X_train, self.X_community,\
  File "/home/users/apopescu/van-khoa/Vis-Priva-Expos/privacy/vispel/vispel/trainer.py", line 64, in trainer
    trained_regressor = train_regressor(regressor, X_train_rd, gt_train_expos, cfg)
  File "/home/users/apopescu/van-khoa/Vis-Priva-Expos/privacy/lib/regressor/regression.py", line 22, in train_regressor
    model.fit(x_train, y_train)
  File "/home/users/apopescu/anaconda3/envs/detectron2/lib/python3.8/site-packages/sklearn/utils/validation.py", line 73, in inner_f
    return f(**kwargs)
  File "/home/users/apopescu/anaconda3/envs/detectron2/lib/python3.8/site-packages/sklearn/model_selection/_search.py", line 736, in fit
    self._run_search(evaluate_candidates)
  File "/home/users/apopescu/anaconda3/envs/detectron2/lib/python3.8/site-packages/sklearn/model_selection/_search.py", line 1188, in _run_search
    evaluate_candidates(ParameterGrid(self.param_grid))
  File "/home/users/apopescu/anaconda3/envs/detectron2/lib/python3.8/site-packages/sklearn/model_selection/_search.py", line 708, in evaluate_candidates
    out = parallel(delayed(_fit_and_score)(clone(base_estimator),
  File "/home/users/apopescu/anaconda3/envs/detectron2/lib/python3.8/site-packages/joblib/parallel.py", line 1042, in __call__
    self.retrieve()
  File "/home/users/apopescu/anaconda3/envs/detectron2/lib/python3.8/site-packages/joblib/parallel.py", line 921, in retrieve
    self._output.extend(job.get(timeout=self.timeout))
  File "/home/users/apopescu/anaconda3/envs/detectron2/lib/python3.8/site-packages/joblib/_parallel_backends.py", line 542, in wrap_future_result
    return future.result(timeout=timeout)
  File "/home/users/apopescu/anaconda3/envs/detectron2/lib/python3.8/concurrent/futures/_base.py", line 439, in result
    return self.__get_result()
  File "/home/users/apopescu/anaconda3/envs/detectron2/lib/python3.8/concurrent/futures/_base.py", line 388, in __get_result
    raise self._exception
  File "/home/users/apopescu/anaconda3/envs/detectron2/lib/python3.8/site-packages/joblib/externals/loky/_base.py", line 625, in _invoke_callbacks
    callback(self)
  File "/home/users/apopescu/anaconda3/envs/detectron2/lib/python3.8/site-packages/joblib/parallel.py", line 347, in __call__
    self.parallel.dispatch_next()
  File "/home/users/apopescu/anaconda3/envs/detectron2/lib/python3.8/site-packages/joblib/parallel.py", line 780, in dispatch_next
    if not self.dispatch_one_batch(self._original_iterator):
  File "/home/users/apopescu/anaconda3/envs/detectron2/lib/python3.8/site-packages/joblib/parallel.py", line 847, in dispatch_one_batch
    self._dispatch(tasks)
  File "/home/users/apopescu/anaconda3/envs/detectron2/lib/python3.8/site-packages/joblib/parallel.py", line 765, in _dispatch
    job = self._backend.apply_async(batch, callback=cb)
  File "/home/users/apopescu/anaconda3/envs/detectron2/lib/python3.8/site-packages/joblib/_parallel_backends.py", line 531, in apply_async
    future = self._workers.submit(SafeFunction(func))
  File "/home/users/apopescu/anaconda3/envs/detectron2/lib/python3.8/site-packages/joblib/externals/loky/reusable_executor.py", line 177, in submit
    return super(_ReusablePoolExecutor, self).submit(
  File "/home/users/apopescu/anaconda3/envs/detectron2/lib/python3.8/site-packages/joblib/externals/loky/process_executor.py", line 1102, in submit
    raise self._flags.broken
joblib.externals.loky.process_executor.TerminatedWorkerError: A worker process managed by the executor was unexpectedly terminated. This could be caused by a segmentation fault while calling the function or by an excessive memory usage causing the Operating System to kill the worker.

The exit codes of the workers are {SIGBUS(-7)}
Traceback (most recent call last):
  File "/home/users/apopescu/anaconda3/envs/detectron2/lib/python3.8/site-packages/joblib/externals/loky/backend/resource_tracker.py", line 281, in main
    del registry[rtype][name]
KeyError: '/loky-173208-dan8zicy'
Traceback (most recent call last):
  File "/home/users/apopescu/anaconda3/envs/detectron2/lib/python3.8/site-packages/joblib/externals/loky/backend/resource_tracker.py", line 281, in main
    del registry[rtype][name]
KeyError: '/loky-173208-mpt2t78y'
Traceback (most recent call last):
  File "/home/users/apopescu/anaconda3/envs/detectron2/lib/python3.8/site-packages/joblib/externals/loky/backend/resource_tracker.py", line 281, in main
    del registry[rtype][name]
KeyError: '/dev/shm/joblib_memmapping_folder_173208_f5cfb4d90dbb40ccb6c06dca99a622a9_5dc7d014df0641e5a55c4a70e61cd2d1'
Traceback (most recent call last):
  File "/home/users/apopescu/anaconda3/envs/detectron2/lib/python3.8/site-packages/joblib/externals/loky/backend/resource_tracker.py", line 281, in main
    del registry[rtype][name]
KeyError: '/dev/shm/joblib_memmapping_folder_173208_f5cfb4d90dbb40ccb6c06dca99a622a9_ff40881b6b0542799b2a88d070144e67'
Traceback (most recent call last):
  File "/home/users/apopescu/anaconda3/envs/detectron2/lib/python3.8/site-packages/joblib/externals/loky/backend/resource_tracker.py", line 281, in main
    del registry[rtype][name]
KeyError: '/loky-173208-fan0v2h7'
Traceback (most recent call last):
  File "/home/users/apopescu/anaconda3/envs/detectron2/lib/python3.8/site-packages/joblib/externals/loky/backend/resource_tracker.py", line 281, in main
    del registry[rtype][name]
KeyError: '/loky-173208-zvqg8s_w'
Traceback (most recent call last):
  File "/home/users/apopescu/anaconda3/envs/detectron2/lib/python3.8/site-packages/joblib/externals/loky/backend/resource_tracker.py", line 281, in main
    del registry[rtype][name]
KeyError: '/loky-173208-medbzavp'
Traceback (most recent call last):
  File "/home/users/apopescu/anaconda3/envs/detectron2/lib/python3.8/site-packages/joblib/externals/loky/backend/resource_tracker.py", line 281, in main
    del registry[rtype][name]
KeyError: '/loky-173208-9izwvmjd'
Traceback (most recent call last):
  File "/home/users/apopescu/anaconda3/envs/detectron2/lib/python3.8/site-packages/joblib/externals/loky/backend/resource_tracker.py", line 281, in main
    del registry[rtype][name]
KeyError: '/loky-173208-mzjex_q3'
Traceback (most recent call last):
  File "/home/users/apopescu/anaconda3/envs/detectron2/lib/python3.8/site-packages/joblib/externals/loky/backend/resource_tracker.py", line 281, in main
    del registry[rtype][name]
KeyError: '/loky-173208-2xvs7v33'
exception calling callback for <Future at 0x2b52a124d190 state=finished raised TerminatedWorkerError>
Traceback (most recent call last):
  File "/home/users/apopescu/anaconda3/envs/detectron2/lib/python3.8/site-packages/joblib/externals/loky/_base.py", line 625, in _invoke_callbacks
    callback(self)
  File "/home/users/apopescu/anaconda3/envs/detectron2/lib/python3.8/site-packages/joblib/parallel.py", line 347, in __call__
    self.parallel.dispatch_next()
  File "/home/users/apopescu/anaconda3/envs/detectron2/lib/python3.8/site-packages/joblib/parallel.py", line 780, in dispatch_next
    if not self.dispatch_one_batch(self._original_iterator):
  File "/home/users/apopescu/anaconda3/envs/detectron2/lib/python3.8/site-packages/joblib/parallel.py", line 847, in dispatch_one_batch
    self._dispatch(tasks)
  File "/home/users/apopescu/anaconda3/envs/detectron2/lib/python3.8/site-packages/joblib/parallel.py", line 765, in _dispatch
    job = self._backend.apply_async(batch, callback=cb)
  File "/home/users/apopescu/anaconda3/envs/detectron2/lib/python3.8/site-packages/joblib/_parallel_backends.py", line 531, in apply_async
    future = self._workers.submit(SafeFunction(func))
  File "/home/users/apopescu/anaconda3/envs/detectron2/lib/python3.8/site-packages/joblib/externals/loky/reusable_executor.py", line 177, in submit
    return super(_ReusablePoolExecutor, self).submit(
  File "/home/users/apopescu/anaconda3/envs/detectron2/lib/python3.8/site-packages/joblib/externals/loky/process_executor.py", line 1102, in submit
    raise self._flags.broken
joblib.externals.loky.process_executor.TerminatedWorkerError: A worker process managed by the executor was unexpectedly terminated. This could be caused by a segmentation fault while calling the function or by an excessive memory usage causing the Operating System to kill the worker.

The exit codes of the workers are {SIGBUS(-7)}
exception calling callback for <Future at 0x2b52a1230910 state=finished raised TerminatedWorkerError>
Traceback (most recent call last):
  File "/home/users/apopescu/anaconda3/envs/detectron2/lib/python3.8/site-packages/joblib/externals/loky/_base.py", line 625, in _invoke_callbacks
    callback(self)
  File "/home/users/apopescu/anaconda3/envs/detectron2/lib/python3.8/site-packages/joblib/parallel.py", line 347, in __call__
    self.parallel.dispatch_next()
  File "/home/users/apopescu/anaconda3/envs/detectron2/lib/python3.8/site-packages/joblib/parallel.py", line 780, in dispatch_next
    if not self.dispatch_one_batch(self._original_iterator):
  File "/home/users/apopescu/anaconda3/envs/detectron2/lib/python3.8/site-packages/joblib/parallel.py", line 847, in dispatch_one_batch
    self._dispatch(tasks)
  File "/home/users/apopescu/anaconda3/envs/detectron2/lib/python3.8/site-packages/joblib/parallel.py", line 765, in _dispatch
    job = self._backend.apply_async(batch, callback=cb)
  File "/home/users/apopescu/anaconda3/envs/detectron2/lib/python3.8/site-packages/joblib/_parallel_backends.py", line 531, in apply_async
    future = self._workers.submit(SafeFunction(func))
  File "/home/users/apopescu/anaconda3/envs/detectron2/lib/python3.8/site-packages/joblib/externals/loky/reusable_executor.py", line 177, in submit
    return super(_ReusablePoolExecutor, self).submit(
  File "/home/users/apopescu/anaconda3/envs/detectron2/lib/python3.8/site-packages/joblib/externals/loky/process_executor.py", line 1102, in submit
    raise self._flags.broken
  File "/home/users/apopescu/anaconda3/envs/detectron2/lib/python3.8/site-packages/joblib/externals/loky/_base.py", line 625, in _invoke_callbacks
    callback(self)
  File "/home/users/apopescu/anaconda3/envs/detectron2/lib/python3.8/site-packages/joblib/parallel.py", line 347, in __call__
    self.parallel.dispatch_next()
  File "/home/users/apopescu/anaconda3/envs/detectron2/lib/python3.8/site-packages/joblib/parallel.py", line 780, in dispatch_next
    if not self.dispatch_one_batch(self._original_iterator):
  File "/home/users/apopescu/anaconda3/envs/detectron2/lib/python3.8/site-packages/joblib/parallel.py", line 847, in dispatch_one_batch
    self._dispatch(tasks)
  File "/home/users/apopescu/anaconda3/envs/detectron2/lib/python3.8/site-packages/joblib/parallel.py", line 765, in _dispatch
    job = self._backend.apply_async(batch, callback=cb)
  File "/home/users/apopescu/anaconda3/envs/detectron2/lib/python3.8/site-packages/joblib/_parallel_backends.py", line 531, in apply_async
    future = self._workers.submit(SafeFunction(func))
  File "/home/users/apopescu/anaconda3/envs/detectron2/lib/python3.8/site-packages/joblib/externals/loky/reusable_executor.py", line 177, in submit
    return super(_ReusablePoolExecutor, self).submit(
  File "/home/users/apopescu/anaconda3/envs/detectron2/lib/python3.8/site-packages/joblib/externals/loky/process_executor.py", line 1102, in submit
    raise self._flags.broken
joblib.externals.loky.process_executor.TerminatedWorkerError: A worker process managed by the executor was unexpectedly terminated. This could be caused by a segmentation fault while calling the function or by an excessive memory usage causing the Operating System to kill the worker.

The exit codes of the workers are {SIGBUS(-7)}
exception calling callback for <Future at 0x2b52a1230d60 state=finished raised TerminatedWorkerError>
Traceback (most recent call last):
  File "/home/users/apopescu/anaconda3/envs/detectron2/lib/python3.8/site-packages/joblib/externals/loky/_base.py", line 625, in _invoke_callbacks
    callback(self)
  File "/home/users/apopescu/anaconda3/envs/detectron2/lib/python3.8/site-packages/joblib/parallel.py", line 347, in __call__
    self.parallel.dispatch_next()
  File "/home/users/apopescu/anaconda3/envs/detectron2/lib/python3.8/site-packages/joblib/parallel.py", line 780, in dispatch_next
    if not self.dispatch_one_batch(self._original_iterator):
  File "/home/users/apopescu/anaconda3/envs/detectron2/lib/python3.8/site-packages/joblib/parallel.py", line 847, in dispatch_one_batch
    self._dispatch(tasks)
  File "/home/users/apopescu/anaconda3/envs/detectron2/lib/python3.8/site-packages/joblib/parallel.py", line 765, in _dispatch
    job = self._backend.apply_async(batch, callback=cb)
  File "/home/users/apopescu/anaconda3/envs/detectron2/lib/python3.8/site-packages/joblib/_parallel_backends.py", line 531, in apply_async
    future = self._workers.submit(SafeFunction(func))
  File "/home/users/apopescu/anaconda3/envs/detectron2/lib/python3.8/site-packages/joblib/externals/loky/reusable_executor.py", line 177, in submit
    return super(_ReusablePoolExecutor, self).submit(
  File "/home/users/apopescu/anaconda3/envs/detectron2/lib/python3.8/site-packages/joblib/externals/loky/process_executor.py", line 1102, in submit
    raise self._flags.broken
  File "/home/users/apopescu/anaconda3/envs/detectron2/lib/python3.8/site-packages/joblib/externals/loky/_base.py", line 625, in _invoke_callbacks
    callback(self)
  File "/home/users/apopescu/anaconda3/envs/detectron2/lib/python3.8/site-packages/joblib/parallel.py", line 347, in __call__
    self.parallel.dispatch_next()
  File "/home/users/apopescu/anaconda3/envs/detectron2/lib/python3.8/site-packages/joblib/parallel.py", line 780, in dispatch_next
    if not self.dispatch_one_batch(self._original_iterator):
  File "/home/users/apopescu/anaconda3/envs/detectron2/lib/python3.8/site-packages/joblib/parallel.py", line 847, in dispatch_one_batch
    self._dispatch(tasks)
  File "/home/users/apopescu/anaconda3/envs/detectron2/lib/python3.8/site-packages/joblib/parallel.py", line 765, in _dispatch
    job = self._backend.apply_async(batch, callback=cb)
  File "/home/users/apopescu/anaconda3/envs/detectron2/lib/python3.8/site-packages/joblib/_parallel_backends.py", line 531, in apply_async
    future = self._workers.submit(SafeFunction(func))
  File "/home/users/apopescu/anaconda3/envs/detectron2/lib/python3.8/site-packages/joblib/externals/loky/reusable_executor.py", line 177, in submit
    return super(_ReusablePoolExecutor, self).submit(
  File "/home/users/apopescu/anaconda3/envs/detectron2/lib/python3.8/site-packages/joblib/externals/loky/process_executor.py", line 1102, in submit
    raise self._flags.broken
  File "/home/users/apopescu/anaconda3/envs/detectron2/lib/python3.8/site-packages/joblib/externals/loky/_base.py", line 625, in _invoke_callbacks
    callback(self)
  File "/home/users/apopescu/anaconda3/envs/detectron2/lib/python3.8/site-packages/joblib/parallel.py", line 347, in __call__
    self.parallel.dispatch_next()
  File "/home/users/apopescu/anaconda3/envs/detectron2/lib/python3.8/site-packages/joblib/parallel.py", line 780, in dispatch_next
    if not self.dispatch_one_batch(self._original_iterator):
  File "/home/users/apopescu/anaconda3/envs/detectron2/lib/python3.8/site-packages/joblib/parallel.py", line 847, in dispatch_one_batch
    self._dispatch(tasks)
  File "/home/users/apopescu/anaconda3/envs/detectron2/lib/python3.8/site-packages/joblib/parallel.py", line 765, in _dispatch
    job = self._backend.apply_async(batch, callback=cb)
  File "/home/users/apopescu/anaconda3/envs/detectron2/lib/python3.8/site-packages/joblib/_parallel_backends.py", line 531, in apply_async
    future = self._workers.submit(SafeFunction(func))
  File "/home/users/apopescu/anaconda3/envs/detectron2/lib/python3.8/site-packages/joblib/externals/loky/reusable_executor.py", line 177, in submit
    return super(_ReusablePoolExecutor, self).submit(
  File "/home/users/apopescu/anaconda3/envs/detectron2/lib/python3.8/site-packages/joblib/externals/loky/process_executor.py", line 1102, in submit
    raise self._flags.broken
joblib.externals.loky.process_executor.TerminatedWorkerError: A worker process managed by the executor was unexpectedly terminated. This could be caused by a segmentation fault while calling the function or by an excessive memory usage causing the Operating System to kill the worker.

The exit codes of the workers are {SIGBUS(-7)}
exception calling callback for <Future at 0x2b3edfef3190 state=finished raised TerminatedWorkerError>
Traceback (most recent call last):
  File "/home/users/apopescu/anaconda3/envs/detectron2/lib/python3.8/site-packages/joblib/externals/loky/_base.py", line 625, in _invoke_callbacks
    callback(self)
  File "/home/users/apopescu/anaconda3/envs/detectron2/lib/python3.8/site-packages/joblib/parallel.py", line 347, in __call__
    self.parallel.dispatch_next()
  File "/home/users/apopescu/anaconda3/envs/detectron2/lib/python3.8/site-packages/joblib/parallel.py", line 780, in dispatch_next
    if not self.dispatch_one_batch(self._original_iterator):
  File "/home/users/apopescu/anaconda3/envs/detectron2/lib/python3.8/site-packages/joblib/parallel.py", line 847, in dispatch_one_batch
    self._dispatch(tasks)
  File "/home/users/apopescu/anaconda3/envs/detectron2/lib/python3.8/site-packages/joblib/parallel.py", line 765, in _dispatch
    job = self._backend.apply_async(batch, callback=cb)
  File "/home/users/apopescu/anaconda3/envs/detectron2/lib/python3.8/site-packages/joblib/_parallel_backends.py", line 531, in apply_async
    future = self._workers.submit(SafeFunction(func))
  File "/home/users/apopescu/anaconda3/envs/detectron2/lib/python3.8/site-packages/joblib/externals/loky/reusable_executor.py", line 177, in submit
    return super(_ReusablePoolExecutor, self).submit(
  File "/home/users/apopescu/anaconda3/envs/detectron2/lib/python3.8/site-packages/joblib/externals/loky/process_executor.py", line 1102, in submit
    raise self._flags.broken
joblib.externals.loky.process_executor.TerminatedWorkerError: A worker process managed by the executor was unexpectedly terminated. This could be caused by a segmentation fault while calling the function or by an excessive memory usage causing the Operating System to kill the worker.

The exit codes of the workers are {SIGBUS(-7)}
exception calling callback for <Future at 0x2b3edfedf910 state=finished raised TerminatedWorkerError>
Traceback (most recent call last):
  File "/home/users/apopescu/anaconda3/envs/detectron2/lib/python3.8/site-packages/joblib/externals/loky/_base.py", line 625, in _invoke_callbacks
    callback(self)
  File "/home/users/apopescu/anaconda3/envs/detectron2/lib/python3.8/site-packages/joblib/parallel.py", line 347, in __call__
    self.parallel.dispatch_next()
  File "/home/users/apopescu/anaconda3/envs/detectron2/lib/python3.8/site-packages/joblib/parallel.py", line 780, in dispatch_next
    if not self.dispatch_one_batch(self._original_iterator):
  File "/home/users/apopescu/anaconda3/envs/detectron2/lib/python3.8/site-packages/joblib/parallel.py", line 847, in dispatch_one_batch
    self._dispatch(tasks)
  File "/home/users/apopescu/anaconda3/envs/detectron2/lib/python3.8/site-packages/joblib/parallel.py", line 765, in _dispatch
    job = self._backend.apply_async(batch, callback=cb)
  File "/home/users/apopescu/anaconda3/envs/detectron2/lib/python3.8/site-packages/joblib/_parallel_backends.py", line 531, in apply_async
    future = self._workers.submit(SafeFunction(func))
  File "/home/users/apopescu/anaconda3/envs/detectron2/lib/python3.8/site-packages/joblib/externals/loky/reusable_executor.py", line 177, in submit
    return super(_ReusablePoolExecutor, self).submit(
  File "/home/users/apopescu/anaconda3/envs/detectron2/lib/python3.8/site-packages/joblib/externals/loky/process_executor.py", line 1102, in submit
    raise self._flags.broken
  File "/home/users/apopescu/anaconda3/envs/detectron2/lib/python3.8/site-packages/joblib/externals/loky/_base.py", line 625, in _invoke_callbacks
    callback(self)
  File "/home/users/apopescu/anaconda3/envs/detectron2/lib/python3.8/site-packages/joblib/parallel.py", line 347, in __call__
    self.parallel.dispatch_next()
  File "/home/users/apopescu/anaconda3/envs/detectron2/lib/python3.8/site-packages/joblib/parallel.py", line 780, in dispatch_next
    if not self.dispatch_one_batch(self._original_iterator):
  File "/home/users/apopescu/anaconda3/envs/detectron2/lib/python3.8/site-packages/joblib/parallel.py", line 847, in dispatch_one_batch
    self._dispatch(tasks)
  File "/home/users/apopescu/anaconda3/envs/detectron2/lib/python3.8/site-packages/joblib/parallel.py", line 765, in _dispatch
    job = self._backend.apply_async(batch, callback=cb)
  File "/home/users/apopescu/anaconda3/envs/detectron2/lib/python3.8/site-packages/joblib/_parallel_backends.py", line 531, in apply_async
    future = self._workers.submit(SafeFunction(func))
  File "/home/users/apopescu/anaconda3/envs/detectron2/lib/python3.8/site-packages/joblib/externals/loky/reusable_executor.py", line 177, in submit
    return super(_ReusablePoolExecutor, self).submit(
  File "/home/users/apopescu/anaconda3/envs/detectron2/lib/python3.8/site-packages/joblib/externals/loky/process_executor.py", line 1102, in submit
    raise self._flags.broken
joblib.externals.loky.process_executor.TerminatedWorkerError: A worker process managed by the executor was unexpectedly terminated. This could be caused by a segmentation fault while calling the function or by an excessive memory usage causing the Operating System to kill the worker.

The exit codes of the workers are {SIGBUS(-7)}
exception calling callback for <Future at 0x2af12e091190 state=finished raised TerminatedWorkerError>
Traceback (most recent call last):
  File "/home/users/apopescu/anaconda3/envs/detectron2/lib/python3.8/site-packages/joblib/externals/loky/_base.py", line 625, in _invoke_callbacks
    callback(self)
  File "/home/users/apopescu/anaconda3/envs/detectron2/lib/python3.8/site-packages/joblib/parallel.py", line 347, in __call__
    self.parallel.dispatch_next()
  File "/home/users/apopescu/anaconda3/envs/detectron2/lib/python3.8/site-packages/joblib/parallel.py", line 780, in dispatch_next
    if not self.dispatch_one_batch(self._original_iterator):
  File "/home/users/apopescu/anaconda3/envs/detectron2/lib/python3.8/site-packages/joblib/parallel.py", line 847, in dispatch_one_batch
    self._dispatch(tasks)
  File "/home/users/apopescu/anaconda3/envs/detectron2/lib/python3.8/site-packages/joblib/parallel.py", line 765, in _dispatch
    job = self._backend.apply_async(batch, callback=cb)
  File "/home/users/apopescu/anaconda3/envs/detectron2/lib/python3.8/site-packages/joblib/_parallel_backends.py", line 531, in apply_async
    future = self._workers.submit(SafeFunction(func))
  File "/home/users/apopescu/anaconda3/envs/detectron2/lib/python3.8/site-packages/joblib/externals/loky/reusable_executor.py", line 177, in submit
    return super(_ReusablePoolExecutor, self).submit(
  File "/home/users/apopescu/anaconda3/envs/detectron2/lib/python3.8/site-packages/joblib/externals/loky/process_executor.py", line 1102, in submit
    raise self._flags.broken
joblib.externals.loky.process_executor.TerminatedWorkerError: A worker process managed by the executor was unexpectedly terminated. This could be caused by a segmentation fault while calling the function or by an excessive memory usage causing the Operating System to kill the worker.

The exit codes of the workers are {SIGKILL(-9)}
exception calling callback for <Future at 0x2af12e0766d0 state=finished raised TerminatedWorkerError>
Traceback (most recent call last):
  File "/home/users/apopescu/anaconda3/envs/detectron2/lib/python3.8/site-packages/joblib/externals/loky/_base.py", line 625, in _invoke_callbacks
    callback(self)
  File "/home/users/apopescu/anaconda3/envs/detectron2/lib/python3.8/site-packages/joblib/parallel.py", line 347, in __call__
    self.parallel.dispatch_next()
  File "/home/users/apopescu/anaconda3/envs/detectron2/lib/python3.8/site-packages/joblib/parallel.py", line 780, in dispatch_next
    if not self.dispatch_one_batch(self._original_iterator):
  File "/home/users/apopescu/anaconda3/envs/detectron2/lib/python3.8/site-packages/joblib/parallel.py", line 847, in dispatch_one_batch
    self._dispatch(tasks)
  File "/home/users/apopescu/anaconda3/envs/detectron2/lib/python3.8/site-packages/joblib/parallel.py", line 765, in _dispatch
    job = self._backend.apply_async(batch, callback=cb)
  File "/home/users/apopescu/anaconda3/envs/detectron2/lib/python3.8/site-packages/joblib/_parallel_backends.py", line 531, in apply_async
    future = self._workers.submit(SafeFunction(func))
  File "/home/users/apopescu/anaconda3/envs/detectron2/lib/python3.8/site-packages/joblib/externals/loky/reusable_executor.py", line 177, in submit
    return super(_ReusablePoolExecutor, self).submit(
  File "/home/users/apopescu/anaconda3/envs/detectron2/lib/python3.8/site-packages/joblib/externals/loky/process_executor.py", line 1102, in submit
    raise self._flags.broken
  File "/home/users/apopescu/anaconda3/envs/detectron2/lib/python3.8/site-packages/joblib/externals/loky/_base.py", line 625, in _invoke_callbacks
    callback(self)
  File "/home/users/apopescu/anaconda3/envs/detectron2/lib/python3.8/site-packages/joblib/parallel.py", line 347, in __call__
    self.parallel.dispatch_next()
  File "/home/users/apopescu/anaconda3/envs/detectron2/lib/python3.8/site-packages/joblib/parallel.py", line 780, in dispatch_next
    if not self.dispatch_one_batch(self._original_iterator):
  File "/home/users/apopescu/anaconda3/envs/detectron2/lib/python3.8/site-packages/joblib/parallel.py", line 847, in dispatch_one_batch
    self._dispatch(tasks)
  File "/home/users/apopescu/anaconda3/envs/detectron2/lib/python3.8/site-packages/joblib/parallel.py", line 765, in _dispatch
    job = self._backend.apply_async(batch, callback=cb)
  File "/home/users/apopescu/anaconda3/envs/detectron2/lib/python3.8/site-packages/joblib/_parallel_backends.py", line 531, in apply_async
    future = self._workers.submit(SafeFunction(func))
  File "/home/users/apopescu/anaconda3/envs/detectron2/lib/python3.8/site-packages/joblib/externals/loky/reusable_executor.py", line 177, in submit
    return super(_ReusablePoolExecutor, self).submit(
  File "/home/users/apopescu/anaconda3/envs/detectron2/lib/python3.8/site-packages/joblib/externals/loky/process_executor.py", line 1102, in submit
    raise self._flags.broken
joblib.externals.loky.process_executor.TerminatedWorkerError: A worker process managed by the executor was unexpectedly terminated. This could be caused by a segmentation fault while calling the function or by an excessive memory usage causing the Operating System to kill the worker.

The exit codes of the workers are {SIGKILL(-9)}
exception calling callback for <Future at 0x2af12e076d60 state=finished raised TerminatedWorkerError>
Traceback (most recent call last):
  File "/home/users/apopescu/anaconda3/envs/detectron2/lib/python3.8/site-packages/joblib/externals/loky/_base.py", line 625, in _invoke_callbacks
    callback(self)
  File "/home/users/apopescu/anaconda3/envs/detectron2/lib/python3.8/site-packages/joblib/parallel.py", line 347, in __call__
    self.parallel.dispatch_next()
  File "/home/users/apopescu/anaconda3/envs/detectron2/lib/python3.8/site-packages/joblib/parallel.py", line 780, in dispatch_next
    if not self.dispatch_one_batch(self._original_iterator):
  File "/home/users/apopescu/anaconda3/envs/detectron2/lib/python3.8/site-packages/joblib/parallel.py", line 847, in dispatch_one_batch
    self._dispatch(tasks)
  File "/home/users/apopescu/anaconda3/envs/detectron2/lib/python3.8/site-packages/joblib/parallel.py", line 765, in _dispatch
    job = self._backend.apply_async(batch, callback=cb)
  File "/home/users/apopescu/anaconda3/envs/detectron2/lib/python3.8/site-packages/joblib/_parallel_backends.py", line 531, in apply_async
    future = self._workers.submit(SafeFunction(func))
  File "/home/users/apopescu/anaconda3/envs/detectron2/lib/python3.8/site-packages/joblib/externals/loky/reusable_executor.py", line 177, in submit
    return super(_ReusablePoolExecutor, self).submit(
  File "/home/users/apopescu/anaconda3/envs/detectron2/lib/python3.8/site-packages/joblib/externals/loky/process_executor.py", line 1102, in submit
    raise self._flags.broken
  File "/home/users/apopescu/anaconda3/envs/detectron2/lib/python3.8/site-packages/joblib/externals/loky/_base.py", line 625, in _invoke_callbacks
    callback(self)
  File "/home/users/apopescu/anaconda3/envs/detectron2/lib/python3.8/site-packages/joblib/parallel.py", line 347, in __call__
    self.parallel.dispatch_next()
  File "/home/users/apopescu/anaconda3/envs/detectron2/lib/python3.8/site-packages/joblib/parallel.py", line 780, in dispatch_next
    if not self.dispatch_one_batch(self._original_iterator):
  File "/home/users/apopescu/anaconda3/envs/detectron2/lib/python3.8/site-packages/joblib/parallel.py", line 847, in dispatch_one_batch
    self._dispatch(tasks)
  File "/home/users/apopescu/anaconda3/envs/detectron2/lib/python3.8/site-packages/joblib/parallel.py", line 765, in _dispatch
    job = self._backend.apply_async(batch, callback=cb)
  File "/home/users/apopescu/anaconda3/envs/detectron2/lib/python3.8/site-packages/joblib/_parallel_backends.py", line 531, in apply_async
    future = self._workers.submit(SafeFunction(func))
  File "/home/users/apopescu/anaconda3/envs/detectron2/lib/python3.8/site-packages/joblib/externals/loky/reusable_executor.py", line 177, in submit
    return super(_ReusablePoolExecutor, self).submit(
  File "/home/users/apopescu/anaconda3/envs/detectron2/lib/python3.8/site-packages/joblib/externals/loky/process_executor.py", line 1102, in submit
    raise self._flags.broken
  File "/home/users/apopescu/anaconda3/envs/detectron2/lib/python3.8/site-packages/joblib/externals/loky/_base.py", line 625, in _invoke_callbacks
    callback(self)
  File "/home/users/apopescu/anaconda3/envs/detectron2/lib/python3.8/site-packages/joblib/parallel.py", line 347, in __call__
    self.parallel.dispatch_next()
  File "/home/users/apopescu/anaconda3/envs/detectron2/lib/python3.8/site-packages/joblib/parallel.py", line 780, in dispatch_next
    if not self.dispatch_one_batch(self._original_iterator):
  File "/home/users/apopescu/anaconda3/envs/detectron2/lib/python3.8/site-packages/joblib/parallel.py", line 847, in dispatch_one_batch
    self._dispatch(tasks)
  File "/home/users/apopescu/anaconda3/envs/detectron2/lib/python3.8/site-packages/joblib/parallel.py", line 765, in _dispatch
    job = self._backend.apply_async(batch, callback=cb)
  File "/home/users/apopescu/anaconda3/envs/detectron2/lib/python3.8/site-packages/joblib/_parallel_backends.py", line 531, in apply_async
    future = self._workers.submit(SafeFunction(func))
  File "/home/users/apopescu/anaconda3/envs/detectron2/lib/python3.8/site-packages/joblib/externals/loky/reusable_executor.py", line 177, in submit
    return super(_ReusablePoolExecutor, self).submit(
  File "/home/users/apopescu/anaconda3/envs/detectron2/lib/python3.8/site-packages/joblib/externals/loky/process_executor.py", line 1102, in submit
    raise self._flags.broken
joblib.externals.loky.process_executor.TerminatedWorkerError: A worker process managed by the executor was unexpectedly terminated. This could be caused by a segmentation fault while calling the function or by an excessive memory usage causing the Operating System to kill the worker.

The exit codes of the workers are {SIGKILL(-9)}
exception calling callback for <Future at 0x2af12e076e80 state=finished raised TerminatedWorkerError>
Traceback (most recent call last):
  File "/home/users/apopescu/anaconda3/envs/detectron2/lib/python3.8/site-packages/joblib/externals/loky/_base.py", line 625, in _invoke_callbacks
    callback(self)
  File "/home/users/apopescu/anaconda3/envs/detectron2/lib/python3.8/site-packages/joblib/parallel.py", line 347, in __call__
    self.parallel.dispatch_next()
  File "/home/users/apopescu/anaconda3/envs/detectron2/lib/python3.8/site-packages/joblib/parallel.py", line 780, in dispatch_next
    if not self.dispatch_one_batch(self._original_iterator):
  File "/home/users/apopescu/anaconda3/envs/detectron2/lib/python3.8/site-packages/joblib/parallel.py", line 847, in dispatch_one_batch
    self._dispatch(tasks)
  File "/home/users/apopescu/anaconda3/envs/detectron2/lib/python3.8/site-packages/joblib/parallel.py", line 765, in _dispatch
    job = self._backend.apply_async(batch, callback=cb)
  File "/home/users/apopescu/anaconda3/envs/detectron2/lib/python3.8/site-packages/joblib/_parallel_backends.py", line 531, in apply_async
    future = self._workers.submit(SafeFunction(func))
  File "/home/users/apopescu/anaconda3/envs/detectron2/lib/python3.8/site-packages/joblib/externals/loky/reusable_executor.py", line 177, in submit
    return super(_ReusablePoolExecutor, self).submit(
  File "/home/users/apopescu/anaconda3/envs/detectron2/lib/python3.8/site-packages/joblib/externals/loky/process_executor.py", line 1102, in submit
    raise self._flags.broken
  File "/home/users/apopescu/anaconda3/envs/detectron2/lib/python3.8/site-packages/joblib/externals/loky/_base.py", line 625, in _invoke_callbacks
    callback(self)
  File "/home/users/apopescu/anaconda3/envs/detectron2/lib/python3.8/site-packages/joblib/parallel.py", line 347, in __call__
    self.parallel.dispatch_next()
  File "/home/users/apopescu/anaconda3/envs/detectron2/lib/python3.8/site-packages/joblib/parallel.py", line 780, in dispatch_next
    if not self.dispatch_one_batch(self._original_iterator):
  File "/home/users/apopescu/anaconda3/envs/detectron2/lib/python3.8/site-packages/joblib/parallel.py", line 847, in dispatch_one_batch
    self._dispatch(tasks)
  File "/home/users/apopescu/anaconda3/envs/detectron2/lib/python3.8/site-packages/joblib/parallel.py", line 765, in _dispatch
    job = self._backend.apply_async(batch, callback=cb)
  File "/home/users/apopescu/anaconda3/envs/detectron2/lib/python3.8/site-packages/joblib/_parallel_backends.py", line 531, in apply_async
    future = self._workers.submit(SafeFunction(func))
  File "/home/users/apopescu/anaconda3/envs/detectron2/lib/python3.8/site-packages/joblib/externals/loky/reusable_executor.py", line 177, in submit
    return super(_ReusablePoolExecutor, self).submit(
  File "/home/users/apopescu/anaconda3/envs/detectron2/lib/python3.8/site-packages/joblib/externals/loky/process_executor.py", line 1102, in submit
    raise self._flags.broken
  File "/home/users/apopescu/anaconda3/envs/detectron2/lib/python3.8/site-packages/joblib/externals/loky/_base.py", line 625, in _invoke_callbacks
    callback(self)
  File "/home/users/apopescu/anaconda3/envs/detectron2/lib/python3.8/site-packages/joblib/parallel.py", line 347, in __call__
    self.parallel.dispatch_next()
  File "/home/users/apopescu/anaconda3/envs/detectron2/lib/python3.8/site-packages/joblib/parallel.py", line 780, in dispatch_next
    if not self.dispatch_one_batch(self._original_iterator):
  File "/home/users/apopescu/anaconda3/envs/detectron2/lib/python3.8/site-packages/joblib/parallel.py", line 847, in dispatch_one_batch
    self._dispatch(tasks)
  File "/home/users/apopescu/anaconda3/envs/detectron2/lib/python3.8/site-packages/joblib/parallel.py", line 765, in _dispatch
    job = self._backend.apply_async(batch, callback=cb)
  File "/home/users/apopescu/anaconda3/envs/detectron2/lib/python3.8/site-packages/joblib/_parallel_backends.py", line 531, in apply_async
    future = self._workers.submit(SafeFunction(func))
  File "/home/users/apopescu/anaconda3/envs/detectron2/lib/python3.8/site-packages/joblib/externals/loky/reusable_executor.py", line 177, in submit
    return super(_ReusablePoolExecutor, self).submit(
  File "/home/users/apopescu/anaconda3/envs/detectron2/lib/python3.8/site-packages/joblib/externals/loky/process_executor.py", line 1102, in submit
    raise self._flags.broken
  File "/home/users/apopescu/anaconda3/envs/detectron2/lib/python3.8/site-packages/joblib/externals/loky/_base.py", line 625, in _invoke_callbacks
    callback(self)
  File "/home/users/apopescu/anaconda3/envs/detectron2/lib/python3.8/site-packages/joblib/parallel.py", line 347, in __call__
    self.parallel.dispatch_next()
  File "/home/users/apopescu/anaconda3/envs/detectron2/lib/python3.8/site-packages/joblib/parallel.py", line 780, in dispatch_next
    if not self.dispatch_one_batch(self._original_iterator):
  File "/home/users/apopescu/anaconda3/envs/detectron2/lib/python3.8/site-packages/joblib/parallel.py", line 847, in dispatch_one_batch
    self._dispatch(tasks)
  File "/home/users/apopescu/anaconda3/envs/detectron2/lib/python3.8/site-packages/joblib/parallel.py", line 765, in _dispatch
    job = self._backend.apply_async(batch, callback=cb)
  File "/home/users/apopescu/anaconda3/envs/detectron2/lib/python3.8/site-packages/joblib/_parallel_backends.py", line 531, in apply_async
    future = self._workers.submit(SafeFunction(func))
  File "/home/users/apopescu/anaconda3/envs/detectron2/lib/python3.8/site-packages/joblib/externals/loky/reusable_executor.py", line 177, in submit
    return super(_ReusablePoolExecutor, self).submit(
  File "/home/users/apopescu/anaconda3/envs/detectron2/lib/python3.8/site-packages/joblib/externals/loky/process_executor.py", line 1102, in submit
    raise self._flags.broken
joblib.externals.loky.process_executor.TerminatedWorkerError: A worker process managed by the executor was unexpectedly terminated. This could be caused by a segmentation fault while calling the function or by an excessive memory usage causing the Operating System to kill the worker.

The exit codes of the workers are {SIGKILL(-9)}
  0%|          | 0/5 [01:40<?, ?it/s]
Traceback (most recent call last):
  File "ft_official.py", line 118, in <module>
    main()
  File "ft_official.py", line 100, in main
    model.train_vispel()
  File "/home/users/apopescu/van-khoa/Vis-Priva-Expos/privacy/vispel/vispel/vispel.py", line 54, in train_vispel
    trained_clusteror, trained_regressor, feature_selector = trainer(self.situation, self.X_train, self.X_community,\
  File "/home/users/apopescu/van-khoa/Vis-Priva-Expos/privacy/vispel/vispel/trainer.py", line 64, in trainer
    trained_regressor = train_regressor(regressor, X_train_rd, gt_train_expos, cfg)
  File "/home/users/apopescu/van-khoa/Vis-Priva-Expos/privacy/lib/regressor/regression.py", line 22, in train_regressor
    model.fit(x_train, y_train)
  File "/home/users/apopescu/anaconda3/envs/detectron2/lib/python3.8/site-packages/sklearn/utils/validation.py", line 73, in inner_f
    return f(**kwargs)
  File "/home/users/apopescu/anaconda3/envs/detectron2/lib/python3.8/site-packages/sklearn/model_selection/_search.py", line 736, in fit
    self._run_search(evaluate_candidates)
  File "/home/users/apopescu/anaconda3/envs/detectron2/lib/python3.8/site-packages/sklearn/model_selection/_search.py", line 1188, in _run_search
    evaluate_candidates(ParameterGrid(self.param_grid))
  File "/home/users/apopescu/anaconda3/envs/detectron2/lib/python3.8/site-packages/sklearn/model_selection/_search.py", line 708, in evaluate_candidates
    out = parallel(delayed(_fit_and_score)(clone(base_estimator),
  File "/home/users/apopescu/anaconda3/envs/detectron2/lib/python3.8/site-packages/joblib/parallel.py", line 1042, in __call__
    self.retrieve()
  File "/home/users/apopescu/anaconda3/envs/detectron2/lib/python3.8/site-packages/joblib/parallel.py", line 921, in retrieve
    self._output.extend(job.get(timeout=self.timeout))
  File "/home/users/apopescu/anaconda3/envs/detectron2/lib/python3.8/site-packages/joblib/_parallel_backends.py", line 542, in wrap_future_result
    return future.result(timeout=timeout)
  File "/home/users/apopescu/anaconda3/envs/detectron2/lib/python3.8/concurrent/futures/_base.py", line 439, in result
    return self.__get_result()
  File "/home/users/apopescu/anaconda3/envs/detectron2/lib/python3.8/concurrent/futures/_base.py", line 388, in __get_result
    raise self._exception
  File "/home/users/apopescu/anaconda3/envs/detectron2/lib/python3.8/site-packages/joblib/externals/loky/_base.py", line 625, in _invoke_callbacks
    callback(self)
  File "/home/users/apopescu/anaconda3/envs/detectron2/lib/python3.8/site-packages/joblib/parallel.py", line 347, in __call__
    self.parallel.dispatch_next()
  File "/home/users/apopescu/anaconda3/envs/detectron2/lib/python3.8/site-packages/joblib/parallel.py", line 780, in dispatch_next
    if not self.dispatch_one_batch(self._original_iterator):
  File "/home/users/apopescu/anaconda3/envs/detectron2/lib/python3.8/site-packages/joblib/parallel.py", line 847, in dispatch_one_batch
    self._dispatch(tasks)
  File "/home/users/apopescu/anaconda3/envs/detectron2/lib/python3.8/site-packages/joblib/parallel.py", line 765, in _dispatch
    job = self._backend.apply_async(batch, callback=cb)
  File "/home/users/apopescu/anaconda3/envs/detectron2/lib/python3.8/site-packages/joblib/_parallel_backends.py", line 531, in apply_async
    future = self._workers.submit(SafeFunction(func))
  File "/home/users/apopescu/anaconda3/envs/detectron2/lib/python3.8/site-packages/joblib/externals/loky/reusable_executor.py", line 177, in submit
    return super(_ReusablePoolExecutor, self).submit(
  File "/home/users/apopescu/anaconda3/envs/detectron2/lib/python3.8/site-packages/joblib/externals/loky/process_executor.py", line 1102, in submit
    raise self._flags.broken
  File "/home/users/apopescu/anaconda3/envs/detectron2/lib/python3.8/site-packages/joblib/externals/loky/_base.py", line 625, in _invoke_callbacks
    callback(self)
  File "/home/users/apopescu/anaconda3/envs/detectron2/lib/python3.8/site-packages/joblib/parallel.py", line 347, in __call__
    self.parallel.dispatch_next()
  File "/home/users/apopescu/anaconda3/envs/detectron2/lib/python3.8/site-packages/joblib/parallel.py", line 780, in dispatch_next
    if not self.dispatch_one_batch(self._original_iterator):
  File "/home/users/apopescu/anaconda3/envs/detectron2/lib/python3.8/site-packages/joblib/parallel.py", line 847, in dispatch_one_batch
    self._dispatch(tasks)
  File "/home/users/apopescu/anaconda3/envs/detectron2/lib/python3.8/site-packages/joblib/parallel.py", line 765, in _dispatch
    job = self._backend.apply_async(batch, callback=cb)
  File "/home/users/apopescu/anaconda3/envs/detectron2/lib/python3.8/site-packages/joblib/_parallel_backends.py", line 531, in apply_async
    future = self._workers.submit(SafeFunction(func))
  File "/home/users/apopescu/anaconda3/envs/detectron2/lib/python3.8/site-packages/joblib/externals/loky/reusable_executor.py", line 177, in submit
    return super(_ReusablePoolExecutor, self).submit(
  File "/home/users/apopescu/anaconda3/envs/detectron2/lib/python3.8/site-packages/joblib/externals/loky/process_executor.py", line 1102, in submit
    raise self._flags.broken
  File "/home/users/apopescu/anaconda3/envs/detectron2/lib/python3.8/site-packages/joblib/externals/loky/_base.py", line 625, in _invoke_callbacks
    callback(self)
  File "/home/users/apopescu/anaconda3/envs/detectron2/lib/python3.8/site-packages/joblib/parallel.py", line 347, in __call__
    self.parallel.dispatch_next()
  File "/home/users/apopescu/anaconda3/envs/detectron2/lib/python3.8/site-packages/joblib/parallel.py", line 780, in dispatch_next
    if not self.dispatch_one_batch(self._original_iterator):
  File "/home/users/apopescu/anaconda3/envs/detectron2/lib/python3.8/site-packages/joblib/parallel.py", line 847, in dispatch_one_batch
    self._dispatch(tasks)
  File "/home/users/apopescu/anaconda3/envs/detectron2/lib/python3.8/site-packages/joblib/parallel.py", line 765, in _dispatch
    job = self._backend.apply_async(batch, callback=cb)
  File "/home/users/apopescu/anaconda3/envs/detectron2/lib/python3.8/site-packages/joblib/_parallel_backends.py", line 531, in apply_async
    future = self._workers.submit(SafeFunction(func))
  File "/home/users/apopescu/anaconda3/envs/detectron2/lib/python3.8/site-packages/joblib/externals/loky/reusable_executor.py", line 177, in submit
    return super(_ReusablePoolExecutor, self).submit(
  File "/home/users/apopescu/anaconda3/envs/detectron2/lib/python3.8/site-packages/joblib/externals/loky/process_executor.py", line 1102, in submit
    raise self._flags.broken
joblib.externals.loky.process_executor.TerminatedWorkerError: A worker process managed by the executor was unexpectedly terminated. This could be caused by a segmentation fault while calling the function or by an excessive memory usage causing the Operating System to kill the worker.

The exit codes of the workers are {SIGBUS(-7)}
  0%|          | 0/5 [01:41<?, ?it/s]
Traceback (most recent call last):
  File "ft_official.py", line 118, in <module>
    main()
  File "ft_official.py", line 100, in main
    model.train_vispel()
  File "/home/users/apopescu/van-khoa/Vis-Priva-Expos/privacy/vispel/vispel/vispel.py", line 54, in train_vispel
    trained_clusteror, trained_regressor, feature_selector = trainer(self.situation, self.X_train, self.X_community,\
  File "/home/users/apopescu/van-khoa/Vis-Priva-Expos/privacy/vispel/vispel/trainer.py", line 64, in trainer
    trained_regressor = train_regressor(regressor, X_train_rd, gt_train_expos, cfg)
  File "/home/users/apopescu/van-khoa/Vis-Priva-Expos/privacy/lib/regressor/regression.py", line 22, in train_regressor
    model.fit(x_train, y_train)
  File "/home/users/apopescu/anaconda3/envs/detectron2/lib/python3.8/site-packages/sklearn/utils/validation.py", line 73, in inner_f
    return f(**kwargs)
  File "/home/users/apopescu/anaconda3/envs/detectron2/lib/python3.8/site-packages/sklearn/model_selection/_search.py", line 736, in fit
    self._run_search(evaluate_candidates)
  File "/home/users/apopescu/anaconda3/envs/detectron2/lib/python3.8/site-packages/sklearn/model_selection/_search.py", line 1188, in _run_search
    evaluate_candidates(ParameterGrid(self.param_grid))
  File "/home/users/apopescu/anaconda3/envs/detectron2/lib/python3.8/site-packages/sklearn/model_selection/_search.py", line 708, in evaluate_candidates
    out = parallel(delayed(_fit_and_score)(clone(base_estimator),
  File "/home/users/apopescu/anaconda3/envs/detectron2/lib/python3.8/site-packages/joblib/parallel.py", line 1042, in __call__
    self.retrieve()
  File "/home/users/apopescu/anaconda3/envs/detectron2/lib/python3.8/site-packages/joblib/parallel.py", line 921, in retrieve
    self._output.extend(job.get(timeout=self.timeout))
  File "/home/users/apopescu/anaconda3/envs/detectron2/lib/python3.8/site-packages/joblib/_parallel_backends.py", line 542, in wrap_future_result
    return future.result(timeout=timeout)
  File "/home/users/apopescu/anaconda3/envs/detectron2/lib/python3.8/concurrent/futures/_base.py", line 439, in result
    return self.__get_result()
  File "/home/users/apopescu/anaconda3/envs/detectron2/lib/python3.8/concurrent/futures/_base.py", line 388, in __get_result
    raise self._exception
  File "/home/users/apopescu/anaconda3/envs/detectron2/lib/python3.8/site-packages/joblib/externals/loky/_base.py", line 625, in _invoke_callbacks
    callback(self)
  File "/home/users/apopescu/anaconda3/envs/detectron2/lib/python3.8/site-packages/joblib/parallel.py", line 347, in __call__
    self.parallel.dispatch_next()
  File "/home/users/apopescu/anaconda3/envs/detectron2/lib/python3.8/site-packages/joblib/parallel.py", line 780, in dispatch_next
    if not self.dispatch_one_batch(self._original_iterator):
  File "/home/users/apopescu/anaconda3/envs/detectron2/lib/python3.8/site-packages/joblib/parallel.py", line 847, in dispatch_one_batch
    self._dispatch(tasks)
  File "/home/users/apopescu/anaconda3/envs/detectron2/lib/python3.8/site-packages/joblib/parallel.py", line 765, in _dispatch
    job = self._backend.apply_async(batch, callback=cb)
  File "/home/users/apopescu/anaconda3/envs/detectron2/lib/python3.8/site-packages/joblib/_parallel_backends.py", line 531, in apply_async
    future = self._workers.submit(SafeFunction(func))
  File "/home/users/apopescu/anaconda3/envs/detectron2/lib/python3.8/site-packages/joblib/externals/loky/reusable_executor.py", line 177, in submit
    return super(_ReusablePoolExecutor, self).submit(
  File "/home/users/apopescu/anaconda3/envs/detectron2/lib/python3.8/site-packages/joblib/externals/loky/process_executor.py", line 1102, in submit
    raise self._flags.broken
  File "/home/users/apopescu/anaconda3/envs/detectron2/lib/python3.8/site-packages/joblib/externals/loky/_base.py", line 625, in _invoke_callbacks
    callback(self)
  File "/home/users/apopescu/anaconda3/envs/detectron2/lib/python3.8/site-packages/joblib/parallel.py", line 347, in __call__
    self.parallel.dispatch_next()
  File "/home/users/apopescu/anaconda3/envs/detectron2/lib/python3.8/site-packages/joblib/parallel.py", line 780, in dispatch_next
    if not self.dispatch_one_batch(self._original_iterator):
  File "/home/users/apopescu/anaconda3/envs/detectron2/lib/python3.8/site-packages/joblib/parallel.py", line 847, in dispatch_one_batch
    self._dispatch(tasks)
  File "/home/users/apopescu/anaconda3/envs/detectron2/lib/python3.8/site-packages/joblib/parallel.py", line 765, in _dispatch
    job = self._backend.apply_async(batch, callback=cb)
  File "/home/users/apopescu/anaconda3/envs/detectron2/lib/python3.8/site-packages/joblib/_parallel_backends.py", line 531, in apply_async
    future = self._workers.submit(SafeFunction(func))
  File "/home/users/apopescu/anaconda3/envs/detectron2/lib/python3.8/site-packages/joblib/externals/loky/reusable_executor.py", line 177, in submit
    return super(_ReusablePoolExecutor, self).submit(
  File "/home/users/apopescu/anaconda3/envs/detectron2/lib/python3.8/site-packages/joblib/externals/loky/process_executor.py", line 1102, in submit
    raise self._flags.broken
joblib.externals.loky.process_executor.TerminatedWorkerError: A worker process managed by the executor was unexpectedly terminated. This could be caused by a segmentation fault while calling the function or by an excessive memory usage causing the Operating System to kill the worker.

The exit codes of the workers are {SIGBUS(-7)}
  0%|          | 0/5 [01:41<?, ?it/s]
Traceback (most recent call last):
  File "ft_official.py", line 118, in <module>
    main()
  File "ft_official.py", line 100, in main
    model.train_vispel()
  File "/home/users/apopescu/van-khoa/Vis-Priva-Expos/privacy/vispel/vispel/vispel.py", line 54, in train_vispel
    trained_clusteror, trained_regressor, feature_selector = trainer(self.situation, self.X_train, self.X_community,\
  File "/home/users/apopescu/van-khoa/Vis-Priva-Expos/privacy/vispel/vispel/trainer.py", line 64, in trainer
    trained_regressor = train_regressor(regressor, X_train_rd, gt_train_expos, cfg)
  File "/home/users/apopescu/van-khoa/Vis-Priva-Expos/privacy/lib/regressor/regression.py", line 22, in train_regressor
    model.fit(x_train, y_train)
  File "/home/users/apopescu/anaconda3/envs/detectron2/lib/python3.8/site-packages/sklearn/utils/validation.py", line 73, in inner_f
    return f(**kwargs)
  File "/home/users/apopescu/anaconda3/envs/detectron2/lib/python3.8/site-packages/sklearn/model_selection/_search.py", line 736, in fit
    self._run_search(evaluate_candidates)
  File "/home/users/apopescu/anaconda3/envs/detectron2/lib/python3.8/site-packages/sklearn/model_selection/_search.py", line 1188, in _run_search
    evaluate_candidates(ParameterGrid(self.param_grid))
  File "/home/users/apopescu/anaconda3/envs/detectron2/lib/python3.8/site-packages/sklearn/model_selection/_search.py", line 708, in evaluate_candidates
    out = parallel(delayed(_fit_and_score)(clone(base_estimator),
  File "/home/users/apopescu/anaconda3/envs/detectron2/lib/python3.8/site-packages/joblib/parallel.py", line 1042, in __call__
    self.retrieve()
  File "/home/users/apopescu/anaconda3/envs/detectron2/lib/python3.8/site-packages/joblib/parallel.py", line 921, in retrieve
    self._output.extend(job.get(timeout=self.timeout))
  File "/home/users/apopescu/anaconda3/envs/detectron2/lib/python3.8/site-packages/joblib/_parallel_backends.py", line 542, in wrap_future_result
    return future.result(timeout=timeout)
  File "/home/users/apopescu/anaconda3/envs/detectron2/lib/python3.8/concurrent/futures/_base.py", line 439, in result
    return self.__get_result()
  File "/home/users/apopescu/anaconda3/envs/detectron2/lib/python3.8/concurrent/futures/_base.py", line 388, in __get_result
    raise self._exception
  File "/home/users/apopescu/anaconda3/envs/detectron2/lib/python3.8/site-packages/joblib/externals/loky/_base.py", line 625, in _invoke_callbacks
    callback(self)
  File "/home/users/apopescu/anaconda3/envs/detectron2/lib/python3.8/site-packages/joblib/parallel.py", line 347, in __call__
    self.parallel.dispatch_next()
  File "/home/users/apopescu/anaconda3/envs/detectron2/lib/python3.8/site-packages/joblib/parallel.py", line 780, in dispatch_next
    if not self.dispatch_one_batch(self._original_iterator):
  File "/home/users/apopescu/anaconda3/envs/detectron2/lib/python3.8/site-packages/joblib/parallel.py", line 847, in dispatch_one_batch
    self._dispatch(tasks)
  File "/home/users/apopescu/anaconda3/envs/detectron2/lib/python3.8/site-packages/joblib/parallel.py", line 765, in _dispatch
    job = self._backend.apply_async(batch, callback=cb)
  File "/home/users/apopescu/anaconda3/envs/detectron2/lib/python3.8/site-packages/joblib/_parallel_backends.py", line 531, in apply_async
    future = self._workers.submit(SafeFunction(func))
  File "/home/users/apopescu/anaconda3/envs/detectron2/lib/python3.8/site-packages/joblib/externals/loky/reusable_executor.py", line 177, in submit
    return super(_ReusablePoolExecutor, self).submit(
  File "/home/users/apopescu/anaconda3/envs/detectron2/lib/python3.8/site-packages/joblib/externals/loky/process_executor.py", line 1102, in submit
    raise self._flags.broken
  File "/home/users/apopescu/anaconda3/envs/detectron2/lib/python3.8/site-packages/joblib/externals/loky/_base.py", line 625, in _invoke_callbacks
    callback(self)
  File "/home/users/apopescu/anaconda3/envs/detectron2/lib/python3.8/site-packages/joblib/parallel.py", line 347, in __call__
    self.parallel.dispatch_next()
  File "/home/users/apopescu/anaconda3/envs/detectron2/lib/python3.8/site-packages/joblib/parallel.py", line 780, in dispatch_next
    if not self.dispatch_one_batch(self._original_iterator):
  File "/home/users/apopescu/anaconda3/envs/detectron2/lib/python3.8/site-packages/joblib/parallel.py", line 847, in dispatch_one_batch
    self._dispatch(tasks)
  File "/home/users/apopescu/anaconda3/envs/detectron2/lib/python3.8/site-packages/joblib/parallel.py", line 765, in _dispatch
    job = self._backend.apply_async(batch, callback=cb)
  File "/home/users/apopescu/anaconda3/envs/detectron2/lib/python3.8/site-packages/joblib/_parallel_backends.py", line 531, in apply_async
    future = self._workers.submit(SafeFunction(func))
  File "/home/users/apopescu/anaconda3/envs/detectron2/lib/python3.8/site-packages/joblib/externals/loky/reusable_executor.py", line 177, in submit
    return super(_ReusablePoolExecutor, self).submit(
  File "/home/users/apopescu/anaconda3/envs/detectron2/lib/python3.8/site-packages/joblib/externals/loky/process_executor.py", line 1102, in submit
    raise self._flags.broken
  File "/home/users/apopescu/anaconda3/envs/detectron2/lib/python3.8/site-packages/joblib/externals/loky/_base.py", line 625, in _invoke_callbacks
    callback(self)
  File "/home/users/apopescu/anaconda3/envs/detectron2/lib/python3.8/site-packages/joblib/parallel.py", line 347, in __call__
    self.parallel.dispatch_next()
  File "/home/users/apopescu/anaconda3/envs/detectron2/lib/python3.8/site-packages/joblib/parallel.py", line 780, in dispatch_next
    if not self.dispatch_one_batch(self._original_iterator):
  File "/home/users/apopescu/anaconda3/envs/detectron2/lib/python3.8/site-packages/joblib/parallel.py", line 847, in dispatch_one_batch
    self._dispatch(tasks)
  File "/home/users/apopescu/anaconda3/envs/detectron2/lib/python3.8/site-packages/joblib/parallel.py", line 765, in _dispatch
    job = self._backend.apply_async(batch, callback=cb)
  File "/home/users/apopescu/anaconda3/envs/detectron2/lib/python3.8/site-packages/joblib/_parallel_backends.py", line 531, in apply_async
    future = self._workers.submit(SafeFunction(func))
  File "/home/users/apopescu/anaconda3/envs/detectron2/lib/python3.8/site-packages/joblib/externals/loky/reusable_executor.py", line 177, in submit
    return super(_ReusablePoolExecutor, self).submit(
  File "/home/users/apopescu/anaconda3/envs/detectron2/lib/python3.8/site-packages/joblib/externals/loky/process_executor.py", line 1102, in submit
    raise self._flags.broken
  File "/home/users/apopescu/anaconda3/envs/detectron2/lib/python3.8/site-packages/joblib/externals/loky/_base.py", line 625, in _invoke_callbacks
    callback(self)
  File "/home/users/apopescu/anaconda3/envs/detectron2/lib/python3.8/site-packages/joblib/parallel.py", line 347, in __call__
    self.parallel.dispatch_next()
  File "/home/users/apopescu/anaconda3/envs/detectron2/lib/python3.8/site-packages/joblib/parallel.py", line 780, in dispatch_next
    if not self.dispatch_one_batch(self._original_iterator):
  File "/home/users/apopescu/anaconda3/envs/detectron2/lib/python3.8/site-packages/joblib/parallel.py", line 847, in dispatch_one_batch
    self._dispatch(tasks)
  File "/home/users/apopescu/anaconda3/envs/detectron2/lib/python3.8/site-packages/joblib/parallel.py", line 765, in _dispatch
    job = self._backend.apply_async(batch, callback=cb)
  File "/home/users/apopescu/anaconda3/envs/detectron2/lib/python3.8/site-packages/joblib/_parallel_backends.py", line 531, in apply_async
    future = self._workers.submit(SafeFunction(func))
  File "/home/users/apopescu/anaconda3/envs/detectron2/lib/python3.8/site-packages/joblib/externals/loky/reusable_executor.py", line 177, in submit
    return super(_ReusablePoolExecutor, self).submit(
  File "/home/users/apopescu/anaconda3/envs/detectron2/lib/python3.8/site-packages/joblib/externals/loky/process_executor.py", line 1102, in submit
    raise self._flags.broken
joblib.externals.loky.process_executor.TerminatedWorkerError: A worker process managed by the executor was unexpectedly terminated. This could be caused by a segmentation fault while calling the function or by an excessive memory usage causing the Operating System to kill the worker.

The exit codes of the workers are {SIGKILL(-9)}
