Config '../configs/rf_kmeans_ft_mobi_cv8.yaml' has no VERSION. Assuming it to be compatible with latest v1.
Config '../configs/rf_kmeans_ft_mobi_cv8.yaml' has no VERSION. Assuming it to be compatible with latest v1.
Config '../configs/rf_kmeans_ft_mobi_cv8.yaml' has no VERSION. Assuming it to be compatible with latest v1.
Config '../configs/rf_kmeans_ft_mobi_cv8.yaml' has no VERSION. Assuming it to be compatible with latest v1.
Config '../configs/rf_kmeans_ft_mobi_cv8.yaml' has no VERSION. Assuming it to be compatible with latest v1.
Config '../configs/rf_kmeans_ft_mobi_cv8.yaml' has no VERSION. Assuming it to be compatible with latest v1.
Config '../configs/rf_kmeans_ft_mobi_cv8.yaml' has no VERSION. Assuming it to be compatible with latest v1.
Config '../configs/rf_kmeans_ft_mobi_cv8.yaml' has no VERSION. Assuming it to be compatible with latest v1.
Config '../configs/rf_kmeans_ft_mobi_cv8.yaml' has no VERSION. Assuming it to be compatible with latest v1.
Config '../configs/rf_kmeans_ft_mobi_cv8.yaml' has no VERSION. Assuming it to be compatible with latest v1.
Config '../configs/rf_kmeans_ft_mobi_cv8.yaml' has no VERSION. Assuming it to be compatible with latest v1.
Config '../configs/rf_kmeans_ft_mobi_cv8.yaml' has no VERSION. Assuming it to be compatible with latest v1.
Config '../configs/rf_kmeans_ft_mobi_cv8.yaml' has no VERSION. Assuming it to be compatible with latest v1.
Config '../configs/rf_kmeans_ft_mobi_cv8.yaml' has no VERSION. Assuming it to be compatible with latest v1.
Config '../configs/rf_kmeans_ft_mobi_cv8.yaml' has no VERSION. Assuming it to be compatible with latest v1.
Config '../configs/rf_kmeans_ft_mobi_cv8.yaml' has no VERSION. Assuming it to be compatible with latest v1.
Config '../configs/rf_kmeans_ft_mobi_cv8.yaml' has no VERSION. Assuming it to be compatible with latest v1.
Config '../configs/rf_kmeans_ft_mobi_cv8.yaml' has no VERSION. Assuming it to be compatible with latest v1.
Config '../configs/rf_kmeans_ft_mobi_cv8.yaml' has no VERSION. Assuming it to be compatible with latest v1.
Config '../configs/rf_kmeans_ft_mobi_cv8.yaml' has no VERSION. Assuming it to be compatible with latest v1.
Config '../configs/rf_kmeans_ft_mobi_cv8.yaml' has no VERSION. Assuming it to be compatible with latest v1.
  0%|          | 0/5 [00:00<?, ?it/s]Config '../configs/rf_kmeans_ft_mobi_cv8.yaml' has no VERSION. Assuming it to be compatible with latest v1.
  0%|          | 0/5 [00:00<?, ?it/s]Config '../configs/rf_kmeans_ft_mobi_cv8.yaml' has no VERSION. Assuming it to be compatible with latest v1.
Config '../configs/rf_kmeans_ft_mobi_cv8.yaml' has no VERSION. Assuming it to be compatible with latest v1.
Config '../configs/rf_kmeans_ft_mobi_cv8.yaml' has no VERSION. Assuming it to be compatible with latest v1.
Config '../configs/rf_kmeans_ft_mobi_cv8.yaml' has no VERSION. Assuming it to be compatible with latest v1.
Config '../configs/rf_kmeans_ft_mobi_cv8.yaml' has no VERSION. Assuming it to be compatible with latest v1.
Config '../configs/rf_kmeans_ft_mobi_cv8.yaml' has no VERSION. Assuming it to be compatible with latest v1.
Config '../configs/rf_kmeans_ft_mobi_cv8.yaml' has no VERSION. Assuming it to be compatible with latest v1.
Config '../configs/rf_kmeans_ft_mobi_cv8.yaml' has no VERSION. Assuming it to be compatible with latest v1.
Config '../configs/rf_kmeans_ft_mobi_cv8.yaml' has no VERSION. Assuming it to be compatible with latest v1.
  0%|          | 0/5 [00:00<?, ?it/s]Config '../configs/rf_kmeans_ft_mobi_cv8.yaml' has no VERSION. Assuming it to be compatible with latest v1.
Config '../configs/rf_kmeans_ft_mobi_cv8.yaml' has no VERSION. Assuming it to be compatible with latest v1.
  0%|          | 0/5 [00:00<?, ?it/s]  0%|          | 0/5 [00:00<?, ?it/s]  0%|          | 0/5 [00:00<?, ?it/s]  0%|          | 0/5 [00:00<?, ?it/s]  0%|          | 0/5 [00:00<?, ?it/s]  0%|          | 0/5 [00:00<?, ?it/s]Config '../configs/rf_kmeans_ft_mobi_cv8.yaml' has no VERSION. Assuming it to be compatible with latest v1.
Config '../configs/rf_kmeans_ft_mobi_cv8.yaml' has no VERSION. Assuming it to be compatible with latest v1.
  0%|          | 0/5 [00:00<?, ?it/s]  0%|          | 0/5 [00:00<?, ?it/s]  0%|          | 0/5 [00:00<?, ?it/s]  0%|          | 0/5 [00:00<?, ?it/s]  0%|          | 0/5 [00:00<?, ?it/s]  0%|          | 0/5 [00:00<?, ?it/s]Config '../configs/rf_kmeans_ft_mobi_cv8.yaml' has no VERSION. Assuming it to be compatible with latest v1.
  0%|          | 0/5 [00:00<?, ?it/s]  0%|          | 0/5 [00:00<?, ?it/s]Config '../configs/rf_kmeans_ft_mobi_cv8.yaml' has no VERSION. Assuming it to be compatible with latest v1.
  0%|          | 0/5 [00:00<?, ?it/s]  0%|          | 0/5 [00:00<?, ?it/s]  0%|          | 0/5 [00:00<?, ?it/s]  0%|          | 0/5 [00:00<?, ?it/s]  0%|          | 0/5 [00:00<?, ?it/s]  0%|          | 0/5 [00:00<?, ?it/s]  0%|          | 0/5 [00:00<?, ?it/s]  0%|          | 0/5 [00:00<?, ?it/s]  0%|          | 0/5 [00:00<?, ?it/s]  0%|          | 0/5 [00:00<?, ?it/s]Config '../configs/rf_kmeans_ft_mobi_cv8.yaml' has no VERSION. Assuming it to be compatible with latest v1.
  0%|          | 0/5 [00:00<?, ?it/s]  0%|          | 0/5 [00:00<?, ?it/s]  0%|          | 0/5 [00:00<?, ?it/s]  0%|          | 0/5 [00:00<?, ?it/s]Config '../configs/rf_kmeans_ft_mobi_cv8.yaml' has no VERSION. Assuming it to be compatible with latest v1.
  0%|          | 0/5 [00:00<?, ?it/s]Config '../configs/rf_kmeans_ft_mobi_cv8.yaml' has no VERSION. Assuming it to be compatible with latest v1.
  0%|          | 0/5 [00:00<?, ?it/s]  0%|          | 0/5 [00:00<?, ?it/s]  0%|          | 0/5 [00:00<?, ?it/s]  0%|          | 0/5 [00:00<?, ?it/s]  0%|          | 0/5 [00:00<?, ?it/s]  0%|          | 0/5 [00:00<?, ?it/s]  0%|          | 0/5 [00:00<?, ?it/s]  0%|          | 0/5 [00:00<?, ?it/s]11 / 22191
11 / 17784
11 / 22191
11 / 17784
11 / 22191
11 / 17784
11 / 22191
11 / 17784
11 / 22191
11 / 17784
11 / 22191
11 / 17784
11 / 22191
11 / 17784
11 / 22191
11 / 17784
11 / 22191
11 / 17784
11 / 22191
11 / 17784
11 / 22191
11 / 17784
11 / 22191
11 / 17784
11 / 22191
11 / 17784
11 / 22191
11 / 17784
11 / 22191
11 / 17784
11 / 22191
11 / 17784
11 / 22191
11 / 17784
11 / 22191
11 / 17784
11 / 22191
11 / 17784
11 / 22191
11 / 17784
11 / 22191
11 / 17784
11 / 22191
11 / 17784
11 / 22191
11 / 17784
11 / 22191
11 / 17784
11 / 22191
11 / 17784
11 / 22191
11 / 17784
11 / 22191
11 / 17784
11 / 22191
11 / 17784
11 / 22191
11 / 17784
11 / 22191
11 / 17784
11 / 22191
11 / 17784
11 / 22191
11 / 17784
11 / 22191
11 / 17784
11 / 22191
11 / 17784
11 / 22191
11 / 17784
11 / 22191
11 / 17784
11 / 22191
11 / 17784
11 / 22191
11 / 17784
11 / 22191
11 / 17784
11 / 22191
11 / 17784
exception calling callback for <Future at 0x2b664a17f190 state=finished raised TerminatedWorkerError>
Traceback (most recent call last):
  File "/home/users/apopescu/anaconda3/envs/detectron2/lib/python3.8/site-packages/joblib/externals/loky/_base.py", line 625, in _invoke_callbacks
    callback(self)
  File "/home/users/apopescu/anaconda3/envs/detectron2/lib/python3.8/site-packages/joblib/parallel.py", line 347, in __call__
    self.parallel.dispatch_next()
  File "/home/users/apopescu/anaconda3/envs/detectron2/lib/python3.8/site-packages/joblib/parallel.py", line 780, in dispatch_next
    if not self.dispatch_one_batch(self._original_iterator):
  File "/home/users/apopescu/anaconda3/envs/detectron2/lib/python3.8/site-packages/joblib/parallel.py", line 847, in dispatch_one_batch
    self._dispatch(tasks)
  File "/home/users/apopescu/anaconda3/envs/detectron2/lib/python3.8/site-packages/joblib/parallel.py", line 765, in _dispatch
    job = self._backend.apply_async(batch, callback=cb)
  File "/home/users/apopescu/anaconda3/envs/detectron2/lib/python3.8/site-packages/joblib/_parallel_backends.py", line 531, in apply_async
    future = self._workers.submit(SafeFunction(func))
  File "/home/users/apopescu/anaconda3/envs/detectron2/lib/python3.8/site-packages/joblib/externals/loky/reusable_executor.py", line 177, in submit
    return super(_ReusablePoolExecutor, self).submit(
  File "/home/users/apopescu/anaconda3/envs/detectron2/lib/python3.8/site-packages/joblib/externals/loky/process_executor.py", line 1102, in submit
    raise self._flags.broken
joblib.externals.loky.process_executor.TerminatedWorkerError: A worker process managed by the executor was unexpectedly terminated. This could be caused by a segmentation fault while calling the function or by an excessive memory usage causing the Operating System to kill the worker.

The exit codes of the workers are {SIGBUS(-7)}
  0%|          | 0/5 [01:04<?, ?it/s]
  0%|          | 0/5 [01:05<?, ?it/s]
Traceback (most recent call last):
  File "ft_official.py", line 118, in <module>
    main()
  File "ft_official.py", line 100, in main
    model.train_vispel()
  File "/home/users/apopescu/van-khoa/Vis-Priva-Expos/privacy/vispel/vispel/vispel.py", line 54, in train_vispel
    trained_clusteror, trained_regressor, feature_selector = trainer(self.situation, self.X_train, self.X_community,\
  File "/home/users/apopescu/van-khoa/Vis-Priva-Expos/privacy/vispel/vispel/trainer.py", line 64, in trainer
    trained_regressor = train_regressor(regressor, X_train_rd, gt_train_expos, cfg)
  File "/home/users/apopescu/van-khoa/Vis-Priva-Expos/privacy/lib/regressor/regression.py", line 22, in train_regressor
    model.fit(x_train, y_train)
  File "/home/users/apopescu/anaconda3/envs/detectron2/lib/python3.8/site-packages/sklearn/utils/validation.py", line 73, in inner_f
    return f(**kwargs)
  File "/home/users/apopescu/anaconda3/envs/detectron2/lib/python3.8/site-packages/sklearn/model_selection/_search.py", line 736, in fit
    self._run_search(evaluate_candidates)
  File "/home/users/apopescu/anaconda3/envs/detectron2/lib/python3.8/site-packages/sklearn/model_selection/_search.py", line 1188, in _run_search
    evaluate_candidates(ParameterGrid(self.param_grid))
  File "/home/users/apopescu/anaconda3/envs/detectron2/lib/python3.8/site-packages/sklearn/model_selection/_search.py", line 708, in evaluate_candidates
    out = parallel(delayed(_fit_and_score)(clone(base_estimator),
  File "/home/users/apopescu/anaconda3/envs/detectron2/lib/python3.8/site-packages/joblib/parallel.py", line 1042, in __call__
    self.retrieve()
  File "/home/users/apopescu/anaconda3/envs/detectron2/lib/python3.8/site-packages/joblib/parallel.py", line 921, in retrieve
    self._output.extend(job.get(timeout=self.timeout))
  File "/home/users/apopescu/anaconda3/envs/detectron2/lib/python3.8/site-packages/joblib/_parallel_backends.py", line 542, in wrap_future_result
    return future.result(timeout=timeout)
  File "/home/users/apopescu/anaconda3/envs/detectron2/lib/python3.8/concurrent/futures/_base.py", line 439, in result
    return self.__get_result()
  File "/home/users/apopescu/anaconda3/envs/detectron2/lib/python3.8/concurrent/futures/_base.py", line 388, in __get_result
    raise self._exception
joblib.externals.loky.process_executor.TerminatedWorkerError: A worker process managed by the executor was unexpectedly terminated. This could be caused by a segmentation fault while calling the function or by an excessive memory usage causing the Operating System to kill the worker.

The exit codes of the workers are {SIGBUS(-7)}
Traceback (most recent call last):
  File "ft_official.py", line 118, in <module>
    main()
  File "ft_official.py", line 100, in main
    model.train_vispel()
  File "/home/users/apopescu/van-khoa/Vis-Priva-Expos/privacy/vispel/vispel/vispel.py", line 54, in train_vispel
    trained_clusteror, trained_regressor, feature_selector = trainer(self.situation, self.X_train, self.X_community,\
  File "/home/users/apopescu/van-khoa/Vis-Priva-Expos/privacy/vispel/vispel/trainer.py", line 64, in trainer
    trained_regressor = train_regressor(regressor, X_train_rd, gt_train_expos, cfg)
  File "/home/users/apopescu/van-khoa/Vis-Priva-Expos/privacy/lib/regressor/regression.py", line 22, in train_regressor
    model.fit(x_train, y_train)
  File "/home/users/apopescu/anaconda3/envs/detectron2/lib/python3.8/site-packages/sklearn/utils/validation.py", line 73, in inner_f
    return f(**kwargs)
  File "/home/users/apopescu/anaconda3/envs/detectron2/lib/python3.8/site-packages/sklearn/model_selection/_search.py", line 736, in fit
    self._run_search(evaluate_candidates)
  File "/home/users/apopescu/anaconda3/envs/detectron2/lib/python3.8/site-packages/sklearn/model_selection/_search.py", line 1188, in _run_search
    evaluate_candidates(ParameterGrid(self.param_grid))
  File "/home/users/apopescu/anaconda3/envs/detectron2/lib/python3.8/site-packages/sklearn/model_selection/_search.py", line 708, in evaluate_candidates
    out = parallel(delayed(_fit_and_score)(clone(base_estimator),
  File "/home/users/apopescu/anaconda3/envs/detectron2/lib/python3.8/site-packages/joblib/parallel.py", line 1042, in __call__
    self.retrieve()
  File "/home/users/apopescu/anaconda3/envs/detectron2/lib/python3.8/site-packages/joblib/parallel.py", line 921, in retrieve
    self._output.extend(job.get(timeout=self.timeout))
  File "/home/users/apopescu/anaconda3/envs/detectron2/lib/python3.8/site-packages/joblib/_parallel_backends.py", line 542, in wrap_future_result
    return future.result(timeout=timeout)
  File "/home/users/apopescu/anaconda3/envs/detectron2/lib/python3.8/concurrent/futures/_base.py", line 439, in result
    return self.__get_result()
  File "/home/users/apopescu/anaconda3/envs/detectron2/lib/python3.8/concurrent/futures/_base.py", line 388, in __get_result
    raise self._exception
joblib.externals.loky.process_executor.TerminatedWorkerError: A worker process managed by the executor was unexpectedly terminated. This could be caused by a segmentation fault while calling the function or by an excessive memory usage causing the Operating System to kill the worker.

The exit codes of the workers are {SIGBUS(-7)}
exception calling callback for <Future at 0x2b2cb53a5190 state=finished raised TerminatedWorkerError>
Traceback (most recent call last):
  File "/home/users/apopescu/anaconda3/envs/detectron2/lib/python3.8/site-packages/joblib/externals/loky/_base.py", line 625, in _invoke_callbacks
    callback(self)
  File "/home/users/apopescu/anaconda3/envs/detectron2/lib/python3.8/site-packages/joblib/parallel.py", line 347, in __call__
    self.parallel.dispatch_next()
  File "/home/users/apopescu/anaconda3/envs/detectron2/lib/python3.8/site-packages/joblib/parallel.py", line 780, in dispatch_next
    if not self.dispatch_one_batch(self._original_iterator):
  File "/home/users/apopescu/anaconda3/envs/detectron2/lib/python3.8/site-packages/joblib/parallel.py", line 847, in dispatch_one_batch
    self._dispatch(tasks)
  File "/home/users/apopescu/anaconda3/envs/detectron2/lib/python3.8/site-packages/joblib/parallel.py", line 765, in _dispatch
    job = self._backend.apply_async(batch, callback=cb)
  File "/home/users/apopescu/anaconda3/envs/detectron2/lib/python3.8/site-packages/joblib/_parallel_backends.py", line 531, in apply_async
    future = self._workers.submit(SafeFunction(func))
  File "/home/users/apopescu/anaconda3/envs/detectron2/lib/python3.8/site-packages/joblib/externals/loky/reusable_executor.py", line 177, in submit
    return super(_ReusablePoolExecutor, self).submit(
  File "/home/users/apopescu/anaconda3/envs/detectron2/lib/python3.8/site-packages/joblib/externals/loky/process_executor.py", line 1102, in submit
    raise self._flags.broken
joblib.externals.loky.process_executor.TerminatedWorkerError: A worker process managed by the executor was unexpectedly terminated. This could be caused by a segmentation fault while calling the function or by an excessive memory usage causing the Operating System to kill the worker.

The exit codes of the workers are {SIGBUS(-7)}
  0%|          | 0/5 [01:15<?, ?it/s]
/home/users/apopescu/anaconda3/envs/detectron2/lib/python3.8/site-packages/joblib/externals/loky/backend/resource_tracker.py:120: UserWarning: resource_tracker: process died unexpectedly, relaunching.  Some folders/sempahores might leak.
  warnings.warn('resource_tracker: process died unexpectedly, '
  0%|          | 0/5 [01:16<?, ?it/s]  0%|          | 0/5 [01:16<?, ?it/s]

  0%|          | 0/5 [01:16<?, ?it/s]
Traceback (most recent call last):
  File "ft_official.py", line 118, in <module>
    main()
  File "ft_official.py", line 100, in main
    model.train_vispel()
  File "/home/users/apopescu/van-khoa/Vis-Priva-Expos/privacy/vispel/vispel/vispel.py", line 54, in train_vispel
    trained_clusteror, trained_regressor, feature_selector = trainer(self.situation, self.X_train, self.X_community,\
  File "/home/users/apopescu/van-khoa/Vis-Priva-Expos/privacy/vispel/vispel/trainer.py", line 64, in trainer
    trained_regressor = train_regressor(regressor, X_train_rd, gt_train_expos, cfg)
  File "/home/users/apopescu/van-khoa/Vis-Priva-Expos/privacy/lib/regressor/regression.py", line 22, in train_regressor
    model.fit(x_train, y_train)
  File "/home/users/apopescu/anaconda3/envs/detectron2/lib/python3.8/site-packages/sklearn/utils/validation.py", line 73, in inner_f
    return f(**kwargs)
  File "/home/users/apopescu/anaconda3/envs/detectron2/lib/python3.8/site-packages/sklearn/model_selection/_search.py", line 736, in fit
    self._run_search(evaluate_candidates)
  File "/home/users/apopescu/anaconda3/envs/detectron2/lib/python3.8/site-packages/sklearn/model_selection/_search.py", line 1188, in _run_search
    evaluate_candidates(ParameterGrid(self.param_grid))
  File "/home/users/apopescu/anaconda3/envs/detectron2/lib/python3.8/site-packages/sklearn/model_selection/_search.py", line 708, in evaluate_candidates
    out = parallel(delayed(_fit_and_score)(clone(base_estimator),
  File "/home/users/apopescu/anaconda3/envs/detectron2/lib/python3.8/site-packages/joblib/parallel.py", line 1042, in __call__
    self.retrieve()
  File "/home/users/apopescu/anaconda3/envs/detectron2/lib/python3.8/site-packages/joblib/parallel.py", line 921, in retrieve
    self._output.extend(job.get(timeout=self.timeout))
  File "/home/users/apopescu/anaconda3/envs/detectron2/lib/python3.8/site-packages/joblib/_parallel_backends.py", line 542, in wrap_future_result
    return future.result(timeout=timeout)
  File "/home/users/apopescu/anaconda3/envs/detectron2/lib/python3.8/concurrent/futures/_base.py", line 439, in result
    return self.__get_result()
  File "/home/users/apopescu/anaconda3/envs/detectron2/lib/python3.8/concurrent/futures/_base.py", line 388, in __get_result
    raise self._exception
joblib.externals.loky.process_executor.TerminatedWorkerError: A worker process managed by the executor was unexpectedly terminated. This could be caused by a segmentation fault while calling the function or by an excessive memory usage causing the Operating System to kill the worker.

The exit codes of the workers are {SIGBUS(-7)}
Traceback (most recent call last):
  File "ft_official.py", line 118, in <module>
    main()
  File "ft_official.py", line 100, in main
    model.train_vispel()
  File "/home/users/apopescu/van-khoa/Vis-Priva-Expos/privacy/vispel/vispel/vispel.py", line 54, in train_vispel
    trained_clusteror, trained_regressor, feature_selector = trainer(self.situation, self.X_train, self.X_community,\
  File "/home/users/apopescu/van-khoa/Vis-Priva-Expos/privacy/vispel/vispel/trainer.py", line 64, in trainer
    trained_regressor = train_regressor(regressor, X_train_rd, gt_train_expos, cfg)
  File "/home/users/apopescu/van-khoa/Vis-Priva-Expos/privacy/lib/regressor/regression.py", line 22, in train_regressor
    model.fit(x_train, y_train)
  File "/home/users/apopescu/anaconda3/envs/detectron2/lib/python3.8/site-packages/sklearn/utils/validation.py", line 73, in inner_f
    return f(**kwargs)
  File "/home/users/apopescu/anaconda3/envs/detectron2/lib/python3.8/site-packages/sklearn/model_selection/_search.py", line 736, in fit
    self._run_search(evaluate_candidates)
  File "/home/users/apopescu/anaconda3/envs/detectron2/lib/python3.8/site-packages/sklearn/model_selection/_search.py", line 1188, in _run_search
    evaluate_candidates(ParameterGrid(self.param_grid))
  File "/home/users/apopescu/anaconda3/envs/detectron2/lib/python3.8/site-packages/sklearn/model_selection/_search.py", line 708, in evaluate_candidates
    out = parallel(delayed(_fit_and_score)(clone(base_estimator),
  File "/home/users/apopescu/anaconda3/envs/detectron2/lib/python3.8/site-packages/joblib/parallel.py", line 1042, in __call__
    self.retrieve()
  File "/home/users/apopescu/anaconda3/envs/detectron2/lib/python3.8/site-packages/joblib/parallel.py", line 921, in retrieve
    self._output.extend(job.get(timeout=self.timeout))
  File "/home/users/apopescu/anaconda3/envs/detectron2/lib/python3.8/site-packages/joblib/_parallel_backends.py", line 542, in wrap_future_result
    return future.result(timeout=timeout)
  File "/home/users/apopescu/anaconda3/envs/detectron2/lib/python3.8/concurrent/futures/_base.py", line 439, in result
    return self.__get_result()
  File "/home/users/apopescu/anaconda3/envs/detectron2/lib/python3.8/concurrent/futures/_base.py", line 388, in __get_result
    raise self._exception
  File "/home/users/apopescu/anaconda3/envs/detectron2/lib/python3.8/site-packages/joblib/externals/loky/_base.py", line 625, in _invoke_callbacks
    callback(self)
  File "/home/users/apopescu/anaconda3/envs/detectron2/lib/python3.8/site-packages/joblib/parallel.py", line 347, in __call__
    self.parallel.dispatch_next()
  File "/home/users/apopescu/anaconda3/envs/detectron2/lib/python3.8/site-packages/joblib/parallel.py", line 780, in dispatch_next
    if not self.dispatch_one_batch(self._original_iterator):
  File "/home/users/apopescu/anaconda3/envs/detectron2/lib/python3.8/site-packages/joblib/parallel.py", line 847, in dispatch_one_batch
    self._dispatch(tasks)
  File "/home/users/apopescu/anaconda3/envs/detectron2/lib/python3.8/site-packages/joblib/parallel.py", line 765, in _dispatch
    job = self._backend.apply_async(batch, callback=cb)
  File "/home/users/apopescu/anaconda3/envs/detectron2/lib/python3.8/site-packages/joblib/_parallel_backends.py", line 531, in apply_async
    future = self._workers.submit(SafeFunction(func))
  File "/home/users/apopescu/anaconda3/envs/detectron2/lib/python3.8/site-packages/joblib/externals/loky/reusable_executor.py", line 177, in submit
    return super(_ReusablePoolExecutor, self).submit(
  File "/home/users/apopescu/anaconda3/envs/detectron2/lib/python3.8/site-packages/joblib/externals/loky/process_executor.py", line 1102, in submit
    raise self._flags.broken
joblib.externals.loky.process_executor.TerminatedWorkerError: A worker process managed by the executor was unexpectedly terminated. This could be caused by a segmentation fault while calling the function or by an excessive memory usage causing the Operating System to kill the worker.

The exit codes of the workers are {SIGBUS(-7)}
Traceback (most recent call last):
  File "ft_official.py", line 118, in <module>
    main()
  File "ft_official.py", line 100, in main
    model.train_vispel()
  File "/home/users/apopescu/van-khoa/Vis-Priva-Expos/privacy/vispel/vispel/vispel.py", line 54, in train_vispel
    trained_clusteror, trained_regressor, feature_selector = trainer(self.situation, self.X_train, self.X_community,\
  File "/home/users/apopescu/van-khoa/Vis-Priva-Expos/privacy/vispel/vispel/trainer.py", line 64, in trainer
    trained_regressor = train_regressor(regressor, X_train_rd, gt_train_expos, cfg)
  File "/home/users/apopescu/van-khoa/Vis-Priva-Expos/privacy/lib/regressor/regression.py", line 22, in train_regressor
    model.fit(x_train, y_train)
  File "/home/users/apopescu/anaconda3/envs/detectron2/lib/python3.8/site-packages/sklearn/utils/validation.py", line 73, in inner_f
    return f(**kwargs)
  File "/home/users/apopescu/anaconda3/envs/detectron2/lib/python3.8/site-packages/sklearn/model_selection/_search.py", line 736, in fit
    self._run_search(evaluate_candidates)
  File "/home/users/apopescu/anaconda3/envs/detectron2/lib/python3.8/site-packages/sklearn/model_selection/_search.py", line 1188, in _run_search
    evaluate_candidates(ParameterGrid(self.param_grid))
  File "/home/users/apopescu/anaconda3/envs/detectron2/lib/python3.8/site-packages/sklearn/model_selection/_search.py", line 708, in evaluate_candidates
    out = parallel(delayed(_fit_and_score)(clone(base_estimator),
  File "/home/users/apopescu/anaconda3/envs/detectron2/lib/python3.8/site-packages/joblib/parallel.py", line 1042, in __call__
    self.retrieve()
  File "/home/users/apopescu/anaconda3/envs/detectron2/lib/python3.8/site-packages/joblib/parallel.py", line 921, in retrieve
    self._output.extend(job.get(timeout=self.timeout))
  File "/home/users/apopescu/anaconda3/envs/detectron2/lib/python3.8/site-packages/joblib/_parallel_backends.py", line 542, in wrap_future_result
    return future.result(timeout=timeout)
  File "/home/users/apopescu/anaconda3/envs/detectron2/lib/python3.8/concurrent/futures/_base.py", line 439, in result
    return self.__get_result()
  File "/home/users/apopescu/anaconda3/envs/detectron2/lib/python3.8/concurrent/futures/_base.py", line 388, in __get_result
    raise self._exception
joblib.externals.loky.process_executor.TerminatedWorkerError: A worker process managed by the executor was unexpectedly terminated. This could be caused by a segmentation fault while calling the function or by an excessive memory usage causing the Operating System to kill the worker.

The exit codes of the workers are {SIGBUS(-7)}
exception calling callback for <Future at 0x2b7612c3a190 state=finished raised TerminatedWorkerError>
Traceback (most recent call last):
  File "/home/users/apopescu/anaconda3/envs/detectron2/lib/python3.8/site-packages/joblib/externals/loky/_base.py", line 625, in _invoke_callbacks
    callback(self)
  File "/home/users/apopescu/anaconda3/envs/detectron2/lib/python3.8/site-packages/joblib/parallel.py", line 347, in __call__
    self.parallel.dispatch_next()
  File "/home/users/apopescu/anaconda3/envs/detectron2/lib/python3.8/site-packages/joblib/parallel.py", line 780, in dispatch_next
    if not self.dispatch_one_batch(self._original_iterator):
  File "/home/users/apopescu/anaconda3/envs/detectron2/lib/python3.8/site-packages/joblib/parallel.py", line 847, in dispatch_one_batch
    self._dispatch(tasks)
  File "/home/users/apopescu/anaconda3/envs/detectron2/lib/python3.8/site-packages/joblib/parallel.py", line 765, in _dispatch
    job = self._backend.apply_async(batch, callback=cb)
  File "/home/users/apopescu/anaconda3/envs/detectron2/lib/python3.8/site-packages/joblib/_parallel_backends.py", line 531, in apply_async
    future = self._workers.submit(SafeFunction(func))
  File "/home/users/apopescu/anaconda3/envs/detectron2/lib/python3.8/site-packages/joblib/externals/loky/reusable_executor.py", line 177, in submit
    return super(_ReusablePoolExecutor, self).submit(
  File "/home/users/apopescu/anaconda3/envs/detectron2/lib/python3.8/site-packages/joblib/externals/loky/process_executor.py", line 1102, in submit
    raise self._flags.broken
joblib.externals.loky.process_executor.TerminatedWorkerError: A worker process managed by the executor was unexpectedly terminated. This could be caused by a segmentation fault while calling the function or by an excessive memory usage causing the Operating System to kill the worker.

The exit codes of the workers are {SIGBUS(-7)}
Traceback (most recent call last):
  File "ft_official.py", line 118, in <module>
    main()
  File "ft_official.py", line 100, in main
    model.train_vispel()
  File "/home/users/apopescu/van-khoa/Vis-Priva-Expos/privacy/vispel/vispel/vispel.py", line 54, in train_vispel
    trained_clusteror, trained_regressor, feature_selector = trainer(self.situation, self.X_train, self.X_community,\
  File "/home/users/apopescu/van-khoa/Vis-Priva-Expos/privacy/vispel/vispel/trainer.py", line 64, in trainer
    trained_regressor = train_regressor(regressor, X_train_rd, gt_train_expos, cfg)
  File "/home/users/apopescu/van-khoa/Vis-Priva-Expos/privacy/lib/regressor/regression.py", line 22, in train_regressor
    model.fit(x_train, y_train)
  File "/home/users/apopescu/anaconda3/envs/detectron2/lib/python3.8/site-packages/sklearn/utils/validation.py", line 73, in inner_f
    return f(**kwargs)
  File "/home/users/apopescu/anaconda3/envs/detectron2/lib/python3.8/site-packages/sklearn/model_selection/_search.py", line 736, in fit
    self._run_search(evaluate_candidates)
  File "/home/users/apopescu/anaconda3/envs/detectron2/lib/python3.8/site-packages/sklearn/model_selection/_search.py", line 1188, in _run_search
    evaluate_candidates(ParameterGrid(self.param_grid))
  File "/home/users/apopescu/anaconda3/envs/detectron2/lib/python3.8/site-packages/sklearn/model_selection/_search.py", line 708, in evaluate_candidates
    out = parallel(delayed(_fit_and_score)(clone(base_estimator),
  File "/home/users/apopescu/anaconda3/envs/detectron2/lib/python3.8/site-packages/joblib/parallel.py", line 1042, in __call__
    self.retrieve()
  File "/home/users/apopescu/anaconda3/envs/detectron2/lib/python3.8/site-packages/joblib/parallel.py", line 921, in retrieve
    self._output.extend(job.get(timeout=self.timeout))
  File "/home/users/apopescu/anaconda3/envs/detectron2/lib/python3.8/site-packages/joblib/_parallel_backends.py", line 542, in wrap_future_result
    return future.result(timeout=timeout)
  File "/home/users/apopescu/anaconda3/envs/detectron2/lib/python3.8/concurrent/futures/_base.py", line 439, in result
    return self.__get_result()
  File "/home/users/apopescu/anaconda3/envs/detectron2/lib/python3.8/concurrent/futures/_base.py", line 388, in __get_result
    raise self._exception
  File "/home/users/apopescu/anaconda3/envs/detectron2/lib/python3.8/site-packages/joblib/externals/loky/_base.py", line 625, in _invoke_callbacks
    callback(self)
  File "/home/users/apopescu/anaconda3/envs/detectron2/lib/python3.8/site-packages/joblib/parallel.py", line 347, in __call__
    self.parallel.dispatch_next()
  File "/home/users/apopescu/anaconda3/envs/detectron2/lib/python3.8/site-packages/joblib/parallel.py", line 780, in dispatch_next
    if not self.dispatch_one_batch(self._original_iterator):
  File "/home/users/apopescu/anaconda3/envs/detectron2/lib/python3.8/site-packages/joblib/parallel.py", line 847, in dispatch_one_batch
    self._dispatch(tasks)
  File "/home/users/apopescu/anaconda3/envs/detectron2/lib/python3.8/site-packages/joblib/parallel.py", line 765, in _dispatch
    job = self._backend.apply_async(batch, callback=cb)
  File "/home/users/apopescu/anaconda3/envs/detectron2/lib/python3.8/site-packages/joblib/_parallel_backends.py", line 531, in apply_async
    future = self._workers.submit(SafeFunction(func))
  File "/home/users/apopescu/anaconda3/envs/detectron2/lib/python3.8/site-packages/joblib/externals/loky/reusable_executor.py", line 177, in submit
    return super(_ReusablePoolExecutor, self).submit(
  File "/home/users/apopescu/anaconda3/envs/detectron2/lib/python3.8/site-packages/joblib/externals/loky/process_executor.py", line 1102, in submit
    raise self._flags.broken
joblib.externals.loky.process_executor.TerminatedWorkerError: A worker process managed by the executor was unexpectedly terminated. This could be caused by a segmentation fault while calling the function or by an excessive memory usage causing the Operating System to kill the worker.

The exit codes of the workers are {SIGBUS(-7)}
  0%|          | 0/5 [01:24<?, ?it/s]
exception calling callback for <Future at 0x2b9b0ca7a190 state=finished raised TerminatedWorkerError>
Traceback (most recent call last):
  File "/home/users/apopescu/anaconda3/envs/detectron2/lib/python3.8/site-packages/joblib/externals/loky/_base.py", line 625, in _invoke_callbacks
    callback(self)
  File "/home/users/apopescu/anaconda3/envs/detectron2/lib/python3.8/site-packages/joblib/parallel.py", line 347, in __call__
    self.parallel.dispatch_next()
  File "/home/users/apopescu/anaconda3/envs/detectron2/lib/python3.8/site-packages/joblib/parallel.py", line 780, in dispatch_next
    if not self.dispatch_one_batch(self._original_iterator):
  File "/home/users/apopescu/anaconda3/envs/detectron2/lib/python3.8/site-packages/joblib/parallel.py", line 847, in dispatch_one_batch
    self._dispatch(tasks)
  File "/home/users/apopescu/anaconda3/envs/detectron2/lib/python3.8/site-packages/joblib/parallel.py", line 765, in _dispatch
    job = self._backend.apply_async(batch, callback=cb)
  File "/home/users/apopescu/anaconda3/envs/detectron2/lib/python3.8/site-packages/joblib/_parallel_backends.py", line 531, in apply_async
    future = self._workers.submit(SafeFunction(func))
  File "/home/users/apopescu/anaconda3/envs/detectron2/lib/python3.8/site-packages/joblib/externals/loky/reusable_executor.py", line 177, in submit
    return super(_ReusablePoolExecutor, self).submit(
  File "/home/users/apopescu/anaconda3/envs/detectron2/lib/python3.8/site-packages/joblib/externals/loky/process_executor.py", line 1102, in submit
    raise self._flags.broken
joblib.externals.loky.process_executor.TerminatedWorkerError: A worker process managed by the executor was unexpectedly terminated. This could be caused by a segmentation fault while calling the function or by an excessive memory usage causing the Operating System to kill the worker.

The exit codes of the workers are {SIGBUS(-7)}
exception calling callback for <Future at 0x2b9b0ca1a910 state=finished raised TerminatedWorkerError>
Traceback (most recent call last):
  File "/home/users/apopescu/anaconda3/envs/detectron2/lib/python3.8/site-packages/joblib/externals/loky/_base.py", line 625, in _invoke_callbacks
    callback(self)
  File "/home/users/apopescu/anaconda3/envs/detectron2/lib/python3.8/site-packages/joblib/parallel.py", line 347, in __call__
    self.parallel.dispatch_next()
  File "/home/users/apopescu/anaconda3/envs/detectron2/lib/python3.8/site-packages/joblib/parallel.py", line 780, in dispatch_next
    if not self.dispatch_one_batch(self._original_iterator):
  File "/home/users/apopescu/anaconda3/envs/detectron2/lib/python3.8/site-packages/joblib/parallel.py", line 847, in dispatch_one_batch
    self._dispatch(tasks)
  File "/home/users/apopescu/anaconda3/envs/detectron2/lib/python3.8/site-packages/joblib/parallel.py", line 765, in _dispatch
    job = self._backend.apply_async(batch, callback=cb)
  File "/home/users/apopescu/anaconda3/envs/detectron2/lib/python3.8/site-packages/joblib/_parallel_backends.py", line 531, in apply_async
    future = self._workers.submit(SafeFunction(func))
  File "/home/users/apopescu/anaconda3/envs/detectron2/lib/python3.8/site-packages/joblib/externals/loky/reusable_executor.py", line 177, in submit
    return super(_ReusablePoolExecutor, self).submit(
  File "/home/users/apopescu/anaconda3/envs/detectron2/lib/python3.8/site-packages/joblib/externals/loky/process_executor.py", line 1102, in submit
    raise self._flags.broken
  File "/home/users/apopescu/anaconda3/envs/detectron2/lib/python3.8/site-packages/joblib/externals/loky/_base.py", line 625, in _invoke_callbacks
    callback(self)
  File "/home/users/apopescu/anaconda3/envs/detectron2/lib/python3.8/site-packages/joblib/parallel.py", line 347, in __call__
    self.parallel.dispatch_next()
  File "/home/users/apopescu/anaconda3/envs/detectron2/lib/python3.8/site-packages/joblib/parallel.py", line 780, in dispatch_next
    if not self.dispatch_one_batch(self._original_iterator):
  File "/home/users/apopescu/anaconda3/envs/detectron2/lib/python3.8/site-packages/joblib/parallel.py", line 847, in dispatch_one_batch
    self._dispatch(tasks)
  File "/home/users/apopescu/anaconda3/envs/detectron2/lib/python3.8/site-packages/joblib/parallel.py", line 765, in _dispatch
    job = self._backend.apply_async(batch, callback=cb)
  File "/home/users/apopescu/anaconda3/envs/detectron2/lib/python3.8/site-packages/joblib/_parallel_backends.py", line 531, in apply_async
    future = self._workers.submit(SafeFunction(func))
  File "/home/users/apopescu/anaconda3/envs/detectron2/lib/python3.8/site-packages/joblib/externals/loky/reusable_executor.py", line 177, in submit
    return super(_ReusablePoolExecutor, self).submit(
  File "/home/users/apopescu/anaconda3/envs/detectron2/lib/python3.8/site-packages/joblib/externals/loky/process_executor.py", line 1102, in submit
    raise self._flags.broken
joblib.externals.loky.process_executor.TerminatedWorkerError: A worker process managed by the executor was unexpectedly terminated. This could be caused by a segmentation fault while calling the function or by an excessive memory usage causing the Operating System to kill the worker.

The exit codes of the workers are {SIGBUS(-7)}
exception calling callback for <Future at 0x2b9b0ca1ad60 state=finished raised TerminatedWorkerError>
Traceback (most recent call last):
  File "/home/users/apopescu/anaconda3/envs/detectron2/lib/python3.8/site-packages/joblib/externals/loky/_base.py", line 625, in _invoke_callbacks
    callback(self)
  File "/home/users/apopescu/anaconda3/envs/detectron2/lib/python3.8/site-packages/joblib/parallel.py", line 347, in __call__
    self.parallel.dispatch_next()
  File "/home/users/apopescu/anaconda3/envs/detectron2/lib/python3.8/site-packages/joblib/parallel.py", line 780, in dispatch_next
    if not self.dispatch_one_batch(self._original_iterator):
  File "/home/users/apopescu/anaconda3/envs/detectron2/lib/python3.8/site-packages/joblib/parallel.py", line 847, in dispatch_one_batch
    self._dispatch(tasks)
  File "/home/users/apopescu/anaconda3/envs/detectron2/lib/python3.8/site-packages/joblib/parallel.py", line 765, in _dispatch
    job = self._backend.apply_async(batch, callback=cb)
  File "/home/users/apopescu/anaconda3/envs/detectron2/lib/python3.8/site-packages/joblib/_parallel_backends.py", line 531, in apply_async
    future = self._workers.submit(SafeFunction(func))
  File "/home/users/apopescu/anaconda3/envs/detectron2/lib/python3.8/site-packages/joblib/externals/loky/reusable_executor.py", line 177, in submit
    return super(_ReusablePoolExecutor, self).submit(
  File "/home/users/apopescu/anaconda3/envs/detectron2/lib/python3.8/site-packages/joblib/externals/loky/process_executor.py", line 1102, in submit
    raise self._flags.broken
  File "/home/users/apopescu/anaconda3/envs/detectron2/lib/python3.8/site-packages/joblib/externals/loky/_base.py", line 625, in _invoke_callbacks
    callback(self)
  File "/home/users/apopescu/anaconda3/envs/detectron2/lib/python3.8/site-packages/joblib/parallel.py", line 347, in __call__
    self.parallel.dispatch_next()
  File "/home/users/apopescu/anaconda3/envs/detectron2/lib/python3.8/site-packages/joblib/parallel.py", line 780, in dispatch_next
    if not self.dispatch_one_batch(self._original_iterator):
  File "/home/users/apopescu/anaconda3/envs/detectron2/lib/python3.8/site-packages/joblib/parallel.py", line 847, in dispatch_one_batch
    self._dispatch(tasks)
  File "/home/users/apopescu/anaconda3/envs/detectron2/lib/python3.8/site-packages/joblib/parallel.py", line 765, in _dispatch
    job = self._backend.apply_async(batch, callback=cb)
  File "/home/users/apopescu/anaconda3/envs/detectron2/lib/python3.8/site-packages/joblib/_parallel_backends.py", line 531, in apply_async
    future = self._workers.submit(SafeFunction(func))
  File "/home/users/apopescu/anaconda3/envs/detectron2/lib/python3.8/site-packages/joblib/externals/loky/reusable_executor.py", line 177, in submit
    return super(_ReusablePoolExecutor, self).submit(
  File "/home/users/apopescu/anaconda3/envs/detectron2/lib/python3.8/site-packages/joblib/externals/loky/process_executor.py", line 1102, in submit
    raise self._flags.broken
  File "/home/users/apopescu/anaconda3/envs/detectron2/lib/python3.8/site-packages/joblib/externals/loky/_base.py", line 625, in _invoke_callbacks
    callback(self)
  File "/home/users/apopescu/anaconda3/envs/detectron2/lib/python3.8/site-packages/joblib/parallel.py", line 347, in __call__
    self.parallel.dispatch_next()
  File "/home/users/apopescu/anaconda3/envs/detectron2/lib/python3.8/site-packages/joblib/parallel.py", line 780, in dispatch_next
    if not self.dispatch_one_batch(self._original_iterator):
  File "/home/users/apopescu/anaconda3/envs/detectron2/lib/python3.8/site-packages/joblib/parallel.py", line 847, in dispatch_one_batch
    self._dispatch(tasks)
  File "/home/users/apopescu/anaconda3/envs/detectron2/lib/python3.8/site-packages/joblib/parallel.py", line 765, in _dispatch
    job = self._backend.apply_async(batch, callback=cb)
  File "/home/users/apopescu/anaconda3/envs/detectron2/lib/python3.8/site-packages/joblib/_parallel_backends.py", line 531, in apply_async
    future = self._workers.submit(SafeFunction(func))
  File "/home/users/apopescu/anaconda3/envs/detectron2/lib/python3.8/site-packages/joblib/externals/loky/reusable_executor.py", line 177, in submit
    return super(_ReusablePoolExecutor, self).submit(
  File "/home/users/apopescu/anaconda3/envs/detectron2/lib/python3.8/site-packages/joblib/externals/loky/process_executor.py", line 1102, in submit
    raise self._flags.broken
joblib.externals.loky.process_executor.TerminatedWorkerError: A worker process managed by the executor was unexpectedly terminated. This could be caused by a segmentation fault while calling the function or by an excessive memory usage causing the Operating System to kill the worker.

The exit codes of the workers are {SIGBUS(-7)}
exception calling callback for <Future at 0x2b9b0ca1ae80 state=finished raised TerminatedWorkerError>
Traceback (most recent call last):
  File "/home/users/apopescu/anaconda3/envs/detectron2/lib/python3.8/site-packages/joblib/externals/loky/_base.py", line 625, in _invoke_callbacks
    callback(self)
  File "/home/users/apopescu/anaconda3/envs/detectron2/lib/python3.8/site-packages/joblib/parallel.py", line 347, in __call__
    self.parallel.dispatch_next()
  File "/home/users/apopescu/anaconda3/envs/detectron2/lib/python3.8/site-packages/joblib/parallel.py", line 780, in dispatch_next
    if not self.dispatch_one_batch(self._original_iterator):
  File "/home/users/apopescu/anaconda3/envs/detectron2/lib/python3.8/site-packages/joblib/parallel.py", line 847, in dispatch_one_batch
    self._dispatch(tasks)
  File "/home/users/apopescu/anaconda3/envs/detectron2/lib/python3.8/site-packages/joblib/parallel.py", line 765, in _dispatch
    job = self._backend.apply_async(batch, callback=cb)
  File "/home/users/apopescu/anaconda3/envs/detectron2/lib/python3.8/site-packages/joblib/_parallel_backends.py", line 531, in apply_async
    future = self._workers.submit(SafeFunction(func))
  File "/home/users/apopescu/anaconda3/envs/detectron2/lib/python3.8/site-packages/joblib/externals/loky/reusable_executor.py", line 177, in submit
    return super(_ReusablePoolExecutor, self).submit(
  File "/home/users/apopescu/anaconda3/envs/detectron2/lib/python3.8/site-packages/joblib/externals/loky/process_executor.py", line 1102, in submit
    raise self._flags.broken
  File "/home/users/apopescu/anaconda3/envs/detectron2/lib/python3.8/site-packages/joblib/externals/loky/_base.py", line 625, in _invoke_callbacks
    callback(self)
  File "/home/users/apopescu/anaconda3/envs/detectron2/lib/python3.8/site-packages/joblib/parallel.py", line 347, in __call__
    self.parallel.dispatch_next()
  File "/home/users/apopescu/anaconda3/envs/detectron2/lib/python3.8/site-packages/joblib/parallel.py", line 780, in dispatch_next
    if not self.dispatch_one_batch(self._original_iterator):
  File "/home/users/apopescu/anaconda3/envs/detectron2/lib/python3.8/site-packages/joblib/parallel.py", line 847, in dispatch_one_batch
    self._dispatch(tasks)
  File "/home/users/apopescu/anaconda3/envs/detectron2/lib/python3.8/site-packages/joblib/parallel.py", line 765, in _dispatch
    job = self._backend.apply_async(batch, callback=cb)
  File "/home/users/apopescu/anaconda3/envs/detectron2/lib/python3.8/site-packages/joblib/_parallel_backends.py", line 531, in apply_async
    future = self._workers.submit(SafeFunction(func))
  File "/home/users/apopescu/anaconda3/envs/detectron2/lib/python3.8/site-packages/joblib/externals/loky/reusable_executor.py", line 177, in submit
    return super(_ReusablePoolExecutor, self).submit(
  File "/home/users/apopescu/anaconda3/envs/detectron2/lib/python3.8/site-packages/joblib/externals/loky/process_executor.py", line 1102, in submit
    raise self._flags.broken
  File "/home/users/apopescu/anaconda3/envs/detectron2/lib/python3.8/site-packages/joblib/externals/loky/_base.py", line 625, in _invoke_callbacks
    callback(self)
  File "/home/users/apopescu/anaconda3/envs/detectron2/lib/python3.8/site-packages/joblib/parallel.py", line 347, in __call__
    self.parallel.dispatch_next()
  File "/home/users/apopescu/anaconda3/envs/detectron2/lib/python3.8/site-packages/joblib/parallel.py", line 780, in dispatch_next
    if not self.dispatch_one_batch(self._original_iterator):
  File "/home/users/apopescu/anaconda3/envs/detectron2/lib/python3.8/site-packages/joblib/parallel.py", line 847, in dispatch_one_batch
    self._dispatch(tasks)
  File "/home/users/apopescu/anaconda3/envs/detectron2/lib/python3.8/site-packages/joblib/parallel.py", line 765, in _dispatch
    job = self._backend.apply_async(batch, callback=cb)
  File "/home/users/apopescu/anaconda3/envs/detectron2/lib/python3.8/site-packages/joblib/_parallel_backends.py", line 531, in apply_async
    future = self._workers.submit(SafeFunction(func))
  File "/home/users/apopescu/anaconda3/envs/detectron2/lib/python3.8/site-packages/joblib/externals/loky/reusable_executor.py", line 177, in submit
    return super(_ReusablePoolExecutor, self).submit(
  File "/home/users/apopescu/anaconda3/envs/detectron2/lib/python3.8/site-packages/joblib/externals/loky/process_executor.py", line 1102, in submit
    raise self._flags.broken
  File "/home/users/apopescu/anaconda3/envs/detectron2/lib/python3.8/site-packages/joblib/externals/loky/_base.py", line 625, in _invoke_callbacks
    callback(self)
  File "/home/users/apopescu/anaconda3/envs/detectron2/lib/python3.8/site-packages/joblib/parallel.py", line 347, in __call__
    self.parallel.dispatch_next()
  File "/home/users/apopescu/anaconda3/envs/detectron2/lib/python3.8/site-packages/joblib/parallel.py", line 780, in dispatch_next
    if not self.dispatch_one_batch(self._original_iterator):
  File "/home/users/apopescu/anaconda3/envs/detectron2/lib/python3.8/site-packages/joblib/parallel.py", line 847, in dispatch_one_batch
    self._dispatch(tasks)
  File "/home/users/apopescu/anaconda3/envs/detectron2/lib/python3.8/site-packages/joblib/parallel.py", line 765, in _dispatch
    job = self._backend.apply_async(batch, callback=cb)
  File "/home/users/apopescu/anaconda3/envs/detectron2/lib/python3.8/site-packages/joblib/_parallel_backends.py", line 531, in apply_async
    future = self._workers.submit(SafeFunction(func))
  File "/home/users/apopescu/anaconda3/envs/detectron2/lib/python3.8/site-packages/joblib/externals/loky/reusable_executor.py", line 177, in submit
    return super(_ReusablePoolExecutor, self).submit(
  File "/home/users/apopescu/anaconda3/envs/detectron2/lib/python3.8/site-packages/joblib/externals/loky/process_executor.py", line 1102, in submit
    raise self._flags.broken
joblib.externals.loky.process_executor.TerminatedWorkerError: A worker process managed by the executor was unexpectedly terminated. This could be caused by a segmentation fault while calling the function or by an excessive memory usage causing the Operating System to kill the worker.

The exit codes of the workers are {SIGBUS(-7)}
/home/users/apopescu/anaconda3/envs/detectron2/lib/python3.8/site-packages/joblib/externals/loky/backend/resource_tracker.py:120: UserWarning: resource_tracker: process died unexpectedly, relaunching.  Some folders/sempahores might leak.
  warnings.warn('resource_tracker: process died unexpectedly, '
  0%|          | 0/5 [01:24<?, ?it/s]
Traceback (most recent call last):
  File "ft_official.py", line 118, in <module>
    main()
  File "ft_official.py", line 100, in main
    model.train_vispel()
  File "/home/users/apopescu/van-khoa/Vis-Priva-Expos/privacy/vispel/vispel/vispel.py", line 54, in train_vispel
    trained_clusteror, trained_regressor, feature_selector = trainer(self.situation, self.X_train, self.X_community,\
  File "/home/users/apopescu/van-khoa/Vis-Priva-Expos/privacy/vispel/vispel/trainer.py", line 64, in trainer
    trained_regressor = train_regressor(regressor, X_train_rd, gt_train_expos, cfg)
  File "/home/users/apopescu/van-khoa/Vis-Priva-Expos/privacy/lib/regressor/regression.py", line 22, in train_regressor
    model.fit(x_train, y_train)
  File "/home/users/apopescu/anaconda3/envs/detectron2/lib/python3.8/site-packages/sklearn/utils/validation.py", line 73, in inner_f
    return f(**kwargs)
  File "/home/users/apopescu/anaconda3/envs/detectron2/lib/python3.8/site-packages/sklearn/model_selection/_search.py", line 736, in fit
    self._run_search(evaluate_candidates)
  File "/home/users/apopescu/anaconda3/envs/detectron2/lib/python3.8/site-packages/sklearn/model_selection/_search.py", line 1188, in _run_search
    evaluate_candidates(ParameterGrid(self.param_grid))
  File "/home/users/apopescu/anaconda3/envs/detectron2/lib/python3.8/site-packages/sklearn/model_selection/_search.py", line 708, in evaluate_candidates
    out = parallel(delayed(_fit_and_score)(clone(base_estimator),
  File "/home/users/apopescu/anaconda3/envs/detectron2/lib/python3.8/site-packages/joblib/parallel.py", line 1042, in __call__
    self.retrieve()
  File "/home/users/apopescu/anaconda3/envs/detectron2/lib/python3.8/site-packages/joblib/parallel.py", line 921, in retrieve
    self._output.extend(job.get(timeout=self.timeout))
  File "/home/users/apopescu/anaconda3/envs/detectron2/lib/python3.8/site-packages/joblib/_parallel_backends.py", line 542, in wrap_future_result
    return future.result(timeout=timeout)
  File "/home/users/apopescu/anaconda3/envs/detectron2/lib/python3.8/concurrent/futures/_base.py", line 439, in result
    return self.__get_result()
  File "/home/users/apopescu/anaconda3/envs/detectron2/lib/python3.8/concurrent/futures/_base.py", line 388, in __get_result
    raise self._exception
joblib.externals.loky.process_executor.TerminatedWorkerError: A worker process managed by the executor was unexpectedly terminated. This could be caused by a segmentation fault while calling the function or by an excessive memory usage causing the Operating System to kill the worker.

The exit codes of the workers are {SIGBUS(-7)}
Traceback (most recent call last):
  File "ft_official.py", line 118, in <module>
    main()
  File "ft_official.py", line 100, in main
    model.train_vispel()
  File "/home/users/apopescu/van-khoa/Vis-Priva-Expos/privacy/vispel/vispel/vispel.py", line 54, in train_vispel
    trained_clusteror, trained_regressor, feature_selector = trainer(self.situation, self.X_train, self.X_community,\
  File "/home/users/apopescu/van-khoa/Vis-Priva-Expos/privacy/vispel/vispel/trainer.py", line 64, in trainer
    trained_regressor = train_regressor(regressor, X_train_rd, gt_train_expos, cfg)
  File "/home/users/apopescu/van-khoa/Vis-Priva-Expos/privacy/lib/regressor/regression.py", line 22, in train_regressor
    model.fit(x_train, y_train)
  File "/home/users/apopescu/anaconda3/envs/detectron2/lib/python3.8/site-packages/sklearn/utils/validation.py", line 73, in inner_f
    return f(**kwargs)
  File "/home/users/apopescu/anaconda3/envs/detectron2/lib/python3.8/site-packages/sklearn/model_selection/_search.py", line 736, in fit
    self._run_search(evaluate_candidates)
  File "/home/users/apopescu/anaconda3/envs/detectron2/lib/python3.8/site-packages/sklearn/model_selection/_search.py", line 1188, in _run_search
    evaluate_candidates(ParameterGrid(self.param_grid))
  File "/home/users/apopescu/anaconda3/envs/detectron2/lib/python3.8/site-packages/sklearn/model_selection/_search.py", line 708, in evaluate_candidates
    out = parallel(delayed(_fit_and_score)(clone(base_estimator),
  File "/home/users/apopescu/anaconda3/envs/detectron2/lib/python3.8/site-packages/joblib/parallel.py", line 1042, in __call__
    self.retrieve()
  File "/home/users/apopescu/anaconda3/envs/detectron2/lib/python3.8/site-packages/joblib/parallel.py", line 921, in retrieve
    self._output.extend(job.get(timeout=self.timeout))
  File "/home/users/apopescu/anaconda3/envs/detectron2/lib/python3.8/site-packages/joblib/_parallel_backends.py", line 542, in wrap_future_result
    return future.result(timeout=timeout)
  File "/home/users/apopescu/anaconda3/envs/detectron2/lib/python3.8/concurrent/futures/_base.py", line 439, in result
    return self.__get_result()
  File "/home/users/apopescu/anaconda3/envs/detectron2/lib/python3.8/concurrent/futures/_base.py", line 388, in __get_result
    raise self._exception
  File "/home/users/apopescu/anaconda3/envs/detectron2/lib/python3.8/site-packages/joblib/externals/loky/_base.py", line 625, in _invoke_callbacks
    callback(self)
  File "/home/users/apopescu/anaconda3/envs/detectron2/lib/python3.8/site-packages/joblib/parallel.py", line 347, in __call__
    self.parallel.dispatch_next()
  File "/home/users/apopescu/anaconda3/envs/detectron2/lib/python3.8/site-packages/joblib/parallel.py", line 780, in dispatch_next
    if not self.dispatch_one_batch(self._original_iterator):
  File "/home/users/apopescu/anaconda3/envs/detectron2/lib/python3.8/site-packages/joblib/parallel.py", line 847, in dispatch_one_batch
    self._dispatch(tasks)
  File "/home/users/apopescu/anaconda3/envs/detectron2/lib/python3.8/site-packages/joblib/parallel.py", line 765, in _dispatch
    job = self._backend.apply_async(batch, callback=cb)
  File "/home/users/apopescu/anaconda3/envs/detectron2/lib/python3.8/site-packages/joblib/_parallel_backends.py", line 531, in apply_async
    future = self._workers.submit(SafeFunction(func))
  File "/home/users/apopescu/anaconda3/envs/detectron2/lib/python3.8/site-packages/joblib/externals/loky/reusable_executor.py", line 177, in submit
    return super(_ReusablePoolExecutor, self).submit(
  File "/home/users/apopescu/anaconda3/envs/detectron2/lib/python3.8/site-packages/joblib/externals/loky/process_executor.py", line 1102, in submit
    raise self._flags.broken
joblib.externals.loky.process_executor.TerminatedWorkerError: A worker process managed by the executor was unexpectedly terminated. This could be caused by a segmentation fault while calling the function or by an excessive memory usage causing the Operating System to kill the worker.

The exit codes of the workers are {SIGBUS(-7)}
/home/users/apopescu/anaconda3/envs/detectron2/lib/python3.8/site-packages/joblib/externals/loky/backend/resource_tracker.py:120: UserWarning: resource_tracker: process died unexpectedly, relaunching.  Some folders/sempahores might leak.
  warnings.warn('resource_tracker: process died unexpectedly, '
  0%|          | 0/5 [01:26<?, ?it/s]
Traceback (most recent call last):
  File "ft_official.py", line 118, in <module>
    main()
  File "ft_official.py", line 100, in main
    model.train_vispel()
  File "/home/users/apopescu/van-khoa/Vis-Priva-Expos/privacy/vispel/vispel/vispel.py", line 54, in train_vispel
    trained_clusteror, trained_regressor, feature_selector = trainer(self.situation, self.X_train, self.X_community,\
  File "/home/users/apopescu/van-khoa/Vis-Priva-Expos/privacy/vispel/vispel/trainer.py", line 64, in trainer
    trained_regressor = train_regressor(regressor, X_train_rd, gt_train_expos, cfg)
  File "/home/users/apopescu/van-khoa/Vis-Priva-Expos/privacy/lib/regressor/regression.py", line 22, in train_regressor
    model.fit(x_train, y_train)
  File "/home/users/apopescu/anaconda3/envs/detectron2/lib/python3.8/site-packages/sklearn/utils/validation.py", line 73, in inner_f
    return f(**kwargs)
  File "/home/users/apopescu/anaconda3/envs/detectron2/lib/python3.8/site-packages/sklearn/model_selection/_search.py", line 736, in fit
    self._run_search(evaluate_candidates)
  File "/home/users/apopescu/anaconda3/envs/detectron2/lib/python3.8/site-packages/sklearn/model_selection/_search.py", line 1188, in _run_search
    evaluate_candidates(ParameterGrid(self.param_grid))
  File "/home/users/apopescu/anaconda3/envs/detectron2/lib/python3.8/site-packages/sklearn/model_selection/_search.py", line 708, in evaluate_candidates
    out = parallel(delayed(_fit_and_score)(clone(base_estimator),
  File "/home/users/apopescu/anaconda3/envs/detectron2/lib/python3.8/site-packages/joblib/parallel.py", line 1042, in __call__
    self.retrieve()
  File "/home/users/apopescu/anaconda3/envs/detectron2/lib/python3.8/site-packages/joblib/parallel.py", line 921, in retrieve
    self._output.extend(job.get(timeout=self.timeout))
  File "/home/users/apopescu/anaconda3/envs/detectron2/lib/python3.8/site-packages/joblib/_parallel_backends.py", line 542, in wrap_future_result
    return future.result(timeout=timeout)
  File "/home/users/apopescu/anaconda3/envs/detectron2/lib/python3.8/concurrent/futures/_base.py", line 439, in result
    return self.__get_result()
  File "/home/users/apopescu/anaconda3/envs/detectron2/lib/python3.8/concurrent/futures/_base.py", line 388, in __get_result
    raise self._exception
joblib.externals.loky.process_executor.TerminatedWorkerError: A worker process managed by the executor was unexpectedly terminated. This could be caused by a segmentation fault while calling the function or by an excessive memory usage causing the Operating System to kill the worker.

The exit codes of the workers are {SIGBUS(-7)}
  0%|          | 0/5 [01:26<?, ?it/s]
Traceback (most recent call last):
  File "ft_official.py", line 118, in <module>
    main()
  File "ft_official.py", line 100, in main
    model.train_vispel()
  File "/home/users/apopescu/van-khoa/Vis-Priva-Expos/privacy/vispel/vispel/vispel.py", line 54, in train_vispel
    trained_clusteror, trained_regressor, feature_selector = trainer(self.situation, self.X_train, self.X_community,\
  File "/home/users/apopescu/van-khoa/Vis-Priva-Expos/privacy/vispel/vispel/trainer.py", line 64, in trainer
    trained_regressor = train_regressor(regressor, X_train_rd, gt_train_expos, cfg)
  File "/home/users/apopescu/van-khoa/Vis-Priva-Expos/privacy/lib/regressor/regression.py", line 22, in train_regressor
    model.fit(x_train, y_train)
  File "/home/users/apopescu/anaconda3/envs/detectron2/lib/python3.8/site-packages/sklearn/utils/validation.py", line 73, in inner_f
    return f(**kwargs)
  File "/home/users/apopescu/anaconda3/envs/detectron2/lib/python3.8/site-packages/sklearn/model_selection/_search.py", line 736, in fit
    self._run_search(evaluate_candidates)
  File "/home/users/apopescu/anaconda3/envs/detectron2/lib/python3.8/site-packages/sklearn/model_selection/_search.py", line 1188, in _run_search
    evaluate_candidates(ParameterGrid(self.param_grid))
  File "/home/users/apopescu/anaconda3/envs/detectron2/lib/python3.8/site-packages/sklearn/model_selection/_search.py", line 708, in evaluate_candidates
    out = parallel(delayed(_fit_and_score)(clone(base_estimator),
  File "/home/users/apopescu/anaconda3/envs/detectron2/lib/python3.8/site-packages/joblib/parallel.py", line 1042, in __call__
    self.retrieve()
  File "/home/users/apopescu/anaconda3/envs/detectron2/lib/python3.8/site-packages/joblib/parallel.py", line 921, in retrieve
    self._output.extend(job.get(timeout=self.timeout))
  File "/home/users/apopescu/anaconda3/envs/detectron2/lib/python3.8/site-packages/joblib/_parallel_backends.py", line 542, in wrap_future_result
    return future.result(timeout=timeout)
  File "/home/users/apopescu/anaconda3/envs/detectron2/lib/python3.8/concurrent/futures/_base.py", line 439, in result
    return self.__get_result()
  File "/home/users/apopescu/anaconda3/envs/detectron2/lib/python3.8/concurrent/futures/_base.py", line 388, in __get_result
    raise self._exception
  File "/home/users/apopescu/anaconda3/envs/detectron2/lib/python3.8/site-packages/joblib/externals/loky/_base.py", line 625, in _invoke_callbacks
    callback(self)
  File "/home/users/apopescu/anaconda3/envs/detectron2/lib/python3.8/site-packages/joblib/parallel.py", line 347, in __call__
    self.parallel.dispatch_next()
  File "/home/users/apopescu/anaconda3/envs/detectron2/lib/python3.8/site-packages/joblib/parallel.py", line 780, in dispatch_next
    if not self.dispatch_one_batch(self._original_iterator):
  File "/home/users/apopescu/anaconda3/envs/detectron2/lib/python3.8/site-packages/joblib/parallel.py", line 847, in dispatch_one_batch
    self._dispatch(tasks)
  File "/home/users/apopescu/anaconda3/envs/detectron2/lib/python3.8/site-packages/joblib/parallel.py", line 765, in _dispatch
    job = self._backend.apply_async(batch, callback=cb)
  File "/home/users/apopescu/anaconda3/envs/detectron2/lib/python3.8/site-packages/joblib/_parallel_backends.py", line 531, in apply_async
    future = self._workers.submit(SafeFunction(func))
  File "/home/users/apopescu/anaconda3/envs/detectron2/lib/python3.8/site-packages/joblib/externals/loky/reusable_executor.py", line 177, in submit
    return super(_ReusablePoolExecutor, self).submit(
  File "/home/users/apopescu/anaconda3/envs/detectron2/lib/python3.8/site-packages/joblib/externals/loky/process_executor.py", line 1102, in submit
    raise self._flags.broken
  File "/home/users/apopescu/anaconda3/envs/detectron2/lib/python3.8/site-packages/joblib/externals/loky/_base.py", line 625, in _invoke_callbacks
    callback(self)
  File "/home/users/apopescu/anaconda3/envs/detectron2/lib/python3.8/site-packages/joblib/parallel.py", line 347, in __call__
    self.parallel.dispatch_next()
  File "/home/users/apopescu/anaconda3/envs/detectron2/lib/python3.8/site-packages/joblib/parallel.py", line 780, in dispatch_next
    if not self.dispatch_one_batch(self._original_iterator):
  File "/home/users/apopescu/anaconda3/envs/detectron2/lib/python3.8/site-packages/joblib/parallel.py", line 847, in dispatch_one_batch
    self._dispatch(tasks)
  File "/home/users/apopescu/anaconda3/envs/detectron2/lib/python3.8/site-packages/joblib/parallel.py", line 765, in _dispatch
    job = self._backend.apply_async(batch, callback=cb)
  File "/home/users/apopescu/anaconda3/envs/detectron2/lib/python3.8/site-packages/joblib/_parallel_backends.py", line 531, in apply_async
    future = self._workers.submit(SafeFunction(func))
  File "/home/users/apopescu/anaconda3/envs/detectron2/lib/python3.8/site-packages/joblib/externals/loky/reusable_executor.py", line 177, in submit
    return super(_ReusablePoolExecutor, self).submit(
  File "/home/users/apopescu/anaconda3/envs/detectron2/lib/python3.8/site-packages/joblib/externals/loky/process_executor.py", line 1102, in submit
    raise self._flags.broken
  File "/home/users/apopescu/anaconda3/envs/detectron2/lib/python3.8/site-packages/joblib/externals/loky/_base.py", line 625, in _invoke_callbacks
    callback(self)
  File "/home/users/apopescu/anaconda3/envs/detectron2/lib/python3.8/site-packages/joblib/parallel.py", line 347, in __call__
    self.parallel.dispatch_next()
  File "/home/users/apopescu/anaconda3/envs/detectron2/lib/python3.8/site-packages/joblib/parallel.py", line 780, in dispatch_next
    if not self.dispatch_one_batch(self._original_iterator):
  File "/home/users/apopescu/anaconda3/envs/detectron2/lib/python3.8/site-packages/joblib/parallel.py", line 847, in dispatch_one_batch
    self._dispatch(tasks)
  File "/home/users/apopescu/anaconda3/envs/detectron2/lib/python3.8/site-packages/joblib/parallel.py", line 765, in _dispatch
    job = self._backend.apply_async(batch, callback=cb)
  File "/home/users/apopescu/anaconda3/envs/detectron2/lib/python3.8/site-packages/joblib/_parallel_backends.py", line 531, in apply_async
    future = self._workers.submit(SafeFunction(func))
  File "/home/users/apopescu/anaconda3/envs/detectron2/lib/python3.8/site-packages/joblib/externals/loky/reusable_executor.py", line 177, in submit
    return super(_ReusablePoolExecutor, self).submit(
  File "/home/users/apopescu/anaconda3/envs/detectron2/lib/python3.8/site-packages/joblib/externals/loky/process_executor.py", line 1102, in submit
    raise self._flags.broken
  File "/home/users/apopescu/anaconda3/envs/detectron2/lib/python3.8/site-packages/joblib/externals/loky/_base.py", line 625, in _invoke_callbacks
    callback(self)
  File "/home/users/apopescu/anaconda3/envs/detectron2/lib/python3.8/site-packages/joblib/parallel.py", line 347, in __call__
    self.parallel.dispatch_next()
  File "/home/users/apopescu/anaconda3/envs/detectron2/lib/python3.8/site-packages/joblib/parallel.py", line 780, in dispatch_next
    if not self.dispatch_one_batch(self._original_iterator):
  File "/home/users/apopescu/anaconda3/envs/detectron2/lib/python3.8/site-packages/joblib/parallel.py", line 847, in dispatch_one_batch
    self._dispatch(tasks)
  File "/home/users/apopescu/anaconda3/envs/detectron2/lib/python3.8/site-packages/joblib/parallel.py", line 765, in _dispatch
    job = self._backend.apply_async(batch, callback=cb)
  File "/home/users/apopescu/anaconda3/envs/detectron2/lib/python3.8/site-packages/joblib/_parallel_backends.py", line 531, in apply_async
    future = self._workers.submit(SafeFunction(func))
  File "/home/users/apopescu/anaconda3/envs/detectron2/lib/python3.8/site-packages/joblib/externals/loky/reusable_executor.py", line 177, in submit
    return super(_ReusablePoolExecutor, self).submit(
  File "/home/users/apopescu/anaconda3/envs/detectron2/lib/python3.8/site-packages/joblib/externals/loky/process_executor.py", line 1102, in submit
    raise self._flags.broken
joblib.externals.loky.process_executor.TerminatedWorkerError: A worker process managed by the executor was unexpectedly terminated. This could be caused by a segmentation fault while calling the function or by an excessive memory usage causing the Operating System to kill the worker.

The exit codes of the workers are {SIGBUS(-7)}
  0%|          | 0/5 [01:31<?, ?it/s]
Traceback (most recent call last):
  File "ft_official.py", line 118, in <module>
    main()
  File "ft_official.py", line 100, in main
    model.train_vispel()
  File "/home/users/apopescu/van-khoa/Vis-Priva-Expos/privacy/vispel/vispel/vispel.py", line 54, in train_vispel
    trained_clusteror, trained_regressor, feature_selector = trainer(self.situation, self.X_train, self.X_community,\
  File "/home/users/apopescu/van-khoa/Vis-Priva-Expos/privacy/vispel/vispel/trainer.py", line 64, in trainer
    trained_regressor = train_regressor(regressor, X_train_rd, gt_train_expos, cfg)
  File "/home/users/apopescu/van-khoa/Vis-Priva-Expos/privacy/lib/regressor/regression.py", line 22, in train_regressor
    model.fit(x_train, y_train)
  File "/home/users/apopescu/anaconda3/envs/detectron2/lib/python3.8/site-packages/sklearn/utils/validation.py", line 73, in inner_f
    return f(**kwargs)
  File "/home/users/apopescu/anaconda3/envs/detectron2/lib/python3.8/site-packages/sklearn/model_selection/_search.py", line 736, in fit
    self._run_search(evaluate_candidates)
  File "/home/users/apopescu/anaconda3/envs/detectron2/lib/python3.8/site-packages/sklearn/model_selection/_search.py", line 1188, in _run_search
    evaluate_candidates(ParameterGrid(self.param_grid))
  File "/home/users/apopescu/anaconda3/envs/detectron2/lib/python3.8/site-packages/sklearn/model_selection/_search.py", line 708, in evaluate_candidates
    out = parallel(delayed(_fit_and_score)(clone(base_estimator),
  File "/home/users/apopescu/anaconda3/envs/detectron2/lib/python3.8/site-packages/joblib/parallel.py", line 1042, in __call__
    self.retrieve()
  File "/home/users/apopescu/anaconda3/envs/detectron2/lib/python3.8/site-packages/joblib/parallel.py", line 921, in retrieve
    self._output.extend(job.get(timeout=self.timeout))
  File "/home/users/apopescu/anaconda3/envs/detectron2/lib/python3.8/site-packages/joblib/_parallel_backends.py", line 542, in wrap_future_result
    return future.result(timeout=timeout)
  File "/home/users/apopescu/anaconda3/envs/detectron2/lib/python3.8/concurrent/futures/_base.py", line 439, in result
    return self.__get_result()
  File "/home/users/apopescu/anaconda3/envs/detectron2/lib/python3.8/concurrent/futures/_base.py", line 388, in __get_result
    raise self._exception
joblib.externals.loky.process_executor.TerminatedWorkerError: A worker process managed by the executor was unexpectedly terminated. This could be caused by a segmentation fault while calling the function or by an excessive memory usage causing the Operating System to kill the worker.

The exit codes of the workers are {SIGBUS(-7)}
exception calling callback for <Future at 0x2b47641f6190 state=finished raised TerminatedWorkerError>
Traceback (most recent call last):
  File "/home/users/apopescu/anaconda3/envs/detectron2/lib/python3.8/site-packages/joblib/externals/loky/_base.py", line 625, in _invoke_callbacks
    callback(self)
  File "/home/users/apopescu/anaconda3/envs/detectron2/lib/python3.8/site-packages/joblib/parallel.py", line 347, in __call__
    self.parallel.dispatch_next()
  File "/home/users/apopescu/anaconda3/envs/detectron2/lib/python3.8/site-packages/joblib/parallel.py", line 780, in dispatch_next
    if not self.dispatch_one_batch(self._original_iterator):
  File "/home/users/apopescu/anaconda3/envs/detectron2/lib/python3.8/site-packages/joblib/parallel.py", line 847, in dispatch_one_batch
    self._dispatch(tasks)
  File "/home/users/apopescu/anaconda3/envs/detectron2/lib/python3.8/site-packages/joblib/parallel.py", line 765, in _dispatch
    job = self._backend.apply_async(batch, callback=cb)
  File "/home/users/apopescu/anaconda3/envs/detectron2/lib/python3.8/site-packages/joblib/_parallel_backends.py", line 531, in apply_async
    future = self._workers.submit(SafeFunction(func))
  File "/home/users/apopescu/anaconda3/envs/detectron2/lib/python3.8/site-packages/joblib/externals/loky/reusable_executor.py", line 177, in submit
    return super(_ReusablePoolExecutor, self).submit(
  File "/home/users/apopescu/anaconda3/envs/detectron2/lib/python3.8/site-packages/joblib/externals/loky/process_executor.py", line 1102, in submit
    raise self._flags.broken
joblib.externals.loky.process_executor.TerminatedWorkerError: A worker process managed by the executor was unexpectedly terminated. This could be caused by a segmentation fault while calling the function or by an excessive memory usage causing the Operating System to kill the worker.

The exit codes of the workers are {SIGBUS(-7)}
  0%|          | 0/5 [01:34<?, ?it/s]
Traceback (most recent call last):
  File "ft_official.py", line 118, in <module>
    main()
  File "ft_official.py", line 100, in main
    model.train_vispel()
  File "/home/users/apopescu/van-khoa/Vis-Priva-Expos/privacy/vispel/vispel/vispel.py", line 54, in train_vispel
    trained_clusteror, trained_regressor, feature_selector = trainer(self.situation, self.X_train, self.X_community,\
  File "/home/users/apopescu/van-khoa/Vis-Priva-Expos/privacy/vispel/vispel/trainer.py", line 64, in trainer
    trained_regressor = train_regressor(regressor, X_train_rd, gt_train_expos, cfg)
  File "/home/users/apopescu/van-khoa/Vis-Priva-Expos/privacy/lib/regressor/regression.py", line 22, in train_regressor
    model.fit(x_train, y_train)
  File "/home/users/apopescu/anaconda3/envs/detectron2/lib/python3.8/site-packages/sklearn/utils/validation.py", line 73, in inner_f
    return f(**kwargs)
  File "/home/users/apopescu/anaconda3/envs/detectron2/lib/python3.8/site-packages/sklearn/model_selection/_search.py", line 736, in fit
    self._run_search(evaluate_candidates)
  File "/home/users/apopescu/anaconda3/envs/detectron2/lib/python3.8/site-packages/sklearn/model_selection/_search.py", line 1188, in _run_search
    evaluate_candidates(ParameterGrid(self.param_grid))
  File "/home/users/apopescu/anaconda3/envs/detectron2/lib/python3.8/site-packages/sklearn/model_selection/_search.py", line 708, in evaluate_candidates
    out = parallel(delayed(_fit_and_score)(clone(base_estimator),
  File "/home/users/apopescu/anaconda3/envs/detectron2/lib/python3.8/site-packages/joblib/parallel.py", line 1042, in __call__
    self.retrieve()
  File "/home/users/apopescu/anaconda3/envs/detectron2/lib/python3.8/site-packages/joblib/parallel.py", line 921, in retrieve
    self._output.extend(job.get(timeout=self.timeout))
  File "/home/users/apopescu/anaconda3/envs/detectron2/lib/python3.8/site-packages/joblib/_parallel_backends.py", line 542, in wrap_future_result
    return future.result(timeout=timeout)
  File "/home/users/apopescu/anaconda3/envs/detectron2/lib/python3.8/concurrent/futures/_base.py", line 439, in result
    return self.__get_result()
  File "/home/users/apopescu/anaconda3/envs/detectron2/lib/python3.8/concurrent/futures/_base.py", line 388, in __get_result
    raise self._exception
  File "/home/users/apopescu/anaconda3/envs/detectron2/lib/python3.8/site-packages/joblib/externals/loky/_base.py", line 625, in _invoke_callbacks
    callback(self)
  File "/home/users/apopescu/anaconda3/envs/detectron2/lib/python3.8/site-packages/joblib/parallel.py", line 347, in __call__
    self.parallel.dispatch_next()
  File "/home/users/apopescu/anaconda3/envs/detectron2/lib/python3.8/site-packages/joblib/parallel.py", line 780, in dispatch_next
    if not self.dispatch_one_batch(self._original_iterator):
  File "/home/users/apopescu/anaconda3/envs/detectron2/lib/python3.8/site-packages/joblib/parallel.py", line 847, in dispatch_one_batch
    self._dispatch(tasks)
  File "/home/users/apopescu/anaconda3/envs/detectron2/lib/python3.8/site-packages/joblib/parallel.py", line 765, in _dispatch
    job = self._backend.apply_async(batch, callback=cb)
  File "/home/users/apopescu/anaconda3/envs/detectron2/lib/python3.8/site-packages/joblib/_parallel_backends.py", line 531, in apply_async
    future = self._workers.submit(SafeFunction(func))
  File "/home/users/apopescu/anaconda3/envs/detectron2/lib/python3.8/site-packages/joblib/externals/loky/reusable_executor.py", line 177, in submit
    return super(_ReusablePoolExecutor, self).submit(
  File "/home/users/apopescu/anaconda3/envs/detectron2/lib/python3.8/site-packages/joblib/externals/loky/process_executor.py", line 1102, in submit
    raise self._flags.broken
joblib.externals.loky.process_executor.TerminatedWorkerError: A worker process managed by the executor was unexpectedly terminated. This could be caused by a segmentation fault while calling the function or by an excessive memory usage causing the Operating System to kill the worker.

The exit codes of the workers are {SIGBUS(-7)}
exception calling callback for <Future at 0x2ac485e89190 state=finished raised TerminatedWorkerError>
Traceback (most recent call last):
  File "/home/users/apopescu/anaconda3/envs/detectron2/lib/python3.8/site-packages/joblib/externals/loky/_base.py", line 625, in _invoke_callbacks
    callback(self)
  File "/home/users/apopescu/anaconda3/envs/detectron2/lib/python3.8/site-packages/joblib/parallel.py", line 347, in __call__
    self.parallel.dispatch_next()
  File "/home/users/apopescu/anaconda3/envs/detectron2/lib/python3.8/site-packages/joblib/parallel.py", line 780, in dispatch_next
    if not self.dispatch_one_batch(self._original_iterator):
  File "/home/users/apopescu/anaconda3/envs/detectron2/lib/python3.8/site-packages/joblib/parallel.py", line 847, in dispatch_one_batch
    self._dispatch(tasks)
  File "/home/users/apopescu/anaconda3/envs/detectron2/lib/python3.8/site-packages/joblib/parallel.py", line 765, in _dispatch
    job = self._backend.apply_async(batch, callback=cb)
  File "/home/users/apopescu/anaconda3/envs/detectron2/lib/python3.8/site-packages/joblib/_parallel_backends.py", line 531, in apply_async
    future = self._workers.submit(SafeFunction(func))
  File "/home/users/apopescu/anaconda3/envs/detectron2/lib/python3.8/site-packages/joblib/externals/loky/reusable_executor.py", line 177, in submit
    return super(_ReusablePoolExecutor, self).submit(
  File "/home/users/apopescu/anaconda3/envs/detectron2/lib/python3.8/site-packages/joblib/externals/loky/process_executor.py", line 1102, in submit
    raise self._flags.broken
joblib.externals.loky.process_executor.TerminatedWorkerError: A worker process managed by the executor was unexpectedly terminated. This could be caused by a segmentation fault while calling the function or by an excessive memory usage causing the Operating System to kill the worker.

The exit codes of the workers are {SIGBUS(-7)}
  0%|          | 0/5 [01:38<?, ?it/s]
Traceback (most recent call last):
  File "ft_official.py", line 118, in <module>
    main()
  File "ft_official.py", line 100, in main
    model.train_vispel()
  File "/home/users/apopescu/van-khoa/Vis-Priva-Expos/privacy/vispel/vispel/vispel.py", line 54, in train_vispel
    trained_clusteror, trained_regressor, feature_selector = trainer(self.situation, self.X_train, self.X_community,\
  File "/home/users/apopescu/van-khoa/Vis-Priva-Expos/privacy/vispel/vispel/trainer.py", line 64, in trainer
    trained_regressor = train_regressor(regressor, X_train_rd, gt_train_expos, cfg)
  File "/home/users/apopescu/van-khoa/Vis-Priva-Expos/privacy/lib/regressor/regression.py", line 22, in train_regressor
    model.fit(x_train, y_train)
  File "/home/users/apopescu/anaconda3/envs/detectron2/lib/python3.8/site-packages/sklearn/utils/validation.py", line 73, in inner_f
    return f(**kwargs)
  File "/home/users/apopescu/anaconda3/envs/detectron2/lib/python3.8/site-packages/sklearn/model_selection/_search.py", line 736, in fit
    self._run_search(evaluate_candidates)
  File "/home/users/apopescu/anaconda3/envs/detectron2/lib/python3.8/site-packages/sklearn/model_selection/_search.py", line 1188, in _run_search
    evaluate_candidates(ParameterGrid(self.param_grid))
  File "/home/users/apopescu/anaconda3/envs/detectron2/lib/python3.8/site-packages/sklearn/model_selection/_search.py", line 708, in evaluate_candidates
    out = parallel(delayed(_fit_and_score)(clone(base_estimator),
  File "/home/users/apopescu/anaconda3/envs/detectron2/lib/python3.8/site-packages/joblib/parallel.py", line 1042, in __call__
    self.retrieve()
  File "/home/users/apopescu/anaconda3/envs/detectron2/lib/python3.8/site-packages/joblib/parallel.py", line 921, in retrieve
    self._output.extend(job.get(timeout=self.timeout))
  File "/home/users/apopescu/anaconda3/envs/detectron2/lib/python3.8/site-packages/joblib/_parallel_backends.py", line 542, in wrap_future_result
    return future.result(timeout=timeout)
  File "/home/users/apopescu/anaconda3/envs/detectron2/lib/python3.8/concurrent/futures/_base.py", line 439, in result
    return self.__get_result()
  File "/home/users/apopescu/anaconda3/envs/detectron2/lib/python3.8/concurrent/futures/_base.py", line 388, in __get_result
    raise self._exception
  File "/home/users/apopescu/anaconda3/envs/detectron2/lib/python3.8/site-packages/joblib/externals/loky/_base.py", line 625, in _invoke_callbacks
    callback(self)
  File "/home/users/apopescu/anaconda3/envs/detectron2/lib/python3.8/site-packages/joblib/parallel.py", line 347, in __call__
    self.parallel.dispatch_next()
  File "/home/users/apopescu/anaconda3/envs/detectron2/lib/python3.8/site-packages/joblib/parallel.py", line 780, in dispatch_next
    if not self.dispatch_one_batch(self._original_iterator):
  File "/home/users/apopescu/anaconda3/envs/detectron2/lib/python3.8/site-packages/joblib/parallel.py", line 847, in dispatch_one_batch
    self._dispatch(tasks)
  File "/home/users/apopescu/anaconda3/envs/detectron2/lib/python3.8/site-packages/joblib/parallel.py", line 765, in _dispatch
    job = self._backend.apply_async(batch, callback=cb)
  File "/home/users/apopescu/anaconda3/envs/detectron2/lib/python3.8/site-packages/joblib/_parallel_backends.py", line 531, in apply_async
    future = self._workers.submit(SafeFunction(func))
  File "/home/users/apopescu/anaconda3/envs/detectron2/lib/python3.8/site-packages/joblib/externals/loky/reusable_executor.py", line 177, in submit
    return super(_ReusablePoolExecutor, self).submit(
  File "/home/users/apopescu/anaconda3/envs/detectron2/lib/python3.8/site-packages/joblib/externals/loky/process_executor.py", line 1102, in submit
    raise self._flags.broken
joblib.externals.loky.process_executor.TerminatedWorkerError: A worker process managed by the executor was unexpectedly terminated. This could be caused by a segmentation fault while calling the function or by an excessive memory usage causing the Operating System to kill the worker.

The exit codes of the workers are {SIGBUS(-7)}
Traceback (most recent call last):
  File "/home/users/apopescu/anaconda3/envs/detectron2/lib/python3.8/site-packages/joblib/externals/loky/backend/resource_tracker.py", line 281, in main
    del registry[rtype][name]
KeyError: '/loky-199074-hnk7l8i6'
Traceback (most recent call last):
  File "/home/users/apopescu/anaconda3/envs/detectron2/lib/python3.8/site-packages/joblib/externals/loky/backend/resource_tracker.py", line 281, in main
    del registry[rtype][name]
KeyError: '/loky-199074-q1a069_h'
Traceback (most recent call last):
  File "/home/users/apopescu/anaconda3/envs/detectron2/lib/python3.8/site-packages/joblib/externals/loky/backend/resource_tracker.py", line 281, in main
    del registry[rtype][name]
KeyError: '/loky-199074-xm282634'
Traceback (most recent call last):
  File "/home/users/apopescu/anaconda3/envs/detectron2/lib/python3.8/site-packages/joblib/externals/loky/backend/resource_tracker.py", line 281, in main
    del registry[rtype][name]
KeyError: '/loky-199074-scbi22um'
Traceback (most recent call last):
  File "/home/users/apopescu/anaconda3/envs/detectron2/lib/python3.8/site-packages/joblib/externals/loky/backend/resource_tracker.py", line 281, in main
    del registry[rtype][name]
KeyError: '/loky-199074-jbr_t_qf'
Traceback (most recent call last):
  File "/home/users/apopescu/anaconda3/envs/detectron2/lib/python3.8/site-packages/joblib/externals/loky/backend/resource_tracker.py", line 281, in main
    del registry[rtype][name]
KeyError: '/dev/shm/joblib_memmapping_folder_199074_08ec325a57fe426c800aba339e73b211_a9d07444c86644a78441062419aa1f06'
Traceback (most recent call last):
  File "/home/users/apopescu/anaconda3/envs/detectron2/lib/python3.8/site-packages/joblib/externals/loky/backend/resource_tracker.py", line 281, in main
    del registry[rtype][name]
KeyError: '/dev/shm/joblib_memmapping_folder_199074_08ec325a57fe426c800aba339e73b211_6659750c3391429ab3e0840b29e65d47'
Traceback (most recent call last):
  File "/home/users/apopescu/anaconda3/envs/detectron2/lib/python3.8/site-packages/joblib/externals/loky/backend/resource_tracker.py", line 281, in main
    del registry[rtype][name]
KeyError: '/loky-199074-n46ag3qk'
Traceback (most recent call last):
  File "/home/users/apopescu/anaconda3/envs/detectron2/lib/python3.8/site-packages/joblib/externals/loky/backend/resource_tracker.py", line 281, in main
    del registry[rtype][name]
KeyError: '/loky-199074-uti835v9'
Traceback (most recent call last):
  File "/home/users/apopescu/anaconda3/envs/detectron2/lib/python3.8/site-packages/joblib/externals/loky/backend/resource_tracker.py", line 281, in main
    del registry[rtype][name]
KeyError: '/loky-199074-w2tz262n'
Traceback (most recent call last):
  File "/home/users/apopescu/anaconda3/envs/detectron2/lib/python3.8/site-packages/joblib/externals/loky/backend/resource_tracker.py", line 281, in main
    del registry[rtype][name]
KeyError: '/loky-199078-l4w7yb_v'
Traceback (most recent call last):
  File "/home/users/apopescu/anaconda3/envs/detectron2/lib/python3.8/site-packages/joblib/externals/loky/backend/resource_tracker.py", line 281, in main
    del registry[rtype][name]
KeyError: '/loky-199078-thyy_9hv'
Traceback (most recent call last):
  File "/home/users/apopescu/anaconda3/envs/detectron2/lib/python3.8/site-packages/joblib/externals/loky/backend/resource_tracker.py", line 281, in main
    del registry[rtype][name]
KeyError: '/dev/shm/joblib_memmapping_folder_199078_8c2153d69db04b74982f789747a0f68e_97853d305e0b491d9a319a6370c9520c'
Traceback (most recent call last):
  File "/home/users/apopescu/anaconda3/envs/detectron2/lib/python3.8/site-packages/joblib/externals/loky/backend/resource_tracker.py", line 281, in main
    del registry[rtype][name]
KeyError: '/dev/shm/joblib_memmapping_folder_199078_8c2153d69db04b74982f789747a0f68e_4c8ec9dbaa65456e8ff637070689dae2'
Traceback (most recent call last):
  File "/home/users/apopescu/anaconda3/envs/detectron2/lib/python3.8/site-packages/joblib/externals/loky/backend/resource_tracker.py", line 281, in main
    del registry[rtype][name]
KeyError: '/loky-199078-7kj_022d'
Traceback (most recent call last):
  File "/home/users/apopescu/anaconda3/envs/detectron2/lib/python3.8/site-packages/joblib/externals/loky/backend/resource_tracker.py", line 281, in main
    del registry[rtype][name]
KeyError: '/loky-199078-4wvc8o98'
Traceback (most recent call last):
  File "/home/users/apopescu/anaconda3/envs/detectron2/lib/python3.8/site-packages/joblib/externals/loky/backend/resource_tracker.py", line 281, in main
    del registry[rtype][name]
KeyError: '/loky-199078-v_xt4q61'
Traceback (most recent call last):
  File "/home/users/apopescu/anaconda3/envs/detectron2/lib/python3.8/site-packages/joblib/externals/loky/backend/resource_tracker.py", line 281, in main
    del registry[rtype][name]
KeyError: '/loky-199078-lqasvzl3'
Traceback (most recent call last):
  File "/home/users/apopescu/anaconda3/envs/detectron2/lib/python3.8/site-packages/joblib/externals/loky/backend/resource_tracker.py", line 281, in main
    del registry[rtype][name]
KeyError: '/loky-199078-nvp839_x'
Traceback (most recent call last):
  File "/home/users/apopescu/anaconda3/envs/detectron2/lib/python3.8/site-packages/joblib/externals/loky/backend/resource_tracker.py", line 281, in main
    del registry[rtype][name]
KeyError: '/loky-199078-dhbv0aay'
Traceback (most recent call last):
  File "/home/users/apopescu/anaconda3/envs/detectron2/lib/python3.8/site-packages/joblib/externals/loky/backend/resource_tracker.py", line 281, in main
    del registry[rtype][name]
KeyError: '/loky-199081-2vl751ku'
Traceback (most recent call last):
  File "/home/users/apopescu/anaconda3/envs/detectron2/lib/python3.8/site-packages/joblib/externals/loky/backend/resource_tracker.py", line 281, in main
    del registry[rtype][name]
KeyError: '/loky-199081-w_ykvkm0'
Traceback (most recent call last):
  File "/home/users/apopescu/anaconda3/envs/detectron2/lib/python3.8/site-packages/joblib/externals/loky/backend/resource_tracker.py", line 281, in main
    del registry[rtype][name]
KeyError: '/loky-199081-4sey80uj'
Traceback (most recent call last):
  File "/home/users/apopescu/anaconda3/envs/detectron2/lib/python3.8/site-packages/joblib/externals/loky/backend/resource_tracker.py", line 281, in main
    del registry[rtype][name]
KeyError: '/loky-199081-v8gld6fp'
Traceback (most recent call last):
  File "/home/users/apopescu/anaconda3/envs/detectron2/lib/python3.8/site-packages/joblib/externals/loky/backend/resource_tracker.py", line 281, in main
    del registry[rtype][name]
KeyError: '/loky-199081-gk11rmhp'
Traceback (most recent call last):
  File "/home/users/apopescu/anaconda3/envs/detectron2/lib/python3.8/site-packages/joblib/externals/loky/backend/resource_tracker.py", line 281, in main
    del registry[rtype][name]
KeyError: '/loky-199081-21eqtfkm'
Traceback (most recent call last):
  File "/home/users/apopescu/anaconda3/envs/detectron2/lib/python3.8/site-packages/joblib/externals/loky/backend/resource_tracker.py", line 281, in main
    del registry[rtype][name]
KeyError: '/loky-199081-qwb_ka4b'
Traceback (most recent call last):
  File "/home/users/apopescu/anaconda3/envs/detectron2/lib/python3.8/site-packages/joblib/externals/loky/backend/resource_tracker.py", line 281, in main
    del registry[rtype][name]
KeyError: '/loky-199081-kb3_r5dh'
Traceback (most recent call last):
  File "/home/users/apopescu/anaconda3/envs/detectron2/lib/python3.8/site-packages/joblib/externals/loky/backend/resource_tracker.py", line 281, in main
    del registry[rtype][name]
KeyError: '/dev/shm/joblib_memmapping_folder_199081_56f2d5dd940d49638246c74f335144ac_d710677016f444e4bcf584e9a38ab2cb'
Traceback (most recent call last):
  File "/home/users/apopescu/anaconda3/envs/detectron2/lib/python3.8/site-packages/joblib/externals/loky/backend/resource_tracker.py", line 281, in main
    del registry[rtype][name]
KeyError: '/dev/shm/joblib_memmapping_folder_199081_56f2d5dd940d49638246c74f335144ac_de06e52d396a42be81743d1e8eefd701'
exception calling callback for <Future at 0x2b3aad65b190 state=finished raised TerminatedWorkerError>
Traceback (most recent call last):
  File "/home/users/apopescu/anaconda3/envs/detectron2/lib/python3.8/site-packages/joblib/externals/loky/_base.py", line 625, in _invoke_callbacks
    callback(self)
  File "/home/users/apopescu/anaconda3/envs/detectron2/lib/python3.8/site-packages/joblib/parallel.py", line 347, in __call__
    self.parallel.dispatch_next()
  File "/home/users/apopescu/anaconda3/envs/detectron2/lib/python3.8/site-packages/joblib/parallel.py", line 780, in dispatch_next
    if not self.dispatch_one_batch(self._original_iterator):
  File "/home/users/apopescu/anaconda3/envs/detectron2/lib/python3.8/site-packages/joblib/parallel.py", line 847, in dispatch_one_batch
    self._dispatch(tasks)
  File "/home/users/apopescu/anaconda3/envs/detectron2/lib/python3.8/site-packages/joblib/parallel.py", line 765, in _dispatch
    job = self._backend.apply_async(batch, callback=cb)
  File "/home/users/apopescu/anaconda3/envs/detectron2/lib/python3.8/site-packages/joblib/_parallel_backends.py", line 531, in apply_async
    future = self._workers.submit(SafeFunction(func))
  File "/home/users/apopescu/anaconda3/envs/detectron2/lib/python3.8/site-packages/joblib/externals/loky/reusable_executor.py", line 177, in submit
    return super(_ReusablePoolExecutor, self).submit(
  File "/home/users/apopescu/anaconda3/envs/detectron2/lib/python3.8/site-packages/joblib/externals/loky/process_executor.py", line 1102, in submit
    raise self._flags.broken
joblib.externals.loky.process_executor.TerminatedWorkerError: A worker process managed by the executor was unexpectedly terminated. This could be caused by a segmentation fault while calling the function or by an excessive memory usage causing the Operating System to kill the worker.

The exit codes of the workers are {SIGBUS(-7)}
  0%|          | 0/5 [01:45<?, ?it/s]
Traceback (most recent call last):
  File "ft_official.py", line 118, in <module>
    main()
  File "ft_official.py", line 100, in main
    model.train_vispel()
  File "/home/users/apopescu/van-khoa/Vis-Priva-Expos/privacy/vispel/vispel/vispel.py", line 54, in train_vispel
    trained_clusteror, trained_regressor, feature_selector = trainer(self.situation, self.X_train, self.X_community,\
  File "/home/users/apopescu/van-khoa/Vis-Priva-Expos/privacy/vispel/vispel/trainer.py", line 64, in trainer
    trained_regressor = train_regressor(regressor, X_train_rd, gt_train_expos, cfg)
  File "/home/users/apopescu/van-khoa/Vis-Priva-Expos/privacy/lib/regressor/regression.py", line 22, in train_regressor
    model.fit(x_train, y_train)
  File "/home/users/apopescu/anaconda3/envs/detectron2/lib/python3.8/site-packages/sklearn/utils/validation.py", line 73, in inner_f
    return f(**kwargs)
  File "/home/users/apopescu/anaconda3/envs/detectron2/lib/python3.8/site-packages/sklearn/model_selection/_search.py", line 736, in fit
    self._run_search(evaluate_candidates)
  File "/home/users/apopescu/anaconda3/envs/detectron2/lib/python3.8/site-packages/sklearn/model_selection/_search.py", line 1188, in _run_search
    evaluate_candidates(ParameterGrid(self.param_grid))
  File "/home/users/apopescu/anaconda3/envs/detectron2/lib/python3.8/site-packages/sklearn/model_selection/_search.py", line 708, in evaluate_candidates
    out = parallel(delayed(_fit_and_score)(clone(base_estimator),
  File "/home/users/apopescu/anaconda3/envs/detectron2/lib/python3.8/site-packages/joblib/parallel.py", line 1042, in __call__
    self.retrieve()
  File "/home/users/apopescu/anaconda3/envs/detectron2/lib/python3.8/site-packages/joblib/parallel.py", line 921, in retrieve
    self._output.extend(job.get(timeout=self.timeout))
  File "/home/users/apopescu/anaconda3/envs/detectron2/lib/python3.8/site-packages/joblib/_parallel_backends.py", line 542, in wrap_future_result
    return future.result(timeout=timeout)
  File "/home/users/apopescu/anaconda3/envs/detectron2/lib/python3.8/concurrent/futures/_base.py", line 439, in result
    return self.__get_result()
  File "/home/users/apopescu/anaconda3/envs/detectron2/lib/python3.8/concurrent/futures/_base.py", line 388, in __get_result
    raise self._exception
  File "/home/users/apopescu/anaconda3/envs/detectron2/lib/python3.8/site-packages/joblib/externals/loky/_base.py", line 625, in _invoke_callbacks
    callback(self)
  File "/home/users/apopescu/anaconda3/envs/detectron2/lib/python3.8/site-packages/joblib/parallel.py", line 347, in __call__
    self.parallel.dispatch_next()
  File "/home/users/apopescu/anaconda3/envs/detectron2/lib/python3.8/site-packages/joblib/parallel.py", line 780, in dispatch_next
    if not self.dispatch_one_batch(self._original_iterator):
  File "/home/users/apopescu/anaconda3/envs/detectron2/lib/python3.8/site-packages/joblib/parallel.py", line 847, in dispatch_one_batch
    self._dispatch(tasks)
  File "/home/users/apopescu/anaconda3/envs/detectron2/lib/python3.8/site-packages/joblib/parallel.py", line 765, in _dispatch
    job = self._backend.apply_async(batch, callback=cb)
  File "/home/users/apopescu/anaconda3/envs/detectron2/lib/python3.8/site-packages/joblib/_parallel_backends.py", line 531, in apply_async
    future = self._workers.submit(SafeFunction(func))
  File "/home/users/apopescu/anaconda3/envs/detectron2/lib/python3.8/site-packages/joblib/externals/loky/reusable_executor.py", line 177, in submit
    return super(_ReusablePoolExecutor, self).submit(
  File "/home/users/apopescu/anaconda3/envs/detectron2/lib/python3.8/site-packages/joblib/externals/loky/process_executor.py", line 1102, in submit
    raise self._flags.broken
joblib.externals.loky.process_executor.TerminatedWorkerError: A worker process managed by the executor was unexpectedly terminated. This could be caused by a segmentation fault while calling the function or by an excessive memory usage causing the Operating System to kill the worker.

The exit codes of the workers are {SIGBUS(-7)}
exception calling callback for <Future at 0x2ab9fb9fd190 state=finished raised TerminatedWorkerError>
Traceback (most recent call last):
  File "/home/users/apopescu/anaconda3/envs/detectron2/lib/python3.8/site-packages/joblib/externals/loky/_base.py", line 625, in _invoke_callbacks
    callback(self)
  File "/home/users/apopescu/anaconda3/envs/detectron2/lib/python3.8/site-packages/joblib/parallel.py", line 347, in __call__
    self.parallel.dispatch_next()
  File "/home/users/apopescu/anaconda3/envs/detectron2/lib/python3.8/site-packages/joblib/parallel.py", line 780, in dispatch_next
    if not self.dispatch_one_batch(self._original_iterator):
  File "/home/users/apopescu/anaconda3/envs/detectron2/lib/python3.8/site-packages/joblib/parallel.py", line 847, in dispatch_one_batch
    self._dispatch(tasks)
  File "/home/users/apopescu/anaconda3/envs/detectron2/lib/python3.8/site-packages/joblib/parallel.py", line 765, in _dispatch
    job = self._backend.apply_async(batch, callback=cb)
  File "/home/users/apopescu/anaconda3/envs/detectron2/lib/python3.8/site-packages/joblib/_parallel_backends.py", line 531, in apply_async
    future = self._workers.submit(SafeFunction(func))
  File "/home/users/apopescu/anaconda3/envs/detectron2/lib/python3.8/site-packages/joblib/externals/loky/reusable_executor.py", line 177, in submit
    return super(_ReusablePoolExecutor, self).submit(
  File "/home/users/apopescu/anaconda3/envs/detectron2/lib/python3.8/site-packages/joblib/externals/loky/process_executor.py", line 1102, in submit
    raise self._flags.broken
joblib.externals.loky.process_executor.TerminatedWorkerError: A worker process managed by the executor was unexpectedly terminated. This could be caused by a segmentation fault while calling the function or by an excessive memory usage causing the Operating System to kill the worker.

The exit codes of the workers are {SIGBUS(-7)}
exception calling callback for <Future at 0x2b29d71cf190 state=finished raised TerminatedWorkerError>
Traceback (most recent call last):
  File "/home/users/apopescu/anaconda3/envs/detectron2/lib/python3.8/site-packages/joblib/externals/loky/_base.py", line 625, in _invoke_callbacks
    callback(self)
  File "/home/users/apopescu/anaconda3/envs/detectron2/lib/python3.8/site-packages/joblib/parallel.py", line 347, in __call__
    self.parallel.dispatch_next()
  File "/home/users/apopescu/anaconda3/envs/detectron2/lib/python3.8/site-packages/joblib/parallel.py", line 780, in dispatch_next
    if not self.dispatch_one_batch(self._original_iterator):
  File "/home/users/apopescu/anaconda3/envs/detectron2/lib/python3.8/site-packages/joblib/parallel.py", line 847, in dispatch_one_batch
    self._dispatch(tasks)
  File "/home/users/apopescu/anaconda3/envs/detectron2/lib/python3.8/site-packages/joblib/parallel.py", line 765, in _dispatch
    job = self._backend.apply_async(batch, callback=cb)
  File "/home/users/apopescu/anaconda3/envs/detectron2/lib/python3.8/site-packages/joblib/_parallel_backends.py", line 531, in apply_async
    future = self._workers.submit(SafeFunction(func))
  File "/home/users/apopescu/anaconda3/envs/detectron2/lib/python3.8/site-packages/joblib/externals/loky/reusable_executor.py", line 177, in submit
    return super(_ReusablePoolExecutor, self).submit(
  File "/home/users/apopescu/anaconda3/envs/detectron2/lib/python3.8/site-packages/joblib/externals/loky/process_executor.py", line 1102, in submit
    raise self._flags.broken
joblib.externals.loky.process_executor.TerminatedWorkerError: A worker process managed by the executor was unexpectedly terminated. This could be caused by a segmentation fault while calling the function or by an excessive memory usage causing the Operating System to kill the worker.

The exit codes of the workers are {SIGBUS(-7)}
  0%|          | 0/5 [01:55<?, ?it/s]
Traceback (most recent call last):
  File "ft_official.py", line 118, in <module>
    main()
  File "ft_official.py", line 100, in main
    model.train_vispel()
  File "/home/users/apopescu/van-khoa/Vis-Priva-Expos/privacy/vispel/vispel/vispel.py", line 54, in train_vispel
    trained_clusteror, trained_regressor, feature_selector = trainer(self.situation, self.X_train, self.X_community,\
  File "/home/users/apopescu/van-khoa/Vis-Priva-Expos/privacy/vispel/vispel/trainer.py", line 64, in trainer
    trained_regressor = train_regressor(regressor, X_train_rd, gt_train_expos, cfg)
  File "/home/users/apopescu/van-khoa/Vis-Priva-Expos/privacy/lib/regressor/regression.py", line 22, in train_regressor
    model.fit(x_train, y_train)
  File "/home/users/apopescu/anaconda3/envs/detectron2/lib/python3.8/site-packages/sklearn/utils/validation.py", line 73, in inner_f
    return f(**kwargs)
  File "/home/users/apopescu/anaconda3/envs/detectron2/lib/python3.8/site-packages/sklearn/model_selection/_search.py", line 736, in fit
    self._run_search(evaluate_candidates)
  File "/home/users/apopescu/anaconda3/envs/detectron2/lib/python3.8/site-packages/sklearn/model_selection/_search.py", line 1188, in _run_search
    evaluate_candidates(ParameterGrid(self.param_grid))
  File "/home/users/apopescu/anaconda3/envs/detectron2/lib/python3.8/site-packages/sklearn/model_selection/_search.py", line 708, in evaluate_candidates
    out = parallel(delayed(_fit_and_score)(clone(base_estimator),
  File "/home/users/apopescu/anaconda3/envs/detectron2/lib/python3.8/site-packages/joblib/parallel.py", line 1042, in __call__
    self.retrieve()
  File "/home/users/apopescu/anaconda3/envs/detectron2/lib/python3.8/site-packages/joblib/parallel.py", line 921, in retrieve
    self._output.extend(job.get(timeout=self.timeout))
  File "/home/users/apopescu/anaconda3/envs/detectron2/lib/python3.8/site-packages/joblib/_parallel_backends.py", line 542, in wrap_future_result
    return future.result(timeout=timeout)
  File "/home/users/apopescu/anaconda3/envs/detectron2/lib/python3.8/concurrent/futures/_base.py", line 439, in result
    return self.__get_result()
  File "/home/users/apopescu/anaconda3/envs/detectron2/lib/python3.8/concurrent/futures/_base.py", line 388, in __get_result
    raise self._exception
  File "/home/users/apopescu/anaconda3/envs/detectron2/lib/python3.8/site-packages/joblib/externals/loky/_base.py", line 625, in _invoke_callbacks
    callback(self)
  File "/home/users/apopescu/anaconda3/envs/detectron2/lib/python3.8/site-packages/joblib/parallel.py", line 347, in __call__
    self.parallel.dispatch_next()
  File "/home/users/apopescu/anaconda3/envs/detectron2/lib/python3.8/site-packages/joblib/parallel.py", line 780, in dispatch_next
    if not self.dispatch_one_batch(self._original_iterator):
  File "/home/users/apopescu/anaconda3/envs/detectron2/lib/python3.8/site-packages/joblib/parallel.py", line 847, in dispatch_one_batch
    self._dispatch(tasks)
  File "/home/users/apopescu/anaconda3/envs/detectron2/lib/python3.8/site-packages/joblib/parallel.py", line 765, in _dispatch
    job = self._backend.apply_async(batch, callback=cb)
  File "/home/users/apopescu/anaconda3/envs/detectron2/lib/python3.8/site-packages/joblib/_parallel_backends.py", line 531, in apply_async
    future = self._workers.submit(SafeFunction(func))
  File "/home/users/apopescu/anaconda3/envs/detectron2/lib/python3.8/site-packages/joblib/externals/loky/reusable_executor.py", line 177, in submit
    return super(_ReusablePoolExecutor, self).submit(
  File "/home/users/apopescu/anaconda3/envs/detectron2/lib/python3.8/site-packages/joblib/externals/loky/process_executor.py", line 1102, in submit
    raise self._flags.broken
joblib.externals.loky.process_executor.TerminatedWorkerError: A worker process managed by the executor was unexpectedly terminated. This could be caused by a segmentation fault while calling the function or by an excessive memory usage causing the Operating System to kill the worker.

The exit codes of the workers are {SIGBUS(-7)}
  0%|          | 0/5 [01:55<?, ?it/s]
Traceback (most recent call last):
  File "ft_official.py", line 118, in <module>
    main()
  File "ft_official.py", line 100, in main
    model.train_vispel()
  File "/home/users/apopescu/van-khoa/Vis-Priva-Expos/privacy/vispel/vispel/vispel.py", line 54, in train_vispel
    trained_clusteror, trained_regressor, feature_selector = trainer(self.situation, self.X_train, self.X_community,\
  File "/home/users/apopescu/van-khoa/Vis-Priva-Expos/privacy/vispel/vispel/trainer.py", line 64, in trainer
    trained_regressor = train_regressor(regressor, X_train_rd, gt_train_expos, cfg)
  File "/home/users/apopescu/van-khoa/Vis-Priva-Expos/privacy/lib/regressor/regression.py", line 22, in train_regressor
    model.fit(x_train, y_train)
  File "/home/users/apopescu/anaconda3/envs/detectron2/lib/python3.8/site-packages/sklearn/utils/validation.py", line 73, in inner_f
    return f(**kwargs)
  File "/home/users/apopescu/anaconda3/envs/detectron2/lib/python3.8/site-packages/sklearn/model_selection/_search.py", line 736, in fit
    self._run_search(evaluate_candidates)
  File "/home/users/apopescu/anaconda3/envs/detectron2/lib/python3.8/site-packages/sklearn/model_selection/_search.py", line 1188, in _run_search
    evaluate_candidates(ParameterGrid(self.param_grid))
  File "/home/users/apopescu/anaconda3/envs/detectron2/lib/python3.8/site-packages/sklearn/model_selection/_search.py", line 708, in evaluate_candidates
    out = parallel(delayed(_fit_and_score)(clone(base_estimator),
  File "/home/users/apopescu/anaconda3/envs/detectron2/lib/python3.8/site-packages/joblib/parallel.py", line 1042, in __call__
    self.retrieve()
  File "/home/users/apopescu/anaconda3/envs/detectron2/lib/python3.8/site-packages/joblib/parallel.py", line 921, in retrieve
    self._output.extend(job.get(timeout=self.timeout))
  File "/home/users/apopescu/anaconda3/envs/detectron2/lib/python3.8/site-packages/joblib/_parallel_backends.py", line 542, in wrap_future_result
    return future.result(timeout=timeout)
  File "/home/users/apopescu/anaconda3/envs/detectron2/lib/python3.8/concurrent/futures/_base.py", line 439, in result
    return self.__get_result()
  File "/home/users/apopescu/anaconda3/envs/detectron2/lib/python3.8/concurrent/futures/_base.py", line 388, in __get_result
    raise self._exception
  File "/home/users/apopescu/anaconda3/envs/detectron2/lib/python3.8/site-packages/joblib/externals/loky/_base.py", line 625, in _invoke_callbacks
    callback(self)
  File "/home/users/apopescu/anaconda3/envs/detectron2/lib/python3.8/site-packages/joblib/parallel.py", line 347, in __call__
    self.parallel.dispatch_next()
  File "/home/users/apopescu/anaconda3/envs/detectron2/lib/python3.8/site-packages/joblib/parallel.py", line 780, in dispatch_next
    if not self.dispatch_one_batch(self._original_iterator):
  File "/home/users/apopescu/anaconda3/envs/detectron2/lib/python3.8/site-packages/joblib/parallel.py", line 847, in dispatch_one_batch
    self._dispatch(tasks)
  File "/home/users/apopescu/anaconda3/envs/detectron2/lib/python3.8/site-packages/joblib/parallel.py", line 765, in _dispatch
    job = self._backend.apply_async(batch, callback=cb)
  File "/home/users/apopescu/anaconda3/envs/detectron2/lib/python3.8/site-packages/joblib/_parallel_backends.py", line 531, in apply_async
    future = self._workers.submit(SafeFunction(func))
  File "/home/users/apopescu/anaconda3/envs/detectron2/lib/python3.8/site-packages/joblib/externals/loky/reusable_executor.py", line 177, in submit
    return super(_ReusablePoolExecutor, self).submit(
  File "/home/users/apopescu/anaconda3/envs/detectron2/lib/python3.8/site-packages/joblib/externals/loky/process_executor.py", line 1102, in submit
    raise self._flags.broken
joblib.externals.loky.process_executor.TerminatedWorkerError: A worker process managed by the executor was unexpectedly terminated. This could be caused by a segmentation fault while calling the function or by an excessive memory usage causing the Operating System to kill the worker.

The exit codes of the workers are {SIGBUS(-7)}
